Workbook
Name L_TAGS: tb_pcm_ativos[tag]
Name L_PESSOAS: tb_pcm_pessoas[nome_pessoa]
Name L_SETORES: tb_pcm_setores[nome_setor]
Name L_FAMILIAS: tb_pcm_familias[nome_familia]

Sheet Leia-me
D1: LEIA-ME · GUIA RÁPIDO | F1: Modelos, guias e novidades
D2: PCM-MAN-002 · Criticidade, MFMEA e plano de manutenção | F2: pcmdireto.me
D3: Leia em 1 minuto, preencha os campos brancos e comece a usar. | F3: Dúvidas e sugestões pelo site
B5: COMO USAR ESTE MODELO
B6: 1 Identifique | D6: 2 Cadastre | E6: 3 Preencha | F6: 4 Imprima e revise
B7: Preencha Elaborado e Aprovado logo abaixo. Vai para o cabeçalho de todas as abas. | D7: Na aba Cadastros, lance TAGs, pessoas e setores uma vez. Eles viram as listas ▼. | E7: Use as abas na ordem do passo a passo. Comece por Criticidade. | F7: Cada aba sai em uma folha A4. Mudou o modelo? Registre na aba Revisões.
B9: 1 IDENTIFICAÇÃO DO DOCUMENTO · vai para o cabeçalho de todas as abas
B10: Título do documento | D10: Criticidade, MFMEA e plano de manutenção | F10: Já vem pronto. Ajuste se quiser.
B11: Objetivo | D11: Classificar os equipamentos, analisar as falhas e transformar a análise em plano e cronograma
B12: Código do documento | D12: PCM-MAN-002
B13: Elaborado por | F13: ✎ preencha
B14: Aprovado por | F14: ✎ preencha
B15: Revisão atual | D15: =IF(COUNTA(tb_pcm_revisoes_modelo[revisao])=0,"-",INDEX(tb_pcm_revisoes_modelo[revisao],COUNTA(tb_pcm_revisoes_modelo[revisao]))) | F15: automático: aba Revisões
B16: Data da revisão | D16: =IF(COUNTA(tb_pcm_revisoes_modelo[revisao])=0,"",IF(INDEX(tb_pcm_revisoes_modelo[data_revisao],COUNTA(tb_pcm_revisoes_modelo[revisao]))="","",RIGHT("0"&DAY(INDEX(tb_pcm_revisoes_modelo[data_revisao],COUNTA(tb_pcm_revisoes_modelo[revisao]))),2)&"/"&CHOOSE(MONTH(INDEX(tb_pcm_revisoes_modelo[data_revisao],COUNTA(tb_pcm_revisoes_modelo[revisao]))),"Jan","Fev","Mar","Abr","Mai","Jun","Jul","Ago","Set","Out","Nov","Dez")&"/"&YEAR(INDEX(tb_pcm_revisoes_modelo[data_revisao],COUNTA(tb_pcm_revisoes_modelo[revisao]))))) | F16: automático: aba Revisões
B18: 2 PASSO A PASSO · clique no nome da aba para abrir
B19: 1 | C19: Cadastros | D19: Cadastre uma vez TAG, equipamento, família e setor, as pessoas, as famílias de equipamento, os setores. Eles aparecem nas setas ▼ das outras abas.
B20: 2 | C20: Criticidade | D20: Para cada TAG, dê nota de 1 a 5 em segurança, qualidade e produção e na frequência de falha (critérios no quadro 6, ao lado da tabela). A classe A, B ou C sai da matriz.
B21: 3 | C21: MFMEA | D21: Comece pelas TAGs classe A. Para cada componente: modo de falha, efeito, causa e controle atual. Dê S, O e D de 1 a 10 (quadro 6, ao lado da tabela); o NPR sai sozinho. Defina a tarefa, o tipo e a frequência.
B22: 4 | C22: Plano | D22: As tarefas da MFMEA entram sozinhas. Complete duração, se exige parada e a data da 1ª execução. Escolha a Periodicidade (Diária, Semanal, Quinzenal, Mensal, Bimestral, Trimestral, Semestral ou Anual): se A cada (dias) estiver vazio, ele é preenchido (Diária 1, Semanal 7, Quinzenal 14, Mensal 30, Bimestral 60, Trimestral 90, Semestral 180, Anual 365). Abaixo, inclua o que não vem da MFMEA: lubrificação, rotinas do fabricante, inspeções legais.
B23: 5 | C23: Cronograma | D23: Não se digita. Escolha o ano na seta: o ● marca a semana do mês de cada atividade (1ª execução + frequência) e a última linha soma as horas.
B25: 3 REGRAS RÁPIDAS
B26: ▼ Lista | D26: Clique na célula e escolha na seta. Valor fora da lista é recusado.
B27: Célula branca | D27: Campo para digitar.
B28: Célula cinza | D28: Cálculo automático. Não digite: a fórmula preenche sozinha.
B29: Datas e números | D29: Datas em dd/mm/aaaa; decimais com vírgula. Vazio = sem informação; zero é valor real.
B30: Impressão | D30: Cada aba já está ajustada para uma folha A4. Use Arquivo > Imprimir sem mudar a escala.
D32: SOBRE O PCM DIRETO | F32: pcmdireto.me
D33: Modelos de manutenção prontos para usar, do planejamento ao controle: criticidade, plano, ordem de serviço, indicadores e auditorias. Todos no mesmo padrão, para a equipe aprender uma vez e usar em todos.

Sheet Criticidade
E1: Criticidade dos ativos | J1: ="Rev. "&'Leia-me'!$D$15&" · "&'Leia-me'!$D$16
E2: Objetivo: Classificar cada ativo em A, B ou C pela matriz consequência × frequência de falha | J2: ="Elaborado: "&'Leia-me'!$D$13&" · Aprovado: "&'Leia-me'!$D$14
A3: Local ou área ▼ | E3: Equipe da análise | M3: Ativos por classe | T3: Ativos avaliados
M4: =IF(COUNTIF(J8:J27,"?*")=0,"","A: "&COUNTIF(J8:J27,"A")&" · B: "&COUNTIF(J8:J27,"B")&" · C: "&COUNTIF(J8:J27,"C")) | T4: =COUNTIF(J8:J27,"?*")&" de 20"
A6: 1 Ativo | E6: 2 Consequência (1 a 5) | I6: 3 Probabilidade e classe | M6: 4 Matriz: consequência × frequência | T6: 5 Estratégia por classe
A7: Nº | B7: TAG ▼ | C7: Equipamento | D7: Família de equipamento | E7: S Segurança | F7: Q Qualidade | G7: P Produção | H7: Maior nota | I7: Frequência de falha | J7: Classe | K7: Estratégia sugerida | M7: Consequência ↓ Frequência → | N7: 1 Rara | O7: 2 Baixa | P7: 3 Média | Q7: 4 Alta | R7: 5 Muito alta | T7: Clique na célula de nota para ver a dica. A classe sai da matriz e vai para a MFMEA.
A8: 1 | C8: =IF(B8="","",IFERROR(INDEX(tb_pcm_ativos[descricao_ativo],MATCH(B8,tb_pcm_ativos[tag],0)),"fora do cadastro")) | D8: =IF(B8="","",IFERROR(INDEX(tb_pcm_ativos[familia],MATCH(B8,tb_pcm_ativos[tag],0))&"","")) | H8: =IF(COUNT(E8:G8)=0,"",MAX(E8:G8)) | J8: =IF(OR(H8="",I8=""),"",IF(E8=5,"A",MID(CHOOSE(H8,"CCCBB","CCBBA","CBBAA","BBAAA","BAAAA"),I8,1))) | K8: =IF(J8="","",IF(J8="A","Preditiva + preventiva",IF(J8="B","Preventiva por tempo ou uso","Corretiva planejada"))) | M8: 5 Muito alta | N8: =COUNTIFS($H$8:$H$27,5,$I$8:$I$27,1) | O8: =COUNTIFS($H$8:$H$27,5,$I$8:$I$27,2) | P8: =COUNTIFS($H$8:$H$27,5,$I$8:$I$27,3) | Q8: =COUNTIFS($H$8:$H$27,5,$I$8:$I$27,4) | R8: =COUNTIFS($H$8:$H$27,5,$I$8:$I$27,5) | T8: A | U8: ="Preditiva + preventiva · "&COUNTIF(J8:J27,"A")&" ativo(s)"&CHAR(10)&"Inspeção por condição e preventiva; peças críticas em estoque; análise de causa em toda falha."
A9: 2 | C9: =IF(B9="","",IFERROR(INDEX(tb_pcm_ativos[descricao_ativo],MATCH(B9,tb_pcm_ativos[tag],0)),"fora do cadastro")) | D9: =IF(B9="","",IFERROR(INDEX(tb_pcm_ativos[familia],MATCH(B9,tb_pcm_ativos[tag],0))&"","")) | H9: =IF(COUNT(E9:G9)=0,"",MAX(E9:G9)) | J9: =IF(OR(H9="",I9=""),"",IF(E9=5,"A",MID(CHOOSE(H9,"CCCBB","CCBBA","CBBAA","BBAAA","BAAAA"),I9,1))) | K9: =IF(J9="","",IF(J9="A","Preditiva + preventiva",IF(J9="B","Preventiva por tempo ou uso","Corretiva planejada"))) | M9: 4 Alta | N9: =COUNTIFS($H$8:$H$27,4,$I$8:$I$27,1) | O9: =COUNTIFS($H$8:$H$27,4,$I$8:$I$27,2) | P9: =COUNTIFS($H$8:$H$27,4,$I$8:$I$27,3) | Q9: =COUNTIFS($H$8:$H$27,4,$I$8:$I$27,4) | R9: =COUNTIFS($H$8:$H$27,4,$I$8:$I$27,5)
A10: 3 | C10: =IF(B10="","",IFERROR(INDEX(tb_pcm_ativos[descricao_ativo],MATCH(B10,tb_pcm_ativos[tag],0)),"fora do cadastro")) | D10: =IF(B10="","",IFERROR(INDEX(tb_pcm_ativos[familia],MATCH(B10,tb_pcm_ativos[tag],0))&"","")) | H10: =IF(COUNT(E10:G10)=0,"",MAX(E10:G10)) | J10: =IF(OR(H10="",I10=""),"",IF(E10=5,"A",MID(CHOOSE(H10,"CCCBB","CCBBA","CBBAA","BBAAA","BAAAA"),I10,1))) | K10: =IF(J10="","",IF(J10="A","Preditiva + preventiva",IF(J10="B","Preventiva por tempo ou uso","Corretiva planejada"))) | M10: 3 Média | N10: =COUNTIFS($H$8:$H$27,3,$I$8:$I$27,1) | O10: =COUNTIFS($H$8:$H$27,3,$I$8:$I$27,2) | P10: =COUNTIFS($H$8:$H$27,3,$I$8:$I$27,3) | Q10: =COUNTIFS($H$8:$H$27,3,$I$8:$I$27,4) | R10: =COUNTIFS($H$8:$H$27,3,$I$8:$I$27,5) | T10: B | U10: ="Preventiva por tempo ou uso · "&COUNTIF(J8:J27,"B")&" ativo(s)"&CHAR(10)&"Peças conforme o prazo de entrega; revisar o plano depois de cada falha."
A11: 4 | C11: =IF(B11="","",IFERROR(INDEX(tb_pcm_ativos[descricao_ativo],MATCH(B11,tb_pcm_ativos[tag],0)),"fora do cadastro")) | D11: =IF(B11="","",IFERROR(INDEX(tb_pcm_ativos[familia],MATCH(B11,tb_pcm_ativos[tag],0))&"","")) | H11: =IF(COUNT(E11:G11)=0,"",MAX(E11:G11)) | J11: =IF(OR(H11="",I11=""),"",IF(E11=5,"A",MID(CHOOSE(H11,"CCCBB","CCBBA","CBBAA","BBAAA","BAAAA"),I11,1))) | K11: =IF(J11="","",IF(J11="A","Preditiva + preventiva",IF(J11="B","Preventiva por tempo ou uso","Corretiva planejada"))) | M11: 2 Baixa | N11: =COUNTIFS($H$8:$H$27,2,$I$8:$I$27,1) | O11: =COUNTIFS($H$8:$H$27,2,$I$8:$I$27,2) | P11: =COUNTIFS($H$8:$H$27,2,$I$8:$I$27,3) | Q11: =COUNTIFS($H$8:$H$27,2,$I$8:$I$27,4) | R11: =COUNTIFS($H$8:$H$27,2,$I$8:$I$27,5)
A12: 5 | C12: =IF(B12="","",IFERROR(INDEX(tb_pcm_ativos[descricao_ativo],MATCH(B12,tb_pcm_ativos[tag],0)),"fora do cadastro")) | D12: =IF(B12="","",IFERROR(INDEX(tb_pcm_ativos[familia],MATCH(B12,tb_pcm_ativos[tag],0))&"","")) | H12: =IF(COUNT(E12:G12)=0,"",MAX(E12:G12)) | J12: =IF(OR(H12="",I12=""),"",IF(E12=5,"A",MID(CHOOSE(H12,"CCCBB","CCBBA","CBBAA","BBAAA","BAAAA"),I12,1))) | K12: =IF(J12="","",IF(J12="A","Preditiva + preventiva",IF(J12="B","Preventiva por tempo ou uso","Corretiva planejada"))) | M12: 1 Muito baixa | N12: =COUNTIFS($H$8:$H$27,1,$I$8:$I$27,1) | O12: =COUNTIFS($H$8:$H$27,1,$I$8:$I$27,2) | P12: =COUNTIFS($H$8:$H$27,1,$I$8:$I$27,3) | Q12: =COUNTIFS($H$8:$H$27,1,$I$8:$I$27,4) | R12: =COUNTIFS($H$8:$H$27,1,$I$8:$I$27,5) | T12: C | U12: ="Corretiva planejada · "&COUNTIF(J8:J27,"C")&" ativo(s)"&CHAR(10)&"Ou operar até falhar, quando for seguro; sem estoque dedicado de peças."
A13: 6 | C13: =IF(B13="","",IFERROR(INDEX(tb_pcm_ativos[descricao_ativo],MATCH(B13,tb_pcm_ativos[tag],0)),"fora do cadastro")) | D13: =IF(B13="","",IFERROR(INDEX(tb_pcm_ativos[familia],MATCH(B13,tb_pcm_ativos[tag],0))&"","")) | H13: =IF(COUNT(E13:G13)=0,"",MAX(E13:G13)) | J13: =IF(OR(H13="",I13=""),"",IF(E13=5,"A",MID(CHOOSE(H13,"CCCBB","CCBBA","CBBAA","BBAAA","BAAAA"),I13,1))) | K13: =IF(J13="","",IF(J13="A","Preditiva + preventiva",IF(J13="B","Preventiva por tempo ou uso","Corretiva planejada"))) | M13: Consequência = maior nota entre S, Q e P. Nota 5 em segurança vira classe A em qualquer quadrado.
A14: 7 | C14: =IF(B14="","",IFERROR(INDEX(tb_pcm_ativos[descricao_ativo],MATCH(B14,tb_pcm_ativos[tag],0)),"fora do cadastro")) | D14: =IF(B14="","",IFERROR(INDEX(tb_pcm_ativos[familia],MATCH(B14,tb_pcm_ativos[tag],0))&"","")) | H14: =IF(COUNT(E14:G14)=0,"",MAX(E14:G14)) | J14: =IF(OR(H14="",I14=""),"",IF(E14=5,"A",MID(CHOOSE(H14,"CCCBB","CCBBA","CBBAA","BBAAA","BAAAA"),I14,1))) | K14: =IF(J14="","",IF(J14="A","Preditiva + preventiva",IF(J14="B","Preventiva por tempo ou uso","Corretiva planejada"))) | M14: 6 Notas: escolha a descrição mais próxima do pior caso crível
A15: 8 | C15: =IF(B15="","",IFERROR(INDEX(tb_pcm_ativos[descricao_ativo],MATCH(B15,tb_pcm_ativos[tag],0)),"fora do cadastro")) | D15: =IF(B15="","",IFERROR(INDEX(tb_pcm_ativos[familia],MATCH(B15,tb_pcm_ativos[tag],0))&"","")) | H15: =IF(COUNT(E15:G15)=0,"",MAX(E15:G15)) | J15: =IF(OR(H15="",I15=""),"",IF(E15=5,"A",MID(CHOOSE(H15,"CCCBB","CCBBA","CBBAA","BBAAA","BAAAA"),I15,1))) | K15: =IF(J15="","",IF(J15="A","Preditiva + preventiva",IF(J15="B","Preventiva por tempo ou uso","Corretiva planejada"))) | M15: Nota | N15: S Segurança e ambiente | Q15: Q Qualidade | T15: P Produção e reserva | W15: Frequência de falha
A16: 9 | C16: =IF(B16="","",IFERROR(INDEX(tb_pcm_ativos[descricao_ativo],MATCH(B16,tb_pcm_ativos[tag],0)),"fora do cadastro")) | D16: =IF(B16="","",IFERROR(INDEX(tb_pcm_ativos[familia],MATCH(B16,tb_pcm_ativos[tag],0))&"","")) | H16: =IF(COUNT(E16:G16)=0,"",MAX(E16:G16)) | J16: =IF(OR(H16="",I16=""),"",IF(E16=5,"A",MID(CHOOSE(H16,"CCCBB","CCBBA","CBBAA","BBAAA","BAAAA"),I16,1))) | K16: =IF(J16="","",IF(J16="A","Preditiva + preventiva",IF(J16="B","Preventiva por tempo ou uso","Corretiva planejada"))) | M16: 5 Muito alto | N16: Lesão grave ou morte, ou dano ambiental grande | Q16: Defeito chega ao cliente ou afeta item de segurança ou legal | T16: A planta para ou uma entrega é perdida | W16: Toda semana ou mais
A17: 10 | C17: =IF(B17="","",IFERROR(INDEX(tb_pcm_ativos[descricao_ativo],MATCH(B17,tb_pcm_ativos[tag],0)),"fora do cadastro")) | D17: =IF(B17="","",IFERROR(INDEX(tb_pcm_ativos[familia],MATCH(B17,tb_pcm_ativos[tag],0))&"","")) | H17: =IF(COUNT(E17:G17)=0,"",MAX(E17:G17)) | J17: =IF(OR(H17="",I17=""),"",IF(E17=5,"A",MID(CHOOSE(H17,"CCCBB","CCBBA","CBBAA","BBAAA","BAAAA"),I17,1))) | K17: =IF(J17="","",IF(J17="A","Preditiva + preventiva",IF(J17="B","Preventiva por tempo ou uso","Corretiva planejada")))
A18: 11 | C18: =IF(B18="","",IFERROR(INDEX(tb_pcm_ativos[descricao_ativo],MATCH(B18,tb_pcm_ativos[tag],0)),"fora do cadastro")) | D18: =IF(B18="","",IFERROR(INDEX(tb_pcm_ativos[familia],MATCH(B18,tb_pcm_ativos[tag],0))&"","")) | H18: =IF(COUNT(E18:G18)=0,"",MAX(E18:G18)) | J18: =IF(OR(H18="",I18=""),"",IF(E18=5,"A",MID(CHOOSE(H18,"CCCBB","CCBBA","CBBAA","BBAAA","BAAAA"),I18,1))) | K18: =IF(J18="","",IF(J18="A","Preditiva + preventiva",IF(J18="B","Preventiva por tempo ou uso","Corretiva planejada"))) | M18: 4 Alto | N18: Lesão com afastamento ou vazamento que sai da planta | Q18: Defeito pode escapar para etapas seguintes ou o cliente | T18: A linha ou área para, sem reserva | W18: Cerca de uma vez por mês
A19: 12 | C19: =IF(B19="","",IFERROR(INDEX(tb_pcm_ativos[descricao_ativo],MATCH(B19,tb_pcm_ativos[tag],0)),"fora do cadastro")) | D19: =IF(B19="","",IFERROR(INDEX(tb_pcm_ativos[familia],MATCH(B19,tb_pcm_ativos[tag],0))&"","")) | H19: =IF(COUNT(E19:G19)=0,"",MAX(E19:G19)) | J19: =IF(OR(H19="",I19=""),"",IF(E19=5,"A",MID(CHOOSE(H19,"CCCBB","CCBBA","CBBAA","BBAAA","BAAAA"),I19,1))) | K19: =IF(J19="","",IF(J19="A","Preditiva + preventiva",IF(J19="B","Preventiva por tempo ou uso","Corretiva planejada")))
A20: 13 | C20: =IF(B20="","",IFERROR(INDEX(tb_pcm_ativos[descricao_ativo],MATCH(B20,tb_pcm_ativos[tag],0)),"fora do cadastro")) | D20: =IF(B20="","",IFERROR(INDEX(tb_pcm_ativos[familia],MATCH(B20,tb_pcm_ativos[tag],0))&"","")) | H20: =IF(COUNT(E20:G20)=0,"",MAX(E20:G20)) | J20: =IF(OR(H20="",I20=""),"",IF(E20=5,"A",MID(CHOOSE(H20,"CCCBB","CCBBA","CBBAA","BBAAA","BAAAA"),I20,1))) | K20: =IF(J20="","",IF(J20="A","Preditiva + preventiva",IF(J20="B","Preventiva por tempo ou uso","Corretiva planejada"))) | M20: 3 Médio | N20: Lesão com atendimento médico ou vazamento reportável | Q20: Perda ou retrabalho de um lote | T20: A linha desacelera ou o contorno custa tempo | W20: A cada 3 a 6 meses
A21: 14 | C21: =IF(B21="","",IFERROR(INDEX(tb_pcm_ativos[descricao_ativo],MATCH(B21,tb_pcm_ativos[tag],0)),"fora do cadastro")) | D21: =IF(B21="","",IFERROR(INDEX(tb_pcm_ativos[familia],MATCH(B21,tb_pcm_ativos[tag],0))&"","")) | H21: =IF(COUNT(E21:G21)=0,"",MAX(E21:G21)) | J21: =IF(OR(H21="",I21=""),"",IF(E21=5,"A",MID(CHOOSE(H21,"CCCBB","CCBBA","CBBAA","BBAAA","BAAAA"),I21,1))) | K21: =IF(J21="","",IF(J21="A","Preditiva + preventiva",IF(J21="B","Preventiva por tempo ou uso","Corretiva planejada")))
A22: 15 | C22: =IF(B22="","",IFERROR(INDEX(tb_pcm_ativos[descricao_ativo],MATCH(B22,tb_pcm_ativos[tag],0)),"fora do cadastro")) | D22: =IF(B22="","",IFERROR(INDEX(tb_pcm_ativos[familia],MATCH(B22,tb_pcm_ativos[tag],0))&"","")) | H22: =IF(COUNT(E22:G22)=0,"",MAX(E22:G22)) | J22: =IF(OR(H22="",I22=""),"",IF(E22=5,"A",MID(CHOOSE(H22,"CCCBB","CCBBA","CBBAA","BBAAA","BAAAA"),I22,1))) | K22: =IF(J22="","",IF(J22="A","Preditiva + preventiva",IF(J22="B","Preventiva por tempo ou uso","Corretiva planejada"))) | M22: 2 Baixo | N22: Primeiros socorros ou pequeno vazamento contido | Q22: Defeito pego na máquina, pouca perda | T22: Há reserva; pequena queda de ritmo | W22: Cerca de uma vez por ano
A23: 16 | C23: =IF(B23="","",IFERROR(INDEX(tb_pcm_ativos[descricao_ativo],MATCH(B23,tb_pcm_ativos[tag],0)),"fora do cadastro")) | D23: =IF(B23="","",IFERROR(INDEX(tb_pcm_ativos[familia],MATCH(B23,tb_pcm_ativos[tag],0))&"","")) | H23: =IF(COUNT(E23:G23)=0,"",MAX(E23:G23)) | J23: =IF(OR(H23="",I23=""),"",IF(E23=5,"A",MID(CHOOSE(H23,"CCCBB","CCBBA","CBBAA","BBAAA","BAAAA"),I23,1))) | K23: =IF(J23="","",IF(J23="A","Preditiva + preventiva",IF(J23="B","Preventiva por tempo ou uso","Corretiva planejada")))
A24: 17 | C24: =IF(B24="","",IFERROR(INDEX(tb_pcm_ativos[descricao_ativo],MATCH(B24,tb_pcm_ativos[tag],0)),"fora do cadastro")) | D24: =IF(B24="","",IFERROR(INDEX(tb_pcm_ativos[familia],MATCH(B24,tb_pcm_ativos[tag],0))&"","")) | H24: =IF(COUNT(E24:G24)=0,"",MAX(E24:G24)) | J24: =IF(OR(H24="",I24=""),"",IF(E24=5,"A",MID(CHOOSE(H24,"CCCBB","CCBBA","CBBAA","BBAAA","BAAAA"),I24,1))) | K24: =IF(J24="","",IF(J24="A","Preditiva + preventiva",IF(J24="B","Preventiva por tempo ou uso","Corretiva planejada"))) | M24: 1 Muito baixo | N24: Sem lesão ou vazamento crível | Q24: Sem efeito no produto | T24: Máquina reserva ou capacidade sobrando: sem perda | W24: Menos de uma vez por ano
A25: 18 | C25: =IF(B25="","",IFERROR(INDEX(tb_pcm_ativos[descricao_ativo],MATCH(B25,tb_pcm_ativos[tag],0)),"fora do cadastro")) | D25: =IF(B25="","",IFERROR(INDEX(tb_pcm_ativos[familia],MATCH(B25,tb_pcm_ativos[tag],0))&"","")) | H25: =IF(COUNT(E25:G25)=0,"",MAX(E25:G25)) | J25: =IF(OR(H25="",I25=""),"",IF(E25=5,"A",MID(CHOOSE(H25,"CCCBB","CCBBA","CBBAA","BBAAA","BAAAA"),I25,1))) | K25: =IF(J25="","",IF(J25="A","Preditiva + preventiva",IF(J25="B","Preventiva por tempo ou uso","Corretiva planejada")))
A26: 19 | C26: =IF(B26="","",IFERROR(INDEX(tb_pcm_ativos[descricao_ativo],MATCH(B26,tb_pcm_ativos[tag],0)),"fora do cadastro")) | D26: =IF(B26="","",IFERROR(INDEX(tb_pcm_ativos[familia],MATCH(B26,tb_pcm_ativos[tag],0))&"","")) | H26: =IF(COUNT(E26:G26)=0,"",MAX(E26:G26)) | J26: =IF(OR(H26="",I26=""),"",IF(E26=5,"A",MID(CHOOSE(H26,"CCCBB","CCBBA","CBBAA","BBAAA","BAAAA"),I26,1))) | K26: =IF(J26="","",IF(J26="A","Preditiva + preventiva",IF(J26="B","Preventiva por tempo ou uso","Corretiva planejada"))) | M26: A produção conta a reserva: com máquina reserva a nota é menor. Revise as notas quando o processo mudar.
A27: 20 | C27: =IF(B27="","",IFERROR(INDEX(tb_pcm_ativos[descricao_ativo],MATCH(B27,tb_pcm_ativos[tag],0)),"fora do cadastro")) | D27: =IF(B27="","",IFERROR(INDEX(tb_pcm_ativos[familia],MATCH(B27,tb_pcm_ativos[tag],0))&"","")) | H27: =IF(COUNT(E27:G27)=0,"",MAX(E27:G27)) | J27: =IF(OR(H27="",I27=""),"",IF(E27=5,"A",MID(CHOOSE(H27,"CCCBB","CCBBA","CBBAA","BBAAA","BAAAA"),I27,1))) | K27: =IF(J27="","",IF(J27="A","Preditiva + preventiva",IF(J27="B","Preventiva por tempo ou uso","Corretiva planejada")))
A28: ● A: crítico ● B: importante ● C: baixo impacto Cinza = calculado; notas no quadro 6.

Sheet MFMEA
F1: MFMEA: análise dos modos de falha das máquinas | N1: ="Rev. "&'Leia-me'!$D$15&" · "&'Leia-me'!$D$16
F2: Objetivo: Analisar os modos de falha das máquinas, avaliar o risco pelo NPR e definir a tarefa de cada um | N2: ="Elaborado: "&'Leia-me'!$D$13&" · Aprovado: "&'Leia-me'!$D$14
A3: Área ou sistema analisado ▼ | F3: Equipe da análise | S3: Modos com risco alto | Z3: Maior NPR
S4: =IF(COUNT(M8:M22)=0,"",COUNTIF(M8:M22,">=200")+COUNTIFS(J8:J22,">=9",M8:M22,"<200")) | Z4: =IF(COUNT(M8:M22)=0,"",MAX(M8:M22))
A6: 1 Falha: o que pode falhar e por quê | J6: 2 Risco | N6: 3 Tarefa de manutenção → vai para o Plano | S6: 4 Classificação do risco pelo NPR | Z6: 5 Como usar
A7: Nº | B7: TAG ▼ | C7: Equipamento | D7: Classe | E7: Componente e função | F7: Modo de falha | G7: Efeito da falha | H7: Causa | I7: Controle atual | J7: Severidade (S) | K7: Ocorrência (O) | L7: Detecção (D) | M7: NPR | N7: Tarefa recomendada | O7: Tipo de tarefa ▼ | P7: A cada (dias) | Q7: Responsável ▼ | S7: NPR = S × O × D, de 1 a 1000. Quanto maior, mais urgente a ação. | Z7: Comece pelas TAGs classe A. Clique nas células S, O e D para ver a dica.
A8: 1 | C8: =IF(B8="","",IFERROR(INDEX(tb_pcm_ativos[descricao_ativo],MATCH(B8,tb_pcm_ativos[tag],0)),"fora do cadastro")) | D8: =IF(B8="","",IFERROR(INDEX(Criticidade!$J$8:$J$27,MATCH(B8,Criticidade!$B$8:$B$27,0)),"?")) | M8: =IF(COUNT(J8:L8)<3,"",J8*K8*L8) | S8: Alto | T8: ="NPR 200 ou mais, ou S 9–10 · "&IF(COUNT(M8:M22)=0,0,COUNTIF(M8:M22,">=200")+COUNTIFS(J8:J22,">=9",M8:M22,"<200"))&" modo(s)"&CHAR(10)&"Agir já: ação corretiva com prazo curto e responsável." | Z8: 1 | AA8: Identifique: escolha a TAG e descreva componente, modo de falha, efeito, causa e controle atual.
A9: 2 | C9: =IF(B9="","",IFERROR(INDEX(tb_pcm_ativos[descricao_ativo],MATCH(B9,tb_pcm_ativos[tag],0)),"fora do cadastro")) | D9: =IF(B9="","",IFERROR(INDEX(Criticidade!$J$8:$J$27,MATCH(B9,Criticidade!$B$8:$B$27,0)),"?")) | M9: =IF(COUNT(J9:L9)<3,"",J9*K9*L9) | S9: Médio | T9: ="NPR de 100 a 199 e S até 8 · "&IF(COUNT(M8:M22)=0,0,COUNTIFS(M8:M22,">=100",M8:M22,"<200",J8:J22,"<9"))&" modo(s)"&CHAR(10)&"Planejar a ação e acompanhar a execução." | Z9: 2 | AA9: Avalie: dê S, O e D de 1 a 10 (quadro 6). O NPR e a cor saem sozinhos.
A10: 3 | C10: =IF(B10="","",IFERROR(INDEX(tb_pcm_ativos[descricao_ativo],MATCH(B10,tb_pcm_ativos[tag],0)),"fora do cadastro")) | D10: =IF(B10="","",IFERROR(INDEX(Criticidade!$J$8:$J$27,MATCH(B10,Criticidade!$B$8:$B$27,0)),"?")) | M10: =IF(COUNT(J10:L10)<3,"",J10*K10*L10) | S10: Baixo | T10: ="NPR abaixo de 100 e S até 8 · "&IF(COUNT(M8:M22)=0,0,COUNTIFS(M8:M22,"<100",J8:J22,"<9"))&" modo(s)"&CHAR(10)&"Manter os controles e revisar na próxima análise." | Z10: 3 | AA10: Planeje: defina tarefa, tipo e frequência; elas descem sozinhas para o Plano.
A11: 4 | C11: =IF(B11="","",IFERROR(INDEX(tb_pcm_ativos[descricao_ativo],MATCH(B11,tb_pcm_ativos[tag],0)),"fora do cadastro")) | D11: =IF(B11="","",IFERROR(INDEX(Criticidade!$J$8:$J$27,MATCH(B11,Criticidade!$B$8:$B$27,0)),"?")) | M11: =IF(COUNT(J11:L11)<3,"",J11*K11*L11) | S11: 6 Notas de 1 a 10: escolha a descrição mais próxima do pior caso crível
A12: 5 | C12: =IF(B12="","",IFERROR(INDEX(tb_pcm_ativos[descricao_ativo],MATCH(B12,tb_pcm_ativos[tag],0)),"fora do cadastro")) | D12: =IF(B12="","",IFERROR(INDEX(Criticidade!$J$8:$J$27,MATCH(B12,Criticidade!$B$8:$B$27,0)),"?")) | M12: =IF(COUNT(J12:L12)<3,"",J12*K12*L12) | S12: Nota | T12: S Severidade do efeito | X12: O Ocorrência da causa | AB12: D Detecção pelo controle (nota alta = difícil detectar)
A13: 6 | C13: =IF(B13="","",IFERROR(INDEX(tb_pcm_ativos[descricao_ativo],MATCH(B13,tb_pcm_ativos[tag],0)),"fora do cadastro")) | D13: =IF(B13="","",IFERROR(INDEX(Criticidade!$J$8:$J$27,MATCH(B13,Criticidade!$B$8:$B$27,0)),"?")) | M13: =IF(COUNT(J13:L13)<3,"",J13*K13*L13) | S13: 10 | T13: Perigoso sem aviso: Afeta a segurança das pessoas ou o meio ambiente, sem aviso prévio | X13: Quase certa: Mais de uma vez por dia | AB13: Quase impossível: Não há controle que detecte a falha
A14: 7 | C14: =IF(B14="","",IFERROR(INDEX(tb_pcm_ativos[descricao_ativo],MATCH(B14,tb_pcm_ativos[tag],0)),"fora do cadastro")) | D14: =IF(B14="","",IFERROR(INDEX(Criticidade!$J$8:$J$27,MATCH(B14,Criticidade!$B$8:$B$27,0)),"?")) | M14: =IF(COUNT(J14:L14)<3,"",J14*K14*L14) | S14: 9 | T14: Perigoso com aviso: Afeta a segurança das pessoas ou o meio ambiente, com aviso prévio | X14: Muito alta: A cada 3 ou 4 dias | AB14: Muito remota: Só se percebe depois que a falha acontece
A15: 8 | C15: =IF(B15="","",IFERROR(INDEX(tb_pcm_ativos[descricao_ativo],MATCH(B15,tb_pcm_ativos[tag],0)),"fora do cadastro")) | D15: =IF(B15="","",IFERROR(INDEX(Criticidade!$J$8:$J$27,MATCH(B15,Criticidade!$B$8:$B$27,0)),"?")) | M15: =IF(COUNT(J15:L15)<3,"",J15*K15*L15) | S15: 8 | T15: Muito alto: Para a linha por mais de 8 h ou perde todo o lote | X15: Alta: Uma vez por semana | AB15: Remota: Inspeção visual eventual, sem rotina
A16: 9 | C16: =IF(B16="","",IFERROR(INDEX(tb_pcm_ativos[descricao_ativo],MATCH(B16,tb_pcm_ativos[tag],0)),"fora do cadastro")) | D16: =IF(B16="","",IFERROR(INDEX(Criticidade!$J$8:$J$27,MATCH(B16,Criticidade!$B$8:$B$27,0)),"?")) | M16: =IF(COUNT(J16:L16)<3,"",J16*K16*L16) | S16: 7 | T16: Alto: Para a linha de 2 a 8 h ou gera refugo grande | X16: Alta: Uma vez por mês | AB16: Muito baixa: Inspeção sem padrão nem frequência definida
A17: 10 | C17: =IF(B17="","",IFERROR(INDEX(tb_pcm_ativos[descricao_ativo],MATCH(B17,tb_pcm_ativos[tag],0)),"fora do cadastro")) | D17: =IF(B17="","",IFERROR(INDEX(Criticidade!$J$8:$J$27,MATCH(B17,Criticidade!$B$8:$B$27,0)),"?")) | M17: =IF(COUNT(J17:L17)<3,"",J17*K17*L17) | S17: 6 | T17: Moderado: Para a linha por até 2 h ou gera retrabalho | X17: Moderada: A cada 3 meses | AB17: Baixa: Inspeção sensitiva com frequência longa
A18: 11 | C18: =IF(B18="","",IFERROR(INDEX(tb_pcm_ativos[descricao_ativo],MATCH(B18,tb_pcm_ativos[tag],0)),"fora do cadastro")) | D18: =IF(B18="","",IFERROR(INDEX(Criticidade!$J$8:$J$27,MATCH(B18,Criticidade!$B$8:$B$27,0)),"?")) | M18: =IF(COUNT(J18:L18)<3,"",J18*K18*L18) | S18: 5 | T18: Baixo: Reduz a velocidade ou o desempenho do equipamento | X18: Moderada: A cada 6 meses | AB18: Moderada: Rota de inspeção sensitiva em dia
A19: 12 | C19: =IF(B19="","",IFERROR(INDEX(tb_pcm_ativos[descricao_ativo],MATCH(B19,tb_pcm_ativos[tag],0)),"fora do cadastro")) | D19: =IF(B19="","",IFERROR(INDEX(Criticidade!$J$8:$J$27,MATCH(B19,Criticidade!$B$8:$B$27,0)),"?")) | M19: =IF(COUNT(J19:L19)<3,"",J19*K19*L19) | S19: 4 | T19: Muito baixo: Exige ajuste; a operação percebe, a produção segue | X19: Moderada: Uma vez por ano | AB19: Moderadamente alta: Medição periódica (folga, temperatura, nível)
A20: 13 | C20: =IF(B20="","",IFERROR(INDEX(tb_pcm_ativos[descricao_ativo],MATCH(B20,tb_pcm_ativos[tag],0)),"fora do cadastro")) | D20: =IF(B20="","",IFERROR(INDEX(Criticidade!$J$8:$J$27,MATCH(B20,Criticidade!$B$8:$B$27,0)),"?")) | M20: =IF(COUNT(J20:L20)<3,"",J20*K20*L20) | S20: 3 | T20: Menor: Pequeno incômodo, sem perda de produção | X20: Baixa: A cada 1 a 3 anos | AB20: Alta: Preditiva em dia (vibração, termografia, óleo)
A21: 14 | C21: =IF(B21="","",IFERROR(INDEX(tb_pcm_ativos[descricao_ativo],MATCH(B21,tb_pcm_ativos[tag],0)),"fora do cadastro")) | D21: =IF(B21="","",IFERROR(INDEX(Criticidade!$J$8:$J$27,MATCH(B21,Criticidade!$B$8:$B$27,0)),"?")) | M21: =IF(COUNT(J21:L21)<3,"",J21*K21*L21) | S21: 2 | T21: Muito menor: Quase imperceptível | X21: Muito baixa: A cada 3 a 6 anos | AB21: Muito alta: Monitoramento contínuo com alarme
A22: 15 | C22: =IF(B22="","",IFERROR(INDEX(tb_pcm_ativos[descricao_ativo],MATCH(B22,tb_pcm_ativos[tag],0)),"fora do cadastro")) | D22: =IF(B22="","",IFERROR(INDEX(Criticidade!$J$8:$J$27,MATCH(B22,Criticidade!$B$8:$B$27,0)),"?")) | M22: =IF(COUNT(J22:L22)<3,"",J22*K22*L22) | S22: 1 | T22: Nenhum: Sem efeito | X22: Remota: Mais de 6 anos ou nunca ocorreu | AB22: Quase certa: Intertravamento ou sensor que para a máquina antes do dano
A23: NPR = S × O × D (notas no quadro 6). NPR: ● Alto: 200 ou mais, ou S 9–10 ● Médio: 100 a 199 ● Baixo: menos de 100 | S23: Dê as notas pelo pior caso crível; revise quando o processo ou os controles mudarem.

Sheet Plano
E1: Plano | J1: ="Rev. "&'Leia-me'!$D$15&" · "&'Leia-me'!$D$16
E2: Objetivo: Atividades da MFMEA e outras: duração, parada, 1ª execução e próxima data | J2: ="Elaborado: "&'Leia-me'!$D$13&" · Aprovado: "&'Leia-me'!$D$14
A3: 1 Atividade: as linhas cinza vêm sozinhas da MFMEA; as de baixo, digite | J3: 2 Programação (preencha)
A4: Nº | B4: TAG ▼ | C4: Equipamento | D4: Componente | E4: Atividade | F4: Tipo ▼ | G4: A cada (dias) | H4: Periodicidade ▼ | I4: Responsável ▼ | J4: Duração (h) | K4: Exige parada ▼ | L4: 1ª execução | M4: Próxima
A5: 1 | B5: =IF(MFMEA!$N$8="","",IF(MFMEA!B8="","",MFMEA!B8)) | C5: =IF(B5="","",IFERROR(INDEX(tb_pcm_ativos[descricao_ativo],MATCH(B5,tb_pcm_ativos[tag],0)),"fora do cadastro")) | D5: =IF(MFMEA!$N$8="","",IF(MFMEA!E8="","",MFMEA!E8)) | E5: =IF(MFMEA!$N$8="","",IF(MFMEA!N8="","",MFMEA!N8)) | F5: =IF(MFMEA!$N$8="","",IF(MFMEA!O8="","",MFMEA!O8)) | G5: =IF(MFMEA!$N$8="","",IF(MFMEA!$P$8="",IF(H5="","",IF(H5="Diária",1,IF(H5="Semanal",7,IF(H5="Quinzenal",14,IF(H5="Mensal",30,IF(H5="Bimestral",60,IF(H5="Trimestral",90,IF(H5="Semestral",180,IF(H5="Anual",365,""))))))))),MFMEA!$P$8)) | I5: =IF(MFMEA!$N$8="","",IF(MFMEA!Q8="","",MFMEA!Q8)) | M5: =IF(OR(L5="",G5="",G5=0),"",IF(L5>=TODAY(),L5,L5+G5*ROUNDUP((TODAY()-L5)/G5,0)))
A6: 2 | B6: =IF(MFMEA!$N$9="","",IF(MFMEA!B9="","",MFMEA!B9)) | C6: =IF(B6="","",IFERROR(INDEX(tb_pcm_ativos[descricao_ativo],MATCH(B6,tb_pcm_ativos[tag],0)),"fora do cadastro")) | D6: =IF(MFMEA!$N$9="","",IF(MFMEA!E9="","",MFMEA!E9)) | E6: =IF(MFMEA!$N$9="","",IF(MFMEA!N9="","",MFMEA!N9)) | F6: =IF(MFMEA!$N$9="","",IF(MFMEA!O9="","",MFMEA!O9)) | G6: =IF(MFMEA!$N$9="","",IF(MFMEA!$P$9="",IF(H6="","",IF(H6="Diária",1,IF(H6="Semanal",7,IF(H6="Quinzenal",14,IF(H6="Mensal",30,IF(H6="Bimestral",60,IF(H6="Trimestral",90,IF(H6="Semestral",180,IF(H6="Anual",365,""))))))))),MFMEA!$P$9)) | I6: =IF(MFMEA!$N$9="","",IF(MFMEA!Q9="","",MFMEA!Q9)) | M6: =IF(OR(L6="",G6="",G6=0),"",IF(L6>=TODAY(),L6,L6+G6*ROUNDUP((TODAY()-L6)/G6,0)))
A7: 3 | B7: =IF(MFMEA!$N$10="","",IF(MFMEA!B10="","",MFMEA!B10)) | C7: =IF(B7="","",IFERROR(INDEX(tb_pcm_ativos[descricao_ativo],MATCH(B7,tb_pcm_ativos[tag],0)),"fora do cadastro")) | D7: =IF(MFMEA!$N$10="","",IF(MFMEA!E10="","",MFMEA!E10)) | E7: =IF(MFMEA!$N$10="","",IF(MFMEA!N10="","",MFMEA!N10)) | F7: =IF(MFMEA!$N$10="","",IF(MFMEA!O10="","",MFMEA!O10)) | G7: =IF(MFMEA!$N$10="","",IF(MFMEA!$P$10="",IF(H7="","",IF(H7="Diária",1,IF(H7="Semanal",7,IF(H7="Quinzenal",14,IF(H7="Mensal",30,IF(H7="Bimestral",60,IF(H7="Trimestral",90,IF(H7="Semestral",180,IF(H7="Anual",365,""))))))))),MFMEA!$P$10)) | I7: =IF(MFMEA!$N$10="","",IF(MFMEA!Q10="","",MFMEA!Q10)) | M7: =IF(OR(L7="",G7="",G7=0),"",IF(L7>=TODAY(),L7,L7+G7*ROUNDUP((TODAY()-L7)/G7,0)))
A8: 4 | B8: =IF(MFMEA!$N$11="","",IF(MFMEA!B11="","",MFMEA!B11)) | C8: =IF(B8="","",IFERROR(INDEX(tb_pcm_ativos[descricao_ativo],MATCH(B8,tb_pcm_ativos[tag],0)),"fora do cadastro")) | D8: =IF(MFMEA!$N$11="","",IF(MFMEA!E11="","",MFMEA!E11)) | E8: =IF(MFMEA!$N$11="","",IF(MFMEA!N11="","",MFMEA!N11)) | F8: =IF(MFMEA!$N$11="","",IF(MFMEA!O11="","",MFMEA!O11)) | G8: =IF(MFMEA!$N$11="","",IF(MFMEA!$P$11="",IF(H8="","",IF(H8="Diária",1,IF(H8="Semanal",7,IF(H8="Quinzenal",14,IF(H8="Mensal",30,IF(H8="Bimestral",60,IF(H8="Trimestral",90,IF(H8="Semestral",180,IF(H8="Anual",365,""))))))))),MFMEA!$P$11)) | I8: =IF(MFMEA!$N$11="","",IF(MFMEA!Q11="","",MFMEA!Q11)) | M8: =IF(OR(L8="",G8="",G8=0),"",IF(L8>=TODAY(),L8,L8+G8*ROUNDUP((TODAY()-L8)/G8,0)))
A9: 5 | B9: =IF(MFMEA!$N$12="","",IF(MFMEA!B12="","",MFMEA!B12)) | C9: =IF(B9="","",IFERROR(INDEX(tb_pcm_ativos[descricao_ativo],MATCH(B9,tb_pcm_ativos[tag],0)),"fora do cadastro")) | D9: =IF(MFMEA!$N$12="","",IF(MFMEA!E12="","",MFMEA!E12)) | E9: =IF(MFMEA!$N$12="","",IF(MFMEA!N12="","",MFMEA!N12)) | F9: =IF(MFMEA!$N$12="","",IF(MFMEA!O12="","",MFMEA!O12)) | G9: =IF(MFMEA!$N$12="","",IF(MFMEA!$P$12="",IF(H9="","",IF(H9="Diária",1,IF(H9="Semanal",7,IF(H9="Quinzenal",14,IF(H9="Mensal",30,IF(H9="Bimestral",60,IF(H9="Trimestral",90,IF(H9="Semestral",180,IF(H9="Anual",365,""))))))))),MFMEA!$P$12)) | I9: =IF(MFMEA!$N$12="","",IF(MFMEA!Q12="","",MFMEA!Q12)) | M9: =IF(OR(L9="",G9="",G9=0),"",IF(L9>=TODAY(),L9,L9+G9*ROUNDUP((TODAY()-L9)/G9,0)))
A10: 6 | B10: =IF(MFMEA!$N$13="","",IF(MFMEA!B13="","",MFMEA!B13)) | C10: =IF(B10="","",IFERROR(INDEX(tb_pcm_ativos[descricao_ativo],MATCH(B10,tb_pcm_ativos[tag],0)),"fora do cadastro")) | D10: =IF(MFMEA!$N$13="","",IF(MFMEA!E13="","",MFMEA!E13)) | E10: =IF(MFMEA!$N$13="","",IF(MFMEA!N13="","",MFMEA!N13)) | F10: =IF(MFMEA!$N$13="","",IF(MFMEA!O13="","",MFMEA!O13)) | G10: =IF(MFMEA!$N$13="","",IF(MFMEA!$P$13="",IF(H10="","",IF(H10="Diária",1,IF(H10="Semanal",7,IF(H10="Quinzenal",14,IF(H10="Mensal",30,IF(H10="Bimestral",60,IF(H10="Trimestral",90,IF(H10="Semestral",180,IF(H10="Anual",365,""))))))))),MFMEA!$P$13)) | I10: =IF(MFMEA!$N$13="","",IF(MFMEA!Q13="","",MFMEA!Q13)) | M10: =IF(OR(L10="",G10="",G10=0),"",IF(L10>=TODAY(),L10,L10+G10*ROUNDUP((TODAY()-L10)/G10,0)))
A11: 7 | B11: =IF(MFMEA!$N$14="","",IF(MFMEA!B14="","",MFMEA!B14)) | C11: =IF(B11="","",IFERROR(INDEX(tb_pcm_ativos[descricao_ativo],MATCH(B11,tb_pcm_ativos[tag],0)),"fora do cadastro")) | D11: =IF(MFMEA!$N$14="","",IF(MFMEA!E14="","",MFMEA!E14)) | E11: =IF(MFMEA!$N$14="","",IF(MFMEA!N14="","",MFMEA!N14)) | F11: =IF(MFMEA!$N$14="","",IF(MFMEA!O14="","",MFMEA!O14)) | G11: =IF(MFMEA!$N$14="","",IF(MFMEA!$P$14="",IF(H11="","",IF(H11="Diária",1,IF(H11="Semanal",7,IF(H11="Quinzenal",14,IF(H11="Mensal",30,IF(H11="Bimestral",60,IF(H11="Trimestral",90,IF(H11="Semestral",180,IF(H11="Anual",365,""))))))))),MFMEA!$P$14)) | I11: =IF(MFMEA!$N$14="","",IF(MFMEA!Q14="","",MFMEA!Q14)) | M11: =IF(OR(L11="",G11="",G11=0),"",IF(L11>=TODAY(),L11,L11+G11*ROUNDUP((TODAY()-L11)/G11,0)))
A12: 8 | B12: =IF(MFMEA!$N$15="","",IF(MFMEA!B15="","",MFMEA!B15)) | C12: =IF(B12="","",IFERROR(INDEX(tb_pcm_ativos[descricao_ativo],MATCH(B12,tb_pcm_ativos[tag],0)),"fora do cadastro")) | D12: =IF(MFMEA!$N$15="","",IF(MFMEA!E15="","",MFMEA!E15)) | E12: =IF(MFMEA!$N$15="","",IF(MFMEA!N15="","",MFMEA!N15)) | F12: =IF(MFMEA!$N$15="","",IF(MFMEA!O15="","",MFMEA!O15)) | G12: =IF(MFMEA!$N$15="","",IF(MFMEA!$P$15="",IF(H12="","",IF(H12="Diária",1,IF(H12="Semanal",7,IF(H12="Quinzenal",14,IF(H12="Mensal",30,IF(H12="Bimestral",60,IF(H12="Trimestral",90,IF(H12="Semestral",180,IF(H12="Anual",365,""))))))))),MFMEA!$P$15)) | I12: =IF(MFMEA!$N$15="","",IF(MFMEA!Q15="","",MFMEA!Q15)) | M12: =IF(OR(L12="",G12="",G12=0),"",IF(L12>=TODAY(),L12,L12+G12*ROUNDUP((TODAY()-L12)/G12,0)))
A13: 9 | B13: =IF(MFMEA!$N$16="","",IF(MFMEA!B16="","",MFMEA!B16)) | C13: =IF(B13="","",IFERROR(INDEX(tb_pcm_ativos[descricao_ativo],MATCH(B13,tb_pcm_ativos[tag],0)),"fora do cadastro")) | D13: =IF(MFMEA!$N$16="","",IF(MFMEA!E16="","",MFMEA!E16)) | E13: =IF(MFMEA!$N$16="","",IF(MFMEA!N16="","",MFMEA!N16)) | F13: =IF(MFMEA!$N$16="","",IF(MFMEA!O16="","",MFMEA!O16)) | G13: =IF(MFMEA!$N$16="","",IF(MFMEA!$P$16="",IF(H13="","",IF(H13="Diária",1,IF(H13="Semanal",7,IF(H13="Quinzenal",14,IF(H13="Mensal",30,IF(H13="Bimestral",60,IF(H13="Trimestral",90,IF(H13="Semestral",180,IF(H13="Anual",365,""))))))))),MFMEA!$P$16)) | I13: =IF(MFMEA!$N$16="","",IF(MFMEA!Q16="","",MFMEA!Q16)) | M13: =IF(OR(L13="",G13="",G13=0),"",IF(L13>=TODAY(),L13,L13+G13*ROUNDUP((TODAY()-L13)/G13,0)))
A14: 10 | B14: =IF(MFMEA!$N$17="","",IF(MFMEA!B17="","",MFMEA!B17)) | C14: =IF(B14="","",IFERROR(INDEX(tb_pcm_ativos[descricao_ativo],MATCH(B14,tb_pcm_ativos[tag],0)),"fora do cadastro")) | D14: =IF(MFMEA!$N$17="","",IF(MFMEA!E17="","",MFMEA!E17)) | E14: =IF(MFMEA!$N$17="","",IF(MFMEA!N17="","",MFMEA!N17)) | F14: =IF(MFMEA!$N$17="","",IF(MFMEA!O17="","",MFMEA!O17)) | G14: =IF(MFMEA!$N$17="","",IF(MFMEA!$P$17="",IF(H14="","",IF(H14="Diária",1,IF(H14="Semanal",7,IF(H14="Quinzenal",14,IF(H14="Mensal",30,IF(H14="Bimestral",60,IF(H14="Trimestral",90,IF(H14="Semestral",180,IF(H14="Anual",365,""))))))))),MFMEA!$P$17)) | I14: =IF(MFMEA!$N$17="","",IF(MFMEA!Q17="","",MFMEA!Q17)) | M14: =IF(OR(L14="",G14="",G14=0),"",IF(L14>=TODAY(),L14,L14+G14*ROUNDUP((TODAY()-L14)/G14,0)))
A15: 11 | B15: =IF(MFMEA!$N$18="","",IF(MFMEA!B18="","",MFMEA!B18)) | C15: =IF(B15="","",IFERROR(INDEX(tb_pcm_ativos[descricao_ativo],MATCH(B15,tb_pcm_ativos[tag],0)),"fora do cadastro")) | D15: =IF(MFMEA!$N$18="","",IF(MFMEA!E18="","",MFMEA!E18)) | E15: =IF(MFMEA!$N$18="","",IF(MFMEA!N18="","",MFMEA!N18)) | F15: =IF(MFMEA!$N$18="","",IF(MFMEA!O18="","",MFMEA!O18)) | G15: =IF(MFMEA!$N$18="","",IF(MFMEA!$P$18="",IF(H15="","",IF(H15="Diária",1,IF(H15="Semanal",7,IF(H15="Quinzenal",14,IF(H15="Mensal",30,IF(H15="Bimestral",60,IF(H15="Trimestral",90,IF(H15="Semestral",180,IF(H15="Anual",365,""))))))))),MFMEA!$P$18)) | I15: =IF(MFMEA!$N$18="","",IF(MFMEA!Q18="","",MFMEA!Q18)) | M15: =IF(OR(L15="",G15="",G15=0),"",IF(L15>=TODAY(),L15,L15+G15*ROUNDUP((TODAY()-L15)/G15,0)))
A16: 12 | B16: =IF(MFMEA!$N$19="","",IF(MFMEA!B19="","",MFMEA!B19)) | C16: =IF(B16="","",IFERROR(INDEX(tb_pcm_ativos[descricao_ativo],MATCH(B16,tb_pcm_ativos[tag],0)),"fora do cadastro")) | D16: =IF(MFMEA!$N$19="","",IF(MFMEA!E19="","",MFMEA!E19)) | E16: =IF(MFMEA!$N$19="","",IF(MFMEA!N19="","",MFMEA!N19)) | F16: =IF(MFMEA!$N$19="","",IF(MFMEA!O19="","",MFMEA!O19)) | G16: =IF(MFMEA!$N$19="","",IF(MFMEA!$P$19="",IF(H16="","",IF(H16="Diária",1,IF(H16="Semanal",7,IF(H16="Quinzenal",14,IF(H16="Mensal",30,IF(H16="Bimestral",60,IF(H16="Trimestral",90,IF(H16="Semestral",180,IF(H16="Anual",365,""))))))))),MFMEA!$P$19)) | I16: =IF(MFMEA!$N$19="","",IF(MFMEA!Q19="","",MFMEA!Q19)) | M16: =IF(OR(L16="",G16="",G16=0),"",IF(L16>=TODAY(),L16,L16+G16*ROUNDUP((TODAY()-L16)/G16,0)))
A17: 13 | B17: =IF(MFMEA!$N$20="","",IF(MFMEA!B20="","",MFMEA!B20)) | C17: =IF(B17="","",IFERROR(INDEX(tb_pcm_ativos[descricao_ativo],MATCH(B17,tb_pcm_ativos[tag],0)),"fora do cadastro")) | D17: =IF(MFMEA!$N$20="","",IF(MFMEA!E20="","",MFMEA!E20)) | E17: =IF(MFMEA!$N$20="","",IF(MFMEA!N20="","",MFMEA!N20)) | F17: =IF(MFMEA!$N$20="","",IF(MFMEA!O20="","",MFMEA!O20)) | G17: =IF(MFMEA!$N$20="","",IF(MFMEA!$P$20="",IF(H17="","",IF(H17="Diária",1,IF(H17="Semanal",7,IF(H17="Quinzenal",14,IF(H17="Mensal",30,IF(H17="Bimestral",60,IF(H17="Trimestral",90,IF(H17="Semestral",180,IF(H17="Anual",365,""))))))))),MFMEA!$P$20)) | I17: =IF(MFMEA!$N$20="","",IF(MFMEA!Q20="","",MFMEA!Q20)) | M17: =IF(OR(L17="",G17="",G17=0),"",IF(L17>=TODAY(),L17,L17+G17*ROUNDUP((TODAY()-L17)/G17,0)))
A18: 14 | B18: =IF(MFMEA!$N$21="","",IF(MFMEA!B21="","",MFMEA!B21)) | C18: =IF(B18="","",IFERROR(INDEX(tb_pcm_ativos[descricao_ativo],MATCH(B18,tb_pcm_ativos[tag],0)),"fora do cadastro")) | D18: =IF(MFMEA!$N$21="","",IF(MFMEA!E21="","",MFMEA!E21)) | E18: =IF(MFMEA!$N$21="","",IF(MFMEA!N21="","",MFMEA!N21)) | F18: =IF(MFMEA!$N$21="","",IF(MFMEA!O21="","",MFMEA!O21)) | G18: =IF(MFMEA!$N$21="","",IF(MFMEA!$P$21="",IF(H18="","",IF(H18="Diária",1,IF(H18="Semanal",7,IF(H18="Quinzenal",14,IF(H18="Mensal",30,IF(H18="Bimestral",60,IF(H18="Trimestral",90,IF(H18="Semestral",180,IF(H18="Anual",365,""))))))))),MFMEA!$P$21)) | I18: =IF(MFMEA!$N$21="","",IF(MFMEA!Q21="","",MFMEA!Q21)) | M18: =IF(OR(L18="",G18="",G18=0),"",IF(L18>=TODAY(),L18,L18+G18*ROUNDUP((TODAY()-L18)/G18,0)))
A19: 15 | B19: =IF(MFMEA!$N$22="","",IF(MFMEA!B22="","",MFMEA!B22)) | C19: =IF(B19="","",IFERROR(INDEX(tb_pcm_ativos[descricao_ativo],MATCH(B19,tb_pcm_ativos[tag],0)),"fora do cadastro")) | D19: =IF(MFMEA!$N$22="","",IF(MFMEA!E22="","",MFMEA!E22)) | E19: =IF(MFMEA!$N$22="","",IF(MFMEA!N22="","",MFMEA!N22)) | F19: =IF(MFMEA!$N$22="","",IF(MFMEA!O22="","",MFMEA!O22)) | G19: =IF(MFMEA!$N$22="","",IF(MFMEA!$P$22="",IF(H19="","",IF(H19="Diária",1,IF(H19="Semanal",7,IF(H19="Quinzenal",14,IF(H19="Mensal",30,IF(H19="Bimestral",60,IF(H19="Trimestral",90,IF(H19="Semestral",180,IF(H19="Anual",365,""))))))))),MFMEA!$P$22)) | I19: =IF(MFMEA!$N$22="","",IF(MFMEA!Q22="","",MFMEA!Q22)) | M19: =IF(OR(L19="",G19="",G19=0),"",IF(L19>=TODAY(),L19,L19+G19*ROUNDUP((TODAY()-L19)/G19,0)))
A20: Outras atividades (fora da MFMEA): lubrificação, rotinas do fabricante, inspeções legais, calibrações
A21: 16 | C21: =IF(B21="","",IFERROR(INDEX(tb_pcm_ativos[descricao_ativo],MATCH(B21,tb_pcm_ativos[tag],0)),"fora do cadastro")) | G21: =IF(H21="","",IF(H21="Diária",1,IF(H21="Semanal",7,IF(H21="Quinzenal",14,IF(H21="Mensal",30,IF(H21="Bimestral",60,IF(H21="Trimestral",90,IF(H21="Semestral",180,IF(H21="Anual",365,""))))))))) | M21: =IF(OR(L21="",G21="",G21=0),"",IF(L21>=TODAY(),L21,L21+G21*ROUNDUP((TODAY()-L21)/G21,0)))
A22: 17 | C22: =IF(B22="","",IFERROR(INDEX(tb_pcm_ativos[descricao_ativo],MATCH(B22,tb_pcm_ativos[tag],0)),"fora do cadastro")) | G22: =IF(H22="","",IF(H22="Diária",1,IF(H22="Semanal",7,IF(H22="Quinzenal",14,IF(H22="Mensal",30,IF(H22="Bimestral",60,IF(H22="Trimestral",90,IF(H22="Semestral",180,IF(H22="Anual",365,""))))))))) | M22: =IF(OR(L22="",G22="",G22=0),"",IF(L22>=TODAY(),L22,L22+G22*ROUNDUP((TODAY()-L22)/G22,0)))
A23: 18 | C23: =IF(B23="","",IFERROR(INDEX(tb_pcm_ativos[descricao_ativo],MATCH(B23,tb_pcm_ativos[tag],0)),"fora do cadastro")) | G23: =IF(H23="","",IF(H23="Diária",1,IF(H23="Semanal",7,IF(H23="Quinzenal",14,IF(H23="Mensal",30,IF(H23="Bimestral",60,IF(H23="Trimestral",90,IF(H23="Semestral",180,IF(H23="Anual",365,""))))))))) | M23: =IF(OR(L23="",G23="",G23=0),"",IF(L23>=TODAY(),L23,L23+G23*ROUNDUP((TODAY()-L23)/G23,0)))
A24: 19 | C24: =IF(B24="","",IFERROR(INDEX(tb_pcm_ativos[descricao_ativo],MATCH(B24,tb_pcm_ativos[tag],0)),"fora do cadastro")) | G24: =IF(H24="","",IF(H24="Diária",1,IF(H24="Semanal",7,IF(H24="Quinzenal",14,IF(H24="Mensal",30,IF(H24="Bimestral",60,IF(H24="Trimestral",90,IF(H24="Semestral",180,IF(H24="Anual",365,""))))))))) | M24: =IF(OR(L24="",G24="",G24=0),"",IF(L24>=TODAY(),L24,L24+G24*ROUNDUP((TODAY()-L24)/G24,0)))
A25: 20 | C25: =IF(B25="","",IFERROR(INDEX(tb_pcm_ativos[descricao_ativo],MATCH(B25,tb_pcm_ativos[tag],0)),"fora do cadastro")) | G25: =IF(H25="","",IF(H25="Diária",1,IF(H25="Semanal",7,IF(H25="Quinzenal",14,IF(H25="Mensal",30,IF(H25="Bimestral",60,IF(H25="Trimestral",90,IF(H25="Semestral",180,IF(H25="Anual",365,""))))))))) | M25: =IF(OR(L25="",G25="",G25=0),"",IF(L25>=TODAY(),L25,L25+G25*ROUNDUP((TODAY()-L25)/G25,0)))
A26: 21 | C26: =IF(B26="","",IFERROR(INDEX(tb_pcm_ativos[descricao_ativo],MATCH(B26,tb_pcm_ativos[tag],0)),"fora do cadastro")) | G26: =IF(H26="","",IF(H26="Diária",1,IF(H26="Semanal",7,IF(H26="Quinzenal",14,IF(H26="Mensal",30,IF(H26="Bimestral",60,IF(H26="Trimestral",90,IF(H26="Semestral",180,IF(H26="Anual",365,""))))))))) | M26: =IF(OR(L26="",G26="",G26=0),"",IF(L26>=TODAY(),L26,L26+G26*ROUNDUP((TODAY()-L26)/G26,0)))
A27: 22 | C27: =IF(B27="","",IFERROR(INDEX(tb_pcm_ativos[descricao_ativo],MATCH(B27,tb_pcm_ativos[tag],0)),"fora do cadastro")) | G27: =IF(H27="","",IF(H27="Diária",1,IF(H27="Semanal",7,IF(H27="Quinzenal",14,IF(H27="Mensal",30,IF(H27="Bimestral",60,IF(H27="Trimestral",90,IF(H27="Semestral",180,IF(H27="Anual",365,""))))))))) | M27: =IF(OR(L27="",G27="",G27=0),"",IF(L27>=TODAY(),L27,L27+G27*ROUNDUP((TODAY()-L27)/G27,0)))
A28: 23 | C28: =IF(B28="","",IFERROR(INDEX(tb_pcm_ativos[descricao_ativo],MATCH(B28,tb_pcm_ativos[tag],0)),"fora do cadastro")) | G28: =IF(H28="","",IF(H28="Diária",1,IF(H28="Semanal",7,IF(H28="Quinzenal",14,IF(H28="Mensal",30,IF(H28="Bimestral",60,IF(H28="Trimestral",90,IF(H28="Semestral",180,IF(H28="Anual",365,""))))))))) | M28: =IF(OR(L28="",G28="",G28=0),"",IF(L28>=TODAY(),L28,L28+G28*ROUNDUP((TODAY()-L28)/G28,0)))
A29: 24 | C29: =IF(B29="","",IFERROR(INDEX(tb_pcm_ativos[descricao_ativo],MATCH(B29,tb_pcm_ativos[tag],0)),"fora do cadastro")) | G29: =IF(H29="","",IF(H29="Diária",1,IF(H29="Semanal",7,IF(H29="Quinzenal",14,IF(H29="Mensal",30,IF(H29="Bimestral",60,IF(H29="Trimestral",90,IF(H29="Semestral",180,IF(H29="Anual",365,""))))))))) | M29: =IF(OR(L29="",G29="",G29=0),"",IF(L29>=TODAY(),L29,L29+G29*ROUNDUP((TODAY()-L29)/G29,0)))
A30: 25 | C30: =IF(B30="","",IFERROR(INDEX(tb_pcm_ativos[descricao_ativo],MATCH(B30,tb_pcm_ativos[tag],0)),"fora do cadastro")) | G30: =IF(H30="","",IF(H30="Diária",1,IF(H30="Semanal",7,IF(H30="Quinzenal",14,IF(H30="Mensal",30,IF(H30="Bimestral",60,IF(H30="Trimestral",90,IF(H30="Semestral",180,IF(H30="Anual",365,""))))))))) | M30: =IF(OR(L30="",G30="",G30=0),"",IF(L30>=TODAY(),L30,L30+G30*ROUNDUP((TODAY()-L30)/G30,0)))
A31: Cinza = vem da MFMEA ou é calculado. ● Próxima execução nos próximos 7 dias ● Exige parada da máquina

Sheet Cronograma
E1: Cronograma | AY1: ="Rev. "&'Leia-me'!$D$15&" · "&'Leia-me'!$D$16
E2: Objetivo: Semanas de cada mês em que cada atividade do Plano deve ser feita | AY2: ="Elaborado: "&'Leia-me'!$D$13&" · Aprovado: "&'Leia-me'!$D$14
A3: Ano ▼ | D3: Semana de hoje | F3: Atividades na semana de hoje | AJ3: Horas planejadas no ano
D4: =IF(YEAR(TODAY())=IF(N($A$4)>0,N($A$4),IF(ISNUMBER(--$A$4),--$A$4,YEAR(TODAY()))),CHOOSE(MONTH(TODAY()),"Jan","Fev","Mar","Abr","Mai","Jun","Jul","Ago","Set","Out","Nov","Dez")&" · "&MIN(5,INT((DAY(TODAY())-1)/7)+1)&"ª semana","") | F4: =IF(D4="","",COUNTIF(INDEX($F$8:$BM$33,0,IF(YEAR(TODAY())=IF(N($A$4)>0,N($A$4),IF(ISNUMBER(--$A$4),--$A$4,YEAR(TODAY()))),(MONTH(TODAY())-1)*5+MIN(5,INT((DAY(TODAY())-1)/7)+1),"")),"●")&" atividade(s) com data nesta semana") | AJ4: =IF(SUM(F34:BM34)=0,"",SUM(F34:BM34))
F5: =IF(MONTH(DATE(IF(N($A$4)>0,N($A$4),IF(ISNUMBER(--$A$4),--$A$4,YEAR(TODAY()))),1,1))=1,DATE(IF(N($A$4)>0,N($A$4),IF(ISNUMBER(--$A$4),--$A$4,YEAR(TODAY()))),1,1),"") | G5: =IF(MONTH(DATE(IF(N($A$4)>0,N($A$4),IF(ISNUMBER(--$A$4),--$A$4,YEAR(TODAY()))),1,8))=1,DATE(IF(N($A$4)>0,N($A$4),IF(ISNUMBER(--$A$4),--$A$4,YEAR(TODAY()))),1,8),"") | H5: =IF(MONTH(DATE(IF(N($A$4)>0,N($A$4),IF(ISNUMBER(--$A$4),--$A$4,YEAR(TODAY()))),1,15))=1,DATE(IF(N($A$4)>0,N($A$4),IF(ISNUMBER(--$A$4),--$A$4,YEAR(TODAY()))),1,15),"") | I5: =IF(MONTH(DATE(IF(N($A$4)>0,N($A$4),IF(ISNUMBER(--$A$4),--$A$4,YEAR(TODAY()))),1,22))=1,DATE(IF(N($A$4)>0,N($A$4),IF(ISNUMBER(--$A$4),--$A$4,YEAR(TODAY()))),1,22),"") | J5: =IF(MONTH(DATE(IF(N($A$4)>0,N($A$4),IF(ISNUMBER(--$A$4),--$A$4,YEAR(TODAY()))),1,29))=1,DATE(IF(N($A$4)>0,N($A$4),IF(ISNUMBER(--$A$4),--$A$4,YEAR(TODAY()))),1,29),"") | K5: =IF(MONTH(DATE(IF(N($A$4)>0,N($A$4),IF(ISNUMBER(--$A$4),--$A$4,YEAR(TODAY()))),2,1))=2,DATE(IF(N($A$4)>0,N($A$4),IF(ISNUMBER(--$A$4),--$A$4,YEAR(TODAY()))),2,1),"") | L5: =IF(MONTH(DATE(IF(N($A$4)>0,N($A$4),IF(ISNUMBER(--$A$4),--$A$4,YEAR(TODAY()))),2,8))=2,DATE(IF(N($A$4)>0,N($A$4),IF(ISNUMBER(--$A$4),--$A$4,YEAR(TODAY()))),2,8),"") | M5: =IF(MONTH(DATE(IF(N($A$4)>0,N($A$4),IF(ISNUMBER(--$A$4),--$A$4,YEAR(TODAY()))),2,15))=2,DATE(IF(N($A$4)>0,N($A$4),IF(ISNUMBER(--$A$4),--$A$4,YEAR(TODAY()))),2,15),"") | N5: =IF(MONTH(DATE(IF(N($A$4)>0,N($A$4),IF(ISNUMBER(--$A$4),--$A$4,YEAR(TODAY()))),2,22))=2,DATE(IF(N($A$4)>0,N($A$4),IF(ISNUMBER(--$A$4),--$A$4,YEAR(TODAY()))),2,22),"") | O5: =IF(MONTH(DATE(IF(N($A$4)>0,N($A$4),IF(ISNUMBER(--$A$4),--$A$4,YEAR(TODAY()))),2,29))=2,DATE(IF(N($A$4)>0,N($A$4),IF(ISNUMBER(--$A$4),--$A$4,YEAR(TODAY()))),2,29),"") | P5: =IF(MONTH(DATE(IF(N($A$4)>0,N($A$4),IF(ISNUMBER(--$A$4),--$A$4,YEAR(TODAY()))),3,1))=3,DATE(IF(N($A$4)>0,N($A$4),IF(ISNUMBER(--$A$4),--$A$4,YEAR(TODAY()))),3,1),"") | Q5: =IF(MONTH(DATE(IF(N($A$4)>0,N($A$4),IF(ISNUMBER(--$A$4),--$A$4,YEAR(TODAY()))),3,8))=3,DATE(IF(N($A$4)>0,N($A$4),IF(ISNUMBER(--$A$4),--$A$4,YEAR(TODAY()))),3,8),"") | R5: =IF(MONTH(DATE(IF(N($A$4)>0,N($A$4),IF(ISNUMBER(--$A$4),--$A$4,YEAR(TODAY()))),3,15))=3,DATE(IF(N($A$4)>0,N($A$4),IF(ISNUMBER(--$A$4),--$A$4,YEAR(TODAY()))),3,15),"") | S5: =IF(MONTH(DATE(IF(N($A$4)>0,N($A$4),IF(ISNUMBER(--$A$4),--$A$4,YEAR(TODAY()))),3,22))=3,DATE(IF(N($A$4)>0,N($A$4),IF(ISNUMBER(--$A$4),--$A$4,YEAR(TODAY()))),3,22),"") | T5: =IF(MONTH(DATE(IF(N($A$4)>0,N($A$4),IF(ISNUMBER(--$A$4),--$A$4,YEAR(TODAY()))),3,29))=3,DATE(IF(N($A$4)>0,N($A$4),IF(ISNUMBER(--$A$4),--$A$4,YEAR(TODAY()))),3,29),"") | U5: =IF(MONTH(DATE(IF(N($A$4)>0,N($A$4),IF(ISNUMBER(--$A$4),--$A$4,YEAR(TODAY()))),4,1))=4,DATE(IF(N($A$4)>0,N($A$4),IF(ISNUMBER(--$A$4),--$A$4,YEAR(TODAY()))),4,1),"") | V5: =IF(MONTH(DATE(IF(N($A$4)>0,N($A$4),IF(ISNUMBER(--$A$4),--$A$4,YEAR(TODAY()))),4,8))=4,DATE(IF(N($A$4)>0,N($A$4),IF(ISNUMBER(--$A$4),--$A$4,YEAR(TODAY()))),4,8),"") | W5: =IF(MONTH(DATE(IF(N($A$4)>0,N($A$4),IF(ISNUMBER(--$A$4),--$A$4,YEAR(TODAY()))),4,15))=4,DATE(IF(N($A$4)>0,N($A$4),IF(ISNUMBER(--$A$4),--$A$4,YEAR(TODAY()))),4,15),"") | X5: =IF(MONTH(DATE(IF(N($A$4)>0,N($A$4),IF(ISNUMBER(--$A$4),--$A$4,YEAR(TODAY()))),4,22))=4,DATE(IF(N($A$4)>0,N($A$4),IF(ISNUMBER(--$A$4),--$A$4,YEAR(TODAY()))),4,22),"") | Y5: =IF(MONTH(DATE(IF(N($A$4)>0,N($A$4),IF(ISNUMBER(--$A$4),--$A$4,YEAR(TODAY()))),4,29))=4,DATE(IF(N($A$4)>0,N($A$4),IF(ISNUMBER(--$A$4),--$A$4,YEAR(TODAY()))),4,29),"") | Z5: =IF(MONTH(DATE(IF(N($A$4)>0,N($A$4),IF(ISNUMBER(--$A$4),--$A$4,YEAR(TODAY()))),5,1))=5,DATE(IF(N($A$4)>0,N($A$4),IF(ISNUMBER(--$A$4),--$A$4,YEAR(TODAY()))),5,1),"") | AA5: =IF(MONTH(DATE(IF(N($A$4)>0,N($A$4),IF(ISNUMBER(--$A$4),--$A$4,YEAR(TODAY()))),5,8))=5,DATE(IF(N($A$4)>0,N($A$4),IF(ISNUMBER(--$A$4),--$A$4,YEAR(TODAY()))),5,8),"") | AB5: =IF(MONTH(DATE(IF(N($A$4)>0,N($A$4),IF(ISNUMBER(--$A$4),--$A$4,YEAR(TODAY()))),5,15))=5,DATE(IF(N($A$4)>0,N($A$4),IF(ISNUMBER(--$A$4),--$A$4,YEAR(TODAY()))),5,15),"") | AC5: =IF(MONTH(DATE(IF(N($A$4)>0,N($A$4),IF(ISNUMBER(--$A$4),--$A$4,YEAR(TODAY()))),5,22))=5,DATE(IF(N($A$4)>0,N($A$4),IF(ISNUMBER(--$A$4),--$A$4,YEAR(TODAY()))),5,22),"") | AD5: =IF(MONTH(DATE(IF(N($A$4)>0,N($A$4),IF(ISNUMBER(--$A$4),--$A$4,YEAR(TODAY()))),5,29))=5,DATE(IF(N($A$4)>0,N($A$4),IF(ISNUMBER(--$A$4),--$A$4,YEAR(TODAY()))),5,29),"") | AE5: =IF(MONTH(DATE(IF(N($A$4)>0,N($A$4),IF(ISNUMBER(--$A$4),--$A$4,YEAR(TODAY()))),6,1))=6,DATE(IF(N($A$4)>0,N($A$4),IF(ISNUMBER(--$A$4),--$A$4,YEAR(TODAY()))),6,1),"") | AF5: =IF(MONTH(DATE(IF(N($A$4)>0,N($A$4),IF(ISNUMBER(--$A$4),--$A$4,YEAR(TODAY()))),6,8))=6,DATE(IF(N($A$4)>0,N($A$4),IF(ISNUMBER(--$A$4),--$A$4,YEAR(TODAY()))),6,8),"") | AG5: =IF(MONTH(DATE(IF(N($A$4)>0,N($A$4),IF(ISNUMBER(--$A$4),--$A$4,YEAR(TODAY()))),6,15))=6,DATE(IF(N($A$4)>0,N($A$4),IF(ISNUMBER(--$A$4),--$A$4,YEAR(TODAY()))),6,15),"") | AH5: =IF(MONTH(DATE(IF(N($A$4)>0,N($A$4),IF(ISNUMBER(--$A$4),--$A$4,YEAR(TODAY()))),6,22))=6,DATE(IF(N($A$4)>0,N($A$4),IF(ISNUMBER(--$A$4),--$A$4,YEAR(TODAY()))),6,22),"") | AI5: =IF(MONTH(DATE(IF(N($A$4)>0,N($A$4),IF(ISNUMBER(--$A$4),--$A$4,YEAR(TODAY()))),6,29))=6,DATE(IF(N($A$4)>0,N($A$4),IF(ISNUMBER(--$A$4),--$A$4,YEAR(TODAY()))),6,29),"") | AJ5: =IF(MONTH(DATE(IF(N($A$4)>0,N($A$4),IF(ISNUMBER(--$A$4),--$A$4,YEAR(TODAY()))),7,1))=7,DATE(IF(N($A$4)>0,N($A$4),IF(ISNUMBER(--$A$4),--$A$4,YEAR(TODAY()))),7,1),"") | AK5: =IF(MONTH(DATE(IF(N($A$4)>0,N($A$4),IF(ISNUMBER(--$A$4),--$A$4,YEAR(TODAY()))),7,8))=7,DATE(IF(N($A$4)>0,N($A$4),IF(ISNUMBER(--$A$4),--$A$4,YEAR(TODAY()))),7,8),"") | AL5: =IF(MONTH(DATE(IF(N($A$4)>0,N($A$4),IF(ISNUMBER(--$A$4),--$A$4,YEAR(TODAY()))),7,15))=7,DATE(IF(N($A$4)>0,N($A$4),IF(ISNUMBER(--$A$4),--$A$4,YEAR(TODAY()))),7,15),"") | AM5: =IF(MONTH(DATE(IF(N($A$4)>0,N($A$4),IF(ISNUMBER(--$A$4),--$A$4,YEAR(TODAY()))),7,22))=7,DATE(IF(N($A$4)>0,N($A$4),IF(ISNUMBER(--$A$4),--$A$4,YEAR(TODAY()))),7,22),"") | AN5: =IF(MONTH(DATE(IF(N($A$4)>0,N($A$4),IF(ISNUMBER(--$A$4),--$A$4,YEAR(TODAY()))),7,29))=7,DATE(IF(N($A$4)>0,N($A$4),IF(ISNUMBER(--$A$4),--$A$4,YEAR(TODAY()))),7,29),"") | AO5: =IF(MONTH(DATE(IF(N($A$4)>0,N($A$4),IF(ISNUMBER(--$A$4),--$A$4,YEAR(TODAY()))),8,1))=8,DATE(IF(N($A$4)>0,N($A$4),IF(ISNUMBER(--$A$4),--$A$4,YEAR(TODAY()))),8,1),"") | AP5: =IF(MONTH(DATE(IF(N($A$4)>0,N($A$4),IF(ISNUMBER(--$A$4),--$A$4,YEAR(TODAY()))),8,8))=8,DATE(IF(N($A$4)>0,N($A$4),IF(ISNUMBER(--$A$4),--$A$4,YEAR(TODAY()))),8,8),"") | AQ5: =IF(MONTH(DATE(IF(N($A$4)>0,N($A$4),IF(ISNUMBER(--$A$4),--$A$4,YEAR(TODAY()))),8,15))=8,DATE(IF(N($A$4)>0,N($A$4),IF(ISNUMBER(--$A$4),--$A$4,YEAR(TODAY()))),8,15),"") | AR5: =IF(MONTH(DATE(IF(N($A$4)>0,N($A$4),IF(ISNUMBER(--$A$4),--$A$4,YEAR(TODAY()))),8,22))=8,DATE(IF(N($A$4)>0,N($A$4),IF(ISNUMBER(--$A$4),--$A$4,YEAR(TODAY()))),8,22),"") | AS5: =IF(MONTH(DATE(IF(N($A$4)>0,N($A$4),IF(ISNUMBER(--$A$4),--$A$4,YEAR(TODAY()))),8,29))=8,DATE(IF(N($A$4)>0,N($A$4),IF(ISNUMBER(--$A$4),--$A$4,YEAR(TODAY()))),8,29),"") | AT5: =IF(MONTH(DATE(IF(N($A$4)>0,N($A$4),IF(ISNUMBER(--$A$4),--$A$4,YEAR(TODAY()))),9,1))=9,DATE(IF(N($A$4)>0,N($A$4),IF(ISNUMBER(--$A$4),--$A$4,YEAR(TODAY()))),9,1),"") | AU5: =IF(MONTH(DATE(IF(N($A$4)>0,N($A$4),IF(ISNUMBER(--$A$4),--$A$4,YEAR(TODAY()))),9,8))=9,DATE(IF(N($A$4)>0,N($A$4),IF(ISNUMBER(--$A$4),--$A$4,YEAR(TODAY()))),9,8),"") | AV5: =IF(MONTH(DATE(IF(N($A$4)>0,N($A$4),IF(ISNUMBER(--$A$4),--$A$4,YEAR(TODAY()))),9,15))=9,DATE(IF(N($A$4)>0,N($A$4),IF(ISNUMBER(--$A$4),--$A$4,YEAR(TODAY()))),9,15),"") | AW5: =IF(MONTH(DATE(IF(N($A$4)>0,N($A$4),IF(ISNUMBER(--$A$4),--$A$4,YEAR(TODAY()))),9,22))=9,DATE(IF(N($A$4)>0,N($A$4),IF(ISNUMBER(--$A$4),--$A$4,YEAR(TODAY()))),9,22),"") | AX5: =IF(MONTH(DATE(IF(N($A$4)>0,N($A$4),IF(ISNUMBER(--$A$4),--$A$4,YEAR(TODAY()))),9,29))=9,DATE(IF(N($A$4)>0,N($A$4),IF(ISNUMBER(--$A$4),--$A$4,YEAR(TODAY()))),9,29),"") | AY5: =IF(MONTH(DATE(IF(N($A$4)>0,N($A$4),IF(ISNUMBER(--$A$4),--$A$4,YEAR(TODAY()))),10,1))=10,DATE(IF(N($A$4)>0,N($A$4),IF(ISNUMBER(--$A$4),--$A$4,YEAR(TODAY()))),10,1),"") | AZ5: =IF(MONTH(DATE(IF(N($A$4)>0,N($A$4),IF(ISNUMBER(--$A$4),--$A$4,YEAR(TODAY()))),10,8))=10,DATE(IF(N($A$4)>0,N($A$4),IF(ISNUMBER(--$A$4),--$A$4,YEAR(TODAY()))),10,8),"") | BA5: =IF(MONTH(DATE(IF(N($A$4)>0,N($A$4),IF(ISNUMBER(--$A$4),--$A$4,YEAR(TODAY()))),10,15))=10,DATE(IF(N($A$4)>0,N($A$4),IF(ISNUMBER(--$A$4),--$A$4,YEAR(TODAY()))),10,15),"") | BB5: =IF(MONTH(DATE(IF(N($A$4)>0,N($A$4),IF(ISNUMBER(--$A$4),--$A$4,YEAR(TODAY()))),10,22))=10,DATE(IF(N($A$4)>0,N($A$4),IF(ISNUMBER(--$A$4),--$A$4,YEAR(TODAY()))),10,22),"") | BC5: =IF(MONTH(DATE(IF(N($A$4)>0,N($A$4),IF(ISNUMBER(--$A$4),--$A$4,YEAR(TODAY()))),10,29))=10,DATE(IF(N($A$4)>0,N($A$4),IF(ISNUMBER(--$A$4),--$A$4,YEAR(TODAY()))),10,29),"") | BD5: =IF(MONTH(DATE(IF(N($A$4)>0,N($A$4),IF(ISNUMBER(--$A$4),--$A$4,YEAR(TODAY()))),11,1))=11,DATE(IF(N($A$4)>0,N($A$4),IF(ISNUMBER(--$A$4),--$A$4,YEAR(TODAY()))),11,1),"") | BE5: =IF(MONTH(DATE(IF(N($A$4)>0,N($A$4),IF(ISNUMBER(--$A$4),--$A$4,YEAR(TODAY()))),11,8))=11,DATE(IF(N($A$4)>0,N($A$4),IF(ISNUMBER(--$A$4),--$A$4,YEAR(TODAY()))),11,8),"") | BF5: =IF(MONTH(DATE(IF(N($A$4)>0,N($A$4),IF(ISNUMBER(--$A$4),--$A$4,YEAR(TODAY()))),11,15))=11,DATE(IF(N($A$4)>0,N($A$4),IF(ISNUMBER(--$A$4),--$A$4,YEAR(TODAY()))),11,15),"") | BG5: =IF(MONTH(DATE(IF(N($A$4)>0,N($A$4),IF(ISNUMBER(--$A$4),--$A$4,YEAR(TODAY()))),11,22))=11,DATE(IF(N($A$4)>0,N($A$4),IF(ISNUMBER(--$A$4),--$A$4,YEAR(TODAY()))),11,22),"") | BH5: =IF(MONTH(DATE(IF(N($A$4)>0,N($A$4),IF(ISNUMBER(--$A$4),--$A$4,YEAR(TODAY()))),11,29))=11,DATE(IF(N($A$4)>0,N($A$4),IF(ISNUMBER(--$A$4),--$A$4,YEAR(TODAY()))),11,29),"") | BI5: =IF(MONTH(DATE(IF(N($A$4)>0,N($A$4),IF(ISNUMBER(--$A$4),--$A$4,YEAR(TODAY()))),12,1))=12,DATE(IF(N($A$4)>0,N($A$4),IF(ISNUMBER(--$A$4),--$A$4,YEAR(TODAY()))),12,1),"") | BJ5: =IF(MONTH(DATE(IF(N($A$4)>0,N($A$4),IF(ISNUMBER(--$A$4),--$A$4,YEAR(TODAY()))),12,8))=12,DATE(IF(N($A$4)>0,N($A$4),IF(ISNUMBER(--$A$4),--$A$4,YEAR(TODAY()))),12,8),"") | BK5: =IF(MONTH(DATE(IF(N($A$4)>0,N($A$4),IF(ISNUMBER(--$A$4),--$A$4,YEAR(TODAY()))),12,15))=12,DATE(IF(N($A$4)>0,N($A$4),IF(ISNUMBER(--$A$4),--$A$4,YEAR(TODAY()))),12,15),"") | BL5: =IF(MONTH(DATE(IF(N($A$4)>0,N($A$4),IF(ISNUMBER(--$A$4),--$A$4,YEAR(TODAY()))),12,22))=12,DATE(IF(N($A$4)>0,N($A$4),IF(ISNUMBER(--$A$4),--$A$4,YEAR(TODAY()))),12,22),"") | BM5: =IF(MONTH(DATE(IF(N($A$4)>0,N($A$4),IF(ISNUMBER(--$A$4),--$A$4,YEAR(TODAY()))),12,29))=12,DATE(IF(N($A$4)>0,N($A$4),IF(ISNUMBER(--$A$4),--$A$4,YEAR(TODAY()))),12,29),"")
A6: Atividade (vem do Plano) | F6: JAN | K6: FEV | P6: MAR | U6: ABR | Z6: MAI | AE6: JUN | AJ6: JUL | AO6: AGO | AT6: SET | AY6: OUT | BD6: NOV | BI6: DEZ
A7: Nº | B7: TAG | C7: Equipamento | D7: Atividade | E7: A cada (dias) | F7: 1 | G7: 2 | H7: 3 | I7: 4 | J7: =IF(ISNUMBER(J$5),5,"–") | K7: 1 | L7: 2 | M7: 3 | N7: 4 | O7: =IF(ISNUMBER(O$5),5,"–") | P7: 1 | Q7: 2 | R7: 3 | S7: 4 | T7: =IF(ISNUMBER(T$5),5,"–") | U7: 1 | V7: 2 | W7: 3 | X7: 4 | Y7: =IF(ISNUMBER(Y$5),5,"–") | Z7: 1 | AA7: 2 | AB7: 3 | AC7: 4 | AD7: =IF(ISNUMBER(AD$5),5,"–") | AE7: 1 | AF7: 2 | AG7: 3 | AH7: 4 | AI7: =IF(ISNUMBER(AI$5),5,"–") | AJ7: 1 | AK7: 2 | AL7: 3 | AM7: 4 | AN7: =IF(ISNUMBER(AN$5),5,"–") | AO7: 1 | AP7: 2 | AQ7: 3 | AR7: 4 | AS7: =IF(ISNUMBER(AS$5),5,"–") | AT7: 1 | AU7: 2 | AV7: 3 | AW7: 4 | AX7: =IF(ISNUMBER(AX$5),5,"–") | AY7: 1 | AZ7: 2 | BA7: 3 | BB7: 4 | BC7: =IF(ISNUMBER(BC$5),5,"–") | BD7: 1 | BE7: 2 | BF7: 3 | BG7: 4 | BH7: =IF(ISNUMBER(BH$5),5,"–") | BI7: 1 | BJ7: 2 | BK7: 3 | BL7: 4 | BM7: =IF(ISNUMBER(BM$5),5,"–")
A8: =Plano!A5 | B8: =IF(Plano!B5="","",Plano!B5) | C8: =IF(B8="","",IFERROR(INDEX(tb_pcm_ativos[descricao_ativo],MATCH(B8,tb_pcm_ativos[tag],0)),"fora do cadastro")) | D8: =IF(Plano!E5="","",Plano!E5) | E8: =IF(Plano!G5="","",Plano!G5) | F8: =IF(OR(NOT(ISNUMBER(F$5)),N(Plano!$G5)=0,N(Plano!$L5)=0),"",IF(Plano!$L5+Plano!$G5*MAX(0,ROUNDUP((F$5-Plano!$L5)/Plano!$G5,0))<=IF(DAY(F$5)>=29,EOMONTH(F$5,0),F$5+6),"●","")) | G8: =IF(OR(NOT(ISNUMBER(G$5)),N(Plano!$G5)=0,N(Plano!$L5)=0),"",IF(Plano!$L5+Plano!$G5*MAX(0,ROUNDUP((G$5-Plano!$L5)/Plano!$G5,0))<=IF(DAY(G$5)>=29,EOMONTH(G$5,0),G$5+6),"●","")) | H8: =IF(OR(NOT(ISNUMBER(H$5)),N(Plano!$G5)=0,N(Plano!$L5)=0),"",IF(Plano!$L5+Plano!$G5*MAX(0,ROUNDUP((H$5-Plano!$L5)/Plano!$G5,0))<=IF(DAY(H$5)>=29,EOMONTH(H$5,0),H$5+6),"●","")) | I8: =IF(OR(NOT(ISNUMBER(I$5)),N(Plano!$G5)=0,N(Plano!$L5)=0),"",IF(Plano!$L5+Plano!$G5*MAX(0,ROUNDUP((I$5-Plano!$L5)/Plano!$G5,0))<=IF(DAY(I$5)>=29,EOMONTH(I$5,0),I$5+6),"●","")) | J8: =IF(OR(NOT(ISNUMBER(J$5)),N(Plano!$G5)=0,N(Plano!$L5)=0),"",IF(Plano!$L5+Plano!$G5*MAX(0,ROUNDUP((J$5-Plano!$L5)/Plano!$G5,0))<=IF(DAY(J$5)>=29,EOMONTH(J$5,0),J$5+6),"●","")) | K8: =IF(OR(NOT(ISNUMBER(K$5)),N(Plano!$G5)=0,N(Plano!$L5)=0),"",IF(Plano!$L5+Plano!$G5*MAX(0,ROUNDUP((K$5-Plano!$L5)/Plano!$G5,0))<=IF(DAY(K$5)>=29,EOMONTH(K$5,0),K$5+6),"●","")) | L8: =IF(OR(NOT(ISNUMBER(L$5)),N(Plano!$G5)=0,N(Plano!$L5)=0),"",IF(Plano!$L5+Plano!$G5*MAX(0,ROUNDUP((L$5-Plano!$L5)/Plano!$G5,0))<=IF(DAY(L$5)>=29,EOMONTH(L$5,0),L$5+6),"●","")) | M8: =IF(OR(NOT(ISNUMBER(M$5)),N(Plano!$G5)=0,N(Plano!$L5)=0),"",IF(Plano!$L5+Plano!$G5*MAX(0,ROUNDUP((M$5-Plano!$L5)/Plano!$G5,0))<=IF(DAY(M$5)>=29,EOMONTH(M$5,0),M$5+6),"●","")) | ... BM8: =IF(OR(NOT(ISNUMBER(BM$5)),N(Plano!$G5)=0,N(Plano!$L5)=0),"",IF(Plano!$L5+Plano!$G5*MAX(0,ROUNDUP((BM$5-Plano!$L5)/Plano!$G5,0))<=IF(DAY(BM$5)>=29,EOMONTH(BM$5,0),BM$5+6),"●",""))
A9: =Plano!A6 | B9: =IF(Plano!B6="","",Plano!B6) | C9: =IF(B9="","",IFERROR(INDEX(tb_pcm_ativos[descricao_ativo],MATCH(B9,tb_pcm_ativos[tag],0)),"fora do cadastro")) | D9: =IF(Plano!E6="","",Plano!E6) | E9: =IF(Plano!G6="","",Plano!G6) | F9: =IF(OR(NOT(ISNUMBER(F$5)),N(Plano!$G6)=0,N(Plano!$L6)=0),"",IF(Plano!$L6+Plano!$G6*MAX(0,ROUNDUP((F$5-Plano!$L6)/Plano!$G6,0))<=IF(DAY(F$5)>=29,EOMONTH(F$5,0),F$5+6),"●","")) | G9: =IF(OR(NOT(ISNUMBER(G$5)),N(Plano!$G6)=0,N(Plano!$L6)=0),"",IF(Plano!$L6+Plano!$G6*MAX(0,ROUNDUP((G$5-Plano!$L6)/Plano!$G6,0))<=IF(DAY(G$5)>=29,EOMONTH(G$5,0),G$5+6),"●","")) | H9: =IF(OR(NOT(ISNUMBER(H$5)),N(Plano!$G6)=0,N(Plano!$L6)=0),"",IF(Plano!$L6+Plano!$G6*MAX(0,ROUNDUP((H$5-Plano!$L6)/Plano!$G6,0))<=IF(DAY(H$5)>=29,EOMONTH(H$5,0),H$5+6),"●","")) | I9: =IF(OR(NOT(ISNUMBER(I$5)),N(Plano!$G6)=0,N(Plano!$L6)=0),"",IF(Plano!$L6+Plano!$G6*MAX(0,ROUNDUP((I$5-Plano!$L6)/Plano!$G6,0))<=IF(DAY(I$5)>=29,EOMONTH(I$5,0),I$5+6),"●","")) | J9: =IF(OR(NOT(ISNUMBER(J$5)),N(Plano!$G6)=0,N(Plano!$L6)=0),"",IF(Plano!$L6+Plano!$G6*MAX(0,ROUNDUP((J$5-Plano!$L6)/Plano!$G6,0))<=IF(DAY(J$5)>=29,EOMONTH(J$5,0),J$5+6),"●","")) | K9: =IF(OR(NOT(ISNUMBER(K$5)),N(Plano!$G6)=0,N(Plano!$L6)=0),"",IF(Plano!$L6+Plano!$G6*MAX(0,ROUNDUP((K$5-Plano!$L6)/Plano!$G6,0))<=IF(DAY(K$5)>=29,EOMONTH(K$5,0),K$5+6),"●","")) | L9: =IF(OR(NOT(ISNUMBER(L$5)),N(Plano!$G6)=0,N(Plano!$L6)=0),"",IF(Plano!$L6+Plano!$G6*MAX(0,ROUNDUP((L$5-Plano!$L6)/Plano!$G6,0))<=IF(DAY(L$5)>=29,EOMONTH(L$5,0),L$5+6),"●","")) | M9: =IF(OR(NOT(ISNUMBER(M$5)),N(Plano!$G6)=0,N(Plano!$L6)=0),"",IF(Plano!$L6+Plano!$G6*MAX(0,ROUNDUP((M$5-Plano!$L6)/Plano!$G6,0))<=IF(DAY(M$5)>=29,EOMONTH(M$5,0),M$5+6),"●","")) | ... BM9: =IF(OR(NOT(ISNUMBER(BM$5)),N(Plano!$G6)=0,N(Plano!$L6)=0),"",IF(Plano!$L6+Plano!$G6*MAX(0,ROUNDUP((BM$5-Plano!$L6)/Plano!$G6,0))<=IF(DAY(BM$5)>=29,EOMONTH(BM$5,0),BM$5+6),"●",""))
