Workbook
Name L_FAMILIAS: tb_pcm_familias[nome_familia]
Name L_PESSOAS: tb_pcm_pessoas[nome_pessoa]
Name L_SETORES: tb_pcm_setores[nome_setor]
Name L_TAGS: tb_pcm_ativos[tag]

Sheet Leia-me
D1: LEIA-ME · GUIA RÁPIDO | F1: Modelos, guias e novidades
D2: PCM-MAN-002 · Criticidade, FMECA e plano de manutenção | F2: pcmdireto.me
D3: Leia em 1 minuto, preencha os campos brancos e comece a usar. | F3: Dúvidas e sugestões pelo site
B5: COMO USAR ESTE MODELO
B6: 1 Identifique | D6: 2 Cadastre | E6: 3 Preencha | F6: 4 Imprima e revise
B7: Preencha Elaborado e Aprovado logo abaixo. Vai para o cabeçalho de todas as abas. | D7: Na aba Cadastros, lance TAGs, pessoas e setores uma vez. Eles viram as listas ▼. | E7: Use as abas na ordem do passo a passo. Comece por Criticidade. | F7: Cada aba sai em uma folha A4. Mudou o modelo? Registre na aba Revisões.
B9: 1 IDENTIFICAÇÃO DO DOCUMENTO · vai para o cabeçalho de todas as abas
B10: Título do documento | D10: Criticidade, FMECA e plano de manutenção | F10: Já vem pronto. Ajuste se quiser.
B11: Objetivo | D11: Classificar os equipamentos, analisar as falhas e transformar a análise em plano e cronograma
B12: Código do documento | D12: PCM-MAN-002
B13: Elaborado por | F13: ✎ preencha
B14: Aprovado por | F14: ✎ preencha
B15: Revisão atual | D15: =IF(COUNTA(tb_pcm_revisoes_modelo[revisao])=0,"-",INDEX(tb_pcm_revisoes_modelo[revisao],COUNTA(tb_pcm_revisoes_modelo[revisao]))) -> 00 | F15: automático: aba Revisões
B16: Data da revisão | D16: =IF(COUNTA(tb_pcm_revisoes_modelo[revisao])=0,"",IF(INDEX(tb_pcm_revisoes_modelo[data_revisao],COUNTA(tb_pcm_revisoes_modelo[revisao]))="","",RIGHT("0"&DAY(INDEX(tb_pcm_revisoes_modelo[data_revisao],COUNTA(tb_pcm_revisoes_modelo[revisao]))),2)&"/"&CHOOSE(MONTH(INDEX(tb_pcm_revisoes_modelo[data_revisao],COUNTA(tb_pcm_revisoes_modelo[revisao]))),"Jan","Fev","Mar","Abr","Mai","Jun","Jul","Ago","Set","Out","Nov","Dez")&"/"&YEAR(INDEX(tb_pcm_revisoes_modelo[data_revisao],COUNTA(tb_pcm_revisoes_modelo[revisao]))))) -> 30/Out/2026 | F16: automático: aba Revisões
B18: 2 PASSO A PASSO · clique no nome da aba para abrir
B19: 1 | C19: Cadastros | D19: Cadastre uma vez TAG, equipamento, família e setor, as pessoas, as famílias de equipamento, os setores. Eles aparecem nas setas ▼ das outras abas.
B20: 2 | C20: Criticidade | D20: Para cada TAG, dê nota de 1 a 5 em segurança, qualidade e produção e na frequência de falha (critérios no quadro Notas, abaixo da tabela). A classe A, B ou C sai da matriz.
B21: 3 | C21: FMECA | D21: Comece pelas TAGs classe A. Para cada componente: modo de falha, efeito, causa e controle atual. Dê S, O e D de 1 a 10 (quadro Notas, abaixo da tabela); o NPR sai sozinho. Defina a tarefa, o tipo e a frequência.
B22: 4 | C22: Plano | D22: As tarefas da FMECA entram sozinhas. Complete duração, se exige parada e a data da 1ª execução. Abaixo, inclua o que não vem da FMECA: lubrificação, rotinas do fabricante, inspeções legais.
B23: 5 | C23: Cronograma | D23: Não se digita. Escolha o ano na seta: o ● marca a semana do mês de cada atividade (1ª execução + frequência) e a última linha soma as horas.
B25: 3 REGRAS RÁPIDAS
B26: ▼ Lista | D26: Clique na célula e escolha na seta. Valor fora da lista é recusado.
B27: Célula branca | D27: Campo para digitar.
B28: Célula cinza | D28: Cálculo automático. Não digite: a fórmula preenche sozinha.
B29: Datas e números | D29: Datas em dd/mm/aaaa; decimais com vírgula. Vazio = sem informação; zero é valor real.
B30: Impressão | D30: Cada aba já está ajustada para uma folha A4. Use Arquivo > Imprimir sem mudar a escala.
D32: SOBRE O PCM DIRETO | F32: pcmdireto.me
D33: Modelos de manutenção prontos para usar, do planejamento ao controle: criticidade, plano, ordem de serviço, indicadores e auditorias. Todos no mesmo padrão, para a equipe aprender uma vez e usar em todos.

Sheet Criticidade
E1: ='Leia-me'!$D$10 -> Criticidade, FMECA e plano de manutenção | O1: ="Rev. "&'Leia-me'!$D$15&" · "&'Leia-me'!$D$16 -> Rev. 00 · 30/Out/2026
E2: ="Objetivo: "&'Leia-me'!$D$11 -> Objetivo: Classificar os equipamentos, analisar as falhas e transformar a análise em plano e cronograma | O2: ="Elaborado: "&'Leia-me'!$D$13&" · Aprovado: "&'Leia-me'!$D$14 -> Elaborado: · Aprovado:
A3: Local ou área ▼ | E3: Equipe da análise | M3: Ativos por classe
M4: =IF(COUNTA(J8:J27)-COUNTBLANK(J8:J27)=0,"","A: "&COUNTIF(J8:J27,"A")&" · B: "&COUNTIF(J8:J27,"B")&" · C: "&COUNTIF(J8:J27,"C"))
A6: 1 Ativo | E6: 2 Consequência (1 a 5) | I6: 3 Probabilidade e classe | M6: 4 Matriz: quantos ativos em cada quadrado | T6: 6 Notas: escolha a descrição mais próxima do pior caso crível
A7: Nº | B7: TAG ▼ | C7: Equipamento | D7: Família de equipamento | E7: (S) Segurança | F7: (Q) Qualidade | G7: (P) Produção | H7: Maior nota | I7: Frequência de falha | J7: Classe | K7: Estratégia sugerida | M7: Consequência ↓ Frequência → | N7: 1 Rara | O7: 2 Baixa | P7: 3 Média | Q7: 4 Alta | R7: 5 Muito alta | T7: Nota | U7: S Segurança e ambiente | V7: Q Qualidade | W7: P Produção e reserva | X7: Frequência de falha
A8: 1 | C8: =IF(B8="","",IFERROR(INDEX(tb_pcm_ativos[descricao_ativo],MATCH(B8,tb_pcm_ativos[tag],0)),"fora do cadastro")) | D8: =IF(B8="","",IFERROR(INDEX(tb_pcm_ativos[familia],MATCH(B8,tb_pcm_ativos[tag],0))&"","")) | H8: =IF(COUNT(E8:G8)=0,"",MAX(E8:G8)) | J8: =IF(OR(H8="",I8=""),"",IF(E8=5,"A",MID(CHOOSE(H8,"CCCBB","CCBBA","CBBAA","BBAAA","BAAAA"),I8,1))) | K8: =IF(J8="","",IF(J8="A",$N$22,IF(J8="B",$N$24,$N$26))) | M8: 5 Muito alta | N8: =COUNTIFS($H$8:$H$27,5,$I$8:$I$27,1) -> 0 | O8: =COUNTIFS($H$8:$H$27,5,$I$8:$I$27,2) -> 0 | P8: =COUNTIFS($H$8:$H$27,5,$I$8:$I$27,3) -> 0 | Q8: =COUNTIFS($H$8:$H$27,5,$I$8:$I$27,4) -> 0 | R8: =COUNTIFS($H$8:$H$27,5,$I$8:$I$27,5) -> 0 | T8: 5 | U8: Muito alto Lesão grave ou morte, ou dano ambiental grande | V8: Muito alto Defeito chega ao cliente ou afeta item de segurança ou legal | W8: Muito alto A planta para ou uma entrega é perdida | X8: Muito alto Toda semana ou mais
A9: 2 | C9: =IF(B9="","",IFERROR(INDEX(tb_pcm_ativos[descricao_ativo],MATCH(B9,tb_pcm_ativos[tag],0)),"fora do cadastro")) | D9: =IF(B9="","",IFERROR(INDEX(tb_pcm_ativos[familia],MATCH(B9,tb_pcm_ativos[tag],0))&"","")) | H9: =IF(COUNT(E9:G9)=0,"",MAX(E9:G9)) | J9: =IF(OR(H9="",I9=""),"",IF(E9=5,"A",MID(CHOOSE(H9,"CCCBB","CCBBA","CBBAA","BBAAA","BAAAA"),I9,1))) | K9: =IF(J9="","",IF(J9="A",$N$22,IF(J9="B",$N$24,$N$26))) | M9: 4 Alta | N9: =COUNTIFS($H$8:$H$27,4,$I$8:$I$27,1) -> 0 | O9: =COUNTIFS($H$8:$H$27,4,$I$8:$I$27,2) -> 0 | P9: =COUNTIFS($H$8:$H$27,4,$I$8:$I$27,3) -> 0 | Q9: =COUNTIFS($H$8:$H$27,4,$I$8:$I$27,4) -> 0 | R9: =COUNTIFS($H$8:$H$27,4,$I$8:$I$27,5) -> 0
A10: 3 | C10: =IF(B10="","",IFERROR(INDEX(tb_pcm_ativos[descricao_ativo],MATCH(B10,tb_pcm_ativos[tag],0)),"fora do cadastro")) | D10: =IF(B10="","",IFERROR(INDEX(tb_pcm_ativos[familia],MATCH(B10,tb_pcm_ativos[tag],0))&"","")) | H10: =IF(COUNT(E10:G10)=0,"",MAX(E10:G10)) | J10: =IF(OR(H10="",I10=""),"",IF(E10=5,"A",MID(CHOOSE(H10,"CCCBB","CCBBA","CBBAA","BBAAA","BAAAA"),I10,1))) | K10: =IF(J10="","",IF(J10="A",$N$22,IF(J10="B",$N$24,$N$26))) | M10: 3 Média | N10: =COUNTIFS($H$8:$H$27,3,$I$8:$I$27,1) -> 0 | O10: =COUNTIFS($H$8:$H$27,3,$I$8:$I$27,2) -> 0 | P10: =COUNTIFS($H$8:$H$27,3,$I$8:$I$27,3) -> 0 | Q10: =COUNTIFS($H$8:$H$27,3,$I$8:$I$27,4) -> 0 | R10: =COUNTIFS($H$8:$H$27,3,$I$8:$I$27,5) -> 0 | T10: 4 | U10: Alto Lesão com afastamento ou vazamento que sai da planta | V10: Alto Defeito pode escapar para etapas seguintes ou o cliente | W10: Alto A linha ou área para, sem reserva | X10: Alto Cerca de uma vez por mês
A11: 4 | C11: =IF(B11="","",IFERROR(INDEX(tb_pcm_ativos[descricao_ativo],MATCH(B11,tb_pcm_ativos[tag],0)),"fora do cadastro")) | D11: =IF(B11="","",IFERROR(INDEX(tb_pcm_ativos[familia],MATCH(B11,tb_pcm_ativos[tag],0))&"","")) | H11: =IF(COUNT(E11:G11)=0,"",MAX(E11:G11)) | J11: =IF(OR(H11="",I11=""),"",IF(E11=5,"A",MID(CHOOSE(H11,"CCCBB","CCBBA","CBBAA","BBAAA","BAAAA"),I11,1))) | K11: =IF(J11="","",IF(J11="A",$N$22,IF(J11="B",$N$24,$N$26))) | M11: 2 Baixa | N11: =COUNTIFS($H$8:$H$27,2,$I$8:$I$27,1) -> 0 | O11: =COUNTIFS($H$8:$H$27,2,$I$8:$I$27,2) -> 0 | P11: =COUNTIFS($H$8:$H$27,2,$I$8:$I$27,3) -> 0 | Q11: =COUNTIFS($H$8:$H$27,2,$I$8:$I$27,4) -> 0 | R11: =COUNTIFS($H$8:$H$27,2,$I$8:$I$27,5) -> 0
A12: 5 | C12: =IF(B12="","",IFERROR(INDEX(tb_pcm_ativos[descricao_ativo],MATCH(B12,tb_pcm_ativos[tag],0)),"fora do cadastro")) | D12: =IF(B12="","",IFERROR(INDEX(tb_pcm_ativos[familia],MATCH(B12,tb_pcm_ativos[tag],0))&"","")) | H12: =IF(COUNT(E12:G12)=0,"",MAX(E12:G12)) | J12: =IF(OR(H12="",I12=""),"",IF(E12=5,"A",MID(CHOOSE(H12,"CCCBB","CCBBA","CBBAA","BBAAA","BAAAA"),I12,1))) | K12: =IF(J12="","",IF(J12="A",$N$22,IF(J12="B",$N$24,$N$26))) | M12: 1 Muito baixa | N12: =COUNTIFS($H$8:$H$27,1,$I$8:$I$27,1) -> 0 | O12: =COUNTIFS($H$8:$H$27,1,$I$8:$I$27,2) -> 0 | P12: =COUNTIFS($H$8:$H$27,1,$I$8:$I$27,3) -> 0 | Q12: =COUNTIFS($H$8:$H$27,1,$I$8:$I$27,4) -> 0 | R12: =COUNTIFS($H$8:$H$27,1,$I$8:$I$27,5) -> 0 | T12: 3 | U12: Médio Lesão com atendimento médico ou vazamento reportável | V12: Médio Perda ou retrabalho de um lote | W12: Médio A linha desacelera ou o contorno custa tempo | X12: Médio A cada 3 a 6 meses
A13: 6 | C13: =IF(B13="","",IFERROR(INDEX(tb_pcm_ativos[descricao_ativo],MATCH(B13,tb_pcm_ativos[tag],0)),"fora do cadastro")) | D13: =IF(B13="","",IFERROR(INDEX(tb_pcm_ativos[familia],MATCH(B13,tb_pcm_ativos[tag],0))&"","")) | H13: =IF(COUNT(E13:G13)=0,"",MAX(E13:G13)) | J13: =IF(OR(H13="",I13=""),"",IF(E13=5,"A",MID(CHOOSE(H13,"CCCBB","CCBBA","CBBAA","BBAAA","BAAAA"),I13,1))) | K13: =IF(J13="","",IF(J13="A",$N$22,IF(J13="B",$N$24,$N$26))) | M13: Consequência = maior nota entre S, Q e P. Segurança 5 vira classe A em qualquer quadrado.
A14: 7 | C14: =IF(B14="","",IFERROR(INDEX(tb_pcm_ativos[descricao_ativo],MATCH(B14,tb_pcm_ativos[tag],0)),"fora do cadastro")) | D14: =IF(B14="","",IFERROR(INDEX(tb_pcm_ativos[familia],MATCH(B14,tb_pcm_ativos[tag],0))&"","")) | H14: =IF(COUNT(E14:G14)=0,"",MAX(E14:G14)) | J14: =IF(OR(H14="",I14=""),"",IF(E14=5,"A",MID(CHOOSE(H14,"CCCBB","CCBBA","CBBAA","BBAAA","BAAAA"),I14,1))) | K14: =IF(J14="","",IF(J14="A",$N$22,IF(J14="B",$N$24,$N$26))) | T14: 2 | U14: Baixo Primeiros socorros ou pequeno vazamento contido | V14: Baixo Defeito pego na máquina, pouca perda | W14: Baixo Há reserva; pequena queda de ritmo | X14: Baixo Cerca de uma vez por ano
A15: 8 | C15: =IF(B15="","",IFERROR(INDEX(tb_pcm_ativos[descricao_ativo],MATCH(B15,tb_pcm_ativos[tag],0)),"fora do cadastro")) | D15: =IF(B15="","",IFERROR(INDEX(tb_pcm_ativos[familia],MATCH(B15,tb_pcm_ativos[tag],0))&"","")) | H15: =IF(COUNT(E15:G15)=0,"",MAX(E15:G15)) | J15: =IF(OR(H15="",I15=""),"",IF(E15=5,"A",MID(CHOOSE(H15,"CCCBB","CCBBA","CBBAA","BBAAA","BAAAA"),I15,1))) | K15: =IF(J15="","",IF(J15="A",$N$22,IF(J15="B",$N$24,$N$26))) | M15: 5 Estratégia por classe (edite à vontade)
A16: 9 | C16: =IF(B16="","",IFERROR(INDEX(tb_pcm_ativos[descricao_ativo],MATCH(B16,tb_pcm_ativos[tag],0)),"fora do cadastro")) | D16: =IF(B16="","",IFERROR(INDEX(tb_pcm_ativos[familia],MATCH(B16,tb_pcm_ativos[tag],0))&"","")) | H16: =IF(COUNT(E16:G16)=0,"",MAX(E16:G16)) | J16: =IF(OR(H16="",I16=""),"",IF(E16=5,"A",MID(CHOOSE(H16,"CCCBB","CCBBA","CBBAA","BBAAA","BAAAA"),I16,1))) | K16: =IF(J16="","",IF(J16="A",$N$22,IF(J16="B",$N$24,$N$26))) | M16: Como usar 1. Dê a nota de 1 a 5 para S, Q e P pelo pior caso crível de falha (critérios no quadro Notas, abaixo da tabela). 2. Dê a frequência de falha de 1 a 5. 3. A classe sai da matriz e vai sozinha para a FMECA. | T16: 1 | U16: Muito baixo Sem lesão ou vazamento crível | V16: Muito baixo Sem efeito no produto | W16: Muito baixo Máquina reserva ou capacidade sobrando: sem perda | X16: Muito baixo Menos de uma vez por ano
A17: 10 | C17: =IF(B17="","",IFERROR(INDEX(tb_pcm_ativos[descricao_ativo],MATCH(B17,tb_pcm_ativos[tag],0)),"fora do cadastro")) | D17: =IF(B17="","",IFERROR(INDEX(tb_pcm_ativos[familia],MATCH(B17,tb_pcm_ativos[tag],0))&"","")) | H17: =IF(COUNT(E17:G17)=0,"",MAX(E17:G17)) | J17: =IF(OR(H17="",I17=""),"",IF(E17=5,"A",MID(CHOOSE(H17,"CCCBB","CCBBA","CBBAA","BBAAA","BAAAA"),I17,1))) | K17: =IF(J17="","",IF(J17="A",$N$22,IF(J17="B",$N$24,$N$26)))
A18: 11 | C18: =IF(B18="","",IFERROR(INDEX(tb_pcm_ativos[descricao_ativo],MATCH(B18,tb_pcm_ativos[tag],0)),"fora do cadastro")) | D18: =IF(B18="","",IFERROR(INDEX(tb_pcm_ativos[familia],MATCH(B18,tb_pcm_ativos[tag],0))&"","")) | H18: =IF(COUNT(E18:G18)=0,"",MAX(E18:G18)) | J18: =IF(OR(H18="",I18=""),"",IF(E18=5,"A",MID(CHOOSE(H18,"CCCBB","CCBBA","CBBAA","BBAAA","BAAAA"),I18,1))) | K18: =IF(J18="","",IF(J18="A",$N$22,IF(J18="B",$N$24,$N$26))) | T18: A produção conta a reserva: um ativo com máquina reserva pontua menos que um sem reserva. Revise as notas quando o processo mudar.
A19: 12 | C19: =IF(B19="","",IFERROR(INDEX(tb_pcm_ativos[descricao_ativo],MATCH(B19,tb_pcm_ativos[tag],0)),"fora do cadastro")) | D19: =IF(B19="","",IFERROR(INDEX(tb_pcm_ativos[familia],MATCH(B19,tb_pcm_ativos[tag],0))&"","")) | H19: =IF(COUNT(E19:G19)=0,"",MAX(E19:G19)) | J19: =IF(OR(H19="",I19=""),"",IF(E19=5,"A",MID(CHOOSE(H19,"CCCBB","CCBBA","CBBAA","BBAAA","BAAAA"),I19,1))) | K19: =IF(J19="","",IF(J19="A",$N$22,IF(J19="B",$N$24,$N$26)))
A20: 13 | C20: =IF(B20="","",IFERROR(INDEX(tb_pcm_ativos[descricao_ativo],MATCH(B20,tb_pcm_ativos[tag],0)),"fora do cadastro")) | D20: =IF(B20="","",IFERROR(INDEX(tb_pcm_ativos[familia],MATCH(B20,tb_pcm_ativos[tag],0))&"","")) | H20: =IF(COUNT(E20:G20)=0,"",MAX(E20:G20)) | J20: =IF(OR(H20="",I20=""),"",IF(E20=5,"A",MID(CHOOSE(H20,"CCCBB","CCBBA","CBBAA","BBAAA","BAAAA"),I20,1))) | K20: =IF(J20="","",IF(J20="A",$N$22,IF(J20="B",$N$24,$N$26)))
A21: 14 | C21: =IF(B21="","",IFERROR(INDEX(tb_pcm_ativos[descricao_ativo],MATCH(B21,tb_pcm_ativos[tag],0)),"fora do cadastro")) | D21: =IF(B21="","",IFERROR(INDEX(tb_pcm_ativos[familia],MATCH(B21,tb_pcm_ativos[tag],0))&"","")) | H21: =IF(COUNT(E21:G21)=0,"",MAX(E21:G21)) | J21: =IF(OR(H21="",I21=""),"",IF(E21=5,"A",MID(CHOOSE(H21,"CCCBB","CCBBA","CBBAA","BBAAA","BAAAA"),I21,1))) | K21: =IF(J21="","",IF(J21="A",$N$22,IF(J21="B",$N$24,$N$26)))
A22: 15 | C22: =IF(B22="","",IFERROR(INDEX(tb_pcm_ativos[descricao_ativo],MATCH(B22,tb_pcm_ativos[tag],0)),"fora do cadastro")) | D22: =IF(B22="","",IFERROR(INDEX(tb_pcm_ativos[familia],MATCH(B22,tb_pcm_ativos[tag],0))&"","")) | H22: =IF(COUNT(E22:G22)=0,"",MAX(E22:G22)) | J22: =IF(OR(H22="",I22=""),"",IF(E22=5,"A",MID(CHOOSE(H22,"CCCBB","CCBBA","CBBAA","BBAAA","BAAAA"),I22,1))) | K22: =IF(J22="","",IF(J22="A",$N$22,IF(J22="B",$N$24,$N$26))) | M22: A | N22: Preditiva + preventiva
A23: 16 | C23: =IF(B23="","",IFERROR(INDEX(tb_pcm_ativos[descricao_ativo],MATCH(B23,tb_pcm_ativos[tag],0)),"fora do cadastro")) | D23: =IF(B23="","",IFERROR(INDEX(tb_pcm_ativos[familia],MATCH(B23,tb_pcm_ativos[tag],0))&"","")) | H23: =IF(COUNT(E23:G23)=0,"",MAX(E23:G23)) | J23: =IF(OR(H23="",I23=""),"",IF(E23=5,"A",MID(CHOOSE(H23,"CCCBB","CCBBA","CBBAA","BBAAA","BAAAA"),I23,1))) | K23: =IF(J23="","",IF(J23="A",$N$22,IF(J23="B",$N$24,$N$26))) | N23: Inspeção por condição e preventiva; peças críticas em estoque; análise de causa em toda falha.
A24: 17 | C24: =IF(B24="","",IFERROR(INDEX(tb_pcm_ativos[descricao_ativo],MATCH(B24,tb_pcm_ativos[tag],0)),"fora do cadastro")) | D24: =IF(B24="","",IFERROR(INDEX(tb_pcm_ativos[familia],MATCH(B24,tb_pcm_ativos[tag],0))&"","")) | H24: =IF(COUNT(E24:G24)=0,"",MAX(E24:G24)) | J24: =IF(OR(H24="",I24=""),"",IF(E24=5,"A",MID(CHOOSE(H24,"CCCBB","CCBBA","CBBAA","BBAAA","BAAAA"),I24,1))) | K24: =IF(J24="","",IF(J24="A",$N$22,IF(J24="B",$N$24,$N$26))) | M24: B | N24: Preventiva por tempo ou uso
A25: 18 | C25: =IF(B25="","",IFERROR(INDEX(tb_pcm_ativos[descricao_ativo],MATCH(B25,tb_pcm_ativos[tag],0)),"fora do cadastro")) | D25: =IF(B25="","",IFERROR(INDEX(tb_pcm_ativos[familia],MATCH(B25,tb_pcm_ativos[tag],0))&"","")) | H25: =IF(COUNT(E25:G25)=0,"",MAX(E25:G25)) | J25: =IF(OR(H25="",I25=""),"",IF(E25=5,"A",MID(CHOOSE(H25,"CCCBB","CCBBA","CBBAA","BBAAA","BAAAA"),I25,1))) | K25: =IF(J25="","",IF(J25="A",$N$22,IF(J25="B",$N$24,$N$26))) | N25: Peças conforme o prazo de entrega; revisar o plano depois de cada falha.
A26: 19 | C26: =IF(B26="","",IFERROR(INDEX(tb_pcm_ativos[descricao_ativo],MATCH(B26,tb_pcm_ativos[tag],0)),"fora do cadastro")) | D26: =IF(B26="","",IFERROR(INDEX(tb_pcm_ativos[familia],MATCH(B26,tb_pcm_ativos[tag],0))&"","")) | H26: =IF(COUNT(E26:G26)=0,"",MAX(E26:G26)) | J26: =IF(OR(H26="",I26=""),"",IF(E26=5,"A",MID(CHOOSE(H26,"CCCBB","CCBBA","CBBAA","BBAAA","BAAAA"),I26,1))) | K26: =IF(J26="","",IF(J26="A",$N$22,IF(J26="B",$N$24,$N$26))) | M26: C | N26: Corretiva planejada
A27: 20 | C27: =IF(B27="","",IFERROR(INDEX(tb_pcm_ativos[descricao_ativo],MATCH(B27,tb_pcm_ativos[tag],0)),"fora do cadastro")) | D27: =IF(B27="","",IFERROR(INDEX(tb_pcm_ativos[familia],MATCH(B27,tb_pcm_ativos[tag],0))&"","")) | H27: =IF(COUNT(E27:G27)=0,"",MAX(E27:G27)) | J27: =IF(OR(H27="",I27=""),"",IF(E27=5,"A",MID(CHOOSE(H27,"CCCBB","CCBBA","CBBAA","BBAAA","BAAAA"),I27,1))) | K27: =IF(J27="","",IF(J27="A",$N$22,IF(J27="B",$N$24,$N$26))) | N27: Ou operar até falhar, quando for seguro; sem estoque dedicado de peças.
A28: ● A: crítico ● B: importante ● C: baixo impacto S segurança · Q qualidade · P produção · cinza = calculado; a estratégia vem do quadro 5.

Sheet FMECA
F1: FMECA | N1: ="Rev. "&'Leia-me'!$D$15&" · "&'Leia-me'!$D$16 -> Rev. 00 · 30/Out/2026
F2: Objetivo: Analisar os modos de falha de cada TAG e definir a tarefa de manutenção de cada um | N2: ="Elaborado: "&'Leia-me'!$D$13&" · Aprovado: "&'Leia-me'!$D$14 -> Elaborado: · Aprovado:
A3: Área ou sistema analisado ▼ | F3: Equipe da análise | K3: Modos com risco alto | O3: Maior NPR
K4: =IF(COUNT(M8:M22)=0,"",COUNTIF(M8:M22,">=200")+COUNTIFS(J8:J22,">=9",M8:M22,"<200")) | O4: =IF(COUNT(M8:M22)=0,"",MAX(M8:M22))
A6: 1 Falha: o que pode falhar e por quê | J6: 2 Risco | N6: 3 Tarefa de manutenção → vai para o Plano | S6: 4 Notas de 1 a 10 para (S) Severidade, (O) Ocorência e (D) Detecção
A7: Nº | B7: TAG ▼ | C7: Equipamento | D7: Classe | E7: Componente | F7: Modo de falha | G7: Efeito da falha | H7: Causa | I7: Controle atual | J7: Severidade (S) | K7: Ocorrência (O) | L7: Detecção (D) | M7: NPR | N7: Tarefa recomendada | O7: Tipo de tarefa ▼ | P7: A cada (dias) | Q7: Responsável ▼ | S7: Nota | T7: S Severidade do efeito | U7: O Ocorrência da causa | V7: D Detecção pelo controle (nota alta = difícil detectar)
A8: 1 | C8: =IF(B8="","",IFERROR(INDEX(tb_pcm_ativos[descricao_ativo],MATCH(B8,tb_pcm_ativos[tag],0)),"fora do cadastro")) | D8: =IF(B8="","",IFERROR(INDEX(Criticidade!$J$8:$J$27,MATCH(B8,Criticidade!$B$8:$B$27,0)),"?")) | M8: =IF(COUNT(J8:L8)<3,"",J8*K8*L8) | S8: 10 | T8: Perigoso sem aviso Afeta a segurança das pessoas ou o meio ambiente, sem aviso prévio | U8: Quase certa Mais de uma vez por dia | V8: Quase impossível Não há controle que detecte a falha
A9: 2 | C9: =IF(B9="","",IFERROR(INDEX(tb_pcm_ativos[descricao_ativo],MATCH(B9,tb_pcm_ativos[tag],0)),"fora do cadastro")) | D9: =IF(B9="","",IFERROR(INDEX(Criticidade!$J$8:$J$27,MATCH(B9,Criticidade!$B$8:$B$27,0)),"?")) | M9: =IF(COUNT(J9:L9)<3,"",J9*K9*L9) | S9: 9 | T9: Perigoso com aviso Afeta a segurança das pessoas ou o meio ambiente, com aviso prévio | U9: Muito alta A cada 3 ou 4 dias | V9: Muito remota Só se percebe depois que a falha acontece
A10: 3 | C10: =IF(B10="","",IFERROR(INDEX(tb_pcm_ativos[descricao_ativo],MATCH(B10,tb_pcm_ativos[tag],0)),"fora do cadastro")) | D10: =IF(B10="","",IFERROR(INDEX(Criticidade!$J$8:$J$27,MATCH(B10,Criticidade!$B$8:$B$27,0)),"?")) | M10: =IF(COUNT(J10:L10)<3,"",J10*K10*L10) | S10: 8 | T10: Muito alto Para a linha por mais de 8 h ou perde todo o lote | U10: Alta Uma vez por semana | V10: Remota Inspeção visual eventual, sem rotina
A11: 4 | C11: =IF(B11="","",IFERROR(INDEX(tb_pcm_ativos[descricao_ativo],MATCH(B11,tb_pcm_ativos[tag],0)),"fora do cadastro")) | D11: =IF(B11="","",IFERROR(INDEX(Criticidade!$J$8:$J$27,MATCH(B11,Criticidade!$B$8:$B$27,0)),"?")) | M11: =IF(COUNT(J11:L11)<3,"",J11*K11*L11) | S11: 7 | T11: Alto Para a linha de 2 a 8 h ou gera refugo grande | U11: Alta Uma vez por mês | V11: Muito baixa Inspeção sem padrão nem frequência definida
A12: 5 | C12: =IF(B12="","",IFERROR(INDEX(tb_pcm_ativos[descricao_ativo],MATCH(B12,tb_pcm_ativos[tag],0)),"fora do cadastro")) | D12: =IF(B12="","",IFERROR(INDEX(Criticidade!$J$8:$J$27,MATCH(B12,Criticidade!$B$8:$B$27,0)),"?")) | M12: =IF(COUNT(J12:L12)<3,"",J12*K12*L12) | S12: 6 | T12: Moderado Para a linha por até 2 h ou gera retrabalho | U12: Moderada A cada 3 meses | V12: Baixa Inspeção sensitiva com frequência longa
A13: 6 | C13: =IF(B13="","",IFERROR(INDEX(tb_pcm_ativos[descricao_ativo],MATCH(B13,tb_pcm_ativos[tag],0)),"fora do cadastro")) | D13: =IF(B13="","",IFERROR(INDEX(Criticidade!$J$8:$J$27,MATCH(B13,Criticidade!$B$8:$B$27,0)),"?")) | M13: =IF(COUNT(J13:L13)<3,"",J13*K13*L13) | S13: 5 | T13: Baixo Reduz a velocidade ou o desempenho do equipamento | U13: Moderada A cada 6 meses | V13: Moderada Rota de inspeção sensitiva em dia
A14: 7 | C14: =IF(B14="","",IFERROR(INDEX(tb_pcm_ativos[descricao_ativo],MATCH(B14,tb_pcm_ativos[tag],0)),"fora do cadastro")) | D14: =IF(B14="","",IFERROR(INDEX(Criticidade!$J$8:$J$27,MATCH(B14,Criticidade!$B$8:$B$27,0)),"?")) | M14: =IF(COUNT(J14:L14)<3,"",J14*K14*L14) | S14: 4 | T14: Muito baixo Exige ajuste; a operação percebe, a produção segue | U14: Moderada Uma vez por ano | V14: Moderadamente alta Medição periódica (folga, temperatura, nível)
A15: 8 | C15: =IF(B15="","",IFERROR(INDEX(tb_pcm_ativos[descricao_ativo],MATCH(B15,tb_pcm_ativos[tag],0)),"fora do cadastro")) | D15: =IF(B15="","",IFERROR(INDEX(Criticidade!$J$8:$J$27,MATCH(B15,Criticidade!$B$8:$B$27,0)),"?")) | M15: =IF(COUNT(J15:L15)<3,"",J15*K15*L15) | S15: 3 | T15: Menor Pequeno incômodo, sem perda de produção | U15: Baixa A cada 1 a 3 anos | V15: Alta Preditiva em dia (vibração, termografia, óleo)
A16: 9 | C16: =IF(B16="","",IFERROR(INDEX(tb_pcm_ativos[descricao_ativo],MATCH(B16,tb_pcm_ativos[tag],0)),"fora do cadastro")) | D16: =IF(B16="","",IFERROR(INDEX(Criticidade!$J$8:$J$27,MATCH(B16,Criticidade!$B$8:$B$27,0)),"?")) | M16: =IF(COUNT(J16:L16)<3,"",J16*K16*L16) | S16: 2 | T16: Muito menor Quase imperceptível | U16: Muito baixa A cada 3 a 6 anos | V16: Muito alta Monitoramento contínuo com alarme
A17: 10 | C17: =IF(B17="","",IFERROR(INDEX(tb_pcm_ativos[descricao_ativo],MATCH(B17,tb_pcm_ativos[tag],0)),"fora do cadastro")) | D17: =IF(B17="","",IFERROR(INDEX(Criticidade!$J$8:$J$27,MATCH(B17,Criticidade!$B$8:$B$27,0)),"?")) | M17: =IF(COUNT(J17:L17)<3,"",J17*K17*L17) | S17: 1 | T17: Nenhum Sem efeito | U17: Remota Mais de 6 anos ou nunca ocorreu | V17: Quase certa Intertravamento ou sensor que para a máquina antes do dano
A18: 11 | C18: =IF(B18="","",IFERROR(INDEX(tb_pcm_ativos[descricao_ativo],MATCH(B18,tb_pcm_ativos[tag],0)),"fora do cadastro")) | D18: =IF(B18="","",IFERROR(INDEX(Criticidade!$J$8:$J$27,MATCH(B18,Criticidade!$B$8:$B$27,0)),"?")) | M18: =IF(COUNT(J18:L18)<3,"",J18*K18*L18) | S18: NPR = S × O × D. Dê as notas pelo pior caso crível; revise quando o processo ou os controles mudarem.
A19: 12 | C19: =IF(B19="","",IFERROR(INDEX(tb_pcm_ativos[descricao_ativo],MATCH(B19,tb_pcm_ativos[tag],0)),"fora do cadastro")) | D19: =IF(B19="","",IFERROR(INDEX(Criticidade!$J$8:$J$27,MATCH(B19,Criticidade!$B$8:$B$27,0)),"?")) | M19: =IF(COUNT(J19:L19)<3,"",J19*K19*L19)
A20: 13 | C20: =IF(B20="","",IFERROR(INDEX(tb_pcm_ativos[descricao_ativo],MATCH(B20,tb_pcm_ativos[tag],0)),"fora do cadastro")) | D20: =IF(B20="","",IFERROR(INDEX(Criticidade!$J$8:$J$27,MATCH(B20,Criticidade!$B$8:$B$27,0)),"?")) | M20: =IF(COUNT(J20:L20)<3,"",J20*K20*L20)
A21: 14 | C21: =IF(B21="","",IFERROR(INDEX(tb_pcm_ativos[descricao_ativo],MATCH(B21,tb_pcm_ativos[tag],0)),"fora do cadastro")) | D21: =IF(B21="","",IFERROR(INDEX(Criticidade!$J$8:$J$27,MATCH(B21,Criticidade!$B$8:$B$27,0)),"?")) | M21: =IF(COUNT(J21:L21)<3,"",J21*K21*L21)
A22: 15 | C22: =IF(B22="","",IFERROR(INDEX(tb_pcm_ativos[descricao_ativo],MATCH(B22,tb_pcm_ativos[tag],0)),"fora do cadastro")) | D22: =IF(B22="","",IFERROR(INDEX(Criticidade!$J$8:$J$27,MATCH(B22,Criticidade!$B$8:$B$27,0)),"?")) | M22: =IF(COUNT(J22:L22)<3,"",J22*K22*L22)
A23: S severidade · O ocorrência · D detecção (nota alta = difícil detectar) · NPR = S × O × D · notas na aba Notas da FMECA. NPR: ● Alto: 200 ou mais, ou S 9–10 ● Médio: 100 a 199 ● Baixo: menos de 100

Sheet Plano
E1: Plano | I1: ="Rev. "&'Leia-me'!$D$15&" · "&'Leia-me'!$D$16 -> Rev. 00 · 30/Out/2026
E2: Objetivo: Atividades da FMECA e outras: duração, parada, 1ª execução e próxima data | I2: ="Elaborado: "&'Leia-me'!$D$13&" · Aprovado: "&'Leia-me'!$D$14 -> Elaborado: · Aprovado:
A3: 1 Atividade: as linhas cinza vêm sozinhas da FMECA; as de baixo, digite | I3: 2 Programação (preencha)
A4: Nº | B4: TAG ▼ | C4: Equipamento | D4: Componente | E4: Atividade | F4: Tipo ▼ | G4: A cada (dias) | H4: Responsável ▼ | I4: Duração (h) | J4: Exige parada ▼ | K4: 1ª execução | L4: Próxima
A5: 1 | B5: =IF(FMECA!$N$8="","",IF(FMECA!B8="","",FMECA!B8)) | C5: =IF(B5="","",IFERROR(INDEX(tb_pcm_ativos[descricao_ativo],MATCH(B5,tb_pcm_ativos[tag],0)),"fora do cadastro")) | D5: =IF(FMECA!$N$8="","",IF(FMECA!E8="","",FMECA!E8)) | E5: =IF(FMECA!$N$8="","",IF(FMECA!N8="","",FMECA!N8)) | F5: =IF(FMECA!$N$8="","",IF(FMECA!O8="","",FMECA!O8)) | G5: =IF(FMECA!$N$8="","",IF(FMECA!P8="","",FMECA!P8)) | H5: =IF(FMECA!$N$8="","",IF(FMECA!Q8="","",FMECA!Q8)) | L5: =IF(OR(K5="",G5="",G5=0),"",IF(K5>=TODAY(),K5,K5+G5*ROUNDUP((TODAY()-K5)/G5,0)))
A6: 2 | B6: =IF(FMECA!$N$9="","",IF(FMECA!B9="","",FMECA!B9)) | C6: =IF(B6="","",IFERROR(INDEX(tb_pcm_ativos[descricao_ativo],MATCH(B6,tb_pcm_ativos[tag],0)),"fora do cadastro")) | D6: =IF(FMECA!$N$9="","",IF(FMECA!E9="","",FMECA!E9)) | E6: =IF(FMECA!$N$9="","",IF(FMECA!N9="","",FMECA!N9)) | F6: =IF(FMECA!$N$9="","",IF(FMECA!O9="","",FMECA!O9)) | G6: =IF(FMECA!$N$9="","",IF(FMECA!P9="","",FMECA!P9)) | H6: =IF(FMECA!$N$9="","",IF(FMECA!Q9="","",FMECA!Q9)) | L6: =IF(OR(K6="",G6="",G6=0),"",IF(K6>=TODAY(),K6,K6+G6*ROUNDUP((TODAY()-K6)/G6,0)))
A7: 3 | B7: =IF(FMECA!$N$10="","",IF(FMECA!B10="","",FMECA!B10)) | C7: =IF(B7="","",IFERROR(INDEX(tb_pcm_ativos[descricao_ativo],MATCH(B7,tb_pcm_ativos[tag],0)),"fora do cadastro")) | D7: =IF(FMECA!$N$10="","",IF(FMECA!E10="","",FMECA!E10)) | E7: =IF(FMECA!$N$10="","",IF(FMECA!N10="","",FMECA!N10)) | F7: =IF(FMECA!$N$10="","",IF(FMECA!O10="","",FMECA!O10)) | G7: =IF(FMECA!$N$10="","",IF(FMECA!P10="","",FMECA!P10)) | H7: =IF(FMECA!$N$10="","",IF(FMECA!Q10="","",FMECA!Q10)) | L7: =IF(OR(K7="",G7="",G7=0),"",IF(K7>=TODAY(),K7,K7+G7*ROUNDUP((TODAY()-K7)/G7,0)))
A8: 4 | B8: =IF(FMECA!$N$11="","",IF(FMECA!B11="","",FMECA!B11)) | C8: =IF(B8="","",IFERROR(INDEX(tb_pcm_ativos[descricao_ativo],MATCH(B8,tb_pcm_ativos[tag],0)),"fora do cadastro")) | D8: =IF(FMECA!$N$11="","",IF(FMECA!E11="","",FMECA!E11)) | E8: =IF(FMECA!$N$11="","",IF(FMECA!N11="","",FMECA!N11)) | F8: =IF(FMECA!$N$11="","",IF(FMECA!O11="","",FMECA!O11)) | G8: =IF(FMECA!$N$11="","",IF(FMECA!P11="","",FMECA!P11)) | H8: =IF(FMECA!$N$11="","",IF(FMECA!Q11="","",FMECA!Q11)) | L8: =IF(OR(K8="",G8="",G8=0),"",IF(K8>=TODAY(),K8,K8+G8*ROUNDUP((TODAY()-K8)/G8,0)))
A9: 5 | B9: =IF(FMECA!$N$12="","",IF(FMECA!B12="","",FMECA!B12)) | C9: =IF(B9="","",IFERROR(INDEX(tb_pcm_ativos[descricao_ativo],MATCH(B9,tb_pcm_ativos[tag],0)),"fora do cadastro")) | D9: =IF(FMECA!$N$12="","",IF(FMECA!E12="","",FMECA!E12)) | E9: =IF(FMECA!$N$12="","",IF(FMECA!N12="","",FMECA!N12)) | F9: =IF(FMECA!$N$12="","",IF(FMECA!O12="","",FMECA!O12)) | G9: =IF(FMECA!$N$12="","",IF(FMECA!P12="","",FMECA!P12)) | H9: =IF(FMECA!$N$12="","",IF(FMECA!Q12="","",FMECA!Q12)) | L9: =IF(OR(K9="",G9="",G9=0),"",IF(K9>=TODAY(),K9,K9+G9*ROUNDUP((TODAY()-K9)/G9,0)))
A10: 6 | B10: =IF(FMECA!$N$13="","",IF(FMECA!B13="","",FMECA!B13)) | C10: =IF(B10="","",IFERROR(INDEX(tb_pcm_ativos[descricao_ativo],MATCH(B10,tb_pcm_ativos[tag],0)),"fora do cadastro")) | D10: =IF(FMECA!$N$13="","",IF(FMECA!E13="","",FMECA!E13)) | E10: =IF(FMECA!$N$13="","",IF(FMECA!N13="","",FMECA!N13)) | F10: =IF(FMECA!$N$13="","",IF(FMECA!O13="","",FMECA!O13)) | G10: =IF(FMECA!$N$13="","",IF(FMECA!P13="","",FMECA!P13)) | H10: =IF(FMECA!$N$13="","",IF(FMECA!Q13="","",FMECA!Q13)) | L10: =IF(OR(K10="",G10="",G10=0),"",IF(K10>=TODAY(),K10,K10+G10*ROUNDUP((TODAY()-K10)/G10,0)))
A11: 7 | B11: =IF(FMECA!$N$14="","",IF(FMECA!B14="","",FMECA!B14)) | C11: =IF(B11="","",IFERROR(INDEX(tb_pcm_ativos[descricao_ativo],MATCH(B11,tb_pcm_ativos[tag],0)),"fora do cadastro")) | D11: =IF(FMECA!$N$14="","",IF(FMECA!E14="","",FMECA!E14)) | E11: =IF(FMECA!$N$14="","",IF(FMECA!N14="","",FMECA!N14)) | F11: =IF(FMECA!$N$14="","",IF(FMECA!O14="","",FMECA!O14)) | G11: =IF(FMECA!$N$14="","",IF(FMECA!P14="","",FMECA!P14)) | H11: =IF(FMECA!$N$14="","",IF(FMECA!Q14="","",FMECA!Q14)) | L11: =IF(OR(K11="",G11="",G11=0),"",IF(K11>=TODAY(),K11,K11+G11*ROUNDUP((TODAY()-K11)/G11,0)))
A12: 8 | B12: =IF(FMECA!$N$15="","",IF(FMECA!B15="","",FMECA!B15)) | C12: =IF(B12="","",IFERROR(INDEX(tb_pcm_ativos[descricao_ativo],MATCH(B12,tb_pcm_ativos[tag],0)),"fora do cadastro")) | D12: =IF(FMECA!$N$15="","",IF(FMECA!E15="","",FMECA!E15)) | E12: =IF(FMECA!$N$15="","",IF(FMECA!N15="","",FMECA!N15)) | F12: =IF(FMECA!$N$15="","",IF(FMECA!O15="","",FMECA!O15)) | G12: =IF(FMECA!$N$15="","",IF(FMECA!P15="","",FMECA!P15)) | H12: =IF(FMECA!$N$15="","",IF(FMECA!Q15="","",FMECA!Q15)) | L12: =IF(OR(K12="",G12="",G12=0),"",IF(K12>=TODAY(),K12,K12+G12*ROUNDUP((TODAY()-K12)/G12,0)))
A13: 9 | B13: =IF(FMECA!$N$16="","",IF(FMECA!B16="","",FMECA!B16)) | C13: =IF(B13="","",IFERROR(INDEX(tb_pcm_ativos[descricao_ativo],MATCH(B13,tb_pcm_ativos[tag],0)),"fora do cadastro")) | D13: =IF(FMECA!$N$16="","",IF(FMECA!E16="","",FMECA!E16)) | E13: =IF(FMECA!$N$16="","",IF(FMECA!N16="","",FMECA!N16)) | F13: =IF(FMECA!$N$16="","",IF(FMECA!O16="","",FMECA!O16)) | G13: =IF(FMECA!$N$16="","",IF(FMECA!P16="","",FMECA!P16)) | H13: =IF(FMECA!$N$16="","",IF(FMECA!Q16="","",FMECA!Q16)) | L13: =IF(OR(K13="",G13="",G13=0),"",IF(K13>=TODAY(),K13,K13+G13*ROUNDUP((TODAY()-K13)/G13,0)))
A14: 10 | B14: =IF(FMECA!$N$17="","",IF(FMECA!B17="","",FMECA!B17)) | C14: =IF(B14="","",IFERROR(INDEX(tb_pcm_ativos[descricao_ativo],MATCH(B14,tb_pcm_ativos[tag],0)),"fora do cadastro")) | D14: =IF(FMECA!$N$17="","",IF(FMECA!E17="","",FMECA!E17)) | E14: =IF(FMECA!$N$17="","",IF(FMECA!N17="","",FMECA!N17)) | F14: =IF(FMECA!$N$17="","",IF(FMECA!O17="","",FMECA!O17)) | G14: =IF(FMECA!$N$17="","",IF(FMECA!P17="","",FMECA!P17)) | H14: =IF(FMECA!$N$17="","",IF(FMECA!Q17="","",FMECA!Q17)) | L14: =IF(OR(K14="",G14="",G14=0),"",IF(K14>=TODAY(),K14,K14+G14*ROUNDUP((TODAY()-K14)/G14,0)))
A15: 11 | B15: =IF(FMECA!$N$18="","",IF(FMECA!B18="","",FMECA!B18)) | C15: =IF(B15="","",IFERROR(INDEX(tb_pcm_ativos[descricao_ativo],MATCH(B15,tb_pcm_ativos[tag],0)),"fora do cadastro")) | D15: =IF(FMECA!$N$18="","",IF(FMECA!E18="","",FMECA!E18)) | E15: =IF(FMECA!$N$18="","",IF(FMECA!N18="","",FMECA!N18)) | F15: =IF(FMECA!$N$18="","",IF(FMECA!O18="","",FMECA!O18)) | G15: =IF(FMECA!$N$18="","",IF(FMECA!P18="","",FMECA!P18)) | H15: =IF(FMECA!$N$18="","",IF(FMECA!Q18="","",FMECA!Q18)) | L15: =IF(OR(K15="",G15="",G15=0),"",IF(K15>=TODAY(),K15,K15+G15*ROUNDUP((TODAY()-K15)/G15,0)))
A16: 12 | B16: =IF(FMECA!$N$19="","",IF(FMECA!B19="","",FMECA!B19)) | C16: =IF(B16="","",IFERROR(INDEX(tb_pcm_ativos[descricao_ativo],MATCH(B16,tb_pcm_ativos[tag],0)),"fora do cadastro")) | D16: =IF(FMECA!$N$19="","",IF(FMECA!E19="","",FMECA!E19)) | E16: =IF(FMECA!$N$19="","",IF(FMECA!N19="","",FMECA!N19)) | F16: =IF(FMECA!$N$19="","",IF(FMECA!O19="","",FMECA!O19)) | G16: =IF(FMECA!$N$19="","",IF(FMECA!P19="","",FMECA!P19)) | H16: =IF(FMECA!$N$19="","",IF(FMECA!Q19="","",FMECA!Q19)) | L16: =IF(OR(K16="",G16="",G16=0),"",IF(K16>=TODAY(),K16,K16+G16*ROUNDUP((TODAY()-K16)/G16,0)))
A17: 13 | B17: =IF(FMECA!$N$20="","",IF(FMECA!B20="","",FMECA!B20)) | C17: =IF(B17="","",IFERROR(INDEX(tb_pcm_ativos[descricao_ativo],MATCH(B17,tb_pcm_ativos[tag],0)),"fora do cadastro")) | D17: =IF(FMECA!$N$20="","",IF(FMECA!E20="","",FMECA!E20)) | E17: =IF(FMECA!$N$20="","",IF(FMECA!N20="","",FMECA!N20)) | F17: =IF(FMECA!$N$20="","",IF(FMECA!O20="","",FMECA!O20)) | G17: =IF(FMECA!$N$20="","",IF(FMECA!P20="","",FMECA!P20)) | H17: =IF(FMECA!$N$20="","",IF(FMECA!Q20="","",FMECA!Q20)) | L17: =IF(OR(K17="",G17="",G17=0),"",IF(K17>=TODAY(),K17,K17+G17*ROUNDUP((TODAY()-K17)/G17,0)))
A18: 14 | B18: =IF(FMECA!$N$21="","",IF(FMECA!B21="","",FMECA!B21)) | C18: =IF(B18="","",IFERROR(INDEX(tb_pcm_ativos[descricao_ativo],MATCH(B18,tb_pcm_ativos[tag],0)),"fora do cadastro")) | D18: =IF(FMECA!$N$21="","",IF(FMECA!E21="","",FMECA!E21)) | E18: =IF(FMECA!$N$21="","",IF(FMECA!N21="","",FMECA!N21)) | F18: =IF(FMECA!$N$21="","",IF(FMECA!O21="","",FMECA!O21)) | G18: =IF(FMECA!$N$21="","",IF(FMECA!P21="","",FMECA!P21)) | H18: =IF(FMECA!$N$21="","",IF(FMECA!Q21="","",FMECA!Q21)) | L18: =IF(OR(K18="",G18="",G18=0),"",IF(K18>=TODAY(),K18,K18+G18*ROUNDUP((TODAY()-K18)/G18,0)))
A19: 15 | B19: =IF(FMECA!$N$22="","",IF(FMECA!B22="","",FMECA!B22)) | C19: =IF(B19="","",IFERROR(INDEX(tb_pcm_ativos[descricao_ativo],MATCH(B19,tb_pcm_ativos[tag],0)),"fora do cadastro")) | D19: =IF(FMECA!$N$22="","",IF(FMECA!E22="","",FMECA!E22)) | E19: =IF(FMECA!$N$22="","",IF(FMECA!N22="","",FMECA!N22)) | F19: =IF(FMECA!$N$22="","",IF(FMECA!O22="","",FMECA!O22)) | G19: =IF(FMECA!$N$22="","",IF(FMECA!P22="","",FMECA!P22)) | H19: =IF(FMECA!$N$22="","",IF(FMECA!Q22="","",FMECA!Q22)) | L19: =IF(OR(K19="",G19="",G19=0),"",IF(K19>=TODAY(),K19,K19+G19*ROUNDUP((TODAY()-K19)/G19,0)))
A20: Outras atividades (fora da FMECA): lubrificação, rotinas do fabricante, inspeções legais, calibrações
A21: 16 | C21: =IF(B21="","",IFERROR(INDEX(tb_pcm_ativos[descricao_ativo],MATCH(B21,tb_pcm_ativos[tag],0)),"fora do cadastro")) | L21: =IF(OR(K21="",G21="",G21=0),"",IF(K21>=TODAY(),K21,K21+G21*ROUNDUP((TODAY()-K21)/G21,0)))
A22: 17 | C22: =IF(B22="","",IFERROR(INDEX(tb_pcm_ativos[descricao_ativo],MATCH(B22,tb_pcm_ativos[tag],0)),"fora do cadastro")) | L22: =IF(OR(K22="",G22="",G22=0),"",IF(K22>=TODAY(),K22,K22+G22*ROUNDUP((TODAY()-K22)/G22,0)))
A23: 18 | C23: =IF(B23="","",IFERROR(INDEX(tb_pcm_ativos[descricao_ativo],MATCH(B23,tb_pcm_ativos[tag],0)),"fora do cadastro")) | L23: =IF(OR(K23="",G23="",G23=0),"",IF(K23>=TODAY(),K23,K23+G23*ROUNDUP((TODAY()-K23)/G23,0)))
A24: 19 | C24: =IF(B24="","",IFERROR(INDEX(tb_pcm_ativos[descricao_ativo],MATCH(B24,tb_pcm_ativos[tag],0)),"fora do cadastro")) | L24: =IF(OR(K24="",G24="",G24=0),"",IF(K24>=TODAY(),K24,K24+G24*ROUNDUP((TODAY()-K24)/G24,0)))
A25: 20 | C25: =IF(B25="","",IFERROR(INDEX(tb_pcm_ativos[descricao_ativo],MATCH(B25,tb_pcm_ativos[tag],0)),"fora do cadastro")) | L25: =IF(OR(K25="",G25="",G25=0),"",IF(K25>=TODAY(),K25,K25+G25*ROUNDUP((TODAY()-K25)/G25,0)))
A26: 21 | C26: =IF(B26="","",IFERROR(INDEX(tb_pcm_ativos[descricao_ativo],MATCH(B26,tb_pcm_ativos[tag],0)),"fora do cadastro")) | L26: =IF(OR(K26="",G26="",G26=0),"",IF(K26>=TODAY(),K26,K26+G26*ROUNDUP((TODAY()-K26)/G26,0)))
A27: 22 | C27: =IF(B27="","",IFERROR(INDEX(tb_pcm_ativos[descricao_ativo],MATCH(B27,tb_pcm_ativos[tag],0)),"fora do cadastro")) | L27: =IF(OR(K27="",G27="",G27=0),"",IF(K27>=TODAY(),K27,K27+G27*ROUNDUP((TODAY()-K27)/G27,0)))
A28: 23 | C28: =IF(B28="","",IFERROR(INDEX(tb_pcm_ativos[descricao_ativo],MATCH(B28,tb_pcm_ativos[tag],0)),"fora do cadastro")) | L28: =IF(OR(K28="",G28="",G28=0),"",IF(K28>=TODAY(),K28,K28+G28*ROUNDUP((TODAY()-K28)/G28,0)))
A29: 24 | C29: =IF(B29="","",IFERROR(INDEX(tb_pcm_ativos[descricao_ativo],MATCH(B29,tb_pcm_ativos[tag],0)),"fora do cadastro")) | L29: =IF(OR(K29="",G29="",G29=0),"",IF(K29>=TODAY(),K29,K29+G29*ROUNDUP((TODAY()-K29)/G29,0)))
A30: 25 | C30: =IF(B30="","",IFERROR(INDEX(tb_pcm_ativos[descricao_ativo],MATCH(B30,tb_pcm_ativos[tag],0)),"fora do cadastro")) | L30: =IF(OR(K30="",G30="",G30=0),"",IF(K30>=TODAY(),K30,K30+G30*ROUNDUP((TODAY()-K30)/G30,0)))
A31: Cinza = vem da FMECA ou é calculado. ● Próxima execução nos próximos 7 dias ● Exige parada da máquina

Sheet Cronograma
E1: Cronograma | AY1: ="Rev. "&'Leia-me'!$D$15&" · "&'Leia-me'!$D$16 -> Rev. 00 · 30/Out/2026
E2: Objetivo: Semanas de cada mês em que cada atividade do Plano deve ser feita | AY2: ="Elaborado: "&'Leia-me'!$D$13&" · Aprovado: "&'Leia-me'!$D$14 -> Elaborado: · Aprovado:
A3: Ano ▼ | D3: Semana de hoje | F3: Atividades na semana de hoje | AJ3: Horas planejadas no ano
D4: =IF(YEAR(TODAY())=IF(N($A$4)>0,N($A$4),IF(ISNUMBER(--$A$4),--$A$4,YEAR(TODAY()))),CHOOSE(MONTH(TODAY()),"Jan","Fev","Mar","Abr","Mai","Jun","Jul","Ago","Set","Out","Nov","Dez")&" · "&MIN(5,INT((DAY(TODAY())-1)/7)+1)&"ª semana","") | F4: =IF(D4="","",COUNTIF(INDEX($F$8:$BM$33,0,IF(YEAR(TODAY())=IF(N($A$4)>0,N($A$4),IF(ISNUMBER(--$A$4),--$A$4,YEAR(TODAY()))),(MONTH(TODAY())-1)*5+MIN(5,INT((DAY(TODAY())-1)/7)+1),"")),"●")&" atividade(s) com data nesta semana") | AJ4: =IF(SUM(F34:BM34)=0,"",SUM(F34:BM34))
F5: =IF(MONTH(DATE(IF(N($A$4)>0,N($A$4),IF(ISNUMBER(--$A$4),--$A$4,YEAR(TODAY()))),1,1))=1,DATE(IF(N($A$4)>0,N($A$4),IF(ISNUMBER(--$A$4),--$A$4,YEAR(TODAY()))),1,1),"") -> 1 | G5: =IF(MONTH(DATE(IF(N($A$4)>0,N($A$4),IF(ISNUMBER(--$A$4),--$A$4,YEAR(TODAY()))),1,8))=1,DATE(IF(N($A$4)>0,N($A$4),IF(ISNUMBER(--$A$4),--$A$4,YEAR(TODAY()))),1,8),"") -> 8 | H5: =IF(MONTH(DATE(IF(N($A$4)>0,N($A$4),IF(ISNUMBER(--$A$4),--$A$4,YEAR(TODAY()))),1,15))=1,DATE(IF(N($A$4)>0,N($A$4),IF(ISNUMBER(--$A$4),--$A$4,YEAR(TODAY()))),1,15),"") -> 15 | I5: =IF(MONTH(DATE(IF(N($A$4)>0,N($A$4),IF(ISNUMBER(--$A$4),--$A$4,YEAR(TODAY()))),1,22))=1,DATE(IF(N($A$4)>0,N($A$4),IF(ISNUMBER(--$A$4),--$A$4,YEAR(TODAY()))),1,22),"") -> 22 | J5: =IF(MONTH(DATE(IF(N($A$4)>0,N($A$4),IF(ISNUMBER(--$A$4),--$A$4,YEAR(TODAY()))),1,29))=1,DATE(IF(N($A$4)>0,N($A$4),IF(ISNUMBER(--$A$4),--$A$4,YEAR(TODAY()))),1,29),"") -> 29 | K5: =IF(MONTH(DATE(IF(N($A$4)>0,N($A$4),IF(ISNUMBER(--$A$4),--$A$4,YEAR(TODAY()))),2,1))=2,DATE(IF(N($A$4)>0,N($A$4),IF(ISNUMBER(--$A$4),--$A$4,YEAR(TODAY()))),2,1),"") -> 32 | L5: =IF(MONTH(DATE(IF(N($A$4)>0,N($A$4),IF(ISNUMBER(--$A$4),--$A$4,YEAR(TODAY()))),2,8))=2,DATE(IF(N($A$4)>0,N($A$4),IF(ISNUMBER(--$A$4),--$A$4,YEAR(TODAY()))),2,8),"") -> 39 | M5: =IF(MONTH(DATE(IF(N($A$4)>0,N($A$4),IF(ISNUMBER(--$A$4),--$A$4,YEAR(TODAY()))),2,15))=2,DATE(IF(N($A$4)>0,N($A$4),IF(ISNUMBER(--$A$4),--$A$4,YEAR(TODAY()))),2,15),"") -> 46 | N5: =IF(MONTH(DATE(IF(N($A$4)>0,N($A$4),IF(ISNUMBER(--$A$4),--$A$4,YEAR(TODAY()))),2,22))=2,DATE(IF(N($A$4)>0,N($A$4),IF(ISNUMBER(--$A$4),--$A$4,YEAR(TODAY()))),2,22),"") -> 53 | O5: =IF(MONTH(DATE(IF(N($A$4)>0,N($A$4),IF(ISNUMBER(--$A$4),--$A$4,YEAR(TODAY()))),2,29))=2,DATE(IF(N($A$4)>0,N($A$4),IF(ISNUMBER(--$A$4),--$A$4,YEAR(TODAY()))),2,29),"") -> 60 | P5: =IF(MONTH(DATE(IF(N($A$4)>0,N($A$4),IF(ISNUMBER(--$A$4),--$A$4,YEAR(TODAY()))),3,1))=3,DATE(IF(N($A$4)>0,N($A$4),IF(ISNUMBER(--$A$4),--$A$4,YEAR(TODAY()))),3,1),"") -> 61 | Q5: =IF(MONTH(DATE(IF(N($A$4)>0,N($A$4),IF(ISNUMBER(--$A$4),--$A$4,YEAR(TODAY()))),3,8))=3,DATE(IF(N($A$4)>0,N($A$4),IF(ISNUMBER(--$A$4),--$A$4,YEAR(TODAY()))),3,8),"") -> 68 | R5: =IF(MONTH(DATE(IF(N($A$4)>0,N($A$4),IF(ISNUMBER(--$A$4),--$A$4,YEAR(TODAY()))),3,15))=3,DATE(IF(N($A$4)>0,N($A$4),IF(ISNUMBER(--$A$4),--$A$4,YEAR(TODAY()))),3,15),"") -> 75 | S5: =IF(MONTH(DATE(IF(N($A$4)>0,N($A$4),IF(ISNUMBER(--$A$4),--$A$4,YEAR(TODAY()))),3,22))=3,DATE(IF(N($A$4)>0,N($A$4),IF(ISNUMBER(--$A$4),--$A$4,YEAR(TODAY()))),3,22),"") -> 82 | T5: =IF(MONTH(DATE(IF(N($A$4)>0,N($A$4),IF(ISNUMBER(--$A$4),--$A$4,YEAR(TODAY()))),3,29))=3,DATE(IF(N($A$4)>0,N($A$4),IF(ISNUMBER(--$A$4),--$A$4,YEAR(TODAY()))),3,29),"") -> 89 | U5: =IF(MONTH(DATE(IF(N($A$4)>0,N($A$4),IF(ISNUMBER(--$A$4),--$A$4,YEAR(TODAY()))),4,1))=4,DATE(IF(N($A$4)>0,N($A$4),IF(ISNUMBER(--$A$4),--$A$4,YEAR(TODAY()))),4,1),"") -> 92 | V5: =IF(MONTH(DATE(IF(N($A$4)>0,N($A$4),IF(ISNUMBER(--$A$4),--$A$4,YEAR(TODAY()))),4,8))=4,DATE(IF(N($A$4)>0,N($A$4),IF(ISNUMBER(--$A$4),--$A$4,YEAR(TODAY()))),4,8),"") -> 99 | W5: =IF(MONTH(DATE(IF(N($A$4)>0,N($A$4),IF(ISNUMBER(--$A$4),--$A$4,YEAR(TODAY()))),4,15))=4,DATE(IF(N($A$4)>0,N($A$4),IF(ISNUMBER(--$A$4),--$A$4,YEAR(TODAY()))),4,15),"") -> 106 | X5: =IF(MONTH(DATE(IF(N($A$4)>0,N($A$4),IF(ISNUMBER(--$A$4),--$A$4,YEAR(TODAY()))),4,22))=4,DATE(IF(N($A$4)>0,N($A$4),IF(ISNUMBER(--$A$4),--$A$4,YEAR(TODAY()))),4,22),"") -> 113 | Y5: =IF(MONTH(DATE(IF(N($A$4)>0,N($A$4),IF(ISNUMBER(--$A$4),--$A$4,YEAR(TODAY()))),4,29))=4,DATE(IF(N($A$4)>0,N($A$4),IF(ISNUMBER(--$A$4),--$A$4,YEAR(TODAY()))),4,29),"") -> 120 | Z5: =IF(MONTH(DATE(IF(N($A$4)>0,N($A$4),IF(ISNUMBER(--$A$4),--$A$4,YEAR(TODAY()))),5,1))=5,DATE(IF(N($A$4)>0,N($A$4),IF(ISNUMBER(--$A$4),--$A$4,YEAR(TODAY()))),5,1),"") -> 122 | AA5: =IF(MONTH(DATE(IF(N($A$4)>0,N($A$4),IF(ISNUMBER(--$A$4),--$A$4,YEAR(TODAY()))),5,8))=5,DATE(IF(N($A$4)>0,N($A$4),IF(ISNUMBER(--$A$4),--$A$4,YEAR(TODAY()))),5,8),"") -> 129 | AB5: =IF(MONTH(DATE(IF(N($A$4)>0,N($A$4),IF(ISNUMBER(--$A$4),--$A$4,YEAR(TODAY()))),5,15))=5,DATE(IF(N($A$4)>0,N($A$4),IF(ISNUMBER(--$A$4),--$A$4,YEAR(TODAY()))),5,15),"") -> 136 | AC5: =IF(MONTH(DATE(IF(N($A$4)>0,N($A$4),IF(ISNUMBER(--$A$4),--$A$4,YEAR(TODAY()))),5,22))=5,DATE(IF(N($A$4)>0,N($A$4),IF(ISNUMBER(--$A$4),--$A$4,YEAR(TODAY()))),5,22),"") -> 143 | AD5: =IF(MONTH(DATE(IF(N($A$4)>0,N($A$4),IF(ISNUMBER(--$A$4),--$A$4,YEAR(TODAY()))),5,29))=5,DATE(IF(N($A$4)>0,N($A$4),IF(ISNUMBER(--$A$4),--$A$4,YEAR(TODAY()))),5,29),"") -> 150 | AE5: =IF(MONTH(DATE(IF(N($A$4)>0,N($A$4),IF(ISNUMBER(--$A$4),--$A$4,YEAR(TODAY()))),6,1))=6,DATE(IF(N($A$4)>0,N($A$4),IF(ISNUMBER(--$A$4),--$A$4,YEAR(TODAY()))),6,1),"") -> 153 | AF5: =IF(MONTH(DATE(IF(N($A$4)>0,N($A$4),IF(ISNUMBER(--$A$4),--$A$4,YEAR(TODAY()))),6,8))=6,DATE(IF(N($A$4)>0,N($A$4),IF(ISNUMBER(--$A$4),--$A$4,YEAR(TODAY()))),6,8),"") -> 160 | AG5: =IF(MONTH(DATE(IF(N($A$4)>0,N($A$4),IF(ISNUMBER(--$A$4),--$A$4,YEAR(TODAY()))),6,15))=6,DATE(IF(N($A$4)>0,N($A$4),IF(ISNUMBER(--$A$4),--$A$4,YEAR(TODAY()))),6,15),"") -> 167 | AH5: =IF(MONTH(DATE(IF(N($A$4)>0,N($A$4),IF(ISNUMBER(--$A$4),--$A$4,YEAR(TODAY()))),6,22))=6,DATE(IF(N($A$4)>0,N($A$4),IF(ISNUMBER(--$A$4),--$A$4,YEAR(TODAY()))),6,22),"") -> 174 | AI5: =IF(MONTH(DATE(IF(N($A$4)>0,N($A$4),IF(ISNUMBER(--$A$4),--$A$4,YEAR(TODAY()))),6,29))=6,DATE(IF(N($A$4)>0,N($A$4),IF(ISNUMBER(--$A$4),--$A$4,YEAR(TODAY()))),6,29),"") -> 181 | AJ5: =IF(MONTH(DATE(IF(N($A$4)>0,N($A$4),IF(ISNUMBER(--$A$4),--$A$4,YEAR(TODAY()))),7,1))=7,DATE(IF(N($A$4)>0,N($A$4),IF(ISNUMBER(--$A$4),--$A$4,YEAR(TODAY()))),7,1),"") -> 183 | AK5: =IF(MONTH(DATE(IF(N($A$4)>0,N($A$4),IF(ISNUMBER(--$A$4),--$A$4,YEAR(TODAY()))),7,8))=7,DATE(IF(N($A$4)>0,N($A$4),IF(ISNUMBER(--$A$4),--$A$4,YEAR(TODAY()))),7,8),"") -> 190 | AL5: =IF(MONTH(DATE(IF(N($A$4)>0,N($A$4),IF(ISNUMBER(--$A$4),--$A$4,YEAR(TODAY()))),7,15))=7,DATE(IF(N($A$4)>0,N($A$4),IF(ISNUMBER(--$A$4),--$A$4,YEAR(TODAY()))),7,15),"") -> 197 | AM5: =IF(MONTH(DATE(IF(N($A$4)>0,N($A$4),IF(ISNUMBER(--$A$4),--$A$4,YEAR(TODAY()))),7,22))=7,DATE(IF(N($A$4)>0,N($A$4),IF(ISNUMBER(--$A$4),--$A$4,YEAR(TODAY()))),7,22),"") -> 204 | AN5: =IF(MONTH(DATE(IF(N($A$4)>0,N($A$4),IF(ISNUMBER(--$A$4),--$A$4,YEAR(TODAY()))),7,29))=7,DATE(IF(N($A$4)>0,N($A$4),IF(ISNUMBER(--$A$4),--$A$4,YEAR(TODAY()))),7,29),"") -> 211 | AO5: =IF(MONTH(DATE(IF(N($A$4)>0,N($A$4),IF(ISNUMBER(--$A$4),--$A$4,YEAR(TODAY()))),8,1))=8,DATE(IF(N($A$4)>0,N($A$4),IF(ISNUMBER(--$A$4),--$A$4,YEAR(TODAY()))),8,1),"") -> 214 | AP5: =IF(MONTH(DATE(IF(N($A$4)>0,N($A$4),IF(ISNUMBER(--$A$4),--$A$4,YEAR(TODAY()))),8,8))=8,DATE(IF(N($A$4)>0,N($A$4),IF(ISNUMBER(--$A$4),--$A$4,YEAR(TODAY()))),8,8),"") -> 221 | AQ5: =IF(MONTH(DATE(IF(N($A$4)>0,N($A$4),IF(ISNUMBER(--$A$4),--$A$4,YEAR(TODAY()))),8,15))=8,DATE(IF(N($A$4)>0,N($A$4),IF(ISNUMBER(--$A$4),--$A$4,YEAR(TODAY()))),8,15),"") -> 228 | AR5: =IF(MONTH(DATE(IF(N($A$4)>0,N($A$4),IF(ISNUMBER(--$A$4),--$A$4,YEAR(TODAY()))),8,22))=8,DATE(IF(N($A$4)>0,N($A$4),IF(ISNUMBER(--$A$4),--$A$4,YEAR(TODAY()))),8,22),"") -> 235 | AS5: =IF(MONTH(DATE(IF(N($A$4)>0,N($A$4),IF(ISNUMBER(--$A$4),--$A$4,YEAR(TODAY()))),8,29))=8,DATE(IF(N($A$4)>0,N($A$4),IF(ISNUMBER(--$A$4),--$A$4,YEAR(TODAY()))),8,29),"") -> 242 | AT5: =IF(MONTH(DATE(IF(N($A$4)>0,N($A$4),IF(ISNUMBER(--$A$4),--$A$4,YEAR(TODAY()))),9,1))=9,DATE(IF(N($A$4)>0,N($A$4),IF(ISNUMBER(--$A$4),--$A$4,YEAR(TODAY()))),9,1),"") -> 245 | AU5: =IF(MONTH(DATE(IF(N($A$4)>0,N($A$4),IF(ISNUMBER(--$A$4),--$A$4,YEAR(TODAY()))),9,8))=9,DATE(IF(N($A$4)>0,N($A$4),IF(ISNUMBER(--$A$4),--$A$4,YEAR(TODAY()))),9,8),"") -> 252 | AV5: =IF(MONTH(DATE(IF(N($A$4)>0,N($A$4),IF(ISNUMBER(--$A$4),--$A$4,YEAR(TODAY()))),9,15))=9,DATE(IF(N($A$4)>0,N($A$4),IF(ISNUMBER(--$A$4),--$A$4,YEAR(TODAY()))),9,15),"") -> 259 | AW5: =IF(MONTH(DATE(IF(N($A$4)>0,N($A$4),IF(ISNUMBER(--$A$4),--$A$4,YEAR(TODAY()))),9,22))=9,DATE(IF(N($A$4)>0,N($A$4),IF(ISNUMBER(--$A$4),--$A$4,YEAR(TODAY()))),9,22),"") -> 266 | AX5: =IF(MONTH(DATE(IF(N($A$4)>0,N($A$4),IF(ISNUMBER(--$A$4),--$A$4,YEAR(TODAY()))),9,29))=9,DATE(IF(N($A$4)>0,N($A$4),IF(ISNUMBER(--$A$4),--$A$4,YEAR(TODAY()))),9,29),"") -> 273 | AY5: =IF(MONTH(DATE(IF(N($A$4)>0,N($A$4),IF(ISNUMBER(--$A$4),--$A$4,YEAR(TODAY()))),10,1))=10,DATE(IF(N($A$4)>0,N($A$4),IF(ISNUMBER(--$A$4),--$A$4,YEAR(TODAY()))),10,1),"") -> 275 | AZ5: =IF(MONTH(DATE(IF(N($A$4)>0,N($A$4),IF(ISNUMBER(--$A$4),--$A$4,YEAR(TODAY()))),10,8))=10,DATE(IF(N($A$4)>0,N($A$4),IF(ISNUMBER(--$A$4),--$A$4,YEAR(TODAY()))),10,8),"") -> 282 | BA5: =IF(MONTH(DATE(IF(N($A$4)>0,N($A$4),IF(ISNUMBER(--$A$4),--$A$4,YEAR(TODAY()))),10,15))=10,DATE(IF(N($A$4)>0,N($A$4),IF(ISNUMBER(--$A$4),--$A$4,YEAR(TODAY()))),10,15),"") -> 289 | BB5: =IF(MONTH(DATE(IF(N($A$4)>0,N($A$4),IF(ISNUMBER(--$A$4),--$A$4,YEAR(TODAY()))),10,22))=10,DATE(IF(N($A$4)>0,N($A$4),IF(ISNUMBER(--$A$4),--$A$4,YEAR(TODAY()))),10,22),"") -> 296 | BC5: =IF(MONTH(DATE(IF(N($A$4)>0,N($A$4),IF(ISNUMBER(--$A$4),--$A$4,YEAR(TODAY()))),10,29))=10,DATE(IF(N($A$4)>0,N($A$4),IF(ISNUMBER(--$A$4),--$A$4,YEAR(TODAY()))),10,29),"") -> 303 | BD5: =IF(MONTH(DATE(IF(N($A$4)>0,N($A$4),IF(ISNUMBER(--$A$4),--$A$4,YEAR(TODAY()))),11,1))=11,DATE(IF(N($A$4)>0,N($A$4),IF(ISNUMBER(--$A$4),--$A$4,YEAR(TODAY()))),11,1),"") -> 306 | BE5: =IF(MONTH(DATE(IF(N($A$4)>0,N($A$4),IF(ISNUMBER(--$A$4),--$A$4,YEAR(TODAY()))),11,8))=11,DATE(IF(N($A$4)>0,N($A$4),IF(ISNUMBER(--$A$4),--$A$4,YEAR(TODAY()))),11,8),"") -> 313 | BF5: =IF(MONTH(DATE(IF(N($A$4)>0,N($A$4),IF(ISNUMBER(--$A$4),--$A$4,YEAR(TODAY()))),11,15))=11,DATE(IF(N($A$4)>0,N($A$4),IF(ISNUMBER(--$A$4),--$A$4,YEAR(TODAY()))),11,15),"") -> 320 | BG5: =IF(MONTH(DATE(IF(N($A$4)>0,N($A$4),IF(ISNUMBER(--$A$4),--$A$4,YEAR(TODAY()))),11,22))=11,DATE(IF(N($A$4)>0,N($A$4),IF(ISNUMBER(--$A$4),--$A$4,YEAR(TODAY()))),11,22),"") -> 327 | BH5: =IF(MONTH(DATE(IF(N($A$4)>0,N($A$4),IF(ISNUMBER(--$A$4),--$A$4,YEAR(TODAY()))),11,29))=11,DATE(IF(N($A$4)>0,N($A$4),IF(ISNUMBER(--$A$4),--$A$4,YEAR(TODAY()))),11,29),"") -> 334 | BI5: =IF(MONTH(DATE(IF(N($A$4)>0,N($A$4),IF(ISNUMBER(--$A$4),--$A$4,YEAR(TODAY()))),12,1))=12,DATE(IF(N($A$4)>0,N($A$4),IF(ISNUMBER(--$A$4),--$A$4,YEAR(TODAY()))),12,1),"") -> 336 | BJ5: =IF(MONTH(DATE(IF(N($A$4)>0,N($A$4),IF(ISNUMBER(--$A$4),--$A$4,YEAR(TODAY()))),12,8))=12,DATE(IF(N($A$4)>0,N($A$4),IF(ISNUMBER(--$A$4),--$A$4,YEAR(TODAY()))),12,8),"") -> 343 | BK5: =IF(MONTH(DATE(IF(N($A$4)>0,N($A$4),IF(ISNUMBER(--$A$4),--$A$4,YEAR(TODAY()))),12,15))=12,DATE(IF(N($A$4)>0,N($A$4),IF(ISNUMBER(--$A$4),--$A$4,YEAR(TODAY()))),12,15),"") -> 350 | BL5: =IF(MONTH(DATE(IF(N($A$4)>0,N($A$4),IF(ISNUMBER(--$A$4),--$A$4,YEAR(TODAY()))),12,22))=12,DATE(IF(N($A$4)>0,N($A$4),IF(ISNUMBER(--$A$4),--$A$4,YEAR(TODAY()))),12,22),"") -> 357 | BM5: =IF(MONTH(DATE(IF(N($A$4)>0,N($A$4),IF(ISNUMBER(--$A$4),--$A$4,YEAR(TODAY()))),12,29))=12,DATE(IF(N($A$4)>0,N($A$4),IF(ISNUMBER(--$A$4),--$A$4,YEAR(TODAY()))),12,29),"") -> 364
A6: Atividade (vem do Plano) | F6: JAN | K6: FEV | P6: MAR | U6: ABR | Z6: MAI | AE6: JUN | AJ6: JUL | AO6: AGO | AT6: SET | AY6: OUT | BD6: NOV | BI6: DEZ
A7: Nº | B7: TAG | C7: Equipamento | D7: Atividade | E7: A cada (dias) | F7: 1 | G7: 2 | H7: 3 | I7: 4 | J7: =IF(ISNUMBER(J$5),5,"–") -> 5 | K7: 1 | L7: 2 | M7: 3 | N7: 4 | O7: =IF(ISNUMBER(O$5),5,"–") -> 5 | P7: 1 | Q7: 2 | R7: 3 | S7: 4 | T7: =IF(ISNUMBER(T$5),5,"–") -> 5 | U7: 1 | V7: 2 | W7: 3 | X7: 4 | Y7: =IF(ISNUMBER(Y$5),5,"–") -> 5 | Z7: 1 | AA7: 2 | AB7: 3 | AC7: 4 | AD7: =IF(ISNUMBER(AD$5),5,"–") -> 5 | AE7: 1 | AF7: 2 | AG7: 3 | AH7: 4 | AI7: =IF(ISNUMBER(AI$5),5,"–") -> 5 | AJ7: 1 | AK7: 2 | AL7: 3 | AM7: 4 | AN7: =IF(ISNUMBER(AN$5),5,"–") -> 5 | AO7: 1 | AP7: 2 | AQ7: 3 | AR7: 4 | AS7: =IF(ISNUMBER(AS$5),5,"–") -> 5 | AT7: 1 | AU7: 2 | AV7: 3 | AW7: 4 | AX7: =IF(ISNUMBER(AX$5),5,"–") -> 5 | AY7: 1 | AZ7: 2 | BA7: 3 | BB7: 4 | BC7: =IF(ISNUMBER(BC$5),5,"–") -> 5 | BD7: 1 | BE7: 2 | BF7: 3 | BG7: 4 | BH7: =IF(ISNUMBER(BH$5),5,"–") -> 5 | BI7: 1 | BJ7: 2 | BK7: 3 | BL7: 4 | BM7: =IF(ISNUMBER(BM$5),5,"–") -> 5
A8: =Plano!A5 -> 1 | B8: =IF(Plano!B5="","",Plano!B5) | C8: =IF(B8="","",IFERROR(INDEX(tb_pcm_ativos[descricao_ativo],MATCH(B8,tb_pcm_ativos[tag],0)),"fora do cadastro")) | D8: =IF(Plano!E5="","",Plano!E5) | E8: =IF(Plano!G5="","",Plano!G5) | F8: =IF(OR(NOT(ISNUMBER(F$5)),N(Plano!$G5)=0,N(Plano!$K5)=0),"",IF(Plano!$K5+Plano!$G5*MAX(0,ROUNDUP((F$5-Plano!$K5)/Plano!$G5,0))<=IF(DAY(F$5)>=29,EOMONTH(F$5,0),F$5+6),"●","")) | G8: =IF(OR(NOT(ISNUMBER(G$5)),N(Plano!$G5)=0,N(Plano!$K5)=0),"",IF(Plano!$K5+Plano!$G5*MAX(0,ROUNDUP((G$5-Plano!$K5)/Plano!$G5,0))<=IF(DAY(G$5)>=29,EOMONTH(G$5,0),G$5+6),"●","")) | H8: =IF(OR(NOT(ISNUMBER(H$5)),N(Plano!$G5)=0,N(Plano!$K5)=0),"",IF(Plano!$K5+Plano!$G5*MAX(0,ROUNDUP((H$5-Plano!$K5)/Plano!$G5,0))<=IF(DAY(H$5)>=29,EOMONTH(H$5,0),H$5+6),"●","")) | I8: =IF(OR(NOT(ISNUMBER(I$5)),N(Plano!$G5)=0,N(Plano!$K5)=0),"",IF(Plano!$K5+Plano!$G5*MAX(0,ROUNDUP((I$5-Plano!$K5)/Plano!$G5,0))<=IF(DAY(I$5)>=29,EOMONTH(I$5,0),I$5+6),"●","")) | J8: =IF(OR(NOT(ISNUMBER(J$5)),N(Plano!$G5)=0,N(Plano!$K5)=0),"",IF(Plano!$K5+Plano!$G5*MAX(0,ROUNDUP((J$5-Plano!$K5)/Plano!$G5,0))<=IF(DAY(J$5)>=29,EOMONTH(J$5,0),J$5+6),"●","")) | K8: =IF(OR(NOT(ISNUMBER(K$5)),N(Plano!$G5)=0,N(Plano!$K5)=0),"",IF(Plano!$K5+Plano!$G5*MAX(0,ROUNDUP((K$5-Plano!$K5)/Plano!$G5,0))<=IF(DAY(K$5)>=29,EOMONTH(K$5,0),K$5+6),"●","")) | L8: =IF(OR(NOT(ISNUMBER(L$5)),N(Plano!$G5)=0,N(Plano!$K5)=0),"",IF(Plano!$K5+Plano!$G5*MAX(0,ROUNDUP((L$5-Plano!$K5)/Plano!$G5,0))<=IF(DAY(L$5)>=29,EOMONTH(L$5,0),L$5+6),"●","")) | M8: =IF(OR(NOT(ISNUMBER(M$5)),N(Plano!$G5)=0,N(Plano!$K5)=0),"",IF(Plano!$K5+Plano!$G5*MAX(0,ROUNDUP((M$5-Plano!$K5)/Plano!$G5,0))<=IF(DAY(M$5)>=29,EOMONTH(M$5,0),M$5+6),"●","")) | ... BM8: =IF(OR(NOT(ISNUMBER(BM$5)),N(Plano!$G5)=0,N(Plano!$K5)=0),"",IF(Plano!$K5+Plano!$G5*MAX(0,ROUNDUP((BM$5-Plano!$K5)/Plano!$G5,0))<=IF(DAY(BM$5)>=29,EOMONTH(BM$5,0),BM$5+6),"●",""))
A9: =Plano!A6 -> 2 | B9: =IF(Plano!B6="","",Plano!B6) | C9: =IF(B9="","",IFERROR(INDEX(tb_pcm_ativos[descricao_ativo],MATCH(B9,tb_pcm_ativos[tag],0)),"fora do cadastro")) | D9: =IF(Plano!E6="","",Plano!E6) | E9: =IF(Plano!G6="","",Plano!G6) | F9: =IF(OR(NOT(ISNUMBER(F$5)),N(Plano!$G6)=0,N(Plano!$K6)=0),"",IF(Plano!$K6+Plano!$G6*MAX(0,ROUNDUP((F$5-Plano!$K6)/Plano!$G6,0))<=IF(DAY(F$5)>=29,EOMONTH(F$5,0),F$5+6),"●","")) | G9: =IF(OR(NOT(ISNUMBER(G$5)),N(Plano!$G6)=0,N(Plano!$K6)=0),"",IF(Plano!$K6+Plano!$G6*MAX(0,ROUNDUP((G$5-Plano!$K6)/Plano!$G6,0))<=IF(DAY(G$5)>=29,EOMONTH(G$5,0),G$5+6),"●","")) | H9: =IF(OR(NOT(ISNUMBER(H$5)),N(Plano!$G6)=0,N(Plano!$K6)=0),"",IF(Plano!$K6+Plano!$G6*MAX(0,ROUNDUP((H$5-Plano!$K6)/Plano!$G6,0))<=IF(DAY(H$5)>=29,EOMONTH(H$5,0),H$5+6),"●","")) | I9: =IF(OR(NOT(ISNUMBER(I$5)),N(Plano!$G6)=0,N(Plano!$K6)=0),"",IF(Plano!$K6+Plano!$G6*MAX(0,ROUNDUP((I$5-Plano!$K6)/Plano!$G6,0))<=IF(DAY(I$5)>=29,EOMONTH(I$5,0),I$5+6),"●","")) | J9: =IF(OR(NOT(ISNUMBER(J$5)),N(Plano!$G6)=0,N(Plano!$K6)=0),"",IF(Plano!$K6+Plano!$G6*MAX(0,ROUNDUP((J$5-Plano!$K6)/Plano!$G6,0))<=IF(DAY(J$5)>=29,EOMONTH(J$5,0),J$5+6),"●","")) | K9: =IF(OR(NOT(ISNUMBER(K$5)),N(Plano!$G6)=0,N(Plano!$K6)=0),"",IF(Plano!$K6+Plano!$G6*MAX(0,ROUNDUP((K$5-Plano!$K6)/Plano!$G6,0))<=IF(DAY(K$5)>=29,EOMONTH(K$5,0),K$5+6),"●","")) | L9: =IF(OR(NOT(ISNUMBER(L$5)),N(Plano!$G6)=0,N(Plano!$K6)=0),"",IF(Plano!$K6+Plano!$G6*MAX(0,ROUNDUP((L$5-Plano!$K6)/Plano!$G6,0))<=IF(DAY(L$5)>=29,EOMONTH(L$5,0),L$5+6),"●","")) | M9: =IF(OR(NOT(ISNUMBER(M$5)),N(Plano!$G6)=0,N(Plano!$K6)=0),"",IF(Plano!$K6+Plano!$G6*MAX(0,ROUNDUP((M$5-Plano!$K6)/Plano!$G6,0))<=IF(DAY(M$5)>=29,EOMONTH(M$5,0),M$5+6),"●","")) | ... BM9: =IF(OR(NOT(ISNUMBER(BM$5)),N(Plano!$G6)=0,N(Plano!$K6)=0),"",IF(Plano!$K6+Plano!$G6*MAX(0,ROUNDUP((BM$5-Plano!$K6)/Plano!$G6,0))<=IF(DAY(BM$5)>=29,EOMONTH(BM$5,0),BM$5+6),"●",""))
A10: =Plano!A7 -> 3 | B10: =IF(Plano!B7="","",Plano!B7) | C10: =IF(B10="","",IFERROR(INDEX(tb_pcm_ativos[descricao_ativo],MATCH(B10,tb_pcm_ativos[tag],0)),"fora do cadastro")) | D10: =IF(Plano!E7="","",Plano!E7) | E10: =IF(Plano!G7="","",Plano!G7) | F10: =IF(OR(NOT(ISNUMBER(F$5)),N(Plano!$G7)=0,N(Plano!$K7)=0),"",IF(Plano!$K7+Plano!$G7*MAX(0,ROUNDUP((F$5-Plano!$K7)/Plano!$G7,0))<=IF(DAY(F$5)>=29,EOMONTH(F$5,0),F$5+6),"●","")) | G10: =IF(OR(NOT(ISNUMBER(G$5)),N(Plano!$G7)=0,N(Plano!$K7)=0),"",IF(Plano!$K7+Plano!$G7*MAX(0,ROUNDUP((G$5-Plano!$K7)/Plano!$G7,0))<=IF(DAY(G$5)>=29,EOMONTH(G$5,0),G$5+6),"●","")) | H10: =IF(OR(NOT(ISNUMBER(H$5)),N(Plano!$G7)=0,N(Plano!$K7)=0),"",IF(Plano!$K7+Plano!$G7*MAX(0,ROUNDUP((H$5-Plano!$K7)/Plano!$G7,0))<=IF(DAY(H$5)>=29,EOMONTH(H$5,0),H$5+6),"●","")) | I10: =IF(OR(NOT(ISNUMBER(I$5)),N(Plano!$G7)=0,N(Plano!$K7)=0),"",IF(Plano!$K7+Plano!$G7*MAX(0,ROUNDUP((I$5-Plano!$K7)/Plano!$G7,0))<=IF(DAY(I$5)>=29,EOMONTH(I$5,0),I$5+6),"●","")) | J10: =IF(OR(NOT(ISNUMBER(J$5)),N(Plano!$G7)=0,N(Plano!$K7)=0),"",IF(Plano!$K7+Plano!$G7*MAX(0,ROUNDUP((J$5-Plano!$K7)/Plano!$G7,0))<=IF(DAY(J$5)>=29,EOMONTH(J$5,0),J$5+6),"●","")) | K10: =IF(OR(NOT(ISNUMBER(K$5)),N(Plano!$G7)=0,N(Plano!$K7)=0),"",IF(Plano!$K7+Plano!$G7*MAX(0,ROUNDUP((K$5-Plano!$K7)/Plano!$G7,0))<=IF(DAY(K$5)>=29,EOMONTH(K$5,0),K$5+6),"●","")) | L10: =IF(OR(NOT(ISNUMBER(L$5)),N(Plano!$G7)=0,N(Plano!$K7)=0),"",IF(Plano!$K7+Plano!$G7*MAX(0,ROUNDUP((L$5-Plano!$K7)/Plano!$G7,0))<=IF(DAY(L$5)>=29,EOMONTH(L$5,0),L$5+6),"●","")) | M10: =IF(OR(NOT(ISNUMBER(M$5)),N(Plano!$G7)=0,N(Plano!$K7)=0),"",IF(Plano!$K7+Plano!$G7*MAX(0,ROUNDUP((M$5-Plano!$K7)/Plano!$G7,0))<=IF(DAY(M$5)>=29,EOMONTH(M$5,0),M$5+6),"●","")) | ... BM10: =IF(OR(NOT(ISNUMBER(BM$5)),N(Plano!$G7)=0,N(Plano!$K7)=0),"",IF(Plano!$K7+Plano!$G7*MAX(0,ROUNDUP((BM$5-Plano!$K7)/Plano!$G7,0))<=IF(DAY(BM$5)>=29,EOMONTH(BM$5,0),BM$5+6),"●",""))
A11: =Plano!A8 -> 4 | B11: =IF(Plano!B8="","",Plano!B8) | C11: =IF(B11="","",IFERROR(INDEX(tb_pcm_ativos[descricao_ativo],MATCH(B11,tb_pcm_ativos[tag],0)),"fora do cadastro")) | D11: =IF(Plano!E8="","",Plano!E8) | E11: =IF(Plano!G8="","",Plano!G8) | F11: =IF(OR(NOT(ISNUMBER(F$5)),N(Plano!$G8)=0,N(Plano!$K8)=0),"",IF(Plano!$K8+Plano!$G8*MAX(0,ROUNDUP((F$5-Plano!$K8)/Plano!$G8,0))<=IF(DAY(F$5)>=29,EOMONTH(F$5,0),F$5+6),"●","")) | G11: =IF(OR(NOT(ISNUMBER(G$5)),N(Plano!$G8)=0,N(Plano!$K8)=0),"",IF(Plano!$K8+Plano!$G8*MAX(0,ROUNDUP((G$5-Plano!$K8)/Plano!$G8,0))<=IF(DAY(G$5)>=29,EOMONTH(G$5,0),G$5+6),"●","")) | H11: =IF(OR(NOT(ISNUMBER(H$5)),N(Plano!$G8)=0,N(Plano!$K8)=0),"",IF(Plano!$K8+Plano!$G8*MAX(0,ROUNDUP((H$5-Plano!$K8)/Plano!$G8,0))<=IF(DAY(H$5)>=29,EOMONTH(H$5,0),H$5+6),"●","")) | I11: =IF(OR(NOT(ISNUMBER(I$5)),N(Plano!$G8)=0,N(Plano!$K8)=0),"",IF(Plano!$K8+Plano!$G8*MAX(0,ROUNDUP((I$5-Plano!$K8)/Plano!$G8,0))<=IF(DAY(I$5)>=29,EOMONTH(I$5,0),I$5+6),"●","")) | J11: =IF(OR(NOT(ISNUMBER(J$5)),N(Plano!$G8)=0,N(Plano!$K8)=0),"",IF(Plano!$K8+Plano!$G8*MAX(0,ROUNDUP((J$5-Plano!$K8)/Plano!$G8,0))<=IF(DAY(J$5)>=29,EOMONTH(J$5,0),J$5+6),"●","")) | K11: =IF(OR(NOT(ISNUMBER(K$5)),N(Plano!$G8)=0,N(Plano!$K8)=0),"",IF(Plano!$K8+Plano!$G8*MAX(0,ROUNDUP((K$5-Plano!$K8)/Plano!$G8,0))<=IF(DAY(K$5)>=29,EOMONTH(K$5,0),K$5+6),"●","")) | L11: =IF(OR(NOT(ISNUMBER(L$5)),N(Plano!$G8)=0,N(Plano!$K8)=0),"",IF(Plano!$K8+Plano!$G8*MAX(0,ROUNDUP((L$5-Plano!$K8)/Plano!$G8,0))<=IF(DAY(L$5)>=29,EOMONTH(L$5,0),L$5+6),"●","")) | M11: =IF(OR(NOT(ISNUMBER(M$5)),N(Plano!$G8)=0,N(Plano!$K8)=0),"",IF(Plano!$K8+Plano!$G8*MAX(0,ROUNDUP((M$5-Plano!$K8)/Plano!$G8,0))<=IF(DAY(M$5)>=29,EOMONTH(M$5,0),M$5+6),"●","")) | ... BM11: =IF(OR(NOT(ISNUMBER(BM$5)),N(Plano!$G8)=0,N(Plano!$K8)=0),"",IF(Plano!$K8+Plano!$G8*MAX(0,ROUNDUP((BM$5-Plano!$K8)/Plano!$G8,0))<=IF(DAY(BM$5)>=29,EOMONTH(BM$5,0),BM$5+6),"●",""))
A12: =Plano!A9 -> 5 | B12: =IF(Plano!B9="","",Plano!B9) | C12: =IF(B12="","",IFERROR(INDEX(tb_pcm_ativos[descricao_ativo],MATCH(B12,tb_pcm_ativos[tag],0)),"fora do cadastro")) | D12: =IF(Plano!E9="","",Plano!E9) | E12: =IF(Plano!G9="","",Plano!G9) | F12: =IF(OR(NOT(ISNUMBER(F$5)),N(Plano!$G9)=0,N(Plano!$K9)=0),"",IF(Plano!$K9+Plano!$G9*MAX(0,ROUNDUP((F$5-Plano!$K9)/Plano!$G9,0))<=IF(DAY(F$5)>=29,EOMONTH(F$5,0),F$5+6),"●","")) | G12: =IF(OR(NOT(ISNUMBER(G$5)),N(Plano!$G9)=0,N(Plano!$K9)=0),"",IF(Plano!$K9+Plano!$G9*MAX(0,ROUNDUP((G$5-Plano!$K9)/Plano!$G9,0))<=IF(DAY(G$5)>=29,EOMONTH(G$5,0),G$5+6),"●","")) | H12: =IF(OR(NOT(ISNUMBER(H$5)),N(Plano!$G9)=0,N(Plano!$K9)=0),"",IF(Plano!$K9+Plano!$G9*MAX(0,ROUNDUP((H$5-Plano!$K9)/Plano!$G9,0))<=IF(DAY(H$5)>=29,EOMONTH(H$5,0),H$5+6),"●","")) | I12: =IF(OR(NOT(ISNUMBER(I$5)),N(Plano!$G9)=0,N(Plano!$K9)=0),"",IF(Plano!$K9+Plano!$G9*MAX(0,ROUNDUP((I$5-Plano!$K9)/Plano!$G9,0))<=IF(DAY(I$5)>=29,EOMONTH(I$5,0),I$5+6),"●","")) | J12: =IF(OR(NOT(ISNUMBER(J$5)),N(Plano!$G9)=0,N(Plano!$K9)=0),"",IF(Plano!$K9+Plano!$G9*MAX(0,ROUNDUP((J$5-Plano!$K9)/Plano!$G9,0))<=IF(DAY(J$5)>=29,EOMONTH(J$5,0),J$5+6),"●","")) | K12: =IF(OR(NOT(ISNUMBER(K$5)),N(Plano!$G9)=0,N(Plano!$K9)=0),"",IF(Plano!$K9+Plano!$G9*MAX(0,ROUNDUP((K$5-Plano!$K9)/Plano!$G9,0))<=IF(DAY(K$5)>=29,EOMONTH(K$5,0),K$5+6),"●","")) | L12: =IF(OR(NOT(ISNUMBER(L$5)),N(Plano!$G9)=0,N(Plano!$K9)=0),"",IF(Plano!$K9+Plano!$G9*MAX(0,ROUNDUP((L$5-Plano!$K9)/Plano!$G9,0))<=IF(DAY(L$5)>=29,EOMONTH(L$5,0),L$5+6),"●","")) | M12: =IF(OR(NOT(ISNUMBER(M$5)),N(Plano!$G9)=0,N(Plano!$K9)=0),"",IF(Plano!$K9+Plano!$G9*MAX(0,ROUNDUP((M$5-Plano!$K9)/Plano!$G9,0))<=IF(DAY(M$5)>=29,EOMONTH(M$5,0),M$5+6),"●","")) | ... BM12: =IF(OR(NOT(ISNUMBER(BM$5)),N(Plano!$G9)=0,N(Plano!$K9)=0),"",IF(Plano!$K9+Plano!$G9*MAX(0,ROUNDUP((BM$5-Plano!$K9)/Plano!$G9,0))<=IF(DAY(BM$5)>=29,EOMONTH(BM$5,0),BM$5+6),"●",""))
