Workbook
Name cad_org_nome: 'Cadastros'!$B$7
Name cad_referencial: 'Cadastros'!$B$8
Name cad_prefixo: 'Cadastros'!$B$9
Name cad_meta_disponibilidade: 'Cadastros'!$B$12
Name cad_pessoa_id: 'Cadastros'!$A$16:$A$35
Name cad_pessoa_nome: 'Cadastros'!$B$16:$B$35
Name cfg_elaborado: 'Config'!$C$19
Name cfg_aprovado: 'Config'!$C$20
Name cfg_revisao: 'Config'!$C$21
Name cfg_data_revisao: 'Config'!$C$22
Name pcmd_origem: 'Config'!$C$23
Name pcmd_emissao: 'Config'!$C$24
Name lst_tipo_documento: 'Listas'!$A$4:$A$13
Name lst_situacao_documento: 'Listas'!$C$4:$C$13
Name lst_sim_nao: 'Listas'!$E$4:$E$5
Name lst_status_requisito: 'Listas'!$G$4:$G$5

Sheet Lista Mestra
C1: Lista mestra de documentos | J1: ="Rev. "&IF(cfg_revisao="","—",cfg_revisao)&IF(ISNUMBER(cfg_data_revisao)," · "&RIGHT("0"&DAY(cfg_data_revisao),2)&"/"&RIGHT("0"&MONTH(cfg_data_revisao),2)&"/"&YEAR(cfg_data_revisao),"")
J2: ="Elaborado: "&IF(cfg_elaborado="","A definir",cfg_elaborado)&CHAR(10)&"Aprovado: "&IF(cfg_aprovado="","A definir",cfg_aprovado)
A3: Código | B3: Título | C3: Tipo | D3: Revisão | E3: Data da revisão | F3: Elaborador | G3: Aprovador | H3: Próxima revisão | I3: Situação | J3: Conferência | K3: Observação
A4: PCMD-01 | B4: Lista mestra de documentos | C4: Planilha (XLSX) | D4: 00 | E4: 46318 | F4: Pessoa A | H4: 46683 | I4: Em elaboração | J4: =IF(A4="","",IF(AND(ISNUMBER(E4),ISNUMBER(H4),H4<E4),"Verificar: próxima revisão anterior à data",IF(AND(G4<>"",I4<>"Aprovado"),"Verificar: aprovador sem situação Aprovado",IF(AND(I4="Aprovado",G4=""),"Verificar: Aprovado sem aprovador","OK")))) | K4: Aguardando aprovação
A5: PCMD-02 | B5: Ativos e criticidade | C5: Planilha (XLSX) | D5: 00 | E5: 46318 | F5: Pessoa A | H5: 46683 | I5: Em elaboração | J5: =IF(A5="","",IF(AND(ISNUMBER(E5),ISNUMBER(H5),H5<E5),"Verificar: próxima revisão anterior à data",IF(AND(G5<>"",I5<>"Aprovado"),"Verificar: aprovador sem situação Aprovado",IF(AND(I5="Aprovado",G5=""),"Verificar: Aprovado sem aprovador","OK")))) | K5: Aguardando aprovação
A6: PCMD-03 | B6: Plano mestre de manutenção | C6: Planilha (XLSX) | D6: 00 | E6: 46318 | F6: Pessoa A | H6: 46683 | I6: Em elaboração | J6: =IF(A6="","",IF(AND(ISNUMBER(E6),ISNUMBER(H6),H6<E6),"Verificar: próxima revisão anterior à data",IF(AND(G6<>"",I6<>"Aprovado"),"Verificar: aprovador sem situação Aprovado",IF(AND(I6="Aprovado",G6=""),"Verificar: Aprovado sem aprovador","OK")))) | K6: Aguardando aprovação
A7: PCMD-04 | B7: Cronograma e acompanhamento mensal | C7: Planilha (XLSX) | D7: 00 | E7: 46318 | F7: Pessoa A | H7: 46683 | I7: Em elaboração | J7: =IF(A7="","",IF(AND(ISNUMBER(E7),ISNUMBER(H7),H7<E7),"Verificar: próxima revisão anterior à data",IF(AND(G7<>"",I7<>"Aprovado"),"Verificar: aprovador sem situação Aprovado",IF(AND(I7="Aprovado",G7=""),"Verificar: Aprovado sem aprovador","OK")))) | K7: Aguardando aprovação
A8: PCMD-05 | B8: Ficha de falha | C8: Planilha (XLSX) | D8: 00 | E8: 46318 | F8: Pessoa A | H8: 46683 | I8: Em elaboração | J8: =IF(A8="","",IF(AND(ISNUMBER(E8),ISNUMBER(H8),H8<E8),"Verificar: próxima revisão anterior à data",IF(AND(G8<>"",I8<>"Aprovado"),"Verificar: aprovador sem situação Aprovado",IF(AND(I8="Aprovado",G8=""),"Verificar: Aprovado sem aprovador","OK")))) | K8: Aguardando aprovação
A9: PCMD-W1 | B9: Manual de Gestão de Ativos | C9: Manual (DOCX) | D9: 00 | E9: 46318 | F9: Pessoa A | H9: 46683 | I9: Em elaboração | J9: =IF(A9="","",IF(AND(ISNUMBER(E9),ISNUMBER(H9),H9<E9),"Verificar: próxima revisão anterior à data",IF(AND(G9<>"",I9<>"Aprovado"),"Verificar: aprovador sem situação Aprovado",IF(AND(I9="Aprovado",G9=""),"Verificar: Aprovado sem aprovador","OK")))) | K9: Aguardando aprovação
A10: PCMD-W2 | B10: Manual de Estratégia de Manutenção | C10: Manual (DOCX) | D10: 00 | E10: 46318 | F10: Pessoa A | H10: 46683 | I10: Em elaboração | J10: =IF(A10="","",IF(AND(ISNUMBER(E10),ISNUMBER(H10),H10<E10),"Verificar: próxima revisão anterior à data",IF(AND(G10<>"",I10<>"Aprovado"),"Verificar: aprovador sem situação Aprovado",IF(AND(I10="Aprovado",G10=""),"Verificar: Aprovado sem aprovador","OK")))) | K10: Aguardando aprovação
J11: =IF(A11="","",IF(AND(ISNUMBER(E11),ISNUMBER(H11),H11<E11),"Verificar: próxima revisão anterior à data",IF(AND(G11<>"",I11<>"Aprovado"),"Verificar: aprovador sem situação Aprovado",IF(AND(I11="Aprovado",G11=""),"Verificar: Aprovado sem aprovador","OK"))))
J12: =IF(A12="","",IF(AND(ISNUMBER(E12),ISNUMBER(H12),H12<E12),"Verificar: próxima revisão anterior à data",IF(AND(G12<>"",I12<>"Aprovado"),"Verificar: aprovador sem situação Aprovado",IF(AND(I12="Aprovado",G12=""),"Verificar: Aprovado sem aprovador","OK"))))
J13: =IF(A13="","",IF(AND(ISNUMBER(E13),ISNUMBER(H13),H13<E13),"Verificar: próxima revisão anterior à data",IF(AND(G13<>"",I13<>"Aprovado"),"Verificar: aprovador sem situação Aprovado",IF(AND(I13="Aprovado",G13=""),"Verificar: Aprovado sem aprovador","OK"))))
J14: =IF(A14="","",IF(AND(ISNUMBER(E14),ISNUMBER(H14),H14<E14),"Verificar: próxima revisão anterior à data",IF(AND(G14<>"",I14<>"Aprovado"),"Verificar: aprovador sem situação Aprovado",IF(AND(I14="Aprovado",G14=""),"Verificar: Aprovado sem aprovador","OK"))))
J15: =IF(A15="","",IF(AND(ISNUMBER(E15),ISNUMBER(H15),H15<E15),"Verificar: próxima revisão anterior à data",IF(AND(G15<>"",I15<>"Aprovado"),"Verificar: aprovador sem situação Aprovado",IF(AND(I15="Aprovado",G15=""),"Verificar: Aprovado sem aprovador","OK"))))
J16: =IF(A16="","",IF(AND(ISNUMBER(E16),ISNUMBER(H16),H16<E16),"Verificar: próxima revisão anterior à data",IF(AND(G16<>"",I16<>"Aprovado"),"Verificar: aprovador sem situação Aprovado",IF(AND(I16="Aprovado",G16=""),"Verificar: Aprovado sem aprovador","OK"))))
J17: =IF(A17="","",IF(AND(ISNUMBER(E17),ISNUMBER(H17),H17<E17),"Verificar: próxima revisão anterior à data",IF(AND(G17<>"",I17<>"Aprovado"),"Verificar: aprovador sem situação Aprovado",IF(AND(I17="Aprovado",G17=""),"Verificar: Aprovado sem aprovador","OK"))))
J18: =IF(A18="","",IF(AND(ISNUMBER(E18),ISNUMBER(H18),H18<E18),"Verificar: próxima revisão anterior à data",IF(AND(G18<>"",I18<>"Aprovado"),"Verificar: aprovador sem situação Aprovado",IF(AND(I18="Aprovado",G18=""),"Verificar: Aprovado sem aprovador","OK"))))
J19: =IF(A19="","",IF(AND(ISNUMBER(E19),ISNUMBER(H19),H19<E19),"Verificar: próxima revisão anterior à data",IF(AND(G19<>"",I19<>"Aprovado"),"Verificar: aprovador sem situação Aprovado",IF(AND(I19="Aprovado",G19=""),"Verificar: Aprovado sem aprovador","OK"))))
J20: =IF(A20="","",IF(AND(ISNUMBER(E20),ISNUMBER(H20),H20<E20),"Verificar: próxima revisão anterior à data",IF(AND(G20<>"",I20<>"Aprovado"),"Verificar: aprovador sem situação Aprovado",IF(AND(I20="Aprovado",G20=""),"Verificar: Aprovado sem aprovador","OK"))))
J21: =IF(A21="","",IF(AND(ISNUMBER(E21),ISNUMBER(H21),H21<E21),"Verificar: próxima revisão anterior à data",IF(AND(G21<>"",I21<>"Aprovado"),"Verificar: aprovador sem situação Aprovado",IF(AND(I21="Aprovado",G21=""),"Verificar: Aprovado sem aprovador","OK"))))
J22: =IF(A22="","",IF(AND(ISNUMBER(E22),ISNUMBER(H22),H22<E22),"Verificar: próxima revisão anterior à data",IF(AND(G22<>"",I22<>"Aprovado"),"Verificar: aprovador sem situação Aprovado",IF(AND(I22="Aprovado",G22=""),"Verificar: Aprovado sem aprovador","OK"))))
... J53: =IF(A53="","",IF(AND(ISNUMBER(E53),ISNUMBER(H53),H53<E53),"Verificar: próxima revisão anterior à data",IF(AND(G53<>"",I53<>"Aprovado"),"Verificar: aprovador sem situação Aprovado",IF(AND(I53="Aprovado",G53=""),"Verificar: Aprovado sem aprovador","OK"))))

Sheet Revisões
C1: Histórico de revisões | E1: ="Rev. "&IF(cfg_revisao="","—",cfg_revisao)&IF(ISNUMBER(cfg_data_revisao)," · "&RIGHT("0"&DAY(cfg_data_revisao),2)&"/"&RIGHT("0"&MONTH(cfg_data_revisao),2)&"/"&YEAR(cfg_data_revisao),"")
E2: ="Elaborado: "&IF(cfg_elaborado="","A definir",cfg_elaborado)&CHAR(10)&"Aprovado: "&IF(cfg_aprovado="","A definir",cfg_aprovado)
A3: Documento | B3: Revisão | C3: Data | D3: Descrição da mudança | E3: Responsável
A4: PCMD-01 | B4: 00 | C4: 46318 | D4: Emissão inicial (exemplo fictício) | E4: Pessoa A
A5: PCMD-02 | B5: 00 | C5: 46318 | D5: Emissão inicial (exemplo fictício) | E5: Pessoa A
A6: PCMD-03 | B6: 00 | C6: 46318 | D6: Emissão inicial (exemplo fictício) | E6: Pessoa A
A7: PCMD-04 | B7: 00 | C7: 46318 | D7: Emissão inicial (exemplo fictício) | E7: Pessoa A
A8: PCMD-05 | B8: 00 | C8: 46318 | D8: Emissão inicial (exemplo fictício) | E8: Pessoa A
A9: PCMD-W1 | B9: 00 | C9: 46318 | D9: Emissão inicial (exemplo fictício) | E9: Pessoa A
A10: PCMD-W2 | B10: 00 | C10: 46318 | D10: Emissão inicial (exemplo fictício) | E10: Pessoa A

Sheet Cadastros
B1: Cadastros | G1: ="Rev. "&IF(cfg_revisao="","—",cfg_revisao)&IF(ISNUMBER(cfg_data_revisao)," · "&RIGHT("0"&DAY(cfg_data_revisao),2)&"/"&RIGHT("0"&MONTH(cfg_data_revisao),2)&"/"&YEAR(cfg_data_revisao),"")
G2: ="Elaborado: "&IF(cfg_elaborado="","A definir",cfg_elaborado)&CHAR(10)&"Aprovado: "&IF(cfg_aprovado="","A definir",cfg_aprovado)
A5: 1 ORGANIZAÇÃO
A6: Campo | B6: Valor | C6: Automático | D6: Orientação
A7: Nome da organização | B7: Indústria Exemplo | D7: Ex.: Indústria Exemplo.
A8: Referencial | B8: GERAL (sem norma) | D8: Padrão GERAL (sem norma). Não cite norma sem fonte oficial, versão e data.
A9: Prefixo dos documentos | B9: PCMD | D9: Padrão PCMD.
A10: Elaborador padrão (ID) | B10: pes-a | C10: =IF(B10="","",IFERROR(INDEX(cad_pessoa_nome,MATCH(B10,cad_pessoa_id,0)),"Pessoa não cadastrada")) | D10: ID do bloco Pessoas, abaixo.
A11: Aprovador padrão (ID) | C11: =IF(B11="","A definir (aprovação não registrada)",IFERROR(INDEX(cad_pessoa_nome,MATCH(B11,cad_pessoa_id,0)),"Pessoa não cadastrada")) | D11: Só informe após aprovação efetiva.
A12: Meta de disponibilidade (%) | C12: =IF(B12="","A definir",B12) | D12: Disponibilidade, MTBF e MTTR não são calculados: regras técnicas pendentes.
A14: 2 PESSOAS E FUNÇÕES
A15: ID da pessoa | B15: Nome | C15: Função | D15: Especialidade | E15: Ativa | F15: Conferência
A16: pes-a | B16: Pessoa A | C16: Planejamento de manutenção | D16: Mecânica | E16: Sim | F16: =IF(A16&B16="","",IF(A16="","ERRO: falta ID",IF(COUNTIF(cad_pessoa_id,A16)>1,"ERRO: ID repetido",IF(B16="","ERRO: falta nome","OK"))))
A17: pes-b | B17: Pessoa B | C17: Técnico de manutenção | D17: Elétrica | E17: Sim | F17: =IF(A17&B17="","",IF(A17="","ERRO: falta ID",IF(COUNTIF(cad_pessoa_id,A17)>1,"ERRO: ID repetido",IF(B17="","ERRO: falta nome","OK"))))
F18: =IF(A18&B18="","",IF(A18="","ERRO: falta ID",IF(COUNTIF(cad_pessoa_id,A18)>1,"ERRO: ID repetido",IF(B18="","ERRO: falta nome","OK"))))
F19: =IF(A19&B19="","",IF(A19="","ERRO: falta ID",IF(COUNTIF(cad_pessoa_id,A19)>1,"ERRO: ID repetido",IF(B19="","ERRO: falta nome","OK"))))
F20: =IF(A20&B20="","",IF(A20="","ERRO: falta ID",IF(COUNTIF(cad_pessoa_id,A20)>1,"ERRO: ID repetido",IF(B20="","ERRO: falta nome","OK"))))
F21: =IF(A21&B21="","",IF(A21="","ERRO: falta ID",IF(COUNTIF(cad_pessoa_id,A21)>1,"ERRO: ID repetido",IF(B21="","ERRO: falta nome","OK"))))
F22: =IF(A22&B22="","",IF(A22="","ERRO: falta ID",IF(COUNTIF(cad_pessoa_id,A22)>1,"ERRO: ID repetido",IF(B22="","ERRO: falta nome","OK"))))
F23: =IF(A23&B23="","",IF(A23="","ERRO: falta ID",IF(COUNTIF(cad_pessoa_id,A23)>1,"ERRO: ID repetido",IF(B23="","ERRO: falta nome","OK"))))
F24: =IF(A24&B24="","",IF(A24="","ERRO: falta ID",IF(COUNTIF(cad_pessoa_id,A24)>1,"ERRO: ID repetido",IF(B24="","ERRO: falta nome","OK"))))
F25: =IF(A25&B25="","",IF(A25="","ERRO: falta ID",IF(COUNTIF(cad_pessoa_id,A25)>1,"ERRO: ID repetido",IF(B25="","ERRO: falta nome","OK"))))
F26: =IF(A26&B26="","",IF(A26="","ERRO: falta ID",IF(COUNTIF(cad_pessoa_id,A26)>1,"ERRO: ID repetido",IF(B26="","ERRO: falta nome","OK"))))
F27: =IF(A27&B27="","",IF(A27="","ERRO: falta ID",IF(COUNTIF(cad_pessoa_id,A27)>1,"ERRO: ID repetido",IF(B27="","ERRO: falta nome","OK"))))
F28: =IF(A28&B28="","",IF(A28="","ERRO: falta ID",IF(COUNTIF(cad_pessoa_id,A28)>1,"ERRO: ID repetido",IF(B28="","ERRO: falta nome","OK"))))
F29: =IF(A29&B29="","",IF(A29="","ERRO: falta ID",IF(COUNTIF(cad_pessoa_id,A29)>1,"ERRO: ID repetido",IF(B29="","ERRO: falta nome","OK"))))
... F35: =IF(A35&B35="","",IF(A35="","ERRO: falta ID",IF(COUNTIF(cad_pessoa_id,A35)>1,"ERRO: ID repetido",IF(B35="","ERRO: falta nome","OK"))))
A37: 3 REQUISITOS E REFERÊNCIAS
A38: ID do requisito | B38: Referência | C38: Versão | D38: Data | E38: Fonte oficial (HTTPS) | F38: Status | G38: Conferência
A39: req-001 | B39: GERAL (sem norma) | F39: Não verificado | G39: =IF(A39&B39="","",IF(F39="Verificado",IF(OR(C39="",NOT(ISNUMBER(D39)),LEFT(E39,8)<>"https://"),"ERRO: Verificado exige versão, data e fonte HTTPS","Verificado pelo responsável (não certifica conformidade)"),"Não verificado: verificar na fonte oficial"))
A40: req-002 | B40: Procedimento interno de bloqueio de energia (fictício) | C40: Rev. 02 | D40: 46154 | E40: https://example.com/procedimento-bloqueio | F40: Verificado | G40: =IF(A40&B40="","",IF(F40="Verificado",IF(OR(C40="",NOT(ISNUMBER(D40)),LEFT(E40,8)<>"https://"),"ERRO: Verificado exige versão, data e fonte HTTPS","Verificado pelo responsável (não certifica conformidade)"),"Não verificado: verificar na fonte oficial"))
A41: req-003 | B41: Manual do fabricante do compressor (fictício) | F41: Não verificado | G41: =IF(A41&B41="","",IF(F41="Verificado",IF(OR(C41="",NOT(ISNUMBER(D41)),LEFT(E41,8)<>"https://"),"ERRO: Verificado exige versão, data e fonte HTTPS","Verificado pelo responsável (não certifica conformidade)"),"Não verificado: verificar na fonte oficial"))
G42: =IF(A42&B42="","",IF(F42="Verificado",IF(OR(C42="",NOT(ISNUMBER(D42)),LEFT(E42,8)<>"https://"),"ERRO: Verificado exige versão, data e fonte HTTPS","Verificado pelo responsável (não certifica conformidade)"),"Não verificado: verificar na fonte oficial"))
G43: =IF(A43&B43="","",IF(F43="Verificado",IF(OR(C43="",NOT(ISNUMBER(D43)),LEFT(E43,8)<>"https://"),"ERRO: Verificado exige versão, data e fonte HTTPS","Verificado pelo responsável (não certifica conformidade)"),"Não verificado: verificar na fonte oficial"))
G44: =IF(A44&B44="","",IF(F44="Verificado",IF(OR(C44="",NOT(ISNUMBER(D44)),LEFT(E44,8)<>"https://"),"ERRO: Verificado exige versão, data e fonte HTTPS","Verificado pelo responsável (não certifica conformidade)"),"Não verificado: verificar na fonte oficial"))
G45: =IF(A45&B45="","",IF(F45="Verificado",IF(OR(C45="",NOT(ISNUMBER(D45)),LEFT(E45,8)<>"https://"),"ERRO: Verificado exige versão, data e fonte HTTPS","Verificado pelo responsável (não certifica conformidade)"),"Não verificado: verificar na fonte oficial"))
G46: =IF(A46&B46="","",IF(F46="Verificado",IF(OR(C46="",NOT(ISNUMBER(D46)),LEFT(E46,8)<>"https://"),"ERRO: Verificado exige versão, data e fonte HTTPS","Verificado pelo responsável (não certifica conformidade)"),"Não verificado: verificar na fonte oficial"))
G47: =IF(A47&B47="","",IF(F47="Verificado",IF(OR(C47="",NOT(ISNUMBER(D47)),LEFT(E47,8)<>"https://"),"ERRO: Verificado exige versão, data e fonte HTTPS","Verificado pelo responsável (não certifica conformidade)"),"Não verificado: verificar na fonte oficial"))
G48: =IF(A48&B48="","",IF(F48="Verificado",IF(OR(C48="",NOT(ISNUMBER(D48)),LEFT(E48,8)<>"https://"),"ERRO: Verificado exige versão, data e fonte HTTPS","Verificado pelo responsável (não certifica conformidade)"),"Não verificado: verificar na fonte oficial"))
G49: =IF(A49&B49="","",IF(F49="Verificado",IF(OR(C49="",NOT(ISNUMBER(D49)),LEFT(E49,8)<>"https://"),"ERRO: Verificado exige versão, data e fonte HTTPS","Verificado pelo responsável (não certifica conformidade)"),"Não verificado: verificar na fonte oficial"))
...

Sheet Config
C1: Controle documental | E1: ="Rev. "&IF(cfg_revisao="","—",cfg_revisao)&IF(ISNUMBER(cfg_data_revisao)," · "&RIGHT("0"&DAY(cfg_data_revisao),2)&"/"&RIGHT("0"&MONTH(cfg_data_revisao),2)&"/"&YEAR(cfg_data_revisao),"")
E2: ="Elaborado: "&IF(cfg_elaborado="","A definir",cfg_elaborado)&CHAR(10)&"Aprovado: "&IF(cfg_aprovado="","A definir",cfg_aprovado)
A7: 1 COMO USAR
A8: 1) Em Cadastros, preencha a organização e cadastre as pessoas.
A9: 2) Ainda em Cadastros, registre as referências (começam Não verificado).
A10: 3) Mantenha a Lista Mestra e as Revisões a cada mudança. A revisão do PCMD-01 na Lista Mestra aparece no cabeçalho.
A11: Fundo azul-claro: preencher. Texto cinza: automático (fórmula, não digite). ERRO em vermelho e Pendente em amarelo pedem ação.
A12: Lista Mestra | B12: Um documento por linha: revisão, datas, elaborador, aprovador e situação.
A13: Revisões | B13: Uma linha por revisão de cada documento.
A14: Cadastros | B14: Organização, pessoas e requisitos (Verificado exige versão, data e fonte HTTPS).
A15: Listas | B15: Valores aceitos nas listas suspensas.
A17: 2 PARÂMETROS DO DOCUMENTO
A18: Parâmetro | C18: Valor
A19: Elaborado por | C19: Pessoa A
A20: Aprovado por (só após aprovação)
A21: Revisão atual (automática, da Lista Mestra) | C21: =IFERROR(INDEX('Lista Mestra'!$D$4:$D$53,MATCH("PCMD-01",'Lista Mestra'!$A$4:$A$53,0))&"","")
A22: Data da revisão (automática) | C22: =IFERROR(IF(INDEX('Lista Mestra'!$E$4:$E$53,MATCH("PCMD-01",'Lista Mestra'!$A$4:$A$53,0))="","",INDEX('Lista Mestra'!$E$4:$E$53,MATCH("PCMD-01",'Lista Mestra'!$A$4:$A$53,0))),"")
A23: Origem dos dados | C23: Demonstração fictícia gerada com a lógica do PCM Direto (não é exportação do app)
A24: Data de emissão | C24: 46318
A26: 3 CONFERÊNCIAS
A27: Aba | B27: Linhas preenchidas | C27: Linhas com ERRO | D27: Capacidade
A28: Lista Mestra | B28: =COUNTA('Lista Mestra'!$A$4:$A$53) | C28: =COUNTIF('Lista Mestra'!$J$4:$J$53,"ERRO*") | D28: =IF(COUNTA('Lista Mestra'!$A$54:$A$2053)>0,"ATENÇÃO: há dados além da linha 53; estenda fórmulas e nomes","OK")
A29: Pessoas | B29: =COUNTA('Cadastros'!$A$16:$A$35) | C29: =COUNTIF('Cadastros'!$F$16:$F$35,"ERRO*") | D29: =IF(COUNTA('Cadastros'!$A$36:$A$2035)>0,"ATENÇÃO: há dados além da linha 35; estenda fórmulas e nomes","OK")
A30: Requisitos | B30: =COUNTA('Cadastros'!$A$39:$A$68) | C30: =COUNTIF('Cadastros'!$G$39:$G$68,"ERRO*") | D30: =IF(COUNTA('Cadastros'!$A$69:$A$2068)>0,"ATENÇÃO: há dados além da linha 68; estenda fórmulas e nomes","OK")
A32: Modelo 1.0.0 · Thiago Oliveira Lima · pcmdireto@gmail.com · Licença MIT · Sem macros, vínculos externos ou envio de dados. Regras completas: COMO-USAR.md.

Sheet Listas
D1: Listas | J1: ="Rev. "&IF(cfg_revisao="","—",cfg_revisao)&IF(ISNUMBER(cfg_data_revisao)," · "&RIGHT("0"&DAY(cfg_data_revisao),2)&"/"&RIGHT("0"&MONTH(cfg_data_revisao),2)&"/"&YEAR(cfg_data_revisao),"")
J2: ="Elaborado: "&IF(cfg_elaborado="","A definir",cfg_elaborado)&CHAR(10)&"Aprovado: "&IF(cfg_aprovado="","A definir",cfg_aprovado)
A3: Tipo de documento | C3: Situação do documento | E3: Sim/Não | G3: Status de requisito
A4: Planilha (XLSX) | C4: Em elaboração | E4: Sim | G4: Não verificado
A5: Manual (DOCX) | C5: Em revisão | E5: Não | G5: Verificado
A6: Outro | C6: Aprovado
C7: Obsoleto
