Workbook
Name pa_situacao: 'Plano de Ação'!$L$4:$L$303
Name pa_conferencia: 'Plano de Ação'!$O$4:$O$303
Name lst_status_acao: Listas!$A$4:$A$43
Name lst_responsavel: Listas!$C$4:$C$43
Name rv_revisao: 'Revisões'!$A$4:$A$33
Name rv_data: 'Revisões'!$B$4:$B$33
Name cfg_elaborado: 'Instruções'!$C$15
Name cfg_aprovado: 'Instruções'!$C$16
Name cfg_revisao: 'Instruções'!$C$17
Name cfg_data_revisao: 'Instruções'!$C$18
Name pcmd_origem: 'Instruções'!$C$19
Name pcmd_emissao: 'Instruções'!$C$20
Name ano_crono: 'Instruções'!$C$21
Name ano_ref: 'Instruções'!$C$22

Sheet Instruções
C1: Plano de ação 5W2H com cronograma Como usar, parâmetros do documento e conferências gerais. | F1: ="Rev. "&IF(cfg_revisao="","—",cfg_revisao)&IF(ISNUMBER(cfg_data_revisao)," · "&RIGHT("0"&DAY(cfg_data_revisao),2)&"/"&RIGHT("0"&MONTH(cfg_data_revisao),2)&"/"&YEAR(cfg_data_revisao),"")
F2: ="Elaborado: "&IF(cfg_elaborado="","A definir",cfg_elaborado)&CHAR(10)&"Aprovado: "&IF(cfg_aprovado="","A definir",cfg_aprovado)
A7: 1. COMO USAR
A8: 1) Em Listas, cadastre os responsáveis. Em Plano de Ação, uma linha por ação com as sete colunas do 5W2H (o quê, por quê, onde, quem, quando, como, quanto).
A9: 2) Escolha o status e informe o % concluído. Situação do prazo e dias restantes são calculados; Atrasada aparece sozinha quando o prazo vence.
A10: 3) O Cronograma desenha as barras do ano abaixo e o Painel resume o plano para a reunião.
A11: Azul-claro: preencher. Cinza: automático (fórmula protegida, não digite). ERRO em vermelho e Pendente em amarelo pedem ação; OK em verde.
A13: 2. PARÂMETROS DO DOCUMENTO
A14: Parâmetro | C14: Valor | E14: Orientação
A15: Elaborado por | E15: Nome de quem preparou o documento.
A16: Aprovado por (só após aprovação) | E16: Preencha somente após a aprovação efetiva.
A17: Revisão atual (automática) | C17: =IFERROR(LOOKUP(2,1/(rv_revisao<>""),rv_revisao)&"","") | E17: Última linha preenchida em Revisões.
A18: Data da revisão (automática) | C18: =IFERROR(1/(1/LOOKUP(2,1/(rv_revisao<>""),rv_data)),"") | E18: Data da mesma linha da revisão atual.
A19: Origem dos dados | E19: Ex.: preenchimento manual, exportação do sistema.
A20: Data de emissão | E20: Data em que este arquivo foi emitido.
A21: Ano do cronograma | E21: Vazio = ano atual.
A22: Ano usado (automático) | C22: =IF(ISNUMBER(ano_crono),ano_crono,YEAR(TODAY())) | E22: Ano aplicado no Cronograma e no Painel.
A24: 3. CONFERÊNCIAS
A25: Aba / verificação | B25: Linhas preenchidas | C25: Linhas com ERRO | D25: Capacidade / resultado
A26: Plano de Ação | B26: =COUNTA('Plano de Ação'!$B$4:$B$303) | C26: =COUNTIF(pa_conferencia,"ERRO*") | D26: =IF(COUNTA('Plano de Ação'!$B$304:$B$2303)>0,"ATENÇÃO: há dados além da linha 303","OK")
A28: 4. ÍNDICE DAS ABAS (clique no nome)
A29: Painel | B29: Avanço, atrasos, investimento e gráficos.
A30: Plano de Ação | B30: Uma linha por ação no formato 5W2H.
A31: Cronograma | B31: Barras mensais entre início e prazo.
A32: Listas | B32: Status e responsáveis.
A33: Revisões | B33: Histórico de revisões.
A35: PCMD-K07 · Modelo 2.0.0 · PCM Direto · Thiago Oliveira Lima · pcmdireto@gmail.com · Licença MIT · Sem macros, vínculos externos ou envio de dados.

Sheet Painel
C1: Painel do plano de ação Consolidado da aba Plano de Ação, pronto para a reunião. Nenhum número é digitado aqui. | L1: ="Rev. "&IF(cfg_revisao="","—",cfg_revisao)&IF(ISNUMBER(cfg_data_revisao)," · "&RIGHT("0"&DAY(cfg_data_revisao),2)&"/"&RIGHT("0"&MONTH(cfg_data_revisao),2)&"/"&YEAR(cfg_data_revisao),"")
L2: ="Elaborado: "&IF(cfg_elaborado="","A definir",cfg_elaborado)&CHAR(10)&"Aprovado: "&IF(cfg_aprovado="","A definir",cfg_aprovado)
A4: AVANÇO MÉDIO DO PLANO | D4: AÇÕES ATRASADAS | G4: VENCEM EM 7 DIAS | J4: INVESTIMENTO PREVISTO
A5: =IFERROR(AVERAGEIFS('Plano de Ação'!$K$4:$K$303,'Plano de Ação'!$B$4:$B$303,"<>",'Plano de Ação'!$J$4:$J$303,"<>Cancelada"),"—") | D5: =COUNTIF(pa_situacao,"Atrasada") | G5: =COUNTIF(pa_situacao,"Vence esta semana") | J5: =SUMIFS('Plano de Ação'!$I$4:$I$303,'Plano de Ação'!$J$4:$J$303,"<>Cancelada")
A6: média do % concluído (sem canceladas) | D6: prazo vencido e não concluídas | G6: prazo nos próximos 7 dias | J6: soma do quanto custa
A8: ="Ações no plano: "&COUNTA('Plano de Ação'!$B$4:$B$303)&" · Concluídas: "&COUNTIF('Plano de Ação'!$J$4:$J$303,"Concluída")&" · Em andamento: "&COUNTIF('Plano de Ação'!$J$4:$J$303,"Em andamento")&" · Não iniciadas: "&COUNTIF('Plano de Ação'!$J$4:$J$303,"Não iniciada")&" · Já investido (concluídas): R$ "&FIXED(SUMIFS('Plano de Ação'!$I$4:$I$303,'Plano de Ação'!$J$4:$J$303,"Concluída"),2)
A10: AÇÕES POR STATUS | E10: AVANÇO POR RESPONSÁVEL | I10: AÇÕES ATIVAS POR MÊS
A28: DADOS DOS GRÁFICOS (automático, não digite)
A29: Status | C29: Valor | E29: Responsável | G29: Valor | I29: Mês | K29: Valor
A30: Não iniciada | C30: =COUNTIF('Plano de Ação'!$J$4:$J$303,"Não iniciada") | E30: =IF(INDEX(lst_responsavel,1)="","",INDEX(lst_responsavel,1)) | G30: =IF(INDEX(lst_responsavel,1)="",0,IFERROR(AVERAGEIFS('Plano de Ação'!$K$4:$K$303,'Plano de Ação'!$E$4:$E$303,INDEX(lst_responsavel,1),'Plano de Ação'!$J$4:$J$303,"<>Cancelada"),0)) | I30: Jan | K30: =Cronograma!E4
A31: Em andamento | C31: =COUNTIF('Plano de Ação'!$J$4:$J$303,"Em andamento") | E31: =IF(INDEX(lst_responsavel,2)="","",INDEX(lst_responsavel,2)) | G31: =IF(INDEX(lst_responsavel,2)="",0,IFERROR(AVERAGEIFS('Plano de Ação'!$K$4:$K$303,'Plano de Ação'!$E$4:$E$303,INDEX(lst_responsavel,2),'Plano de Ação'!$J$4:$J$303,"<>Cancelada"),0)) | I31: Fev | K31: =Cronograma!F4
A32: Concluída | C32: =COUNTIF('Plano de Ação'!$J$4:$J$303,"Concluída") | E32: =IF(INDEX(lst_responsavel,3)="","",INDEX(lst_responsavel,3)) | G32: =IF(INDEX(lst_responsavel,3)="",0,IFERROR(AVERAGEIFS('Plano de Ação'!$K$4:$K$303,'Plano de Ação'!$E$4:$E$303,INDEX(lst_responsavel,3),'Plano de Ação'!$J$4:$J$303,"<>Cancelada"),0)) | I32: Mar | K32: =Cronograma!G4
A33: Cancelada | C33: =COUNTIF('Plano de Ação'!$J$4:$J$303,"Cancelada") | E33: =IF(INDEX(lst_responsavel,4)="","",INDEX(lst_responsavel,4)) | G33: =IF(INDEX(lst_responsavel,4)="",0,IFERROR(AVERAGEIFS('Plano de Ação'!$K$4:$K$303,'Plano de Ação'!$E$4:$E$303,INDEX(lst_responsavel,4),'Plano de Ação'!$J$4:$J$303,"<>Cancelada"),0)) | I33: Abr | K33: =Cronograma!H4
E34: =IF(INDEX(lst_responsavel,5)="","",INDEX(lst_responsavel,5)) | G34: =IF(INDEX(lst_responsavel,5)="",0,IFERROR(AVERAGEIFS('Plano de Ação'!$K$4:$K$303,'Plano de Ação'!$E$4:$E$303,INDEX(lst_responsavel,5),'Plano de Ação'!$J$4:$J$303,"<>Cancelada"),0)) | I34: Mai | K34: =Cronograma!I4
E35: =IF(INDEX(lst_responsavel,6)="","",INDEX(lst_responsavel,6)) | G35: =IF(INDEX(lst_responsavel,6)="",0,IFERROR(AVERAGEIFS('Plano de Ação'!$K$4:$K$303,'Plano de Ação'!$E$4:$E$303,INDEX(lst_responsavel,6),'Plano de Ação'!$J$4:$J$303,"<>Cancelada"),0)) | I35: Jun | K35: =Cronograma!J4
E36: =IF(INDEX(lst_responsavel,7)="","",INDEX(lst_responsavel,7)) | G36: =IF(INDEX(lst_responsavel,7)="",0,IFERROR(AVERAGEIFS('Plano de Ação'!$K$4:$K$303,'Plano de Ação'!$E$4:$E$303,INDEX(lst_responsavel,7),'Plano de Ação'!$J$4:$J$303,"<>Cancelada"),0)) | I36: Jul | K36: =Cronograma!K4
E37: =IF(INDEX(lst_responsavel,8)="","",INDEX(lst_responsavel,8)) | G37: =IF(INDEX(lst_responsavel,8)="",0,IFERROR(AVERAGEIFS('Plano de Ação'!$K$4:$K$303,'Plano de Ação'!$E$4:$E$303,INDEX(lst_responsavel,8),'Plano de Ação'!$J$4:$J$303,"<>Cancelada"),0)) | I37: Ago | K37: =Cronograma!L4
E38: =IF(INDEX(lst_responsavel,9)="","",INDEX(lst_responsavel,9)) | G38: =IF(INDEX(lst_responsavel,9)="",0,IFERROR(AVERAGEIFS('Plano de Ação'!$K$4:$K$303,'Plano de Ação'!$E$4:$E$303,INDEX(lst_responsavel,9),'Plano de Ação'!$J$4:$J$303,"<>Cancelada"),0)) | I38: Set | K38: =Cronograma!M4
E39: =IF(INDEX(lst_responsavel,10)="","",INDEX(lst_responsavel,10)) | G39: =IF(INDEX(lst_responsavel,10)="",0,IFERROR(AVERAGEIFS('Plano de Ação'!$K$4:$K$303,'Plano de Ação'!$E$4:$E$303,INDEX(lst_responsavel,10),'Plano de Ação'!$J$4:$J$303,"<>Cancelada"),0)) | I39: Out | K39: =Cronograma!N4
I40: Nov | K40: =Cronograma!O4
I41: Dez | K41: =Cronograma!P4

Sheet Plano de Ação
C1: Plano de ação 5W2H Uma linha por ação: o quê, por quê, onde, quem, quando, como e quanto custa. | O1: ="Rev. "&IF(cfg_revisao="","—",cfg_revisao)&IF(ISNUMBER(cfg_data_revisao)," · "&RIGHT("0"&DAY(cfg_data_revisao),2)&"/"&RIGHT("0"&MONTH(cfg_data_revisao),2)&"/"&YEAR(cfg_data_revisao),"")
O2: ="Elaborado: "&IF(cfg_elaborado="","A definir",cfg_elaborado)&CHAR(10)&"Aprovado: "&IF(cfg_aprovado="","A definir",cfg_aprovado)
A3: Nº | B3: O quê (What) | C3: Por quê (Why) | D3: Onde (Where) | E3: Quem (Who) | F3: Quando — início | G3: Quando — prazo | H3: Como (How) | I3: Quanto custa (How much) | J3: Status | K3: % concluído | L3: Situação do prazo | M3: Dias restantes | N3: Observação | O3: Conferência
L4: =IF(B4="","",IF(J4="Concluída","Concluída",IF(J4="Cancelada","—",IF(NOT(ISNUMBER(G4)),"Sem prazo",IF(G4<TODAY(),"Atrasada",IF(G4-TODAY()<=7,"Vence esta semana","No prazo")))))) | M4: =IF(OR(B4="",NOT(ISNUMBER(G4)),J4="Concluída",J4="Cancelada"),"",G4-TODAY()) | O4: =IF(A4&B4="","",IF(A4="","ERRO: falta o número",IF(COUNTIF($A$4:$A$303,A4)>1,"ERRO: número repetido",IF(B4="","ERRO: falta o quê",IF(AND(ISNUMBER(F4),ISNUMBER(G4),G4<F4),"ERRO: prazo anterior ao início",IF(AND(J4="Concluída",N(K4)<1),"Verificar: concluída com % menor que 100%",IF(AND(N(K4)=1,J4<>"Concluída"),"Verificar: 100% sem status Concluída",IF(OR(E4="",NOT(ISNUMBER(F4)),NOT(ISNUMBER(G4)),J4=""),"Pendente: quem, início, prazo e status","OK"))))))))
L5: =IF(B5="","",IF(J5="Concluída","Concluída",IF(J5="Cancelada","—",IF(NOT(ISNUMBER(G5)),"Sem prazo",IF(G5<TODAY(),"Atrasada",IF(G5-TODAY()<=7,"Vence esta semana","No prazo")))))) | M5: =IF(OR(B5="",NOT(ISNUMBER(G5)),J5="Concluída",J5="Cancelada"),"",G5-TODAY()) | O5: =IF(A5&B5="","",IF(A5="","ERRO: falta o número",IF(COUNTIF($A$4:$A$303,A5)>1,"ERRO: número repetido",IF(B5="","ERRO: falta o quê",IF(AND(ISNUMBER(F5),ISNUMBER(G5),G5<F5),"ERRO: prazo anterior ao início",IF(AND(J5="Concluída",N(K5)<1),"Verificar: concluída com % menor que 100%",IF(AND(N(K5)=1,J5<>"Concluída"),"Verificar: 100% sem status Concluída",IF(OR(E5="",NOT(ISNUMBER(F5)),NOT(ISNUMBER(G5)),J5=""),"Pendente: quem, início, prazo e status","OK"))))))))
L6: =IF(B6="","",IF(J6="Concluída","Concluída",IF(J6="Cancelada","—",IF(NOT(ISNUMBER(G6)),"Sem prazo",IF(G6<TODAY(),"Atrasada",IF(G6-TODAY()<=7,"Vence esta semana","No prazo")))))) | M6: =IF(OR(B6="",NOT(ISNUMBER(G6)),J6="Concluída",J6="Cancelada"),"",G6-TODAY()) | O6: =IF(A6&B6="","",IF(A6="","ERRO: falta o número",IF(COUNTIF($A$4:$A$303,A6)>1,"ERRO: número repetido",IF(B6="","ERRO: falta o quê",IF(AND(ISNUMBER(F6),ISNUMBER(G6),G6<F6),"ERRO: prazo anterior ao início",IF(AND(J6="Concluída",N(K6)<1),"Verificar: concluída com % menor que 100%",IF(AND(N(K6)=1,J6<>"Concluída"),"Verificar: 100% sem status Concluída",IF(OR(E6="",NOT(ISNUMBER(F6)),NOT(ISNUMBER(G6)),J6=""),"Pendente: quem, início, prazo e status","OK"))))))))
L7: =IF(B7="","",IF(J7="Concluída","Concluída",IF(J7="Cancelada","—",IF(NOT(ISNUMBER(G7)),"Sem prazo",IF(G7<TODAY(),"Atrasada",IF(G7-TODAY()<=7,"Vence esta semana","No prazo")))))) | M7: =IF(OR(B7="",NOT(ISNUMBER(G7)),J7="Concluída",J7="Cancelada"),"",G7-TODAY()) | O7: =IF(A7&B7="","",IF(A7="","ERRO: falta o número",IF(COUNTIF($A$4:$A$303,A7)>1,"ERRO: número repetido",IF(B7="","ERRO: falta o quê",IF(AND(ISNUMBER(F7),ISNUMBER(G7),G7<F7),"ERRO: prazo anterior ao início",IF(AND(J7="Concluída",N(K7)<1),"Verificar: concluída com % menor que 100%",IF(AND(N(K7)=1,J7<>"Concluída"),"Verificar: 100% sem status Concluída",IF(OR(E7="",NOT(ISNUMBER(F7)),NOT(ISNUMBER(G7)),J7=""),"Pendente: quem, início, prazo e status","OK"))))))))
L8: =IF(B8="","",IF(J8="Concluída","Concluída",IF(J8="Cancelada","—",IF(NOT(ISNUMBER(G8)),"Sem prazo",IF(G8<TODAY(),"Atrasada",IF(G8-TODAY()<=7,"Vence esta semana","No prazo")))))) | M8: =IF(OR(B8="",NOT(ISNUMBER(G8)),J8="Concluída",J8="Cancelada"),"",G8-TODAY()) | O8: =IF(A8&B8="","",IF(A8="","ERRO: falta o número",IF(COUNTIF($A$4:$A$303,A8)>1,"ERRO: número repetido",IF(B8="","ERRO: falta o quê",IF(AND(ISNUMBER(F8),ISNUMBER(G8),G8<F8),"ERRO: prazo anterior ao início",IF(AND(J8="Concluída",N(K8)<1),"Verificar: concluída com % menor que 100%",IF(AND(N(K8)=1,J8<>"Concluída"),"Verificar: 100% sem status Concluída",IF(OR(E8="",NOT(ISNUMBER(F8)),NOT(ISNUMBER(G8)),J8=""),"Pendente: quem, início, prazo e status","OK"))))))))
L9: =IF(B9="","",IF(J9="Concluída","Concluída",IF(J9="Cancelada","—",IF(NOT(ISNUMBER(G9)),"Sem prazo",IF(G9<TODAY(),"Atrasada",IF(G9-TODAY()<=7,"Vence esta semana","No prazo")))))) | M9: =IF(OR(B9="",NOT(ISNUMBER(G9)),J9="Concluída",J9="Cancelada"),"",G9-TODAY()) | O9: =IF(A9&B9="","",IF(A9="","ERRO: falta o número",IF(COUNTIF($A$4:$A$303,A9)>1,"ERRO: número repetido",IF(B9="","ERRO: falta o quê",IF(AND(ISNUMBER(F9),ISNUMBER(G9),G9<F9),"ERRO: prazo anterior ao início",IF(AND(J9="Concluída",N(K9)<1),"Verificar: concluída com % menor que 100%",IF(AND(N(K9)=1,J9<>"Concluída"),"Verificar: 100% sem status Concluída",IF(OR(E9="",NOT(ISNUMBER(F9)),NOT(ISNUMBER(G9)),J9=""),"Pendente: quem, início, prazo e status","OK"))))))))
L10: =IF(B10="","",IF(J10="Concluída","Concluída",IF(J10="Cancelada","—",IF(NOT(ISNUMBER(G10)),"Sem prazo",IF(G10<TODAY(),"Atrasada",IF(G10-TODAY()<=7,"Vence esta semana","No prazo")))))) | M10: =IF(OR(B10="",NOT(ISNUMBER(G10)),J10="Concluída",J10="Cancelada"),"",G10-TODAY()) | O10: =IF(A10&B10="","",IF(A10="","ERRO: falta o número",IF(COUNTIF($A$4:$A$303,A10)>1,"ERRO: número repetido",IF(B10="","ERRO: falta o quê",IF(AND(ISNUMBER(F10),ISNUMBER(G10),G10<F10),"ERRO: prazo anterior ao início",IF(AND(J10="Concluída",N(K10)<1),"Verificar: concluída com % menor que 100%",IF(AND(N(K10)=1,J10<>"Concluída"),"Verificar: 100% sem status Concluída",IF(OR(E10="",NOT(ISNUMBER(F10)),NOT(ISNUMBER(G10)),J10=""),"Pendente: quem, início, prazo e status","OK"))))))))
L11: =IF(B11="","",IF(J11="Concluída","Concluída",IF(J11="Cancelada","—",IF(NOT(ISNUMBER(G11)),"Sem prazo",IF(G11<TODAY(),"Atrasada",IF(G11-TODAY()<=7,"Vence esta semana","No prazo")))))) | M11: =IF(OR(B11="",NOT(ISNUMBER(G11)),J11="Concluída",J11="Cancelada"),"",G11-TODAY()) | O11: =IF(A11&B11="","",IF(A11="","ERRO: falta o número",IF(COUNTIF($A$4:$A$303,A11)>1,"ERRO: número repetido",IF(B11="","ERRO: falta o quê",IF(AND(ISNUMBER(F11),ISNUMBER(G11),G11<F11),"ERRO: prazo anterior ao início",IF(AND(J11="Concluída",N(K11)<1),"Verificar: concluída com % menor que 100%",IF(AND(N(K11)=1,J11<>"Concluída"),"Verificar: 100% sem status Concluída",IF(OR(E11="",NOT(ISNUMBER(F11)),NOT(ISNUMBER(G11)),J11=""),"Pendente: quem, início, prazo e status","OK"))))))))
L12: =IF(B12="","",IF(J12="Concluída","Concluída",IF(J12="Cancelada","—",IF(NOT(ISNUMBER(G12)),"Sem prazo",IF(G12<TODAY(),"Atrasada",IF(G12-TODAY()<=7,"Vence esta semana","No prazo")))))) | M12: =IF(OR(B12="",NOT(ISNUMBER(G12)),J12="Concluída",J12="Cancelada"),"",G12-TODAY()) | O12: =IF(A12&B12="","",IF(A12="","ERRO: falta o número",IF(COUNTIF($A$4:$A$303,A12)>1,"ERRO: número repetido",IF(B12="","ERRO: falta o quê",IF(AND(ISNUMBER(F12),ISNUMBER(G12),G12<F12),"ERRO: prazo anterior ao início",IF(AND(J12="Concluída",N(K12)<1),"Verificar: concluída com % menor que 100%",IF(AND(N(K12)=1,J12<>"Concluída"),"Verificar: 100% sem status Concluída",IF(OR(E12="",NOT(ISNUMBER(F12)),NOT(ISNUMBER(G12)),J12=""),"Pendente: quem, início, prazo e status","OK"))))))))
L13: =IF(B13="","",IF(J13="Concluída","Concluída",IF(J13="Cancelada","—",IF(NOT(ISNUMBER(G13)),"Sem prazo",IF(G13<TODAY(),"Atrasada",IF(G13-TODAY()<=7,"Vence esta semana","No prazo")))))) | M13: =IF(OR(B13="",NOT(ISNUMBER(G13)),J13="Concluída",J13="Cancelada"),"",G13-TODAY()) | O13: =IF(A13&B13="","",IF(A13="","ERRO: falta o número",IF(COUNTIF($A$4:$A$303,A13)>1,"ERRO: número repetido",IF(B13="","ERRO: falta o quê",IF(AND(ISNUMBER(F13),ISNUMBER(G13),G13<F13),"ERRO: prazo anterior ao início",IF(AND(J13="Concluída",N(K13)<1),"Verificar: concluída com % menor que 100%",IF(AND(N(K13)=1,J13<>"Concluída"),"Verificar: 100% sem status Concluída",IF(OR(E13="",NOT(ISNUMBER(F13)),NOT(ISNUMBER(G13)),J13=""),"Pendente: quem, início, prazo e status","OK"))))))))
L14: =IF(B14="","",IF(J14="Concluída","Concluída",IF(J14="Cancelada","—",IF(NOT(ISNUMBER(G14)),"Sem prazo",IF(G14<TODAY(),"Atrasada",IF(G14-TODAY()<=7,"Vence esta semana","No prazo")))))) | M14: =IF(OR(B14="",NOT(ISNUMBER(G14)),J14="Concluída",J14="Cancelada"),"",G14-TODAY()) | O14: =IF(A14&B14="","",IF(A14="","ERRO: falta o número",IF(COUNTIF($A$4:$A$303,A14)>1,"ERRO: número repetido",IF(B14="","ERRO: falta o quê",IF(AND(ISNUMBER(F14),ISNUMBER(G14),G14<F14),"ERRO: prazo anterior ao início",IF(AND(J14="Concluída",N(K14)<1),"Verificar: concluída com % menor que 100%",IF(AND(N(K14)=1,J14<>"Concluída"),"Verificar: 100% sem status Concluída",IF(OR(E14="",NOT(ISNUMBER(F14)),NOT(ISNUMBER(G14)),J14=""),"Pendente: quem, início, prazo e status","OK"))))))))
L15: =IF(B15="","",IF(J15="Concluída","Concluída",IF(J15="Cancelada","—",IF(NOT(ISNUMBER(G15)),"Sem prazo",IF(G15<TODAY(),"Atrasada",IF(G15-TODAY()<=7,"Vence esta semana","No prazo")))))) | M15: =IF(OR(B15="",NOT(ISNUMBER(G15)),J15="Concluída",J15="Cancelada"),"",G15-TODAY()) | O15: =IF(A15&B15="","",IF(A15="","ERRO: falta o número",IF(COUNTIF($A$4:$A$303,A15)>1,"ERRO: número repetido",IF(B15="","ERRO: falta o quê",IF(AND(ISNUMBER(F15),ISNUMBER(G15),G15<F15),"ERRO: prazo anterior ao início",IF(AND(J15="Concluída",N(K15)<1),"Verificar: concluída com % menor que 100%",IF(AND(N(K15)=1,J15<>"Concluída"),"Verificar: 100% sem status Concluída",IF(OR(E15="",NOT(ISNUMBER(F15)),NOT(ISNUMBER(G15)),J15=""),"Pendente: quem, início, prazo e status","OK"))))))))
... L303: =IF(B303="","",IF(J303="Concluída","Concluída",IF(J303="Cancelada","—",IF(NOT(ISNUMBER(G303)),"Sem prazo",IF(G303<TODAY(),"Atrasada",IF(G303-TODAY()<=7,"Vence esta semana","No prazo")))))) | M303: =IF(OR(B303="",NOT(ISNUMBER(G303)),J303="Concluída",J303="Cancelada"),"",G303-TODAY()) | O303: =IF(A303&B303="","",IF(A303="","ERRO: falta o número",IF(COUNTIF($A$4:$A$303,A303)>1,"ERRO: número repetido",IF(B303="","ERRO: falta o quê",IF(AND(ISNUMBER(F303),ISNUMBER(G303),G303<F303),"ERRO: prazo anterior ao início",IF(AND(J303="Concluída",N(K303)<1),"Verificar: concluída com % menor que 100%",IF(AND(N(K303)=1,J303<>"Concluída"),"Verificar: 100% sem status Concluída",IF(OR(E303="",NOT(ISNUMBER(F303)),NOT(ISNUMBER(G303)),J303=""),"Pendente: quem, início, prazo e status","OK"))))))))

Sheet Cronograma
C1: Cronograma das ações Barra desenhada entre o início e o prazo de cada ação, na cor da situação. Não marque à mão. | P1: ="Rev. "&IF(cfg_revisao="","—",cfg_revisao)&IF(ISNUMBER(cfg_data_revisao)," · "&RIGHT("0"&DAY(cfg_data_revisao),2)&"/"&RIGHT("0"&MONTH(cfg_data_revisao),2)&"/"&YEAR(cfg_data_revisao),"")
P2: ="Elaborado: "&IF(cfg_elaborado="","A definir",cfg_elaborado)&CHAR(10)&"Aprovado: "&IF(cfg_aprovado="","A definir",cfg_aprovado)
A3: Nº | B3: Ação | C3: Responsável | D3: Situação | E3: Jan | F3: Fev | G3: Mar | H3: Abr | I3: Mai | J3: Jun | K3: Jul | L3: Ago | M3: Set | N3: Out | O3: Nov | P3: Dez
A4: ="Ações ativas no mês · ano "&ano_ref | E4: =COUNTIF(E5:E304,1) | F4: =COUNTIF(F5:F304,1) | G4: =COUNTIF(G5:G304,1) | H4: =COUNTIF(H5:H304,1) | I4: =COUNTIF(I5:I304,1) | J4: =COUNTIF(J5:J304,1) | K4: =COUNTIF(K5:K304,1) | L4: =COUNTIF(L5:L304,1) | ... P4: =COUNTIF(P5:P304,1)
A5: =IF('Plano de Ação'!$B4<>"",'Plano de Ação'!A4&"","") | B5: =IF('Plano de Ação'!$B4<>"",'Plano de Ação'!B4,"") | C5: =IF('Plano de Ação'!$B4<>"",'Plano de Ação'!E4&"","") | D5: =IF('Plano de Ação'!$B4<>"",'Plano de Ação'!L4,"") | E5: =IF(OR(NOT('Plano de Ação'!$B4<>""),NOT(ISNUMBER('Plano de Ação'!$F4)),NOT(ISNUMBER('Plano de Ação'!$G4)),'Plano de Ação'!$J4="Cancelada"),0,IF(AND('Plano de Ação'!$F4<=EOMONTH(DATE(ano_ref,1,1),0),'Plano de Ação'!$G4>=DATE(ano_ref,1,1)),1,0)) | F5: =IF(OR(NOT('Plano de Ação'!$B4<>""),NOT(ISNUMBER('Plano de Ação'!$F4)),NOT(ISNUMBER('Plano de Ação'!$G4)),'Plano de Ação'!$J4="Cancelada"),0,IF(AND('Plano de Ação'!$F4<=EOMONTH(DATE(ano_ref,2,1),0),'Plano de Ação'!$G4>=DATE(ano_ref,2,1)),1,0)) | G5: =IF(OR(NOT('Plano de Ação'!$B4<>""),NOT(ISNUMBER('Plano de Ação'!$F4)),NOT(ISNUMBER('Plano de Ação'!$G4)),'Plano de Ação'!$J4="Cancelada"),0,IF(AND('Plano de Ação'!$F4<=EOMONTH(DATE(ano_ref,3,1),0),'Plano de Ação'!$G4>=DATE(ano_ref,3,1)),1,0)) | H5: =IF(OR(NOT('Plano de Ação'!$B4<>""),NOT(ISNUMBER('Plano de Ação'!$F4)),NOT(ISNUMBER('Plano de Ação'!$G4)),'Plano de Ação'!$J4="Cancelada"),0,IF(AND('Plano de Ação'!$F4<=EOMONTH(DATE(ano_ref,4,1),0),'Plano de Ação'!$G4>=DATE(ano_ref,4,1)),1,0)) | I5: =IF(OR(NOT('Plano de Ação'!$B4<>""),NOT(ISNUMBER('Plano de Ação'!$F4)),NOT(ISNUMBER('Plano de Ação'!$G4)),'Plano de Ação'!$J4="Cancelada"),0,IF(AND('Plano de Ação'!$F4<=EOMONTH(DATE(ano_ref,5,1),0),'Plano de Ação'!$G4>=DATE(ano_ref,5,1)),1,0)) | J5: =IF(OR(NOT('Plano de Ação'!$B4<>""),NOT(ISNUMBER('Plano de Ação'!$F4)),NOT(ISNUMBER('Plano de Ação'!$G4)),'Plano de Ação'!$J4="Cancelada"),0,IF(AND('Plano de Ação'!$F4<=EOMONTH(DATE(ano_ref,6,1),0),'Plano de Ação'!$G4>=DATE(ano_ref,6,1)),1,0)) | K5: =IF(OR(NOT('Plano de Ação'!$B4<>""),NOT(ISNUMBER('Plano de Ação'!$F4)),NOT(ISNUMBER('Plano de Ação'!$G4)),'Plano de Ação'!$J4="Cancelada"),0,IF(AND('Plano de Ação'!$F4<=EOMONTH(DATE(ano_ref,7,1),0),'Plano de Ação'!$G4>=DATE(ano_ref,7,1)),1,0)) | L5: =IF(OR(NOT('Plano de Ação'!$B4<>""),NOT(ISNUMBER('Plano de Ação'!$F4)),NOT(ISNUMBER('Plano de Ação'!$G4)),'Plano de Ação'!$J4="Cancelada"),0,IF(AND('Plano de Ação'!$F4<=EOMONTH(DATE(ano_ref,8,1),0),'Plano de Ação'!$G4>=DATE(ano_ref,8,1)),1,0)) | M5: =IF(OR(NOT('Plano de Ação'!$B4<>""),NOT(ISNUMBER('Plano de Ação'!$F4)),NOT(ISNUMBER('Plano de Ação'!$G4)),'Plano de Ação'!$J4="Cancelada"),0,IF(AND('Plano de Ação'!$F4<=EOMONTH(DATE(ano_ref,9,1),0),'Plano de Ação'!$G4>=DATE(ano_ref,9,1)),1,0)) | N5: =IF(OR(NOT('Plano de Ação'!$B4<>""),NOT(ISNUMBER('Plano de Ação'!$F4)),NOT(ISNUMBER('Plano de Ação'!$G4)),'Plano de Ação'!$J4="Cancelada"),0,IF(AND('Plano de Ação'!$F4<=EOMONTH(DATE(ano_ref,10,1),0),'Plano de Ação'!$G4>=DATE(ano_ref,10,1)),1,0)) | O5: =IF(OR(NOT('Plano de Ação'!$B4<>""),NOT(ISNUMBER('Plano de Ação'!$F4)),NOT(ISNUMBER('Plano de Ação'!$G4)),'Plano de Ação'!$J4="Cancelada"),0,IF(AND('Plano de Ação'!$F4<=EOMONTH(DATE(ano_ref,11,1),0),'Plano de Ação'!$G4>=DATE(ano_ref,11,1)),1,0)) | P5: =IF(OR(NOT('Plano de Ação'!$B4<>""),NOT(ISNUMBER('Plano de Ação'!$F4)),NOT(ISNUMBER('Plano de Ação'!$G4)),'Plano de Ação'!$J4="Cancelada"),0,IF(AND('Plano de Ação'!$F4<=EOMONTH(DATE(ano_ref,12,1),0),'Plano de Ação'!$G4>=DATE(ano_ref,12,1)),1,0))
A6: =IF('Plano de Ação'!$B5<>"",'Plano de Ação'!A5&"","") | B6: =IF('Plano de Ação'!$B5<>"",'Plano de Ação'!B5,"") | C6: =IF('Plano de Ação'!$B5<>"",'Plano de Ação'!E5&"","") | D6: =IF('Plano de Ação'!$B5<>"",'Plano de Ação'!L5,"") | E6: =IF(OR(NOT('Plano de Ação'!$B5<>""),NOT(ISNUMBER('Plano de Ação'!$F5)),NOT(ISNUMBER('Plano de Ação'!$G5)),'Plano de Ação'!$J5="Cancelada"),0,IF(AND('Plano de Ação'!$F5<=EOMONTH(DATE(ano_ref,1,1),0),'Plano de Ação'!$G5>=DATE(ano_ref,1,1)),1,0)) | F6: =IF(OR(NOT('Plano de Ação'!$B5<>""),NOT(ISNUMBER('Plano de Ação'!$F5)),NOT(ISNUMBER('Plano de Ação'!$G5)),'Plano de Ação'!$J5="Cancelada"),0,IF(AND('Plano de Ação'!$F5<=EOMONTH(DATE(ano_ref,2,1),0),'Plano de Ação'!$G5>=DATE(ano_ref,2,1)),1,0)) | G6: =IF(OR(NOT('Plano de Ação'!$B5<>""),NOT(ISNUMBER('Plano de Ação'!$F5)),NOT(ISNUMBER('Plano de Ação'!$G5)),'Plano de Ação'!$J5="Cancelada"),0,IF(AND('Plano de Ação'!$F5<=EOMONTH(DATE(ano_ref,3,1),0),'Plano de Ação'!$G5>=DATE(ano_ref,3,1)),1,0)) | H6: =IF(OR(NOT('Plano de Ação'!$B5<>""),NOT(ISNUMBER('Plano de Ação'!$F5)),NOT(ISNUMBER('Plano de Ação'!$G5)),'Plano de Ação'!$J5="Cancelada"),0,IF(AND('Plano de Ação'!$F5<=EOMONTH(DATE(ano_ref,4,1),0),'Plano de Ação'!$G5>=DATE(ano_ref,4,1)),1,0)) | I6: =IF(OR(NOT('Plano de Ação'!$B5<>""),NOT(ISNUMBER('Plano de Ação'!$F5)),NOT(ISNUMBER('Plano de Ação'!$G5)),'Plano de Ação'!$J5="Cancelada"),0,IF(AND('Plano de Ação'!$F5<=EOMONTH(DATE(ano_ref,5,1),0),'Plano de Ação'!$G5>=DATE(ano_ref,5,1)),1,0)) | J6: =IF(OR(NOT('Plano de Ação'!$B5<>""),NOT(ISNUMBER('Plano de Ação'!$F5)),NOT(ISNUMBER('Plano de Ação'!$G5)),'Plano de Ação'!$J5="Cancelada"),0,IF(AND('Plano de Ação'!$F5<=EOMONTH(DATE(ano_ref,6,1),0),'Plano de Ação'!$G5>=DATE(ano_ref,6,1)),1,0)) | K6: =IF(OR(NOT('Plano de Ação'!$B5<>""),NOT(ISNUMBER('Plano de Ação'!$F5)),NOT(ISNUMBER('Plano de Ação'!$G5)),'Plano de Ação'!$J5="Cancelada"),0,IF(AND('Plano de Ação'!$F5<=EOMONTH(DATE(ano_ref,7,1),0),'Plano de Ação'!$G5>=DATE(ano_ref,7,1)),1,0)) | L6: =IF(OR(NOT('Plano de Ação'!$B5<>""),NOT(ISNUMBER('Plano de Ação'!$F5)),NOT(ISNUMBER('Plano de Ação'!$G5)),'Plano de Ação'!$J5="Cancelada"),0,IF(AND('Plano de Ação'!$F5<=EOMONTH(DATE(ano_ref,8,1),0),'Plano de Ação'!$G5>=DATE(ano_ref,8,1)),1,0)) | M6: =IF(OR(NOT('Plano de Ação'!$B5<>""),NOT(ISNUMBER('Plano de Ação'!$F5)),NOT(ISNUMBER('Plano de Ação'!$G5)),'Plano de Ação'!$J5="Cancelada"),0,IF(AND('Plano de Ação'!$F5<=EOMONTH(DATE(ano_ref,9,1),0),'Plano de Ação'!$G5>=DATE(ano_ref,9,1)),1,0)) | N6: =IF(OR(NOT('Plano de Ação'!$B5<>""),NOT(ISNUMBER('Plano de Ação'!$F5)),NOT(ISNUMBER('Plano de Ação'!$G5)),'Plano de Ação'!$J5="Cancelada"),0,IF(AND('Plano de Ação'!$F5<=EOMONTH(DATE(ano_ref,10,1),0),'Plano de Ação'!$G5>=DATE(ano_ref,10,1)),1,0)) | O6: =IF(OR(NOT('Plano de Ação'!$B5<>""),NOT(ISNUMBER('Plano de Ação'!$F5)),NOT(ISNUMBER('Plano de Ação'!$G5)),'Plano de Ação'!$J5="Cancelada"),0,IF(AND('Plano de Ação'!$F5<=EOMONTH(DATE(ano_ref,11,1),0),'Plano de Ação'!$G5>=DATE(ano_ref,11,1)),1,0)) | P6: =IF(OR(NOT('Plano de Ação'!$B5<>""),NOT(ISNUMBER('Plano de Ação'!$F5)),NOT(ISNUMBER('Plano de Ação'!$G5)),'Plano de Ação'!$J5="Cancelada"),0,IF(AND('Plano de Ação'!$F5<=EOMONTH(DATE(ano_ref,12,1),0),'Plano de Ação'!$G5>=DATE(ano_ref,12,1)),1,0))
A7: =IF('Plano de Ação'!$B6<>"",'Plano de Ação'!A6&"","") | B7: =IF('Plano de Ação'!$B6<>"",'Plano de Ação'!B6,"") | C7: =IF('Plano de Ação'!$B6<>"",'Plano de Ação'!E6&"","") | D7: =IF('Plano de Ação'!$B6<>"",'Plano de Ação'!L6,"") | E7: =IF(OR(NOT('Plano de Ação'!$B6<>""),NOT(ISNUMBER('Plano de Ação'!$F6)),NOT(ISNUMBER('Plano de Ação'!$G6)),'Plano de Ação'!$J6="Cancelada"),0,IF(AND('Plano de Ação'!$F6<=EOMONTH(DATE(ano_ref,1,1),0),'Plano de Ação'!$G6>=DATE(ano_ref,1,1)),1,0)) | F7: =IF(OR(NOT('Plano de Ação'!$B6<>""),NOT(ISNUMBER('Plano de Ação'!$F6)),NOT(ISNUMBER('Plano de Ação'!$G6)),'Plano de Ação'!$J6="Cancelada"),0,IF(AND('Plano de Ação'!$F6<=EOMONTH(DATE(ano_ref,2,1),0),'Plano de Ação'!$G6>=DATE(ano_ref,2,1)),1,0)) | G7: =IF(OR(NOT('Plano de Ação'!$B6<>""),NOT(ISNUMBER('Plano de Ação'!$F6)),NOT(ISNUMBER('Plano de Ação'!$G6)),'Plano de Ação'!$J6="Cancelada"),0,IF(AND('Plano de Ação'!$F6<=EOMONTH(DATE(ano_ref,3,1),0),'Plano de Ação'!$G6>=DATE(ano_ref,3,1)),1,0)) | H7: =IF(OR(NOT('Plano de Ação'!$B6<>""),NOT(ISNUMBER('Plano de Ação'!$F6)),NOT(ISNUMBER('Plano de Ação'!$G6)),'Plano de Ação'!$J6="Cancelada"),0,IF(AND('Plano de Ação'!$F6<=EOMONTH(DATE(ano_ref,4,1),0),'Plano de Ação'!$G6>=DATE(ano_ref,4,1)),1,0)) | I7: =IF(OR(NOT('Plano de Ação'!$B6<>""),NOT(ISNUMBER('Plano de Ação'!$F6)),NOT(ISNUMBER('Plano de Ação'!$G6)),'Plano de Ação'!$J6="Cancelada"),0,IF(AND('Plano de Ação'!$F6<=EOMONTH(DATE(ano_ref,5,1),0),'Plano de Ação'!$G6>=DATE(ano_ref,5,1)),1,0)) | J7: =IF(OR(NOT('Plano de Ação'!$B6<>""),NOT(ISNUMBER('Plano de Ação'!$F6)),NOT(ISNUMBER('Plano de Ação'!$G6)),'Plano de Ação'!$J6="Cancelada"),0,IF(AND('Plano de Ação'!$F6<=EOMONTH(DATE(ano_ref,6,1),0),'Plano de Ação'!$G6>=DATE(ano_ref,6,1)),1,0)) | K7: =IF(OR(NOT('Plano de Ação'!$B6<>""),NOT(ISNUMBER('Plano de Ação'!$F6)),NOT(ISNUMBER('Plano de Ação'!$G6)),'Plano de Ação'!$J6="Cancelada"),0,IF(AND('Plano de Ação'!$F6<=EOMONTH(DATE(ano_ref,7,1),0),'Plano de Ação'!$G6>=DATE(ano_ref,7,1)),1,0)) | L7: =IF(OR(NOT('Plano de Ação'!$B6<>""),NOT(ISNUMBER('Plano de Ação'!$F6)),NOT(ISNUMBER('Plano de Ação'!$G6)),'Plano de Ação'!$J6="Cancelada"),0,IF(AND('Plano de Ação'!$F6<=EOMONTH(DATE(ano_ref,8,1),0),'Plano de Ação'!$G6>=DATE(ano_ref,8,1)),1,0)) | M7: =IF(OR(NOT('Plano de Ação'!$B6<>""),NOT(ISNUMBER('Plano de Ação'!$F6)),NOT(ISNUMBER('Plano de Ação'!$G6)),'Plano de Ação'!$J6="Cancelada"),0,IF(AND('Plano de Ação'!$F6<=EOMONTH(DATE(ano_ref,9,1),0),'Plano de Ação'!$G6>=DATE(ano_ref,9,1)),1,0)) | N7: =IF(OR(NOT('Plano de Ação'!$B6<>""),NOT(ISNUMBER('Plano de Ação'!$F6)),NOT(ISNUMBER('Plano de Ação'!$G6)),'Plano de Ação'!$J6="Cancelada"),0,IF(AND('Plano de Ação'!$F6<=EOMONTH(DATE(ano_ref,10,1),0),'Plano de Ação'!$G6>=DATE(ano_ref,10,1)),1,0)) | O7: =IF(OR(NOT('Plano de Ação'!$B6<>""),NOT(ISNUMBER('Plano de Ação'!$F6)),NOT(ISNUMBER('Plano de Ação'!$G6)),'Plano de Ação'!$J6="Cancelada"),0,IF(AND('Plano de Ação'!$F6<=EOMONTH(DATE(ano_ref,11,1),0),'Plano de Ação'!$G6>=DATE(ano_ref,11,1)),1,0)) | P7: =IF(OR(NOT('Plano de Ação'!$B6<>""),NOT(ISNUMBER('Plano de Ação'!$F6)),NOT(ISNUMBER('Plano de Ação'!$G6)),'Plano de Ação'!$J6="Cancelada"),0,IF(AND('Plano de Ação'!$F6<=EOMONTH(DATE(ano_ref,12,1),0),'Plano de Ação'!$G6>=DATE(ano_ref,12,1)),1,0))
A8: =IF('Plano de Ação'!$B7<>"",'Plano de Ação'!A7&"","") | B8: =IF('Plano de Ação'!$B7<>"",'Plano de Ação'!B7,"") | C8: =IF('Plano de Ação'!$B7<>"",'Plano de Ação'!E7&"","") | D8: =IF('Plano de Ação'!$B7<>"",'Plano de Ação'!L7,"") | E8: =IF(OR(NOT('Plano de Ação'!$B7<>""),NOT(ISNUMBER('Plano de Ação'!$F7)),NOT(ISNUMBER('Plano de Ação'!$G7)),'Plano de Ação'!$J7="Cancelada"),0,IF(AND('Plano de Ação'!$F7<=EOMONTH(DATE(ano_ref,1,1),0),'Plano de Ação'!$G7>=DATE(ano_ref,1,1)),1,0)) | F8: =IF(OR(NOT('Plano de Ação'!$B7<>""),NOT(ISNUMBER('Plano de Ação'!$F7)),NOT(ISNUMBER('Plano de Ação'!$G7)),'Plano de Ação'!$J7="Cancelada"),0,IF(AND('Plano de Ação'!$F7<=EOMONTH(DATE(ano_ref,2,1),0),'Plano de Ação'!$G7>=DATE(ano_ref,2,1)),1,0)) | G8: =IF(OR(NOT('Plano de Ação'!$B7<>""),NOT(ISNUMBER('Plano de Ação'!$F7)),NOT(ISNUMBER('Plano de Ação'!$G7)),'Plano de Ação'!$J7="Cancelada"),0,IF(AND('Plano de Ação'!$F7<=EOMONTH(DATE(ano_ref,3,1),0),'Plano de Ação'!$G7>=DATE(ano_ref,3,1)),1,0)) | H8: =IF(OR(NOT('Plano de Ação'!$B7<>""),NOT(ISNUMBER('Plano de Ação'!$F7)),NOT(ISNUMBER('Plano de Ação'!$G7)),'Plano de Ação'!$J7="Cancelada"),0,IF(AND('Plano de Ação'!$F7<=EOMONTH(DATE(ano_ref,4,1),0),'Plano de Ação'!$G7>=DATE(ano_ref,4,1)),1,0)) | I8: =IF(OR(NOT('Plano de Ação'!$B7<>""),NOT(ISNUMBER('Plano de Ação'!$F7)),NOT(ISNUMBER('Plano de Ação'!$G7)),'Plano de Ação'!$J7="Cancelada"),0,IF(AND('Plano de Ação'!$F7<=EOMONTH(DATE(ano_ref,5,1),0),'Plano de Ação'!$G7>=DATE(ano_ref,5,1)),1,0)) | J8: =IF(OR(NOT('Plano de Ação'!$B7<>""),NOT(ISNUMBER('Plano de Ação'!$F7)),NOT(ISNUMBER('Plano de Ação'!$G7)),'Plano de Ação'!$J7="Cancelada"),0,IF(AND('Plano de Ação'!$F7<=EOMONTH(DATE(ano_ref,6,1),0),'Plano de Ação'!$G7>=DATE(ano_ref,6,1)),1,0)) | K8: =IF(OR(NOT('Plano de Ação'!$B7<>""),NOT(ISNUMBER('Plano de Ação'!$F7)),NOT(ISNUMBER('Plano de Ação'!$G7)),'Plano de Ação'!$J7="Cancelada"),0,IF(AND('Plano de Ação'!$F7<=EOMONTH(DATE(ano_ref,7,1),0),'Plano de Ação'!$G7>=DATE(ano_ref,7,1)),1,0)) | L8: =IF(OR(NOT('Plano de Ação'!$B7<>""),NOT(ISNUMBER('Plano de Ação'!$F7)),NOT(ISNUMBER('Plano de Ação'!$G7)),'Plano de Ação'!$J7="Cancelada"),0,IF(AND('Plano de Ação'!$F7<=EOMONTH(DATE(ano_ref,8,1),0),'Plano de Ação'!$G7>=DATE(ano_ref,8,1)),1,0)) | M8: =IF(OR(NOT('Plano de Ação'!$B7<>""),NOT(ISNUMBER('Plano de Ação'!$F7)),NOT(ISNUMBER('Plano de Ação'!$G7)),'Plano de Ação'!$J7="Cancelada"),0,IF(AND('Plano de Ação'!$F7<=EOMONTH(DATE(ano_ref,9,1),0),'Plano de Ação'!$G7>=DATE(ano_ref,9,1)),1,0)) | N8: =IF(OR(NOT('Plano de Ação'!$B7<>""),NOT(ISNUMBER('Plano de Ação'!$F7)),NOT(ISNUMBER('Plano de Ação'!$G7)),'Plano de Ação'!$J7="Cancelada"),0,IF(AND('Plano de Ação'!$F7<=EOMONTH(DATE(ano_ref,10,1),0),'Plano de Ação'!$G7>=DATE(ano_ref,10,1)),1,0)) | O8: =IF(OR(NOT('Plano de Ação'!$B7<>""),NOT(ISNUMBER('Plano de Ação'!$F7)),NOT(ISNUMBER('Plano de Ação'!$G7)),'Plano de Ação'!$J7="Cancelada"),0,IF(AND('Plano de Ação'!$F7<=EOMONTH(DATE(ano_ref,11,1),0),'Plano de Ação'!$G7>=DATE(ano_ref,11,1)),1,0)) | P8: =IF(OR(NOT('Plano de Ação'!$B7<>""),NOT(ISNUMBER('Plano de Ação'!$F7)),NOT(ISNUMBER('Plano de Ação'!$G7)),'Plano de Ação'!$J7="Cancelada"),0,IF(AND('Plano de Ação'!$F7<=EOMONTH(DATE(ano_ref,12,1),0),'Plano de Ação'!$G7>=DATE(ano_ref,12,1)),1,0))
A9: =IF('Plano de Ação'!$B8<>"",'Plano de Ação'!A8&"","") | B9: =IF('Plano de Ação'!$B8<>"",'Plano de Ação'!B8,"") | C9: =IF('Plano de Ação'!$B8<>"",'Plano de Ação'!E8&"","") | D9: =IF('Plano de Ação'!$B8<>"",'Plano de Ação'!L8,"") | E9: =IF(OR(NOT('Plano de Ação'!$B8<>""),NOT(ISNUMBER('Plano de Ação'!$F8)),NOT(ISNUMBER('Plano de Ação'!$G8)),'Plano de Ação'!$J8="Cancelada"),0,IF(AND('Plano de Ação'!$F8<=EOMONTH(DATE(ano_ref,1,1),0),'Plano de Ação'!$G8>=DATE(ano_ref,1,1)),1,0)) | F9: =IF(OR(NOT('Plano de Ação'!$B8<>""),NOT(ISNUMBER('Plano de Ação'!$F8)),NOT(ISNUMBER('Plano de Ação'!$G8)),'Plano de Ação'!$J8="Cancelada"),0,IF(AND('Plano de Ação'!$F8<=EOMONTH(DATE(ano_ref,2,1),0),'Plano de Ação'!$G8>=DATE(ano_ref,2,1)),1,0)) | G9: =IF(OR(NOT('Plano de Ação'!$B8<>""),NOT(ISNUMBER('Plano de Ação'!$F8)),NOT(ISNUMBER('Plano de Ação'!$G8)),'Plano de Ação'!$J8="Cancelada"),0,IF(AND('Plano de Ação'!$F8<=EOMONTH(DATE(ano_ref,3,1),0),'Plano de Ação'!$G8>=DATE(ano_ref,3,1)),1,0)) | H9: =IF(OR(NOT('Plano de Ação'!$B8<>""),NOT(ISNUMBER('Plano de Ação'!$F8)),NOT(ISNUMBER('Plano de Ação'!$G8)),'Plano de Ação'!$J8="Cancelada"),0,IF(AND('Plano de Ação'!$F8<=EOMONTH(DATE(ano_ref,4,1),0),'Plano de Ação'!$G8>=DATE(ano_ref,4,1)),1,0)) | I9: =IF(OR(NOT('Plano de Ação'!$B8<>""),NOT(ISNUMBER('Plano de Ação'!$F8)),NOT(ISNUMBER('Plano de Ação'!$G8)),'Plano de Ação'!$J8="Cancelada"),0,IF(AND('Plano de Ação'!$F8<=EOMONTH(DATE(ano_ref,5,1),0),'Plano de Ação'!$G8>=DATE(ano_ref,5,1)),1,0)) | J9: =IF(OR(NOT('Plano de Ação'!$B8<>""),NOT(ISNUMBER('Plano de Ação'!$F8)),NOT(ISNUMBER('Plano de Ação'!$G8)),'Plano de Ação'!$J8="Cancelada"),0,IF(AND('Plano de Ação'!$F8<=EOMONTH(DATE(ano_ref,6,1),0),'Plano de Ação'!$G8>=DATE(ano_ref,6,1)),1,0)) | K9: =IF(OR(NOT('Plano de Ação'!$B8<>""),NOT(ISNUMBER('Plano de Ação'!$F8)),NOT(ISNUMBER('Plano de Ação'!$G8)),'Plano de Ação'!$J8="Cancelada"),0,IF(AND('Plano de Ação'!$F8<=EOMONTH(DATE(ano_ref,7,1),0),'Plano de Ação'!$G8>=DATE(ano_ref,7,1)),1,0)) | L9: =IF(OR(NOT('Plano de Ação'!$B8<>""),NOT(ISNUMBER('Plano de Ação'!$F8)),NOT(ISNUMBER('Plano de Ação'!$G8)),'Plano de Ação'!$J8="Cancelada"),0,IF(AND('Plano de Ação'!$F8<=EOMONTH(DATE(ano_ref,8,1),0),'Plano de Ação'!$G8>=DATE(ano_ref,8,1)),1,0)) | M9: =IF(OR(NOT('Plano de Ação'!$B8<>""),NOT(ISNUMBER('Plano de Ação'!$F8)),NOT(ISNUMBER('Plano de Ação'!$G8)),'Plano de Ação'!$J8="Cancelada"),0,IF(AND('Plano de Ação'!$F8<=EOMONTH(DATE(ano_ref,9,1),0),'Plano de Ação'!$G8>=DATE(ano_ref,9,1)),1,0)) | N9: =IF(OR(NOT('Plano de Ação'!$B8<>""),NOT(ISNUMBER('Plano de Ação'!$F8)),NOT(ISNUMBER('Plano de Ação'!$G8)),'Plano de Ação'!$J8="Cancelada"),0,IF(AND('Plano de Ação'!$F8<=EOMONTH(DATE(ano_ref,10,1),0),'Plano de Ação'!$G8>=DATE(ano_ref,10,1)),1,0)) | O9: =IF(OR(NOT('Plano de Ação'!$B8<>""),NOT(ISNUMBER('Plano de Ação'!$F8)),NOT(ISNUMBER('Plano de Ação'!$G8)),'Plano de Ação'!$J8="Cancelada"),0,IF(AND('Plano de Ação'!$F8<=EOMONTH(DATE(ano_ref,11,1),0),'Plano de Ação'!$G8>=DATE(ano_ref,11,1)),1,0)) | P9: =IF(OR(NOT('Plano de Ação'!$B8<>""),NOT(ISNUMBER('Plano de Ação'!$F8)),NOT(ISNUMBER('Plano de Ação'!$G8)),'Plano de Ação'!$J8="Cancelada"),0,IF(AND('Plano de Ação'!$F8<=EOMONTH(DATE(ano_ref,12,1),0),'Plano de Ação'!$G8>=DATE(ano_ref,12,1)),1,0))
A10: =IF('Plano de Ação'!$B9<>"",'Plano de Ação'!A9&"","") | B10: =IF('Plano de Ação'!$B9<>"",'Plano de Ação'!B9,"") | C10: =IF('Plano de Ação'!$B9<>"",'Plano de Ação'!E9&"","") | D10: =IF('Plano de Ação'!$B9<>"",'Plano de Ação'!L9,"") | E10: =IF(OR(NOT('Plano de Ação'!$B9<>""),NOT(ISNUMBER('Plano de Ação'!$F9)),NOT(ISNUMBER('Plano de Ação'!$G9)),'Plano de Ação'!$J9="Cancelada"),0,IF(AND('Plano de Ação'!$F9<=EOMONTH(DATE(ano_ref,1,1),0),'Plano de Ação'!$G9>=DATE(ano_ref,1,1)),1,0)) | F10: =IF(OR(NOT('Plano de Ação'!$B9<>""),NOT(ISNUMBER('Plano de Ação'!$F9)),NOT(ISNUMBER('Plano de Ação'!$G9)),'Plano de Ação'!$J9="Cancelada"),0,IF(AND('Plano de Ação'!$F9<=EOMONTH(DATE(ano_ref,2,1),0),'Plano de Ação'!$G9>=DATE(ano_ref,2,1)),1,0)) | G10: =IF(OR(NOT('Plano de Ação'!$B9<>""),NOT(ISNUMBER('Plano de Ação'!$F9)),NOT(ISNUMBER('Plano de Ação'!$G9)),'Plano de Ação'!$J9="Cancelada"),0,IF(AND('Plano de Ação'!$F9<=EOMONTH(DATE(ano_ref,3,1),0),'Plano de Ação'!$G9>=DATE(ano_ref,3,1)),1,0)) | H10: =IF(OR(NOT('Plano de Ação'!$B9<>""),NOT(ISNUMBER('Plano de Ação'!$F9)),NOT(ISNUMBER('Plano de Ação'!$G9)),'Plano de Ação'!$J9="Cancelada"),0,IF(AND('Plano de Ação'!$F9<=EOMONTH(DATE(ano_ref,4,1),0),'Plano de Ação'!$G9>=DATE(ano_ref,4,1)),1,0)) | I10: =IF(OR(NOT('Plano de Ação'!$B9<>""),NOT(ISNUMBER('Plano de Ação'!$F9)),NOT(ISNUMBER('Plano de Ação'!$G9)),'Plano de Ação'!$J9="Cancelada"),0,IF(AND('Plano de Ação'!$F9<=EOMONTH(DATE(ano_ref,5,1),0),'Plano de Ação'!$G9>=DATE(ano_ref,5,1)),1,0)) | J10: =IF(OR(NOT('Plano de Ação'!$B9<>""),NOT(ISNUMBER('Plano de Ação'!$F9)),NOT(ISNUMBER('Plano de Ação'!$G9)),'Plano de Ação'!$J9="Cancelada"),0,IF(AND('Plano de Ação'!$F9<=EOMONTH(DATE(ano_ref,6,1),0),'Plano de Ação'!$G9>=DATE(ano_ref,6,1)),1,0)) | K10: =IF(OR(NOT('Plano de Ação'!$B9<>""),NOT(ISNUMBER('Plano de Ação'!$F9)),NOT(ISNUMBER('Plano de Ação'!$G9)),'Plano de Ação'!$J9="Cancelada"),0,IF(AND('Plano de Ação'!$F9<=EOMONTH(DATE(ano_ref,7,1),0),'Plano de Ação'!$G9>=DATE(ano_ref,7,1)),1,0)) | L10: =IF(OR(NOT('Plano de Ação'!$B9<>""),NOT(ISNUMBER('Plano de Ação'!$F9)),NOT(ISNUMBER('Plano de Ação'!$G9)),'Plano de Ação'!$J9="Cancelada"),0,IF(AND('Plano de Ação'!$F9<=EOMONTH(DATE(ano_ref,8,1),0),'Plano de Ação'!$G9>=DATE(ano_ref,8,1)),1,0)) | M10: =IF(OR(NOT('Plano de Ação'!$B9<>""),NOT(ISNUMBER('Plano de Ação'!$F9)),NOT(ISNUMBER('Plano de Ação'!$G9)),'Plano de Ação'!$J9="Cancelada"),0,IF(AND('Plano de Ação'!$F9<=EOMONTH(DATE(ano_ref,9,1),0),'Plano de Ação'!$G9>=DATE(ano_ref,9,1)),1,0)) | N10: =IF(OR(NOT('Plano de Ação'!$B9<>""),NOT(ISNUMBER('Plano de Ação'!$F9)),NOT(ISNUMBER('Plano de Ação'!$G9)),'Plano de Ação'!$J9="Cancelada"),0,IF(AND('Plano de Ação'!$F9<=EOMONTH(DATE(ano_ref,10,1),0),'Plano de Ação'!$G9>=DATE(ano_ref,10,1)),1,0)) | O10: =IF(OR(NOT('Plano de Ação'!$B9<>""),NOT(ISNUMBER('Plano de Ação'!$F9)),NOT(ISNUMBER('Plano de Ação'!$G9)),'Plano de Ação'!$J9="Cancelada"),0,IF(AND('Plano de Ação'!$F9<=EOMONTH(DATE(ano_ref,11,1),0),'Plano de Ação'!$G9>=DATE(ano_ref,11,1)),1,0)) | P10: =IF(OR(NOT('Plano de Ação'!$B9<>""),NOT(ISNUMBER('Plano de Ação'!$F9)),NOT(ISNUMBER('Plano de Ação'!$G9)),'Plano de Ação'!$J9="Cancelada"),0,IF(AND('Plano de Ação'!$F9<=EOMONTH(DATE(ano_ref,12,1),0),'Plano de Ação'!$G9>=DATE(ano_ref,12,1)),1,0))
A11: =IF('Plano de Ação'!$B10<>"",'Plano de Ação'!A10&"","") | B11: =IF('Plano de Ação'!$B10<>"",'Plano de Ação'!B10,"") | C11: =IF('Plano de Ação'!$B10<>"",'Plano de Ação'!E10&"","") | D11: =IF('Plano de Ação'!$B10<>"",'Plano de Ação'!L10,"") | E11: =IF(OR(NOT('Plano de Ação'!$B10<>""),NOT(ISNUMBER('Plano de Ação'!$F10)),NOT(ISNUMBER('Plano de Ação'!$G10)),'Plano de Ação'!$J10="Cancelada"),0,IF(AND('Plano de Ação'!$F10<=EOMONTH(DATE(ano_ref,1,1),0),'Plano de Ação'!$G10>=DATE(ano_ref,1,1)),1,0)) | F11: =IF(OR(NOT('Plano de Ação'!$B10<>""),NOT(ISNUMBER('Plano de Ação'!$F10)),NOT(ISNUMBER('Plano de Ação'!$G10)),'Plano de Ação'!$J10="Cancelada"),0,IF(AND('Plano de Ação'!$F10<=EOMONTH(DATE(ano_ref,2,1),0),'Plano de Ação'!$G10>=DATE(ano_ref,2,1)),1,0)) | G11: =IF(OR(NOT('Plano de Ação'!$B10<>""),NOT(ISNUMBER('Plano de Ação'!$F10)),NOT(ISNUMBER('Plano de Ação'!$G10)),'Plano de Ação'!$J10="Cancelada"),0,IF(AND('Plano de Ação'!$F10<=EOMONTH(DATE(ano_ref,3,1),0),'Plano de Ação'!$G10>=DATE(ano_ref,3,1)),1,0)) | H11: =IF(OR(NOT('Plano de Ação'!$B10<>""),NOT(ISNUMBER('Plano de Ação'!$F10)),NOT(ISNUMBER('Plano de Ação'!$G10)),'Plano de Ação'!$J10="Cancelada"),0,IF(AND('Plano de Ação'!$F10<=EOMONTH(DATE(ano_ref,4,1),0),'Plano de Ação'!$G10>=DATE(ano_ref,4,1)),1,0)) | I11: =IF(OR(NOT('Plano de Ação'!$B10<>""),NOT(ISNUMBER('Plano de Ação'!$F10)),NOT(ISNUMBER('Plano de Ação'!$G10)),'Plano de Ação'!$J10="Cancelada"),0,IF(AND('Plano de Ação'!$F10<=EOMONTH(DATE(ano_ref,5,1),0),'Plano de Ação'!$G10>=DATE(ano_ref,5,1)),1,0)) | J11: =IF(OR(NOT('Plano de Ação'!$B10<>""),NOT(ISNUMBER('Plano de Ação'!$F10)),NOT(ISNUMBER('Plano de Ação'!$G10)),'Plano de Ação'!$J10="Cancelada"),0,IF(AND('Plano de Ação'!$F10<=EOMONTH(DATE(ano_ref,6,1),0),'Plano de Ação'!$G10>=DATE(ano_ref,6,1)),1,0)) | K11: =IF(OR(NOT('Plano de Ação'!$B10<>""),NOT(ISNUMBER('Plano de Ação'!$F10)),NOT(ISNUMBER('Plano de Ação'!$G10)),'Plano de Ação'!$J10="Cancelada"),0,IF(AND('Plano de Ação'!$F10<=EOMONTH(DATE(ano_ref,7,1),0),'Plano de Ação'!$G10>=DATE(ano_ref,7,1)),1,0)) | L11: =IF(OR(NOT('Plano de Ação'!$B10<>""),NOT(ISNUMBER('Plano de Ação'!$F10)),NOT(ISNUMBER('Plano de Ação'!$G10)),'Plano de Ação'!$J10="Cancelada"),0,IF(AND('Plano de Ação'!$F10<=EOMONTH(DATE(ano_ref,8,1),0),'Plano de Ação'!$G10>=DATE(ano_ref,8,1)),1,0)) | M11: =IF(OR(NOT('Plano de Ação'!$B10<>""),NOT(ISNUMBER('Plano de Ação'!$F10)),NOT(ISNUMBER('Plano de Ação'!$G10)),'Plano de Ação'!$J10="Cancelada"),0,IF(AND('Plano de Ação'!$F10<=EOMONTH(DATE(ano_ref,9,1),0),'Plano de Ação'!$G10>=DATE(ano_ref,9,1)),1,0)) | N11: =IF(OR(NOT('Plano de Ação'!$B10<>""),NOT(ISNUMBER('Plano de Ação'!$F10)),NOT(ISNUMBER('Plano de Ação'!$G10)),'Plano de Ação'!$J10="Cancelada"),0,IF(AND('Plano de Ação'!$F10<=EOMONTH(DATE(ano_ref,10,1),0),'Plano de Ação'!$G10>=DATE(ano_ref,10,1)),1,0)) | O11: =IF(OR(NOT('Plano de Ação'!$B10<>""),NOT(ISNUMBER('Plano de Ação'!$F10)),NOT(ISNUMBER('Plano de Ação'!$G10)),'Plano de Ação'!$J10="Cancelada"),0,IF(AND('Plano de Ação'!$F10<=EOMONTH(DATE(ano_ref,11,1),0),'Plano de Ação'!$G10>=DATE(ano_ref,11,1)),1,0)) | P11: =IF(OR(NOT('Plano de Ação'!$B10<>""),NOT(ISNUMBER('Plano de Ação'!$F10)),NOT(ISNUMBER('Plano de Ação'!$G10)),'Plano de Ação'!$J10="Cancelada"),0,IF(AND('Plano de Ação'!$F10<=EOMONTH(DATE(ano_ref,12,1),0),'Plano de Ação'!$G10>=DATE(ano_ref,12,1)),1,0))
A12: =IF('Plano de Ação'!$B11<>"",'Plano de Ação'!A11&"","") | B12: =IF('Plano de Ação'!$B11<>"",'Plano de Ação'!B11,"") | C12: =IF('Plano de Ação'!$B11<>"",'Plano de Ação'!E11&"","") | D12: =IF('Plano de Ação'!$B11<>"",'Plano de Ação'!L11,"") | E12: =IF(OR(NOT('Plano de Ação'!$B11<>""),NOT(ISNUMBER('Plano de Ação'!$F11)),NOT(ISNUMBER('Plano de Ação'!$G11)),'Plano de Ação'!$J11="Cancelada"),0,IF(AND('Plano de Ação'!$F11<=EOMONTH(DATE(ano_ref,1,1),0),'Plano de Ação'!$G11>=DATE(ano_ref,1,1)),1,0)) | F12: =IF(OR(NOT('Plano de Ação'!$B11<>""),NOT(ISNUMBER('Plano de Ação'!$F11)),NOT(ISNUMBER('Plano de Ação'!$G11)),'Plano de Ação'!$J11="Cancelada"),0,IF(AND('Plano de Ação'!$F11<=EOMONTH(DATE(ano_ref,2,1),0),'Plano de Ação'!$G11>=DATE(ano_ref,2,1)),1,0)) | G12: =IF(OR(NOT('Plano de Ação'!$B11<>""),NOT(ISNUMBER('Plano de Ação'!$F11)),NOT(ISNUMBER('Plano de Ação'!$G11)),'Plano de Ação'!$J11="Cancelada"),0,IF(AND('Plano de Ação'!$F11<=EOMONTH(DATE(ano_ref,3,1),0),'Plano de Ação'!$G11>=DATE(ano_ref,3,1)),1,0)) | H12: =IF(OR(NOT('Plano de Ação'!$B11<>""),NOT(ISNUMBER('Plano de Ação'!$F11)),NOT(ISNUMBER('Plano de Ação'!$G11)),'Plano de Ação'!$J11="Cancelada"),0,IF(AND('Plano de Ação'!$F11<=EOMONTH(DATE(ano_ref,4,1),0),'Plano de Ação'!$G11>=DATE(ano_ref,4,1)),1,0)) | I12: =IF(OR(NOT('Plano de Ação'!$B11<>""),NOT(ISNUMBER('Plano de Ação'!$F11)),NOT(ISNUMBER('Plano de Ação'!$G11)),'Plano de Ação'!$J11="Cancelada"),0,IF(AND('Plano de Ação'!$F11<=EOMONTH(DATE(ano_ref,5,1),0),'Plano de Ação'!$G11>=DATE(ano_ref,5,1)),1,0)) | J12: =IF(OR(NOT('Plano de Ação'!$B11<>""),NOT(ISNUMBER('Plano de Ação'!$F11)),NOT(ISNUMBER('Plano de Ação'!$G11)),'Plano de Ação'!$J11="Cancelada"),0,IF(AND('Plano de Ação'!$F11<=EOMONTH(DATE(ano_ref,6,1),0),'Plano de Ação'!$G11>=DATE(ano_ref,6,1)),1,0)) | K12: =IF(OR(NOT('Plano de Ação'!$B11<>""),NOT(ISNUMBER('Plano de Ação'!$F11)),NOT(ISNUMBER('Plano de Ação'!$G11)),'Plano de Ação'!$J11="Cancelada"),0,IF(AND('Plano de Ação'!$F11<=EOMONTH(DATE(ano_ref,7,1),0),'Plano de Ação'!$G11>=DATE(ano_ref,7,1)),1,0)) | L12: =IF(OR(NOT('Plano de Ação'!$B11<>""),NOT(ISNUMBER('Plano de Ação'!$F11)),NOT(ISNUMBER('Plano de Ação'!$G11)),'Plano de Ação'!$J11="Cancelada"),0,IF(AND('Plano de Ação'!$F11<=EOMONTH(DATE(ano_ref,8,1),0),'Plano de Ação'!$G11>=DATE(ano_ref,8,1)),1,0)) | M12: =IF(OR(NOT('Plano de Ação'!$B11<>""),NOT(ISNUMBER('Plano de Ação'!$F11)),NOT(ISNUMBER('Plano de Ação'!$G11)),'Plano de Ação'!$J11="Cancelada"),0,IF(AND('Plano de Ação'!$F11<=EOMONTH(DATE(ano_ref,9,1),0),'Plano de Ação'!$G11>=DATE(ano_ref,9,1)),1,0)) | N12: =IF(OR(NOT('Plano de Ação'!$B11<>""),NOT(ISNUMBER('Plano de Ação'!$F11)),NOT(ISNUMBER('Plano de Ação'!$G11)),'Plano de Ação'!$J11="Cancelada"),0,IF(AND('Plano de Ação'!$F11<=EOMONTH(DATE(ano_ref,10,1),0),'Plano de Ação'!$G11>=DATE(ano_ref,10,1)),1,0)) | O12: =IF(OR(NOT('Plano de Ação'!$B11<>""),NOT(ISNUMBER('Plano de Ação'!$F11)),NOT(ISNUMBER('Plano de Ação'!$G11)),'Plano de Ação'!$J11="Cancelada"),0,IF(AND('Plano de Ação'!$F11<=EOMONTH(DATE(ano_ref,11,1),0),'Plano de Ação'!$G11>=DATE(ano_ref,11,1)),1,0)) | P12: =IF(OR(NOT('Plano de Ação'!$B11<>""),NOT(ISNUMBER('Plano de Ação'!$F11)),NOT(ISNUMBER('Plano de Ação'!$G11)),'Plano de Ação'!$J11="Cancelada"),0,IF(AND('Plano de Ação'!$F11<=EOMONTH(DATE(ano_ref,12,1),0),'Plano de Ação'!$G11>=DATE(ano_ref,12,1)),1,0))
A13: =IF('Plano de Ação'!$B12<>"",'Plano de Ação'!A12&"","") | B13: =IF('Plano de Ação'!$B12<>"",'Plano de Ação'!B12,"") | C13: =IF('Plano de Ação'!$B12<>"",'Plano de Ação'!E12&"","") | D13: =IF('Plano de Ação'!$B12<>"",'Plano de Ação'!L12,"") | E13: =IF(OR(NOT('Plano de Ação'!$B12<>""),NOT(ISNUMBER('Plano de Ação'!$F12)),NOT(ISNUMBER('Plano de Ação'!$G12)),'Plano de Ação'!$J12="Cancelada"),0,IF(AND('Plano de Ação'!$F12<=EOMONTH(DATE(ano_ref,1,1),0),'Plano de Ação'!$G12>=DATE(ano_ref,1,1)),1,0)) | F13: =IF(OR(NOT('Plano de Ação'!$B12<>""),NOT(ISNUMBER('Plano de Ação'!$F12)),NOT(ISNUMBER('Plano de Ação'!$G12)),'Plano de Ação'!$J12="Cancelada"),0,IF(AND('Plano de Ação'!$F12<=EOMONTH(DATE(ano_ref,2,1),0),'Plano de Ação'!$G12>=DATE(ano_ref,2,1)),1,0)) | G13: =IF(OR(NOT('Plano de Ação'!$B12<>""),NOT(ISNUMBER('Plano de Ação'!$F12)),NOT(ISNUMBER('Plano de Ação'!$G12)),'Plano de Ação'!$J12="Cancelada"),0,IF(AND('Plano de Ação'!$F12<=EOMONTH(DATE(ano_ref,3,1),0),'Plano de Ação'!$G12>=DATE(ano_ref,3,1)),1,0)) | H13: =IF(OR(NOT('Plano de Ação'!$B12<>""),NOT(ISNUMBER('Plano de Ação'!$F12)),NOT(ISNUMBER('Plano de Ação'!$G12)),'Plano de Ação'!$J12="Cancelada"),0,IF(AND('Plano de Ação'!$F12<=EOMONTH(DATE(ano_ref,4,1),0),'Plano de Ação'!$G12>=DATE(ano_ref,4,1)),1,0)) | I13: =IF(OR(NOT('Plano de Ação'!$B12<>""),NOT(ISNUMBER('Plano de Ação'!$F12)),NOT(ISNUMBER('Plano de Ação'!$G12)),'Plano de Ação'!$J12="Cancelada"),0,IF(AND('Plano de Ação'!$F12<=EOMONTH(DATE(ano_ref,5,1),0),'Plano de Ação'!$G12>=DATE(ano_ref,5,1)),1,0)) | J13: =IF(OR(NOT('Plano de Ação'!$B12<>""),NOT(ISNUMBER('Plano de Ação'!$F12)),NOT(ISNUMBER('Plano de Ação'!$G12)),'Plano de Ação'!$J12="Cancelada"),0,IF(AND('Plano de Ação'!$F12<=EOMONTH(DATE(ano_ref,6,1),0),'Plano de Ação'!$G12>=DATE(ano_ref,6,1)),1,0)) | K13: =IF(OR(NOT('Plano de Ação'!$B12<>""),NOT(ISNUMBER('Plano de Ação'!$F12)),NOT(ISNUMBER('Plano de Ação'!$G12)),'Plano de Ação'!$J12="Cancelada"),0,IF(AND('Plano de Ação'!$F12<=EOMONTH(DATE(ano_ref,7,1),0),'Plano de Ação'!$G12>=DATE(ano_ref,7,1)),1,0)) | L13: =IF(OR(NOT('Plano de Ação'!$B12<>""),NOT(ISNUMBER('Plano de Ação'!$F12)),NOT(ISNUMBER('Plano de Ação'!$G12)),'Plano de Ação'!$J12="Cancelada"),0,IF(AND('Plano de Ação'!$F12<=EOMONTH(DATE(ano_ref,8,1),0),'Plano de Ação'!$G12>=DATE(ano_ref,8,1)),1,0)) | M13: =IF(OR(NOT('Plano de Ação'!$B12<>""),NOT(ISNUMBER('Plano de Ação'!$F12)),NOT(ISNUMBER('Plano de Ação'!$G12)),'Plano de Ação'!$J12="Cancelada"),0,IF(AND('Plano de Ação'!$F12<=EOMONTH(DATE(ano_ref,9,1),0),'Plano de Ação'!$G12>=DATE(ano_ref,9,1)),1,0)) | N13: =IF(OR(NOT('Plano de Ação'!$B12<>""),NOT(ISNUMBER('Plano de Ação'!$F12)),NOT(ISNUMBER('Plano de Ação'!$G12)),'Plano de Ação'!$J12="Cancelada"),0,IF(AND('Plano de Ação'!$F12<=EOMONTH(DATE(ano_ref,10,1),0),'Plano de Ação'!$G12>=DATE(ano_ref,10,1)),1,0)) | O13: =IF(OR(NOT('Plano de Ação'!$B12<>""),NOT(ISNUMBER('Plano de Ação'!$F12)),NOT(ISNUMBER('Plano de Ação'!$G12)),'Plano de Ação'!$J12="Cancelada"),0,IF(AND('Plano de Ação'!$F12<=EOMONTH(DATE(ano_ref,11,1),0),'Plano de Ação'!$G12>=DATE(ano_ref,11,1)),1,0)) | P13: =IF(OR(NOT('Plano de Ação'!$B12<>""),NOT(ISNUMBER('Plano de Ação'!$F12)),NOT(ISNUMBER('Plano de Ação'!$G12)),'Plano de Ação'!$J12="Cancelada"),0,IF(AND('Plano de Ação'!$F12<=EOMONTH(DATE(ano_ref,12,1),0),'Plano de Ação'!$G12>=DATE(ano_ref,12,1)),1,0))
A14: =IF('Plano de Ação'!$B13<>"",'Plano de Ação'!A13&"","") | B14: =IF('Plano de Ação'!$B13<>"",'Plano de Ação'!B13,"") | C14: =IF('Plano de Ação'!$B13<>"",'Plano de Ação'!E13&"","") | D14: =IF('Plano de Ação'!$B13<>"",'Plano de Ação'!L13,"") | E14: =IF(OR(NOT('Plano de Ação'!$B13<>""),NOT(ISNUMBER('Plano de Ação'!$F13)),NOT(ISNUMBER('Plano de Ação'!$G13)),'Plano de Ação'!$J13="Cancelada"),0,IF(AND('Plano de Ação'!$F13<=EOMONTH(DATE(ano_ref,1,1),0),'Plano de Ação'!$G13>=DATE(ano_ref,1,1)),1,0)) | F14: =IF(OR(NOT('Plano de Ação'!$B13<>""),NOT(ISNUMBER('Plano de Ação'!$F13)),NOT(ISNUMBER('Plano de Ação'!$G13)),'Plano de Ação'!$J13="Cancelada"),0,IF(AND('Plano de Ação'!$F13<=EOMONTH(DATE(ano_ref,2,1),0),'Plano de Ação'!$G13>=DATE(ano_ref,2,1)),1,0)) | G14: =IF(OR(NOT('Plano de Ação'!$B13<>""),NOT(ISNUMBER('Plano de Ação'!$F13)),NOT(ISNUMBER('Plano de Ação'!$G13)),'Plano de Ação'!$J13="Cancelada"),0,IF(AND('Plano de Ação'!$F13<=EOMONTH(DATE(ano_ref,3,1),0),'Plano de Ação'!$G13>=DATE(ano_ref,3,1)),1,0)) | H14: =IF(OR(NOT('Plano de Ação'!$B13<>""),NOT(ISNUMBER('Plano de Ação'!$F13)),NOT(ISNUMBER('Plano de Ação'!$G13)),'Plano de Ação'!$J13="Cancelada"),0,IF(AND('Plano de Ação'!$F13<=EOMONTH(DATE(ano_ref,4,1),0),'Plano de Ação'!$G13>=DATE(ano_ref,4,1)),1,0)) | I14: =IF(OR(NOT('Plano de Ação'!$B13<>""),NOT(ISNUMBER('Plano de Ação'!$F13)),NOT(ISNUMBER('Plano de Ação'!$G13)),'Plano de Ação'!$J13="Cancelada"),0,IF(AND('Plano de Ação'!$F13<=EOMONTH(DATE(ano_ref,5,1),0),'Plano de Ação'!$G13>=DATE(ano_ref,5,1)),1,0)) | J14: =IF(OR(NOT('Plano de Ação'!$B13<>""),NOT(ISNUMBER('Plano de Ação'!$F13)),NOT(ISNUMBER('Plano de Ação'!$G13)),'Plano de Ação'!$J13="Cancelada"),0,IF(AND('Plano de Ação'!$F13<=EOMONTH(DATE(ano_ref,6,1),0),'Plano de Ação'!$G13>=DATE(ano_ref,6,1)),1,0)) | K14: =IF(OR(NOT('Plano de Ação'!$B13<>""),NOT(ISNUMBER('Plano de Ação'!$F13)),NOT(ISNUMBER('Plano de Ação'!$G13)),'Plano de Ação'!$J13="Cancelada"),0,IF(AND('Plano de Ação'!$F13<=EOMONTH(DATE(ano_ref,7,1),0),'Plano de Ação'!$G13>=DATE(ano_ref,7,1)),1,0)) | L14: =IF(OR(NOT('Plano de Ação'!$B13<>""),NOT(ISNUMBER('Plano de Ação'!$F13)),NOT(ISNUMBER('Plano de Ação'!$G13)),'Plano de Ação'!$J13="Cancelada"),0,IF(AND('Plano de Ação'!$F13<=EOMONTH(DATE(ano_ref,8,1),0),'Plano de Ação'!$G13>=DATE(ano_ref,8,1)),1,0)) | M14: =IF(OR(NOT('Plano de Ação'!$B13<>""),NOT(ISNUMBER('Plano de Ação'!$F13)),NOT(ISNUMBER('Plano de Ação'!$G13)),'Plano de Ação'!$J13="Cancelada"),0,IF(AND('Plano de Ação'!$F13<=EOMONTH(DATE(ano_ref,9,1),0),'Plano de Ação'!$G13>=DATE(ano_ref,9,1)),1,0)) | N14: =IF(OR(NOT('Plano de Ação'!$B13<>""),NOT(ISNUMBER('Plano de Ação'!$F13)),NOT(ISNUMBER('Plano de Ação'!$G13)),'Plano de Ação'!$J13="Cancelada"),0,IF(AND('Plano de Ação'!$F13<=EOMONTH(DATE(ano_ref,10,1),0),'Plano de Ação'!$G13>=DATE(ano_ref,10,1)),1,0)) | O14: =IF(OR(NOT('Plano de Ação'!$B13<>""),NOT(ISNUMBER('Plano de Ação'!$F13)),NOT(ISNUMBER('Plano de Ação'!$G13)),'Plano de Ação'!$J13="Cancelada"),0,IF(AND('Plano de Ação'!$F13<=EOMONTH(DATE(ano_ref,11,1),0),'Plano de Ação'!$G13>=DATE(ano_ref,11,1)),1,0)) | P14: =IF(OR(NOT('Plano de Ação'!$B13<>""),NOT(ISNUMBER('Plano de Ação'!$F13)),NOT(ISNUMBER('Plano de Ação'!$G13)),'Plano de Ação'!$J13="Cancelada"),0,IF(AND('Plano de Ação'!$F13<=EOMONTH(DATE(ano_ref,12,1),0),'Plano de Ação'!$G13>=DATE(ano_ref,12,1)),1,0))
A15: =IF('Plano de Ação'!$B14<>"",'Plano de Ação'!A14&"","") | B15: =IF('Plano de Ação'!$B14<>"",'Plano de Ação'!B14,"") | C15: =IF('Plano de Ação'!$B14<>"",'Plano de Ação'!E14&"","") | D15: =IF('Plano de Ação'!$B14<>"",'Plano de Ação'!L14,"") | E15: =IF(OR(NOT('Plano de Ação'!$B14<>""),NOT(ISNUMBER('Plano de Ação'!$F14)),NOT(ISNUMBER('Plano de Ação'!$G14)),'Plano de Ação'!$J14="Cancelada"),0,IF(AND('Plano de Ação'!$F14<=EOMONTH(DATE(ano_ref,1,1),0),'Plano de Ação'!$G14>=DATE(ano_ref,1,1)),1,0)) | F15: =IF(OR(NOT('Plano de Ação'!$B14<>""),NOT(ISNUMBER('Plano de Ação'!$F14)),NOT(ISNUMBER('Plano de Ação'!$G14)),'Plano de Ação'!$J14="Cancelada"),0,IF(AND('Plano de Ação'!$F14<=EOMONTH(DATE(ano_ref,2,1),0),'Plano de Ação'!$G14>=DATE(ano_ref,2,1)),1,0)) | G15: =IF(OR(NOT('Plano de Ação'!$B14<>""),NOT(ISNUMBER('Plano de Ação'!$F14)),NOT(ISNUMBER('Plano de Ação'!$G14)),'Plano de Ação'!$J14="Cancelada"),0,IF(AND('Plano de Ação'!$F14<=EOMONTH(DATE(ano_ref,3,1),0),'Plano de Ação'!$G14>=DATE(ano_ref,3,1)),1,0)) | H15: =IF(OR(NOT('Plano de Ação'!$B14<>""),NOT(ISNUMBER('Plano de Ação'!$F14)),NOT(ISNUMBER('Plano de Ação'!$G14)),'Plano de Ação'!$J14="Cancelada"),0,IF(AND('Plano de Ação'!$F14<=EOMONTH(DATE(ano_ref,4,1),0),'Plano de Ação'!$G14>=DATE(ano_ref,4,1)),1,0)) | I15: =IF(OR(NOT('Plano de Ação'!$B14<>""),NOT(ISNUMBER('Plano de Ação'!$F14)),NOT(ISNUMBER('Plano de Ação'!$G14)),'Plano de Ação'!$J14="Cancelada"),0,IF(AND('Plano de Ação'!$F14<=EOMONTH(DATE(ano_ref,5,1),0),'Plano de Ação'!$G14>=DATE(ano_ref,5,1)),1,0)) | J15: =IF(OR(NOT('Plano de Ação'!$B14<>""),NOT(ISNUMBER('Plano de Ação'!$F14)),NOT(ISNUMBER('Plano de Ação'!$G14)),'Plano de Ação'!$J14="Cancelada"),0,IF(AND('Plano de Ação'!$F14<=EOMONTH(DATE(ano_ref,6,1),0),'Plano de Ação'!$G14>=DATE(ano_ref,6,1)),1,0)) | K15: =IF(OR(NOT('Plano de Ação'!$B14<>""),NOT(ISNUMBER('Plano de Ação'!$F14)),NOT(ISNUMBER('Plano de Ação'!$G14)),'Plano de Ação'!$J14="Cancelada"),0,IF(AND('Plano de Ação'!$F14<=EOMONTH(DATE(ano_ref,7,1),0),'Plano de Ação'!$G14>=DATE(ano_ref,7,1)),1,0)) | L15: =IF(OR(NOT('Plano de Ação'!$B14<>""),NOT(ISNUMBER('Plano de Ação'!$F14)),NOT(ISNUMBER('Plano de Ação'!$G14)),'Plano de Ação'!$J14="Cancelada"),0,IF(AND('Plano de Ação'!$F14<=EOMONTH(DATE(ano_ref,8,1),0),'Plano de Ação'!$G14>=DATE(ano_ref,8,1)),1,0)) | M15: =IF(OR(NOT('Plano de Ação'!$B14<>""),NOT(ISNUMBER('Plano de Ação'!$F14)),NOT(ISNUMBER('Plano de Ação'!$G14)),'Plano de Ação'!$J14="Cancelada"),0,IF(AND('Plano de Ação'!$F14<=EOMONTH(DATE(ano_ref,9,1),0),'Plano de Ação'!$G14>=DATE(ano_ref,9,1)),1,0)) | N15: =IF(OR(NOT('Plano de Ação'!$B14<>""),NOT(ISNUMBER('Plano de Ação'!$F14)),NOT(ISNUMBER('Plano de Ação'!$G14)),'Plano de Ação'!$J14="Cancelada"),0,IF(AND('Plano de Ação'!$F14<=EOMONTH(DATE(ano_ref,10,1),0),'Plano de Ação'!$G14>=DATE(ano_ref,10,1)),1,0)) | O15: =IF(OR(NOT('Plano de Ação'!$B14<>""),NOT(ISNUMBER('Plano de Ação'!$F14)),NOT(ISNUMBER('Plano de Ação'!$G14)),'Plano de Ação'!$J14="Cancelada"),0,IF(AND('Plano de Ação'!$F14<=EOMONTH(DATE(ano_ref,11,1),0),'Plano de Ação'!$G14>=DATE(ano_ref,11,1)),1,0)) | P15: =IF(OR(NOT('Plano de Ação'!$B14<>""),NOT(ISNUMBER('Plano de Ação'!$F14)),NOT(ISNUMBER('Plano de Ação'!$G14)),'Plano de Ação'!$J14="Cancelada"),0,IF(AND('Plano de Ação'!$F14<=EOMONTH(DATE(ano_ref,12,1),0),'Plano de Ação'!$G14>=DATE(ano_ref,12,1)),1,0))
A16: =IF('Plano de Ação'!$B15<>"",'Plano de Ação'!A15&"","") | B16: =IF('Plano de Ação'!$B15<>"",'Plano de Ação'!B15,"") | C16: =IF('Plano de Ação'!$B15<>"",'Plano de Ação'!E15&"","") | D16: =IF('Plano de Ação'!$B15<>"",'Plano de Ação'!L15,"") | E16: =IF(OR(NOT('Plano de Ação'!$B15<>""),NOT(ISNUMBER('Plano de Ação'!$F15)),NOT(ISNUMBER('Plano de Ação'!$G15)),'Plano de Ação'!$J15="Cancelada"),0,IF(AND('Plano de Ação'!$F15<=EOMONTH(DATE(ano_ref,1,1),0),'Plano de Ação'!$G15>=DATE(ano_ref,1,1)),1,0)) | F16: =IF(OR(NOT('Plano de Ação'!$B15<>""),NOT(ISNUMBER('Plano de Ação'!$F15)),NOT(ISNUMBER('Plano de Ação'!$G15)),'Plano de Ação'!$J15="Cancelada"),0,IF(AND('Plano de Ação'!$F15<=EOMONTH(DATE(ano_ref,2,1),0),'Plano de Ação'!$G15>=DATE(ano_ref,2,1)),1,0)) | G16: =IF(OR(NOT('Plano de Ação'!$B15<>""),NOT(ISNUMBER('Plano de Ação'!$F15)),NOT(ISNUMBER('Plano de Ação'!$G15)),'Plano de Ação'!$J15="Cancelada"),0,IF(AND('Plano de Ação'!$F15<=EOMONTH(DATE(ano_ref,3,1),0),'Plano de Ação'!$G15>=DATE(ano_ref,3,1)),1,0)) | H16: =IF(OR(NOT('Plano de Ação'!$B15<>""),NOT(ISNUMBER('Plano de Ação'!$F15)),NOT(ISNUMBER('Plano de Ação'!$G15)),'Plano de Ação'!$J15="Cancelada"),0,IF(AND('Plano de Ação'!$F15<=EOMONTH(DATE(ano_ref,4,1),0),'Plano de Ação'!$G15>=DATE(ano_ref,4,1)),1,0)) | I16: =IF(OR(NOT('Plano de Ação'!$B15<>""),NOT(ISNUMBER('Plano de Ação'!$F15)),NOT(ISNUMBER('Plano de Ação'!$G15)),'Plano de Ação'!$J15="Cancelada"),0,IF(AND('Plano de Ação'!$F15<=EOMONTH(DATE(ano_ref,5,1),0),'Plano de Ação'!$G15>=DATE(ano_ref,5,1)),1,0)) | J16: =IF(OR(NOT('Plano de Ação'!$B15<>""),NOT(ISNUMBER('Plano de Ação'!$F15)),NOT(ISNUMBER('Plano de Ação'!$G15)),'Plano de Ação'!$J15="Cancelada"),0,IF(AND('Plano de Ação'!$F15<=EOMONTH(DATE(ano_ref,6,1),0),'Plano de Ação'!$G15>=DATE(ano_ref,6,1)),1,0)) | K16: =IF(OR(NOT('Plano de Ação'!$B15<>""),NOT(ISNUMBER('Plano de Ação'!$F15)),NOT(ISNUMBER('Plano de Ação'!$G15)),'Plano de Ação'!$J15="Cancelada"),0,IF(AND('Plano de Ação'!$F15<=EOMONTH(DATE(ano_ref,7,1),0),'Plano de Ação'!$G15>=DATE(ano_ref,7,1)),1,0)) | L16: =IF(OR(NOT('Plano de Ação'!$B15<>""),NOT(ISNUMBER('Plano de Ação'!$F15)),NOT(ISNUMBER('Plano de Ação'!$G15)),'Plano de Ação'!$J15="Cancelada"),0,IF(AND('Plano de Ação'!$F15<=EOMONTH(DATE(ano_ref,8,1),0),'Plano de Ação'!$G15>=DATE(ano_ref,8,1)),1,0)) | M16: =IF(OR(NOT('Plano de Ação'!$B15<>""),NOT(ISNUMBER('Plano de Ação'!$F15)),NOT(ISNUMBER('Plano de Ação'!$G15)),'Plano de Ação'!$J15="Cancelada"),0,IF(AND('Plano de Ação'!$F15<=EOMONTH(DATE(ano_ref,9,1),0),'Plano de Ação'!$G15>=DATE(ano_ref,9,1)),1,0)) | N16: =IF(OR(NOT('Plano de Ação'!$B15<>""),NOT(ISNUMBER('Plano de Ação'!$F15)),NOT(ISNUMBER('Plano de Ação'!$G15)),'Plano de Ação'!$J15="Cancelada"),0,IF(AND('Plano de Ação'!$F15<=EOMONTH(DATE(ano_ref,10,1),0),'Plano de Ação'!$G15>=DATE(ano_ref,10,1)),1,0)) | O16: =IF(OR(NOT('Plano de Ação'!$B15<>""),NOT(ISNUMBER('Plano de Ação'!$F15)),NOT(ISNUMBER('Plano de Ação'!$G15)),'Plano de Ação'!$J15="Cancelada"),0,IF(AND('Plano de Ação'!$F15<=EOMONTH(DATE(ano_ref,11,1),0),'Plano de Ação'!$G15>=DATE(ano_ref,11,1)),1,0)) | P16: =IF(OR(NOT('Plano de Ação'!$B15<>""),NOT(ISNUMBER('Plano de Ação'!$F15)),NOT(ISNUMBER('Plano de Ação'!$G15)),'Plano de Ação'!$J15="Cancelada"),0,IF(AND('Plano de Ação'!$F15<=EOMONTH(DATE(ano_ref,12,1),0),'Plano de Ação'!$G15>=DATE(ano_ref,12,1)),1,0))
