Workbook
Name at_codigo: Ativos!$A$4:$A$203
Name at_criticidade: Ativos!$F$4:$F$203
Name at_situacao: Ativos!$G$4:$G$203
Name at_conferencia: Ativos!$I$4:$I$203
Name pl_plano: Planos!$A$4:$A$303
Name pl_situacao: Planos!$I$4:$I$303
Name pl_conferencia: Planos!$M$4:$M$303
Name lst_setor: Listas!$A$4:$A$33
Name lst_situacao_ativo: Listas!$C$4:$C$33
Name lst_tipo_plano: Listas!$E$4:$E$33
Name rv_revisao: 'Revisões'!$A$4:$A$33
Name rv_data: 'Revisões'!$B$4:$B$33
Name cfg_elaborado: 'Instruções'!$C$15
Name cfg_aprovado: 'Instruções'!$C$16
Name cfg_revisao: 'Instruções'!$C$17
Name cfg_data_revisao: 'Instruções'!$C$18
Name pcmd_origem: 'Instruções'!$C$19
Name pcmd_emissao: 'Instruções'!$C$20
Name crono_ano: 'Instruções'!$C$21
Name crono_ano_ref: 'Instruções'!$C$22

Sheet Instruções
C1: Controle de ativos e manutenção preventiva Como usar, parâmetros do documento e conferências gerais. | F1: ="Rev. "&IF(cfg_revisao="","—",cfg_revisao)&IF(ISNUMBER(cfg_data_revisao)," · "&RIGHT("0"&DAY(cfg_data_revisao),2)&"/"&RIGHT("0"&MONTH(cfg_data_revisao),2)&"/"&YEAR(cfg_data_revisao),"")
F2: ="Elaborado: "&IF(cfg_elaborado="","A definir",cfg_elaborado)&CHAR(10)&"Aprovado: "&IF(cfg_aprovado="","A definir",cfg_aprovado)
A7: 1. COMO USAR
A8: 1) Em Listas, cadastre os setores. Em Ativos, cadastre cada equipamento com setor e criticidade (A, B ou C).
A9: 2) Em Planos, uma linha por atividade: ativo, periodicidade em dias, última execução e duração. Próxima execução, dias restantes e situação são calculados.
A10: 3) O Cronograma Anual mostra quantas vezes cada plano cai em cada mês do ano abaixo e soma as horas — útil para dimensionar equipe e negociar parada.
A11: Azul-claro: preencher. Cinza: automático (fórmula protegida, não digite). ERRO em vermelho e Pendente em amarelo pedem ação; OK em verde.
A13: 2. PARÂMETROS DO DOCUMENTO
A14: Parâmetro | C14: Valor | E14: Orientação
A15: Elaborado por | E15: Nome de quem preparou o documento.
A16: Aprovado por (só após aprovação) | E16: Preencha somente após a aprovação efetiva.
A17: Revisão atual (automática) | C17: =IFERROR(LOOKUP(2,1/(rv_revisao<>""),rv_revisao)&"","") | E17: Última linha preenchida em Revisões.
A18: Data da revisão (automática) | C18: =IFERROR(1/(1/LOOKUP(2,1/(rv_revisao<>""),rv_data)),"") | E18: Data da mesma linha da revisão atual.
A19: Origem dos dados | E19: Ex.: preenchimento manual, exportação do sistema.
A20: Data de emissão | E20: Data em que este arquivo foi emitido.
A21: Ano do cronograma | E21: Vazio = ano atual.
A22: Ano usado (automático) | C22: =IF(ISNUMBER(crono_ano),crono_ano,YEAR(TODAY())) | E22: Ano aplicado no Cronograma Anual e no Painel.
A24: 3. CONFERÊNCIAS
A25: Aba / verificação | B25: Linhas preenchidas | C25: Linhas com ERRO | D25: Capacidade / resultado
A26: Ativos | B26: =COUNTA(at_codigo) | C26: =COUNTIF(at_conferencia,"ERRO*") | D26: =IF(COUNTA(Ativos!$A$204:$A$2203)>0,"ATENÇÃO: há dados além da linha 203; estenda fórmulas e nomes","OK")
A27: Planos | B27: =COUNTA(pl_plano) | C27: =COUNTIF(pl_conferencia,"ERRO*") | D27: =IF(COUNTA(Planos!$A$304:$A$2303)>0,"ATENÇÃO: há dados além da linha 303; estenda fórmulas e nomes","OK")
A29: 4. ÍNDICE DAS ABAS (clique no nome)
A30: Painel | B30: Planos vencidos, em dia, horas por mês e vencidos por criticidade.
A31: Ativos | B31: Uma linha por equipamento; criticidade A, B ou C.
A32: Planos | B32: Uma linha por atividade; próxima execução e situação calculadas.
A33: Cronograma Anual | B33: Execuções e horas previstas por mês, montadas automaticamente.
A34: Listas | B34: Setores, situações e tipos usados nas listas suspensas.
A35: Revisões | B35: Histórico de revisões deste arquivo.
A37: PCMD-K01 · Modelo 2.0.0 · PCM Direto · Thiago Oliveira Lima · pcmdireto@gmail.com · Licença MIT · Sem macros, vínculos externos ou envio de dados.

Sheet Painel
C1: Painel de manutenção preventiva Calculado a partir das abas Ativos, Planos e Cronograma Anual. Nenhum número é digitado aqui. | L1: ="Rev. "&IF(cfg_revisao="","—",cfg_revisao)&IF(ISNUMBER(cfg_data_revisao)," · "&RIGHT("0"&DAY(cfg_data_revisao),2)&"/"&RIGHT("0"&MONTH(cfg_data_revisao),2)&"/"&YEAR(cfg_data_revisao),"")
L2: ="Elaborado: "&IF(cfg_elaborado="","A definir",cfg_elaborado)&CHAR(10)&"Aprovado: "&IF(cfg_aprovado="","A definir",cfg_aprovado)
A4: ATIVOS CADASTRADOS | D4: PLANOS ATIVOS | G4: PLANOS VENCIDOS | J4: PLANOS EM DIA
A5: =COUNTA(at_codigo) | D5: =COUNTA(pl_plano) | G5: =COUNTIF(pl_situacao,"Vencido") | J5: =IFERROR(COUNTIF(pl_situacao,"Em dia")/(COUNTA(pl_plano)-COUNTIF(pl_situacao,"Sem data")),"—")
A6: equipamentos | D6: atividades programadas | G6: precisam de ação | J6: em dia ÷ planos com data
A8: ="Vencem nos próximos 7 dias: "&COUNTIF(pl_situacao,"Programar")&" · Vencidos em ativos críticos (A): "&COUNTIFS(pl_situacao,"Vencido",Planos!$L$4:$L$303,"A")&" · Horas planejadas em "&crono_ano_ref&": "&FIXED(SUM('Cronograma Anual'!$F$5:$Q$5),1)&" h"
A10: SITUAÇÃO DOS PLANOS | E10: HORAS PLANEJADAS POR MÊS | I10: VENCIDOS POR CRITICIDADE
A28: DADOS DOS GRÁFICOS (automático, não digite)
A29: Situação | C29: Valor | E29: Mês | G29: Valor | I29: Criticidade | K29: Valor
A30: Vencido | C30: =COUNTIF(pl_situacao,"Vencido") | E30: Jan | G30: ='Cronograma Anual'!F5 | I30: Classe A | K30: =COUNTIFS(pl_situacao,"Vencido",Planos!$L$4:$L$303,"A")
A31: Programar | C31: =COUNTIF(pl_situacao,"Programar") | E31: Fev | G31: ='Cronograma Anual'!G5 | I31: Classe B | K31: =COUNTIFS(pl_situacao,"Vencido",Planos!$L$4:$L$303,"B")
A32: Em dia | C32: =COUNTIF(pl_situacao,"Em dia") | E32: Mar | G32: ='Cronograma Anual'!H5 | I32: Classe C | K32: =COUNTIFS(pl_situacao,"Vencido",Planos!$L$4:$L$303,"C")
A33: Sem data | C33: =COUNTIF(pl_situacao,"Sem data") | E33: Abr | G33: ='Cronograma Anual'!I5
E34: Mai | G34: ='Cronograma Anual'!J5
E35: Jun | G35: ='Cronograma Anual'!K5
E36: Jul | G36: ='Cronograma Anual'!L5
E37: Ago | G37: ='Cronograma Anual'!M5
E38: Set | G38: ='Cronograma Anual'!N5
E39: Out | G39: ='Cronograma Anual'!O5
E40: Nov | G40: ='Cronograma Anual'!P5
E41: Dez | G41: ='Cronograma Anual'!Q5

Sheet Ativos
C1: Cadastro de ativos Uma linha por equipamento. A criticidade (A, B ou C) prioriza os planos. | I1: ="Rev. "&IF(cfg_revisao="","—",cfg_revisao)&IF(ISNUMBER(cfg_data_revisao)," · "&RIGHT("0"&DAY(cfg_data_revisao),2)&"/"&RIGHT("0"&MONTH(cfg_data_revisao),2)&"/"&YEAR(cfg_data_revisao),"")
I2: ="Elaborado: "&IF(cfg_elaborado="","A definir",cfg_elaborado)&CHAR(10)&"Aprovado: "&IF(cfg_aprovado="","A definir",cfg_aprovado)
A3: Código | B3: Descrição | C3: Setor | D3: Fabricante | E3: Ano | F3: Criticidade | G3: Situação | H3: Planos vinculados | I3: Conferência
H4: =IF(A4="","",COUNTIF(Planos!$B$4:$B$303,A4)) | I4: =IF(A4&B4="","",IF(A4="","ERRO: falta o código",IF(COUNTIF(at_codigo,A4)>1,"ERRO: código repetido",IF(F4="","Pendente: defina a criticidade",IF(AND(H4=0,G4<>"Desativado"),"Verificar: ativo sem plano de manutenção","OK")))))
H5: =IF(A5="","",COUNTIF(Planos!$B$4:$B$303,A5)) | I5: =IF(A5&B5="","",IF(A5="","ERRO: falta o código",IF(COUNTIF(at_codigo,A5)>1,"ERRO: código repetido",IF(F5="","Pendente: defina a criticidade",IF(AND(H5=0,G5<>"Desativado"),"Verificar: ativo sem plano de manutenção","OK")))))
H6: =IF(A6="","",COUNTIF(Planos!$B$4:$B$303,A6)) | I6: =IF(A6&B6="","",IF(A6="","ERRO: falta o código",IF(COUNTIF(at_codigo,A6)>1,"ERRO: código repetido",IF(F6="","Pendente: defina a criticidade",IF(AND(H6=0,G6<>"Desativado"),"Verificar: ativo sem plano de manutenção","OK")))))
H7: =IF(A7="","",COUNTIF(Planos!$B$4:$B$303,A7)) | I7: =IF(A7&B7="","",IF(A7="","ERRO: falta o código",IF(COUNTIF(at_codigo,A7)>1,"ERRO: código repetido",IF(F7="","Pendente: defina a criticidade",IF(AND(H7=0,G7<>"Desativado"),"Verificar: ativo sem plano de manutenção","OK")))))
H8: =IF(A8="","",COUNTIF(Planos!$B$4:$B$303,A8)) | I8: =IF(A8&B8="","",IF(A8="","ERRO: falta o código",IF(COUNTIF(at_codigo,A8)>1,"ERRO: código repetido",IF(F8="","Pendente: defina a criticidade",IF(AND(H8=0,G8<>"Desativado"),"Verificar: ativo sem plano de manutenção","OK")))))
H9: =IF(A9="","",COUNTIF(Planos!$B$4:$B$303,A9)) | I9: =IF(A9&B9="","",IF(A9="","ERRO: falta o código",IF(COUNTIF(at_codigo,A9)>1,"ERRO: código repetido",IF(F9="","Pendente: defina a criticidade",IF(AND(H9=0,G9<>"Desativado"),"Verificar: ativo sem plano de manutenção","OK")))))
H10: =IF(A10="","",COUNTIF(Planos!$B$4:$B$303,A10)) | I10: =IF(A10&B10="","",IF(A10="","ERRO: falta o código",IF(COUNTIF(at_codigo,A10)>1,"ERRO: código repetido",IF(F10="","Pendente: defina a criticidade",IF(AND(H10=0,G10<>"Desativado"),"Verificar: ativo sem plano de manutenção","OK")))))
H11: =IF(A11="","",COUNTIF(Planos!$B$4:$B$303,A11)) | I11: =IF(A11&B11="","",IF(A11="","ERRO: falta o código",IF(COUNTIF(at_codigo,A11)>1,"ERRO: código repetido",IF(F11="","Pendente: defina a criticidade",IF(AND(H11=0,G11<>"Desativado"),"Verificar: ativo sem plano de manutenção","OK")))))
H12: =IF(A12="","",COUNTIF(Planos!$B$4:$B$303,A12)) | I12: =IF(A12&B12="","",IF(A12="","ERRO: falta o código",IF(COUNTIF(at_codigo,A12)>1,"ERRO: código repetido",IF(F12="","Pendente: defina a criticidade",IF(AND(H12=0,G12<>"Desativado"),"Verificar: ativo sem plano de manutenção","OK")))))
H13: =IF(A13="","",COUNTIF(Planos!$B$4:$B$303,A13)) | I13: =IF(A13&B13="","",IF(A13="","ERRO: falta o código",IF(COUNTIF(at_codigo,A13)>1,"ERRO: código repetido",IF(F13="","Pendente: defina a criticidade",IF(AND(H13=0,G13<>"Desativado"),"Verificar: ativo sem plano de manutenção","OK")))))
H14: =IF(A14="","",COUNTIF(Planos!$B$4:$B$303,A14)) | I14: =IF(A14&B14="","",IF(A14="","ERRO: falta o código",IF(COUNTIF(at_codigo,A14)>1,"ERRO: código repetido",IF(F14="","Pendente: defina a criticidade",IF(AND(H14=0,G14<>"Desativado"),"Verificar: ativo sem plano de manutenção","OK")))))
H15: =IF(A15="","",COUNTIF(Planos!$B$4:$B$303,A15)) | I15: =IF(A15&B15="","",IF(A15="","ERRO: falta o código",IF(COUNTIF(at_codigo,A15)>1,"ERRO: código repetido",IF(F15="","Pendente: defina a criticidade",IF(AND(H15=0,G15<>"Desativado"),"Verificar: ativo sem plano de manutenção","OK")))))
... H203: =IF(A203="","",COUNTIF(Planos!$B$4:$B$303,A203)) | I203: =IF(A203&B203="","",IF(A203="","ERRO: falta o código",IF(COUNTIF(at_codigo,A203)>1,"ERRO: código repetido",IF(F203="","Pendente: defina a criticidade",IF(AND(H203=0,G203<>"Desativado"),"Verificar: ativo sem plano de manutenção","OK")))))

Sheet Planos
C1: Biblioteca de planos de manutenção Próxima execução, dias restantes e situação vêm da última execução e da periodicidade. | M1: ="Rev. "&IF(cfg_revisao="","—",cfg_revisao)&IF(ISNUMBER(cfg_data_revisao)," · "&RIGHT("0"&DAY(cfg_data_revisao),2)&"/"&RIGHT("0"&MONTH(cfg_data_revisao),2)&"/"&YEAR(cfg_data_revisao),"")
M2: ="Elaborado: "&IF(cfg_elaborado="","A definir",cfg_elaborado)&CHAR(10)&"Aprovado: "&IF(cfg_aprovado="","A definir",cfg_aprovado)
A3: Plano | B3: Ativo | C3: Descrição da atividade | D3: Tipo | E3: Periodicidade (dias) | F3: Última execução | G3: Próxima execução | H3: Dias restantes | I3: Situação | J3: Responsável | K3: Duração (h) | L3: Criticidade do ativo | M3: Conferência
G4: =IF(OR(NOT(ISNUMBER(F4)),N(E4)<=0),"",F4+E4) | H4: =IF(G4="","",G4-TODAY()) | I4: =IF(A4="","",IF(G4="","Sem data",IF(H4<0,"Vencido",IF(H4<=7,"Programar","Em dia")))) | L4: =IF(B4="","",IFERROR(INDEX(at_criticidade,MATCH(B4,at_codigo,0))&"","")) | M4: =IF(A4&B4&C4="","",IF(A4="","ERRO: falta o código do plano",IF(COUNTIF(pl_plano,A4)>1,"ERRO: plano repetido",IF(B4="","ERRO: falta o ativo",IF(ISNA(MATCH(B4,at_codigo,0)),"ERRO: ativo não cadastrado",IF(INDEX(at_situacao,MATCH(B4,at_codigo,0))="Desativado","Verificar: ativo desativado",IF(N(E4)<=0,"Pendente: informe a periodicidade",IF(NOT(ISNUMBER(F4)),"Pendente: informe a última execução",IF(F4>TODAY(),"ERRO: última execução no futuro","OK")))))))))
G5: =IF(OR(NOT(ISNUMBER(F5)),N(E5)<=0),"",F5+E5) | H5: =IF(G5="","",G5-TODAY()) | I5: =IF(A5="","",IF(G5="","Sem data",IF(H5<0,"Vencido",IF(H5<=7,"Programar","Em dia")))) | L5: =IF(B5="","",IFERROR(INDEX(at_criticidade,MATCH(B5,at_codigo,0))&"","")) | M5: =IF(A5&B5&C5="","",IF(A5="","ERRO: falta o código do plano",IF(COUNTIF(pl_plano,A5)>1,"ERRO: plano repetido",IF(B5="","ERRO: falta o ativo",IF(ISNA(MATCH(B5,at_codigo,0)),"ERRO: ativo não cadastrado",IF(INDEX(at_situacao,MATCH(B5,at_codigo,0))="Desativado","Verificar: ativo desativado",IF(N(E5)<=0,"Pendente: informe a periodicidade",IF(NOT(ISNUMBER(F5)),"Pendente: informe a última execução",IF(F5>TODAY(),"ERRO: última execução no futuro","OK")))))))))
G6: =IF(OR(NOT(ISNUMBER(F6)),N(E6)<=0),"",F6+E6) | H6: =IF(G6="","",G6-TODAY()) | I6: =IF(A6="","",IF(G6="","Sem data",IF(H6<0,"Vencido",IF(H6<=7,"Programar","Em dia")))) | L6: =IF(B6="","",IFERROR(INDEX(at_criticidade,MATCH(B6,at_codigo,0))&"","")) | M6: =IF(A6&B6&C6="","",IF(A6="","ERRO: falta o código do plano",IF(COUNTIF(pl_plano,A6)>1,"ERRO: plano repetido",IF(B6="","ERRO: falta o ativo",IF(ISNA(MATCH(B6,at_codigo,0)),"ERRO: ativo não cadastrado",IF(INDEX(at_situacao,MATCH(B6,at_codigo,0))="Desativado","Verificar: ativo desativado",IF(N(E6)<=0,"Pendente: informe a periodicidade",IF(NOT(ISNUMBER(F6)),"Pendente: informe a última execução",IF(F6>TODAY(),"ERRO: última execução no futuro","OK")))))))))
G7: =IF(OR(NOT(ISNUMBER(F7)),N(E7)<=0),"",F7+E7) | H7: =IF(G7="","",G7-TODAY()) | I7: =IF(A7="","",IF(G7="","Sem data",IF(H7<0,"Vencido",IF(H7<=7,"Programar","Em dia")))) | L7: =IF(B7="","",IFERROR(INDEX(at_criticidade,MATCH(B7,at_codigo,0))&"","")) | M7: =IF(A7&B7&C7="","",IF(A7="","ERRO: falta o código do plano",IF(COUNTIF(pl_plano,A7)>1,"ERRO: plano repetido",IF(B7="","ERRO: falta o ativo",IF(ISNA(MATCH(B7,at_codigo,0)),"ERRO: ativo não cadastrado",IF(INDEX(at_situacao,MATCH(B7,at_codigo,0))="Desativado","Verificar: ativo desativado",IF(N(E7)<=0,"Pendente: informe a periodicidade",IF(NOT(ISNUMBER(F7)),"Pendente: informe a última execução",IF(F7>TODAY(),"ERRO: última execução no futuro","OK")))))))))
G8: =IF(OR(NOT(ISNUMBER(F8)),N(E8)<=0),"",F8+E8) | H8: =IF(G8="","",G8-TODAY()) | I8: =IF(A8="","",IF(G8="","Sem data",IF(H8<0,"Vencido",IF(H8<=7,"Programar","Em dia")))) | L8: =IF(B8="","",IFERROR(INDEX(at_criticidade,MATCH(B8,at_codigo,0))&"","")) | M8: =IF(A8&B8&C8="","",IF(A8="","ERRO: falta o código do plano",IF(COUNTIF(pl_plano,A8)>1,"ERRO: plano repetido",IF(B8="","ERRO: falta o ativo",IF(ISNA(MATCH(B8,at_codigo,0)),"ERRO: ativo não cadastrado",IF(INDEX(at_situacao,MATCH(B8,at_codigo,0))="Desativado","Verificar: ativo desativado",IF(N(E8)<=0,"Pendente: informe a periodicidade",IF(NOT(ISNUMBER(F8)),"Pendente: informe a última execução",IF(F8>TODAY(),"ERRO: última execução no futuro","OK")))))))))
G9: =IF(OR(NOT(ISNUMBER(F9)),N(E9)<=0),"",F9+E9) | H9: =IF(G9="","",G9-TODAY()) | I9: =IF(A9="","",IF(G9="","Sem data",IF(H9<0,"Vencido",IF(H9<=7,"Programar","Em dia")))) | L9: =IF(B9="","",IFERROR(INDEX(at_criticidade,MATCH(B9,at_codigo,0))&"","")) | M9: =IF(A9&B9&C9="","",IF(A9="","ERRO: falta o código do plano",IF(COUNTIF(pl_plano,A9)>1,"ERRO: plano repetido",IF(B9="","ERRO: falta o ativo",IF(ISNA(MATCH(B9,at_codigo,0)),"ERRO: ativo não cadastrado",IF(INDEX(at_situacao,MATCH(B9,at_codigo,0))="Desativado","Verificar: ativo desativado",IF(N(E9)<=0,"Pendente: informe a periodicidade",IF(NOT(ISNUMBER(F9)),"Pendente: informe a última execução",IF(F9>TODAY(),"ERRO: última execução no futuro","OK")))))))))
G10: =IF(OR(NOT(ISNUMBER(F10)),N(E10)<=0),"",F10+E10) | H10: =IF(G10="","",G10-TODAY()) | I10: =IF(A10="","",IF(G10="","Sem data",IF(H10<0,"Vencido",IF(H10<=7,"Programar","Em dia")))) | L10: =IF(B10="","",IFERROR(INDEX(at_criticidade,MATCH(B10,at_codigo,0))&"","")) | M10: =IF(A10&B10&C10="","",IF(A10="","ERRO: falta o código do plano",IF(COUNTIF(pl_plano,A10)>1,"ERRO: plano repetido",IF(B10="","ERRO: falta o ativo",IF(ISNA(MATCH(B10,at_codigo,0)),"ERRO: ativo não cadastrado",IF(INDEX(at_situacao,MATCH(B10,at_codigo,0))="Desativado","Verificar: ativo desativado",IF(N(E10)<=0,"Pendente: informe a periodicidade",IF(NOT(ISNUMBER(F10)),"Pendente: informe a última execução",IF(F10>TODAY(),"ERRO: última execução no futuro","OK")))))))))
G11: =IF(OR(NOT(ISNUMBER(F11)),N(E11)<=0),"",F11+E11) | H11: =IF(G11="","",G11-TODAY()) | I11: =IF(A11="","",IF(G11="","Sem data",IF(H11<0,"Vencido",IF(H11<=7,"Programar","Em dia")))) | L11: =IF(B11="","",IFERROR(INDEX(at_criticidade,MATCH(B11,at_codigo,0))&"","")) | M11: =IF(A11&B11&C11="","",IF(A11="","ERRO: falta o código do plano",IF(COUNTIF(pl_plano,A11)>1,"ERRO: plano repetido",IF(B11="","ERRO: falta o ativo",IF(ISNA(MATCH(B11,at_codigo,0)),"ERRO: ativo não cadastrado",IF(INDEX(at_situacao,MATCH(B11,at_codigo,0))="Desativado","Verificar: ativo desativado",IF(N(E11)<=0,"Pendente: informe a periodicidade",IF(NOT(ISNUMBER(F11)),"Pendente: informe a última execução",IF(F11>TODAY(),"ERRO: última execução no futuro","OK")))))))))
G12: =IF(OR(NOT(ISNUMBER(F12)),N(E12)<=0),"",F12+E12) | H12: =IF(G12="","",G12-TODAY()) | I12: =IF(A12="","",IF(G12="","Sem data",IF(H12<0,"Vencido",IF(H12<=7,"Programar","Em dia")))) | L12: =IF(B12="","",IFERROR(INDEX(at_criticidade,MATCH(B12,at_codigo,0))&"","")) | M12: =IF(A12&B12&C12="","",IF(A12="","ERRO: falta o código do plano",IF(COUNTIF(pl_plano,A12)>1,"ERRO: plano repetido",IF(B12="","ERRO: falta o ativo",IF(ISNA(MATCH(B12,at_codigo,0)),"ERRO: ativo não cadastrado",IF(INDEX(at_situacao,MATCH(B12,at_codigo,0))="Desativado","Verificar: ativo desativado",IF(N(E12)<=0,"Pendente: informe a periodicidade",IF(NOT(ISNUMBER(F12)),"Pendente: informe a última execução",IF(F12>TODAY(),"ERRO: última execução no futuro","OK")))))))))
G13: =IF(OR(NOT(ISNUMBER(F13)),N(E13)<=0),"",F13+E13) | H13: =IF(G13="","",G13-TODAY()) | I13: =IF(A13="","",IF(G13="","Sem data",IF(H13<0,"Vencido",IF(H13<=7,"Programar","Em dia")))) | L13: =IF(B13="","",IFERROR(INDEX(at_criticidade,MATCH(B13,at_codigo,0))&"","")) | M13: =IF(A13&B13&C13="","",IF(A13="","ERRO: falta o código do plano",IF(COUNTIF(pl_plano,A13)>1,"ERRO: plano repetido",IF(B13="","ERRO: falta o ativo",IF(ISNA(MATCH(B13,at_codigo,0)),"ERRO: ativo não cadastrado",IF(INDEX(at_situacao,MATCH(B13,at_codigo,0))="Desativado","Verificar: ativo desativado",IF(N(E13)<=0,"Pendente: informe a periodicidade",IF(NOT(ISNUMBER(F13)),"Pendente: informe a última execução",IF(F13>TODAY(),"ERRO: última execução no futuro","OK")))))))))
G14: =IF(OR(NOT(ISNUMBER(F14)),N(E14)<=0),"",F14+E14) | H14: =IF(G14="","",G14-TODAY()) | I14: =IF(A14="","",IF(G14="","Sem data",IF(H14<0,"Vencido",IF(H14<=7,"Programar","Em dia")))) | L14: =IF(B14="","",IFERROR(INDEX(at_criticidade,MATCH(B14,at_codigo,0))&"","")) | M14: =IF(A14&B14&C14="","",IF(A14="","ERRO: falta o código do plano",IF(COUNTIF(pl_plano,A14)>1,"ERRO: plano repetido",IF(B14="","ERRO: falta o ativo",IF(ISNA(MATCH(B14,at_codigo,0)),"ERRO: ativo não cadastrado",IF(INDEX(at_situacao,MATCH(B14,at_codigo,0))="Desativado","Verificar: ativo desativado",IF(N(E14)<=0,"Pendente: informe a periodicidade",IF(NOT(ISNUMBER(F14)),"Pendente: informe a última execução",IF(F14>TODAY(),"ERRO: última execução no futuro","OK")))))))))
G15: =IF(OR(NOT(ISNUMBER(F15)),N(E15)<=0),"",F15+E15) | H15: =IF(G15="","",G15-TODAY()) | I15: =IF(A15="","",IF(G15="","Sem data",IF(H15<0,"Vencido",IF(H15<=7,"Programar","Em dia")))) | L15: =IF(B15="","",IFERROR(INDEX(at_criticidade,MATCH(B15,at_codigo,0))&"","")) | M15: =IF(A15&B15&C15="","",IF(A15="","ERRO: falta o código do plano",IF(COUNTIF(pl_plano,A15)>1,"ERRO: plano repetido",IF(B15="","ERRO: falta o ativo",IF(ISNA(MATCH(B15,at_codigo,0)),"ERRO: ativo não cadastrado",IF(INDEX(at_situacao,MATCH(B15,at_codigo,0))="Desativado","Verificar: ativo desativado",IF(N(E15)<=0,"Pendente: informe a periodicidade",IF(NOT(ISNUMBER(F15)),"Pendente: informe a última execução",IF(F15>TODAY(),"ERRO: última execução no futuro","OK")))))))))
... G303: =IF(OR(NOT(ISNUMBER(F303)),N(E303)<=0),"",F303+E303) | H303: =IF(G303="","",G303-TODAY()) | I303: =IF(A303="","",IF(G303="","Sem data",IF(H303<0,"Vencido",IF(H303<=7,"Programar","Em dia")))) | L303: =IF(B303="","",IFERROR(INDEX(at_criticidade,MATCH(B303,at_codigo,0))&"","")) | M303: =IF(A303&B303&C303="","",IF(A303="","ERRO: falta o código do plano",IF(COUNTIF(pl_plano,A303)>1,"ERRO: plano repetido",IF(B303="","ERRO: falta o ativo",IF(ISNA(MATCH(B303,at_codigo,0)),"ERRO: ativo não cadastrado",IF(INDEX(at_situacao,MATCH(B303,at_codigo,0))="Desativado","Verificar: ativo desativado",IF(N(E303)<=0,"Pendente: informe a periodicidade",IF(NOT(ISNUMBER(F303)),"Pendente: informe a última execução",IF(F303>TODAY(),"ERRO: última execução no futuro","OK")))))))))

Sheet Cronograma Anual
C1: Cronograma anual de manutenção Execuções previstas por mês, projetadas a partir da próxima execução e da periodicidade. Não marque nada à mão. | R1: ="Rev. "&IF(cfg_revisao="","—",cfg_revisao)&IF(ISNUMBER(cfg_data_revisao)," · "&RIGHT("0"&DAY(cfg_data_revisao),2)&"/"&RIGHT("0"&MONTH(cfg_data_revisao),2)&"/"&YEAR(cfg_data_revisao),"")
R2: ="Elaborado: "&IF(cfg_elaborado="","A definir",cfg_elaborado)&CHAR(10)&"Aprovado: "&IF(cfg_aprovado="","A definir",cfg_aprovado)
A3: Plano | B3: Ativo | C3: Atividade | D3: Periodicidade (dias) | E3: Duração (h) | F3: Jan | G3: Fev | H3: Mar | I3: Abr | J3: Mai | K3: Jun | L3: Jul | M3: Ago | N3: Set | O3: Out | P3: Nov | Q3: Dez | R3: Total no ano
A4: ="Execuções no mês · ano "&crono_ano_ref | F4: =SUM(F6:F305) | G4: =SUM(G6:G305) | H4: =SUM(H6:H305) | I4: =SUM(I6:I305) | J4: =SUM(J6:J305) | K4: =SUM(K6:K305) | L4: =SUM(L6:L305) | M4: =SUM(M6:M305) | ... Q4: =SUM(Q6:Q305) | R4: =SUM(F4:Q4)
A5: Horas planejadas no mês | F5: =SUMPRODUCT(F6:F305,$E$6:$E$305) | G5: =SUMPRODUCT(G6:G305,$E$6:$E$305) | H5: =SUMPRODUCT(H6:H305,$E$6:$E$305) | I5: =SUMPRODUCT(I6:I305,$E$6:$E$305) | J5: =SUMPRODUCT(J6:J305,$E$6:$E$305) | K5: =SUMPRODUCT(K6:K305,$E$6:$E$305) | L5: =SUMPRODUCT(L6:L305,$E$6:$E$305) | M5: =SUMPRODUCT(M6:M305,$E$6:$E$305) | ... Q5: =SUMPRODUCT(Q6:Q305,$E$6:$E$305) | R5: =SUM(F5:Q5)
A6: =IF(Planos!$A4="","",Planos!A4&"") | B6: =IF(Planos!$A4="","",Planos!B4&"") | C6: =IF(Planos!$A4="","",Planos!C4&"") | D6: =IF(Planos!$A4="","",N(Planos!E4)) | E6: =IF(Planos!$A4="","",N(Planos!K4)) | F6: =IF(OR(Planos!$A4="",NOT(ISNUMBER(Planos!$G4)),N(Planos!$E4)<=0),0,IF(Planos!$G4>EOMONTH(DATE(crono_ano_ref,1,1),0),0,MAX(0,INT((EOMONTH(DATE(crono_ano_ref,1,1),0)-IF(Planos!$G4>=DATE(crono_ano_ref,1,1),Planos!$G4,Planos!$G4+CEILING((DATE(crono_ano_ref,1,1)-Planos!$G4)/Planos!$E4,1)*Planos!$E4))/Planos!$E4)+1))) | G6: =IF(OR(Planos!$A4="",NOT(ISNUMBER(Planos!$G4)),N(Planos!$E4)<=0),0,IF(Planos!$G4>EOMONTH(DATE(crono_ano_ref,2,1),0),0,MAX(0,INT((EOMONTH(DATE(crono_ano_ref,2,1),0)-IF(Planos!$G4>=DATE(crono_ano_ref,2,1),Planos!$G4,Planos!$G4+CEILING((DATE(crono_ano_ref,2,1)-Planos!$G4)/Planos!$E4,1)*Planos!$E4))/Planos!$E4)+1))) | H6: =IF(OR(Planos!$A4="",NOT(ISNUMBER(Planos!$G4)),N(Planos!$E4)<=0),0,IF(Planos!$G4>EOMONTH(DATE(crono_ano_ref,3,1),0),0,MAX(0,INT((EOMONTH(DATE(crono_ano_ref,3,1),0)-IF(Planos!$G4>=DATE(crono_ano_ref,3,1),Planos!$G4,Planos!$G4+CEILING((DATE(crono_ano_ref,3,1)-Planos!$G4)/Planos!$E4,1)*Planos!$E4))/Planos!$E4)+1))) | I6: =IF(OR(Planos!$A4="",NOT(ISNUMBER(Planos!$G4)),N(Planos!$E4)<=0),0,IF(Planos!$G4>EOMONTH(DATE(crono_ano_ref,4,1),0),0,MAX(0,INT((EOMONTH(DATE(crono_ano_ref,4,1),0)-IF(Planos!$G4>=DATE(crono_ano_ref,4,1),Planos!$G4,Planos!$G4+CEILING((DATE(crono_ano_ref,4,1)-Planos!$G4)/Planos!$E4,1)*Planos!$E4))/Planos!$E4)+1))) | J6: =IF(OR(Planos!$A4="",NOT(ISNUMBER(Planos!$G4)),N(Planos!$E4)<=0),0,IF(Planos!$G4>EOMONTH(DATE(crono_ano_ref,5,1),0),0,MAX(0,INT((EOMONTH(DATE(crono_ano_ref,5,1),0)-IF(Planos!$G4>=DATE(crono_ano_ref,5,1),Planos!$G4,Planos!$G4+CEILING((DATE(crono_ano_ref,5,1)-Planos!$G4)/Planos!$E4,1)*Planos!$E4))/Planos!$E4)+1))) | K6: =IF(OR(Planos!$A4="",NOT(ISNUMBER(Planos!$G4)),N(Planos!$E4)<=0),0,IF(Planos!$G4>EOMONTH(DATE(crono_ano_ref,6,1),0),0,MAX(0,INT((EOMONTH(DATE(crono_ano_ref,6,1),0)-IF(Planos!$G4>=DATE(crono_ano_ref,6,1),Planos!$G4,Planos!$G4+CEILING((DATE(crono_ano_ref,6,1)-Planos!$G4)/Planos!$E4,1)*Planos!$E4))/Planos!$E4)+1))) | L6: =IF(OR(Planos!$A4="",NOT(ISNUMBER(Planos!$G4)),N(Planos!$E4)<=0),0,IF(Planos!$G4>EOMONTH(DATE(crono_ano_ref,7,1),0),0,MAX(0,INT((EOMONTH(DATE(crono_ano_ref,7,1),0)-IF(Planos!$G4>=DATE(crono_ano_ref,7,1),Planos!$G4,Planos!$G4+CEILING((DATE(crono_ano_ref,7,1)-Planos!$G4)/Planos!$E4,1)*Planos!$E4))/Planos!$E4)+1))) | M6: =IF(OR(Planos!$A4="",NOT(ISNUMBER(Planos!$G4)),N(Planos!$E4)<=0),0,IF(Planos!$G4>EOMONTH(DATE(crono_ano_ref,8,1),0),0,MAX(0,INT((EOMONTH(DATE(crono_ano_ref,8,1),0)-IF(Planos!$G4>=DATE(crono_ano_ref,8,1),Planos!$G4,Planos!$G4+CEILING((DATE(crono_ano_ref,8,1)-Planos!$G4)/Planos!$E4,1)*Planos!$E4))/Planos!$E4)+1))) | N6: =IF(OR(Planos!$A4="",NOT(ISNUMBER(Planos!$G4)),N(Planos!$E4)<=0),0,IF(Planos!$G4>EOMONTH(DATE(crono_ano_ref,9,1),0),0,MAX(0,INT((EOMONTH(DATE(crono_ano_ref,9,1),0)-IF(Planos!$G4>=DATE(crono_ano_ref,9,1),Planos!$G4,Planos!$G4+CEILING((DATE(crono_ano_ref,9,1)-Planos!$G4)/Planos!$E4,1)*Planos!$E4))/Planos!$E4)+1))) | O6: =IF(OR(Planos!$A4="",NOT(ISNUMBER(Planos!$G4)),N(Planos!$E4)<=0),0,IF(Planos!$G4>EOMONTH(DATE(crono_ano_ref,10,1),0),0,MAX(0,INT((EOMONTH(DATE(crono_ano_ref,10,1),0)-IF(Planos!$G4>=DATE(crono_ano_ref,10,1),Planos!$G4,Planos!$G4+CEILING((DATE(crono_ano_ref,10,1)-Planos!$G4)/Planos!$E4,1)*Planos!$E4))/Planos!$E4)+1))) | P6: =IF(OR(Planos!$A4="",NOT(ISNUMBER(Planos!$G4)),N(Planos!$E4)<=0),0,IF(Planos!$G4>EOMONTH(DATE(crono_ano_ref,11,1),0),0,MAX(0,INT((EOMONTH(DATE(crono_ano_ref,11,1),0)-IF(Planos!$G4>=DATE(crono_ano_ref,11,1),Planos!$G4,Planos!$G4+CEILING((DATE(crono_ano_ref,11,1)-Planos!$G4)/Planos!$E4,1)*Planos!$E4))/Planos!$E4)+1))) | Q6: =IF(OR(Planos!$A4="",NOT(ISNUMBER(Planos!$G4)),N(Planos!$E4)<=0),0,IF(Planos!$G4>EOMONTH(DATE(crono_ano_ref,12,1),0),0,MAX(0,INT((EOMONTH(DATE(crono_ano_ref,12,1),0)-IF(Planos!$G4>=DATE(crono_ano_ref,12,1),Planos!$G4,Planos!$G4+CEILING((DATE(crono_ano_ref,12,1)-Planos!$G4)/Planos!$E4,1)*Planos!$E4))/Planos!$E4)+1))) | R6: =SUM(F6:Q6)
A7: =IF(Planos!$A5="","",Planos!A5&"") | B7: =IF(Planos!$A5="","",Planos!B5&"") | C7: =IF(Planos!$A5="","",Planos!C5&"") | D7: =IF(Planos!$A5="","",N(Planos!E5)) | E7: =IF(Planos!$A5="","",N(Planos!K5)) | F7: =IF(OR(Planos!$A5="",NOT(ISNUMBER(Planos!$G5)),N(Planos!$E5)<=0),0,IF(Planos!$G5>EOMONTH(DATE(crono_ano_ref,1,1),0),0,MAX(0,INT((EOMONTH(DATE(crono_ano_ref,1,1),0)-IF(Planos!$G5>=DATE(crono_ano_ref,1,1),Planos!$G5,Planos!$G5+CEILING((DATE(crono_ano_ref,1,1)-Planos!$G5)/Planos!$E5,1)*Planos!$E5))/Planos!$E5)+1))) | G7: =IF(OR(Planos!$A5="",NOT(ISNUMBER(Planos!$G5)),N(Planos!$E5)<=0),0,IF(Planos!$G5>EOMONTH(DATE(crono_ano_ref,2,1),0),0,MAX(0,INT((EOMONTH(DATE(crono_ano_ref,2,1),0)-IF(Planos!$G5>=DATE(crono_ano_ref,2,1),Planos!$G5,Planos!$G5+CEILING((DATE(crono_ano_ref,2,1)-Planos!$G5)/Planos!$E5,1)*Planos!$E5))/Planos!$E5)+1))) | H7: =IF(OR(Planos!$A5="",NOT(ISNUMBER(Planos!$G5)),N(Planos!$E5)<=0),0,IF(Planos!$G5>EOMONTH(DATE(crono_ano_ref,3,1),0),0,MAX(0,INT((EOMONTH(DATE(crono_ano_ref,3,1),0)-IF(Planos!$G5>=DATE(crono_ano_ref,3,1),Planos!$G5,Planos!$G5+CEILING((DATE(crono_ano_ref,3,1)-Planos!$G5)/Planos!$E5,1)*Planos!$E5))/Planos!$E5)+1))) | I7: =IF(OR(Planos!$A5="",NOT(ISNUMBER(Planos!$G5)),N(Planos!$E5)<=0),0,IF(Planos!$G5>EOMONTH(DATE(crono_ano_ref,4,1),0),0,MAX(0,INT((EOMONTH(DATE(crono_ano_ref,4,1),0)-IF(Planos!$G5>=DATE(crono_ano_ref,4,1),Planos!$G5,Planos!$G5+CEILING((DATE(crono_ano_ref,4,1)-Planos!$G5)/Planos!$E5,1)*Planos!$E5))/Planos!$E5)+1))) | J7: =IF(OR(Planos!$A5="",NOT(ISNUMBER(Planos!$G5)),N(Planos!$E5)<=0),0,IF(Planos!$G5>EOMONTH(DATE(crono_ano_ref,5,1),0),0,MAX(0,INT((EOMONTH(DATE(crono_ano_ref,5,1),0)-IF(Planos!$G5>=DATE(crono_ano_ref,5,1),Planos!$G5,Planos!$G5+CEILING((DATE(crono_ano_ref,5,1)-Planos!$G5)/Planos!$E5,1)*Planos!$E5))/Planos!$E5)+1))) | K7: =IF(OR(Planos!$A5="",NOT(ISNUMBER(Planos!$G5)),N(Planos!$E5)<=0),0,IF(Planos!$G5>EOMONTH(DATE(crono_ano_ref,6,1),0),0,MAX(0,INT((EOMONTH(DATE(crono_ano_ref,6,1),0)-IF(Planos!$G5>=DATE(crono_ano_ref,6,1),Planos!$G5,Planos!$G5+CEILING((DATE(crono_ano_ref,6,1)-Planos!$G5)/Planos!$E5,1)*Planos!$E5))/Planos!$E5)+1))) | L7: =IF(OR(Planos!$A5="",NOT(ISNUMBER(Planos!$G5)),N(Planos!$E5)<=0),0,IF(Planos!$G5>EOMONTH(DATE(crono_ano_ref,7,1),0),0,MAX(0,INT((EOMONTH(DATE(crono_ano_ref,7,1),0)-IF(Planos!$G5>=DATE(crono_ano_ref,7,1),Planos!$G5,Planos!$G5+CEILING((DATE(crono_ano_ref,7,1)-Planos!$G5)/Planos!$E5,1)*Planos!$E5))/Planos!$E5)+1))) | M7: =IF(OR(Planos!$A5="",NOT(ISNUMBER(Planos!$G5)),N(Planos!$E5)<=0),0,IF(Planos!$G5>EOMONTH(DATE(crono_ano_ref,8,1),0),0,MAX(0,INT((EOMONTH(DATE(crono_ano_ref,8,1),0)-IF(Planos!$G5>=DATE(crono_ano_ref,8,1),Planos!$G5,Planos!$G5+CEILING((DATE(crono_ano_ref,8,1)-Planos!$G5)/Planos!$E5,1)*Planos!$E5))/Planos!$E5)+1))) | N7: =IF(OR(Planos!$A5="",NOT(ISNUMBER(Planos!$G5)),N(Planos!$E5)<=0),0,IF(Planos!$G5>EOMONTH(DATE(crono_ano_ref,9,1),0),0,MAX(0,INT((EOMONTH(DATE(crono_ano_ref,9,1),0)-IF(Planos!$G5>=DATE(crono_ano_ref,9,1),Planos!$G5,Planos!$G5+CEILING((DATE(crono_ano_ref,9,1)-Planos!$G5)/Planos!$E5,1)*Planos!$E5))/Planos!$E5)+1))) | O7: =IF(OR(Planos!$A5="",NOT(ISNUMBER(Planos!$G5)),N(Planos!$E5)<=0),0,IF(Planos!$G5>EOMONTH(DATE(crono_ano_ref,10,1),0),0,MAX(0,INT((EOMONTH(DATE(crono_ano_ref,10,1),0)-IF(Planos!$G5>=DATE(crono_ano_ref,10,1),Planos!$G5,Planos!$G5+CEILING((DATE(crono_ano_ref,10,1)-Planos!$G5)/Planos!$E5,1)*Planos!$E5))/Planos!$E5)+1))) | P7: =IF(OR(Planos!$A5="",NOT(ISNUMBER(Planos!$G5)),N(Planos!$E5)<=0),0,IF(Planos!$G5>EOMONTH(DATE(crono_ano_ref,11,1),0),0,MAX(0,INT((EOMONTH(DATE(crono_ano_ref,11,1),0)-IF(Planos!$G5>=DATE(crono_ano_ref,11,1),Planos!$G5,Planos!$G5+CEILING((DATE(crono_ano_ref,11,1)-Planos!$G5)/Planos!$E5,1)*Planos!$E5))/Planos!$E5)+1))) | Q7: =IF(OR(Planos!$A5="",NOT(ISNUMBER(Planos!$G5)),N(Planos!$E5)<=0),0,IF(Planos!$G5>EOMONTH(DATE(crono_ano_ref,12,1),0),0,MAX(0,INT((EOMONTH(DATE(crono_ano_ref,12,1),0)-IF(Planos!$G5>=DATE(crono_ano_ref,12,1),Planos!$G5,Planos!$G5+CEILING((DATE(crono_ano_ref,12,1)-Planos!$G5)/Planos!$E5,1)*Planos!$E5))/Planos!$E5)+1))) | R7: =SUM(F7:Q7)
A8: =IF(Planos!$A6="","",Planos!A6&"") | B8: =IF(Planos!$A6="","",Planos!B6&"") | C8: =IF(Planos!$A6="","",Planos!C6&"") | D8: =IF(Planos!$A6="","",N(Planos!E6)) | E8: =IF(Planos!$A6="","",N(Planos!K6)) | F8: =IF(OR(Planos!$A6="",NOT(ISNUMBER(Planos!$G6)),N(Planos!$E6)<=0),0,IF(Planos!$G6>EOMONTH(DATE(crono_ano_ref,1,1),0),0,MAX(0,INT((EOMONTH(DATE(crono_ano_ref,1,1),0)-IF(Planos!$G6>=DATE(crono_ano_ref,1,1),Planos!$G6,Planos!$G6+CEILING((DATE(crono_ano_ref,1,1)-Planos!$G6)/Planos!$E6,1)*Planos!$E6))/Planos!$E6)+1))) | G8: =IF(OR(Planos!$A6="",NOT(ISNUMBER(Planos!$G6)),N(Planos!$E6)<=0),0,IF(Planos!$G6>EOMONTH(DATE(crono_ano_ref,2,1),0),0,MAX(0,INT((EOMONTH(DATE(crono_ano_ref,2,1),0)-IF(Planos!$G6>=DATE(crono_ano_ref,2,1),Planos!$G6,Planos!$G6+CEILING((DATE(crono_ano_ref,2,1)-Planos!$G6)/Planos!$E6,1)*Planos!$E6))/Planos!$E6)+1))) | H8: =IF(OR(Planos!$A6="",NOT(ISNUMBER(Planos!$G6)),N(Planos!$E6)<=0),0,IF(Planos!$G6>EOMONTH(DATE(crono_ano_ref,3,1),0),0,MAX(0,INT((EOMONTH(DATE(crono_ano_ref,3,1),0)-IF(Planos!$G6>=DATE(crono_ano_ref,3,1),Planos!$G6,Planos!$G6+CEILING((DATE(crono_ano_ref,3,1)-Planos!$G6)/Planos!$E6,1)*Planos!$E6))/Planos!$E6)+1))) | I8: =IF(OR(Planos!$A6="",NOT(ISNUMBER(Planos!$G6)),N(Planos!$E6)<=0),0,IF(Planos!$G6>EOMONTH(DATE(crono_ano_ref,4,1),0),0,MAX(0,INT((EOMONTH(DATE(crono_ano_ref,4,1),0)-IF(Planos!$G6>=DATE(crono_ano_ref,4,1),Planos!$G6,Planos!$G6+CEILING((DATE(crono_ano_ref,4,1)-Planos!$G6)/Planos!$E6,1)*Planos!$E6))/Planos!$E6)+1))) | J8: =IF(OR(Planos!$A6="",NOT(ISNUMBER(Planos!$G6)),N(Planos!$E6)<=0),0,IF(Planos!$G6>EOMONTH(DATE(crono_ano_ref,5,1),0),0,MAX(0,INT((EOMONTH(DATE(crono_ano_ref,5,1),0)-IF(Planos!$G6>=DATE(crono_ano_ref,5,1),Planos!$G6,Planos!$G6+CEILING((DATE(crono_ano_ref,5,1)-Planos!$G6)/Planos!$E6,1)*Planos!$E6))/Planos!$E6)+1))) | K8: =IF(OR(Planos!$A6="",NOT(ISNUMBER(Planos!$G6)),N(Planos!$E6)<=0),0,IF(Planos!$G6>EOMONTH(DATE(crono_ano_ref,6,1),0),0,MAX(0,INT((EOMONTH(DATE(crono_ano_ref,6,1),0)-IF(Planos!$G6>=DATE(crono_ano_ref,6,1),Planos!$G6,Planos!$G6+CEILING((DATE(crono_ano_ref,6,1)-Planos!$G6)/Planos!$E6,1)*Planos!$E6))/Planos!$E6)+1))) | L8: =IF(OR(Planos!$A6="",NOT(ISNUMBER(Planos!$G6)),N(Planos!$E6)<=0),0,IF(Planos!$G6>EOMONTH(DATE(crono_ano_ref,7,1),0),0,MAX(0,INT((EOMONTH(DATE(crono_ano_ref,7,1),0)-IF(Planos!$G6>=DATE(crono_ano_ref,7,1),Planos!$G6,Planos!$G6+CEILING((DATE(crono_ano_ref,7,1)-Planos!$G6)/Planos!$E6,1)*Planos!$E6))/Planos!$E6)+1))) | M8: =IF(OR(Planos!$A6="",NOT(ISNUMBER(Planos!$G6)),N(Planos!$E6)<=0),0,IF(Planos!$G6>EOMONTH(DATE(crono_ano_ref,8,1),0),0,MAX(0,INT((EOMONTH(DATE(crono_ano_ref,8,1),0)-IF(Planos!$G6>=DATE(crono_ano_ref,8,1),Planos!$G6,Planos!$G6+CEILING((DATE(crono_ano_ref,8,1)-Planos!$G6)/Planos!$E6,1)*Planos!$E6))/Planos!$E6)+1))) | N8: =IF(OR(Planos!$A6="",NOT(ISNUMBER(Planos!$G6)),N(Planos!$E6)<=0),0,IF(Planos!$G6>EOMONTH(DATE(crono_ano_ref,9,1),0),0,MAX(0,INT((EOMONTH(DATE(crono_ano_ref,9,1),0)-IF(Planos!$G6>=DATE(crono_ano_ref,9,1),Planos!$G6,Planos!$G6+CEILING((DATE(crono_ano_ref,9,1)-Planos!$G6)/Planos!$E6,1)*Planos!$E6))/Planos!$E6)+1))) | O8: =IF(OR(Planos!$A6="",NOT(ISNUMBER(Planos!$G6)),N(Planos!$E6)<=0),0,IF(Planos!$G6>EOMONTH(DATE(crono_ano_ref,10,1),0),0,MAX(0,INT((EOMONTH(DATE(crono_ano_ref,10,1),0)-IF(Planos!$G6>=DATE(crono_ano_ref,10,1),Planos!$G6,Planos!$G6+CEILING((DATE(crono_ano_ref,10,1)-Planos!$G6)/Planos!$E6,1)*Planos!$E6))/Planos!$E6)+1))) | P8: =IF(OR(Planos!$A6="",NOT(ISNUMBER(Planos!$G6)),N(Planos!$E6)<=0),0,IF(Planos!$G6>EOMONTH(DATE(crono_ano_ref,11,1),0),0,MAX(0,INT((EOMONTH(DATE(crono_ano_ref,11,1),0)-IF(Planos!$G6>=DATE(crono_ano_ref,11,1),Planos!$G6,Planos!$G6+CEILING((DATE(crono_ano_ref,11,1)-Planos!$G6)/Planos!$E6,1)*Planos!$E6))/Planos!$E6)+1))) | Q8: =IF(OR(Planos!$A6="",NOT(ISNUMBER(Planos!$G6)),N(Planos!$E6)<=0),0,IF(Planos!$G6>EOMONTH(DATE(crono_ano_ref,12,1),0),0,MAX(0,INT((EOMONTH(DATE(crono_ano_ref,12,1),0)-IF(Planos!$G6>=DATE(crono_ano_ref,12,1),Planos!$G6,Planos!$G6+CEILING((DATE(crono_ano_ref,12,1)-Planos!$G6)/Planos!$E6,1)*Planos!$E6))/Planos!$E6)+1))) | R8: =SUM(F8:Q8)
A9: =IF(Planos!$A7="","",Planos!A7&"") | B9: =IF(Planos!$A7="","",Planos!B7&"") | C9: =IF(Planos!$A7="","",Planos!C7&"") | D9: =IF(Planos!$A7="","",N(Planos!E7)) | E9: =IF(Planos!$A7="","",N(Planos!K7)) | F9: =IF(OR(Planos!$A7="",NOT(ISNUMBER(Planos!$G7)),N(Planos!$E7)<=0),0,IF(Planos!$G7>EOMONTH(DATE(crono_ano_ref,1,1),0),0,MAX(0,INT((EOMONTH(DATE(crono_ano_ref,1,1),0)-IF(Planos!$G7>=DATE(crono_ano_ref,1,1),Planos!$G7,Planos!$G7+CEILING((DATE(crono_ano_ref,1,1)-Planos!$G7)/Planos!$E7,1)*Planos!$E7))/Planos!$E7)+1))) | G9: =IF(OR(Planos!$A7="",NOT(ISNUMBER(Planos!$G7)),N(Planos!$E7)<=0),0,IF(Planos!$G7>EOMONTH(DATE(crono_ano_ref,2,1),0),0,MAX(0,INT((EOMONTH(DATE(crono_ano_ref,2,1),0)-IF(Planos!$G7>=DATE(crono_ano_ref,2,1),Planos!$G7,Planos!$G7+CEILING((DATE(crono_ano_ref,2,1)-Planos!$G7)/Planos!$E7,1)*Planos!$E7))/Planos!$E7)+1))) | H9: =IF(OR(Planos!$A7="",NOT(ISNUMBER(Planos!$G7)),N(Planos!$E7)<=0),0,IF(Planos!$G7>EOMONTH(DATE(crono_ano_ref,3,1),0),0,MAX(0,INT((EOMONTH(DATE(crono_ano_ref,3,1),0)-IF(Planos!$G7>=DATE(crono_ano_ref,3,1),Planos!$G7,Planos!$G7+CEILING((DATE(crono_ano_ref,3,1)-Planos!$G7)/Planos!$E7,1)*Planos!$E7))/Planos!$E7)+1))) | I9: =IF(OR(Planos!$A7="",NOT(ISNUMBER(Planos!$G7)),N(Planos!$E7)<=0),0,IF(Planos!$G7>EOMONTH(DATE(crono_ano_ref,4,1),0),0,MAX(0,INT((EOMONTH(DATE(crono_ano_ref,4,1),0)-IF(Planos!$G7>=DATE(crono_ano_ref,4,1),Planos!$G7,Planos!$G7+CEILING((DATE(crono_ano_ref,4,1)-Planos!$G7)/Planos!$E7,1)*Planos!$E7))/Planos!$E7)+1))) | J9: =IF(OR(Planos!$A7="",NOT(ISNUMBER(Planos!$G7)),N(Planos!$E7)<=0),0,IF(Planos!$G7>EOMONTH(DATE(crono_ano_ref,5,1),0),0,MAX(0,INT((EOMONTH(DATE(crono_ano_ref,5,1),0)-IF(Planos!$G7>=DATE(crono_ano_ref,5,1),Planos!$G7,Planos!$G7+CEILING((DATE(crono_ano_ref,5,1)-Planos!$G7)/Planos!$E7,1)*Planos!$E7))/Planos!$E7)+1))) | K9: =IF(OR(Planos!$A7="",NOT(ISNUMBER(Planos!$G7)),N(Planos!$E7)<=0),0,IF(Planos!$G7>EOMONTH(DATE(crono_ano_ref,6,1),0),0,MAX(0,INT((EOMONTH(DATE(crono_ano_ref,6,1),0)-IF(Planos!$G7>=DATE(crono_ano_ref,6,1),Planos!$G7,Planos!$G7+CEILING((DATE(crono_ano_ref,6,1)-Planos!$G7)/Planos!$E7,1)*Planos!$E7))/Planos!$E7)+1))) | L9: =IF(OR(Planos!$A7="",NOT(ISNUMBER(Planos!$G7)),N(Planos!$E7)<=0),0,IF(Planos!$G7>EOMONTH(DATE(crono_ano_ref,7,1),0),0,MAX(0,INT((EOMONTH(DATE(crono_ano_ref,7,1),0)-IF(Planos!$G7>=DATE(crono_ano_ref,7,1),Planos!$G7,Planos!$G7+CEILING((DATE(crono_ano_ref,7,1)-Planos!$G7)/Planos!$E7,1)*Planos!$E7))/Planos!$E7)+1))) | M9: =IF(OR(Planos!$A7="",NOT(ISNUMBER(Planos!$G7)),N(Planos!$E7)<=0),0,IF(Planos!$G7>EOMONTH(DATE(crono_ano_ref,8,1),0),0,MAX(0,INT((EOMONTH(DATE(crono_ano_ref,8,1),0)-IF(Planos!$G7>=DATE(crono_ano_ref,8,1),Planos!$G7,Planos!$G7+CEILING((DATE(crono_ano_ref,8,1)-Planos!$G7)/Planos!$E7,1)*Planos!$E7))/Planos!$E7)+1))) | N9: =IF(OR(Planos!$A7="",NOT(ISNUMBER(Planos!$G7)),N(Planos!$E7)<=0),0,IF(Planos!$G7>EOMONTH(DATE(crono_ano_ref,9,1),0),0,MAX(0,INT((EOMONTH(DATE(crono_ano_ref,9,1),0)-IF(Planos!$G7>=DATE(crono_ano_ref,9,1),Planos!$G7,Planos!$G7+CEILING((DATE(crono_ano_ref,9,1)-Planos!$G7)/Planos!$E7,1)*Planos!$E7))/Planos!$E7)+1))) | O9: =IF(OR(Planos!$A7="",NOT(ISNUMBER(Planos!$G7)),N(Planos!$E7)<=0),0,IF(Planos!$G7>EOMONTH(DATE(crono_ano_ref,10,1),0),0,MAX(0,INT((EOMONTH(DATE(crono_ano_ref,10,1),0)-IF(Planos!$G7>=DATE(crono_ano_ref,10,1),Planos!$G7,Planos!$G7+CEILING((DATE(crono_ano_ref,10,1)-Planos!$G7)/Planos!$E7,1)*Planos!$E7))/Planos!$E7)+1))) | P9: =IF(OR(Planos!$A7="",NOT(ISNUMBER(Planos!$G7)),N(Planos!$E7)<=0),0,IF(Planos!$G7>EOMONTH(DATE(crono_ano_ref,11,1),0),0,MAX(0,INT((EOMONTH(DATE(crono_ano_ref,11,1),0)-IF(Planos!$G7>=DATE(crono_ano_ref,11,1),Planos!$G7,Planos!$G7+CEILING((DATE(crono_ano_ref,11,1)-Planos!$G7)/Planos!$E7,1)*Planos!$E7))/Planos!$E7)+1))) | Q9: =IF(OR(Planos!$A7="",NOT(ISNUMBER(Planos!$G7)),N(Planos!$E7)<=0),0,IF(Planos!$G7>EOMONTH(DATE(crono_ano_ref,12,1),0),0,MAX(0,INT((EOMONTH(DATE(crono_ano_ref,12,1),0)-IF(Planos!$G7>=DATE(crono_ano_ref,12,1),Planos!$G7,Planos!$G7+CEILING((DATE(crono_ano_ref,12,1)-Planos!$G7)/Planos!$E7,1)*Planos!$E7))/Planos!$E7)+1))) | R9: =SUM(F9:Q9)
A10: =IF(Planos!$A8="","",Planos!A8&"") | B10: =IF(Planos!$A8="","",Planos!B8&"") | C10: =IF(Planos!$A8="","",Planos!C8&"") | D10: =IF(Planos!$A8="","",N(Planos!E8)) | E10: =IF(Planos!$A8="","",N(Planos!K8)) | F10: =IF(OR(Planos!$A8="",NOT(ISNUMBER(Planos!$G8)),N(Planos!$E8)<=0),0,IF(Planos!$G8>EOMONTH(DATE(crono_ano_ref,1,1),0),0,MAX(0,INT((EOMONTH(DATE(crono_ano_ref,1,1),0)-IF(Planos!$G8>=DATE(crono_ano_ref,1,1),Planos!$G8,Planos!$G8+CEILING((DATE(crono_ano_ref,1,1)-Planos!$G8)/Planos!$E8,1)*Planos!$E8))/Planos!$E8)+1))) | G10: =IF(OR(Planos!$A8="",NOT(ISNUMBER(Planos!$G8)),N(Planos!$E8)<=0),0,IF(Planos!$G8>EOMONTH(DATE(crono_ano_ref,2,1),0),0,MAX(0,INT((EOMONTH(DATE(crono_ano_ref,2,1),0)-IF(Planos!$G8>=DATE(crono_ano_ref,2,1),Planos!$G8,Planos!$G8+CEILING((DATE(crono_ano_ref,2,1)-Planos!$G8)/Planos!$E8,1)*Planos!$E8))/Planos!$E8)+1))) | H10: =IF(OR(Planos!$A8="",NOT(ISNUMBER(Planos!$G8)),N(Planos!$E8)<=0),0,IF(Planos!$G8>EOMONTH(DATE(crono_ano_ref,3,1),0),0,MAX(0,INT((EOMONTH(DATE(crono_ano_ref,3,1),0)-IF(Planos!$G8>=DATE(crono_ano_ref,3,1),Planos!$G8,Planos!$G8+CEILING((DATE(crono_ano_ref,3,1)-Planos!$G8)/Planos!$E8,1)*Planos!$E8))/Planos!$E8)+1))) | I10: =IF(OR(Planos!$A8="",NOT(ISNUMBER(Planos!$G8)),N(Planos!$E8)<=0),0,IF(Planos!$G8>EOMONTH(DATE(crono_ano_ref,4,1),0),0,MAX(0,INT((EOMONTH(DATE(crono_ano_ref,4,1),0)-IF(Planos!$G8>=DATE(crono_ano_ref,4,1),Planos!$G8,Planos!$G8+CEILING((DATE(crono_ano_ref,4,1)-Planos!$G8)/Planos!$E8,1)*Planos!$E8))/Planos!$E8)+1))) | J10: =IF(OR(Planos!$A8="",NOT(ISNUMBER(Planos!$G8)),N(Planos!$E8)<=0),0,IF(Planos!$G8>EOMONTH(DATE(crono_ano_ref,5,1),0),0,MAX(0,INT((EOMONTH(DATE(crono_ano_ref,5,1),0)-IF(Planos!$G8>=DATE(crono_ano_ref,5,1),Planos!$G8,Planos!$G8+CEILING((DATE(crono_ano_ref,5,1)-Planos!$G8)/Planos!$E8,1)*Planos!$E8))/Planos!$E8)+1))) | K10: =IF(OR(Planos!$A8="",NOT(ISNUMBER(Planos!$G8)),N(Planos!$E8)<=0),0,IF(Planos!$G8>EOMONTH(DATE(crono_ano_ref,6,1),0),0,MAX(0,INT((EOMONTH(DATE(crono_ano_ref,6,1),0)-IF(Planos!$G8>=DATE(crono_ano_ref,6,1),Planos!$G8,Planos!$G8+CEILING((DATE(crono_ano_ref,6,1)-Planos!$G8)/Planos!$E8,1)*Planos!$E8))/Planos!$E8)+1))) | L10: =IF(OR(Planos!$A8="",NOT(ISNUMBER(Planos!$G8)),N(Planos!$E8)<=0),0,IF(Planos!$G8>EOMONTH(DATE(crono_ano_ref,7,1),0),0,MAX(0,INT((EOMONTH(DATE(crono_ano_ref,7,1),0)-IF(Planos!$G8>=DATE(crono_ano_ref,7,1),Planos!$G8,Planos!$G8+CEILING((DATE(crono_ano_ref,7,1)-Planos!$G8)/Planos!$E8,1)*Planos!$E8))/Planos!$E8)+1))) | M10: =IF(OR(Planos!$A8="",NOT(ISNUMBER(Planos!$G8)),N(Planos!$E8)<=0),0,IF(Planos!$G8>EOMONTH(DATE(crono_ano_ref,8,1),0),0,MAX(0,INT((EOMONTH(DATE(crono_ano_ref,8,1),0)-IF(Planos!$G8>=DATE(crono_ano_ref,8,1),Planos!$G8,Planos!$G8+CEILING((DATE(crono_ano_ref,8,1)-Planos!$G8)/Planos!$E8,1)*Planos!$E8))/Planos!$E8)+1))) | N10: =IF(OR(Planos!$A8="",NOT(ISNUMBER(Planos!$G8)),N(Planos!$E8)<=0),0,IF(Planos!$G8>EOMONTH(DATE(crono_ano_ref,9,1),0),0,MAX(0,INT((EOMONTH(DATE(crono_ano_ref,9,1),0)-IF(Planos!$G8>=DATE(crono_ano_ref,9,1),Planos!$G8,Planos!$G8+CEILING((DATE(crono_ano_ref,9,1)-Planos!$G8)/Planos!$E8,1)*Planos!$E8))/Planos!$E8)+1))) | O10: =IF(OR(Planos!$A8="",NOT(ISNUMBER(Planos!$G8)),N(Planos!$E8)<=0),0,IF(Planos!$G8>EOMONTH(DATE(crono_ano_ref,10,1),0),0,MAX(0,INT((EOMONTH(DATE(crono_ano_ref,10,1),0)-IF(Planos!$G8>=DATE(crono_ano_ref,10,1),Planos!$G8,Planos!$G8+CEILING((DATE(crono_ano_ref,10,1)-Planos!$G8)/Planos!$E8,1)*Planos!$E8))/Planos!$E8)+1))) | P10: =IF(OR(Planos!$A8="",NOT(ISNUMBER(Planos!$G8)),N(Planos!$E8)<=0),0,IF(Planos!$G8>EOMONTH(DATE(crono_ano_ref,11,1),0),0,MAX(0,INT((EOMONTH(DATE(crono_ano_ref,11,1),0)-IF(Planos!$G8>=DATE(crono_ano_ref,11,1),Planos!$G8,Planos!$G8+CEILING((DATE(crono_ano_ref,11,1)-Planos!$G8)/Planos!$E8,1)*Planos!$E8))/Planos!$E8)+1))) | Q10: =IF(OR(Planos!$A8="",NOT(ISNUMBER(Planos!$G8)),N(Planos!$E8)<=0),0,IF(Planos!$G8>EOMONTH(DATE(crono_ano_ref,12,1),0),0,MAX(0,INT((EOMONTH(DATE(crono_ano_ref,12,1),0)-IF(Planos!$G8>=DATE(crono_ano_ref,12,1),Planos!$G8,Planos!$G8+CEILING((DATE(crono_ano_ref,12,1)-Planos!$G8)/Planos!$E8,1)*Planos!$E8))/Planos!$E8)+1))) | R10: =SUM(F10:Q10)
A11: =IF(Planos!$A9="","",Planos!A9&"") | B11: =IF(Planos!$A9="","",Planos!B9&"") | C11: =IF(Planos!$A9="","",Planos!C9&"") | D11: =IF(Planos!$A9="","",N(Planos!E9)) | E11: =IF(Planos!$A9="","",N(Planos!K9)) | F11: =IF(OR(Planos!$A9="",NOT(ISNUMBER(Planos!$G9)),N(Planos!$E9)<=0),0,IF(Planos!$G9>EOMONTH(DATE(crono_ano_ref,1,1),0),0,MAX(0,INT((EOMONTH(DATE(crono_ano_ref,1,1),0)-IF(Planos!$G9>=DATE(crono_ano_ref,1,1),Planos!$G9,Planos!$G9+CEILING((DATE(crono_ano_ref,1,1)-Planos!$G9)/Planos!$E9,1)*Planos!$E9))/Planos!$E9)+1))) | G11: =IF(OR(Planos!$A9="",NOT(ISNUMBER(Planos!$G9)),N(Planos!$E9)<=0),0,IF(Planos!$G9>EOMONTH(DATE(crono_ano_ref,2,1),0),0,MAX(0,INT((EOMONTH(DATE(crono_ano_ref,2,1),0)-IF(Planos!$G9>=DATE(crono_ano_ref,2,1),Planos!$G9,Planos!$G9+CEILING((DATE(crono_ano_ref,2,1)-Planos!$G9)/Planos!$E9,1)*Planos!$E9))/Planos!$E9)+1))) | H11: =IF(OR(Planos!$A9="",NOT(ISNUMBER(Planos!$G9)),N(Planos!$E9)<=0),0,IF(Planos!$G9>EOMONTH(DATE(crono_ano_ref,3,1),0),0,MAX(0,INT((EOMONTH(DATE(crono_ano_ref,3,1),0)-IF(Planos!$G9>=DATE(crono_ano_ref,3,1),Planos!$G9,Planos!$G9+CEILING((DATE(crono_ano_ref,3,1)-Planos!$G9)/Planos!$E9,1)*Planos!$E9))/Planos!$E9)+1))) | I11: =IF(OR(Planos!$A9="",NOT(ISNUMBER(Planos!$G9)),N(Planos!$E9)<=0),0,IF(Planos!$G9>EOMONTH(DATE(crono_ano_ref,4,1),0),0,MAX(0,INT((EOMONTH(DATE(crono_ano_ref,4,1),0)-IF(Planos!$G9>=DATE(crono_ano_ref,4,1),Planos!$G9,Planos!$G9+CEILING((DATE(crono_ano_ref,4,1)-Planos!$G9)/Planos!$E9,1)*Planos!$E9))/Planos!$E9)+1))) | J11: =IF(OR(Planos!$A9="",NOT(ISNUMBER(Planos!$G9)),N(Planos!$E9)<=0),0,IF(Planos!$G9>EOMONTH(DATE(crono_ano_ref,5,1),0),0,MAX(0,INT((EOMONTH(DATE(crono_ano_ref,5,1),0)-IF(Planos!$G9>=DATE(crono_ano_ref,5,1),Planos!$G9,Planos!$G9+CEILING((DATE(crono_ano_ref,5,1)-Planos!$G9)/Planos!$E9,1)*Planos!$E9))/Planos!$E9)+1))) | K11: =IF(OR(Planos!$A9="",NOT(ISNUMBER(Planos!$G9)),N(Planos!$E9)<=0),0,IF(Planos!$G9>EOMONTH(DATE(crono_ano_ref,6,1),0),0,MAX(0,INT((EOMONTH(DATE(crono_ano_ref,6,1),0)-IF(Planos!$G9>=DATE(crono_ano_ref,6,1),Planos!$G9,Planos!$G9+CEILING((DATE(crono_ano_ref,6,1)-Planos!$G9)/Planos!$E9,1)*Planos!$E9))/Planos!$E9)+1))) | L11: =IF(OR(Planos!$A9="",NOT(ISNUMBER(Planos!$G9)),N(Planos!$E9)<=0),0,IF(Planos!$G9>EOMONTH(DATE(crono_ano_ref,7,1),0),0,MAX(0,INT((EOMONTH(DATE(crono_ano_ref,7,1),0)-IF(Planos!$G9>=DATE(crono_ano_ref,7,1),Planos!$G9,Planos!$G9+CEILING((DATE(crono_ano_ref,7,1)-Planos!$G9)/Planos!$E9,1)*Planos!$E9))/Planos!$E9)+1))) | M11: =IF(OR(Planos!$A9="",NOT(ISNUMBER(Planos!$G9)),N(Planos!$E9)<=0),0,IF(Planos!$G9>EOMONTH(DATE(crono_ano_ref,8,1),0),0,MAX(0,INT((EOMONTH(DATE(crono_ano_ref,8,1),0)-IF(Planos!$G9>=DATE(crono_ano_ref,8,1),Planos!$G9,Planos!$G9+CEILING((DATE(crono_ano_ref,8,1)-Planos!$G9)/Planos!$E9,1)*Planos!$E9))/Planos!$E9)+1))) | N11: =IF(OR(Planos!$A9="",NOT(ISNUMBER(Planos!$G9)),N(Planos!$E9)<=0),0,IF(Planos!$G9>EOMONTH(DATE(crono_ano_ref,9,1),0),0,MAX(0,INT((EOMONTH(DATE(crono_ano_ref,9,1),0)-IF(Planos!$G9>=DATE(crono_ano_ref,9,1),Planos!$G9,Planos!$G9+CEILING((DATE(crono_ano_ref,9,1)-Planos!$G9)/Planos!$E9,1)*Planos!$E9))/Planos!$E9)+1))) | O11: =IF(OR(Planos!$A9="",NOT(ISNUMBER(Planos!$G9)),N(Planos!$E9)<=0),0,IF(Planos!$G9>EOMONTH(DATE(crono_ano_ref,10,1),0),0,MAX(0,INT((EOMONTH(DATE(crono_ano_ref,10,1),0)-IF(Planos!$G9>=DATE(crono_ano_ref,10,1),Planos!$G9,Planos!$G9+CEILING((DATE(crono_ano_ref,10,1)-Planos!$G9)/Planos!$E9,1)*Planos!$E9))/Planos!$E9)+1))) | P11: =IF(OR(Planos!$A9="",NOT(ISNUMBER(Planos!$G9)),N(Planos!$E9)<=0),0,IF(Planos!$G9>EOMONTH(DATE(crono_ano_ref,11,1),0),0,MAX(0,INT((EOMONTH(DATE(crono_ano_ref,11,1),0)-IF(Planos!$G9>=DATE(crono_ano_ref,11,1),Planos!$G9,Planos!$G9+CEILING((DATE(crono_ano_ref,11,1)-Planos!$G9)/Planos!$E9,1)*Planos!$E9))/Planos!$E9)+1))) | Q11: =IF(OR(Planos!$A9="",NOT(ISNUMBER(Planos!$G9)),N(Planos!$E9)<=0),0,IF(Planos!$G9>EOMONTH(DATE(crono_ano_ref,12,1),0),0,MAX(0,INT((EOMONTH(DATE(crono_ano_ref,12,1),0)-IF(Planos!$G9>=DATE(crono_ano_ref,12,1),Planos!$G9,Planos!$G9+CEILING((DATE(crono_ano_ref,12,1)-Planos!$G9)/Planos!$E9,1)*Planos!$E9))/Planos!$E9)+1))) | R11: =SUM(F11:Q11)
A12: =IF(Planos!$A10="","",Planos!A10&"") | B12: =IF(Planos!$A10="","",Planos!B10&"") | C12: =IF(Planos!$A10="","",Planos!C10&"") | D12: =IF(Planos!$A10="","",N(Planos!E10)) | E12: =IF(Planos!$A10="","",N(Planos!K10)) | F12: =IF(OR(Planos!$A10="",NOT(ISNUMBER(Planos!$G10)),N(Planos!$E10)<=0),0,IF(Planos!$G10>EOMONTH(DATE(crono_ano_ref,1,1),0),0,MAX(0,INT((EOMONTH(DATE(crono_ano_ref,1,1),0)-IF(Planos!$G10>=DATE(crono_ano_ref,1,1),Planos!$G10,Planos!$G10+CEILING((DATE(crono_ano_ref,1,1)-Planos!$G10)/Planos!$E10,1)*Planos!$E10))/Planos!$E10)+1))) | G12: =IF(OR(Planos!$A10="",NOT(ISNUMBER(Planos!$G10)),N(Planos!$E10)<=0),0,IF(Planos!$G10>EOMONTH(DATE(crono_ano_ref,2,1),0),0,MAX(0,INT((EOMONTH(DATE(crono_ano_ref,2,1),0)-IF(Planos!$G10>=DATE(crono_ano_ref,2,1),Planos!$G10,Planos!$G10+CEILING((DATE(crono_ano_ref,2,1)-Planos!$G10)/Planos!$E10,1)*Planos!$E10))/Planos!$E10)+1))) | H12: =IF(OR(Planos!$A10="",NOT(ISNUMBER(Planos!$G10)),N(Planos!$E10)<=0),0,IF(Planos!$G10>EOMONTH(DATE(crono_ano_ref,3,1),0),0,MAX(0,INT((EOMONTH(DATE(crono_ano_ref,3,1),0)-IF(Planos!$G10>=DATE(crono_ano_ref,3,1),Planos!$G10,Planos!$G10+CEILING((DATE(crono_ano_ref,3,1)-Planos!$G10)/Planos!$E10,1)*Planos!$E10))/Planos!$E10)+1))) | I12: =IF(OR(Planos!$A10="",NOT(ISNUMBER(Planos!$G10)),N(Planos!$E10)<=0),0,IF(Planos!$G10>EOMONTH(DATE(crono_ano_ref,4,1),0),0,MAX(0,INT((EOMONTH(DATE(crono_ano_ref,4,1),0)-IF(Planos!$G10>=DATE(crono_ano_ref,4,1),Planos!$G10,Planos!$G10+CEILING((DATE(crono_ano_ref,4,1)-Planos!$G10)/Planos!$E10,1)*Planos!$E10))/Planos!$E10)+1))) | J12: =IF(OR(Planos!$A10="",NOT(ISNUMBER(Planos!$G10)),N(Planos!$E10)<=0),0,IF(Planos!$G10>EOMONTH(DATE(crono_ano_ref,5,1),0),0,MAX(0,INT((EOMONTH(DATE(crono_ano_ref,5,1),0)-IF(Planos!$G10>=DATE(crono_ano_ref,5,1),Planos!$G10,Planos!$G10+CEILING((DATE(crono_ano_ref,5,1)-Planos!$G10)/Planos!$E10,1)*Planos!$E10))/Planos!$E10)+1))) | K12: =IF(OR(Planos!$A10="",NOT(ISNUMBER(Planos!$G10)),N(Planos!$E10)<=0),0,IF(Planos!$G10>EOMONTH(DATE(crono_ano_ref,6,1),0),0,MAX(0,INT((EOMONTH(DATE(crono_ano_ref,6,1),0)-IF(Planos!$G10>=DATE(crono_ano_ref,6,1),Planos!$G10,Planos!$G10+CEILING((DATE(crono_ano_ref,6,1)-Planos!$G10)/Planos!$E10,1)*Planos!$E10))/Planos!$E10)+1))) | L12: =IF(OR(Planos!$A10="",NOT(ISNUMBER(Planos!$G10)),N(Planos!$E10)<=0),0,IF(Planos!$G10>EOMONTH(DATE(crono_ano_ref,7,1),0),0,MAX(0,INT((EOMONTH(DATE(crono_ano_ref,7,1),0)-IF(Planos!$G10>=DATE(crono_ano_ref,7,1),Planos!$G10,Planos!$G10+CEILING((DATE(crono_ano_ref,7,1)-Planos!$G10)/Planos!$E10,1)*Planos!$E10))/Planos!$E10)+1))) | M12: =IF(OR(Planos!$A10="",NOT(ISNUMBER(Planos!$G10)),N(Planos!$E10)<=0),0,IF(Planos!$G10>EOMONTH(DATE(crono_ano_ref,8,1),0),0,MAX(0,INT((EOMONTH(DATE(crono_ano_ref,8,1),0)-IF(Planos!$G10>=DATE(crono_ano_ref,8,1),Planos!$G10,Planos!$G10+CEILING((DATE(crono_ano_ref,8,1)-Planos!$G10)/Planos!$E10,1)*Planos!$E10))/Planos!$E10)+1))) | N12: =IF(OR(Planos!$A10="",NOT(ISNUMBER(Planos!$G10)),N(Planos!$E10)<=0),0,IF(Planos!$G10>EOMONTH(DATE(crono_ano_ref,9,1),0),0,MAX(0,INT((EOMONTH(DATE(crono_ano_ref,9,1),0)-IF(Planos!$G10>=DATE(crono_ano_ref,9,1),Planos!$G10,Planos!$G10+CEILING((DATE(crono_ano_ref,9,1)-Planos!$G10)/Planos!$E10,1)*Planos!$E10))/Planos!$E10)+1))) | O12: =IF(OR(Planos!$A10="",NOT(ISNUMBER(Planos!$G10)),N(Planos!$E10)<=0),0,IF(Planos!$G10>EOMONTH(DATE(crono_ano_ref,10,1),0),0,MAX(0,INT((EOMONTH(DATE(crono_ano_ref,10,1),0)-IF(Planos!$G10>=DATE(crono_ano_ref,10,1),Planos!$G10,Planos!$G10+CEILING((DATE(crono_ano_ref,10,1)-Planos!$G10)/Planos!$E10,1)*Planos!$E10))/Planos!$E10)+1))) | P12: =IF(OR(Planos!$A10="",NOT(ISNUMBER(Planos!$G10)),N(Planos!$E10)<=0),0,IF(Planos!$G10>EOMONTH(DATE(crono_ano_ref,11,1),0),0,MAX(0,INT((EOMONTH(DATE(crono_ano_ref,11,1),0)-IF(Planos!$G10>=DATE(crono_ano_ref,11,1),Planos!$G10,Planos!$G10+CEILING((DATE(crono_ano_ref,11,1)-Planos!$G10)/Planos!$E10,1)*Planos!$E10))/Planos!$E10)+1))) | Q12: =IF(OR(Planos!$A10="",NOT(ISNUMBER(Planos!$G10)),N(Planos!$E10)<=0),0,IF(Planos!$G10>EOMONTH(DATE(crono_ano_ref,12,1),0),0,MAX(0,INT((EOMONTH(DATE(crono_ano_ref,12,1),0)-IF(Planos!$G10>=DATE(crono_ano_ref,12,1),Planos!$G10,Planos!$G10+CEILING((DATE(crono_ano_ref,12,1)-Planos!$G10)/Planos!$E10,1)*Planos!$E10))/Planos!$E10)+1))) | R12: =SUM(F12:Q12)
A13: =IF(Planos!$A11="","",Planos!A11&"") | B13: =IF(Planos!$A11="","",Planos!B11&"") | C13: =IF(Planos!$A11="","",Planos!C11&"") | D13: =IF(Planos!$A11="","",N(Planos!E11)) | E13: =IF(Planos!$A11="","",N(Planos!K11)) | F13: =IF(OR(Planos!$A11="",NOT(ISNUMBER(Planos!$G11)),N(Planos!$E11)<=0),0,IF(Planos!$G11>EOMONTH(DATE(crono_ano_ref,1,1),0),0,MAX(0,INT((EOMONTH(DATE(crono_ano_ref,1,1),0)-IF(Planos!$G11>=DATE(crono_ano_ref,1,1),Planos!$G11,Planos!$G11+CEILING((DATE(crono_ano_ref,1,1)-Planos!$G11)/Planos!$E11,1)*Planos!$E11))/Planos!$E11)+1))) | G13: =IF(OR(Planos!$A11="",NOT(ISNUMBER(Planos!$G11)),N(Planos!$E11)<=0),0,IF(Planos!$G11>EOMONTH(DATE(crono_ano_ref,2,1),0),0,MAX(0,INT((EOMONTH(DATE(crono_ano_ref,2,1),0)-IF(Planos!$G11>=DATE(crono_ano_ref,2,1),Planos!$G11,Planos!$G11+CEILING((DATE(crono_ano_ref,2,1)-Planos!$G11)/Planos!$E11,1)*Planos!$E11))/Planos!$E11)+1))) | H13: =IF(OR(Planos!$A11="",NOT(ISNUMBER(Planos!$G11)),N(Planos!$E11)<=0),0,IF(Planos!$G11>EOMONTH(DATE(crono_ano_ref,3,1),0),0,MAX(0,INT((EOMONTH(DATE(crono_ano_ref,3,1),0)-IF(Planos!$G11>=DATE(crono_ano_ref,3,1),Planos!$G11,Planos!$G11+CEILING((DATE(crono_ano_ref,3,1)-Planos!$G11)/Planos!$E11,1)*Planos!$E11))/Planos!$E11)+1))) | I13: =IF(OR(Planos!$A11="",NOT(ISNUMBER(Planos!$G11)),N(Planos!$E11)<=0),0,IF(Planos!$G11>EOMONTH(DATE(crono_ano_ref,4,1),0),0,MAX(0,INT((EOMONTH(DATE(crono_ano_ref,4,1),0)-IF(Planos!$G11>=DATE(crono_ano_ref,4,1),Planos!$G11,Planos!$G11+CEILING((DATE(crono_ano_ref,4,1)-Planos!$G11)/Planos!$E11,1)*Planos!$E11))/Planos!$E11)+1))) | J13: =IF(OR(Planos!$A11="",NOT(ISNUMBER(Planos!$G11)),N(Planos!$E11)<=0),0,IF(Planos!$G11>EOMONTH(DATE(crono_ano_ref,5,1),0),0,MAX(0,INT((EOMONTH(DATE(crono_ano_ref,5,1),0)-IF(Planos!$G11>=DATE(crono_ano_ref,5,1),Planos!$G11,Planos!$G11+CEILING((DATE(crono_ano_ref,5,1)-Planos!$G11)/Planos!$E11,1)*Planos!$E11))/Planos!$E11)+1))) | K13: =IF(OR(Planos!$A11="",NOT(ISNUMBER(Planos!$G11)),N(Planos!$E11)<=0),0,IF(Planos!$G11>EOMONTH(DATE(crono_ano_ref,6,1),0),0,MAX(0,INT((EOMONTH(DATE(crono_ano_ref,6,1),0)-IF(Planos!$G11>=DATE(crono_ano_ref,6,1),Planos!$G11,Planos!$G11+CEILING((DATE(crono_ano_ref,6,1)-Planos!$G11)/Planos!$E11,1)*Planos!$E11))/Planos!$E11)+1))) | L13: =IF(OR(Planos!$A11="",NOT(ISNUMBER(Planos!$G11)),N(Planos!$E11)<=0),0,IF(Planos!$G11>EOMONTH(DATE(crono_ano_ref,7,1),0),0,MAX(0,INT((EOMONTH(DATE(crono_ano_ref,7,1),0)-IF(Planos!$G11>=DATE(crono_ano_ref,7,1),Planos!$G11,Planos!$G11+CEILING((DATE(crono_ano_ref,7,1)-Planos!$G11)/Planos!$E11,1)*Planos!$E11))/Planos!$E11)+1))) | M13: =IF(OR(Planos!$A11="",NOT(ISNUMBER(Planos!$G11)),N(Planos!$E11)<=0),0,IF(Planos!$G11>EOMONTH(DATE(crono_ano_ref,8,1),0),0,MAX(0,INT((EOMONTH(DATE(crono_ano_ref,8,1),0)-IF(Planos!$G11>=DATE(crono_ano_ref,8,1),Planos!$G11,Planos!$G11+CEILING((DATE(crono_ano_ref,8,1)-Planos!$G11)/Planos!$E11,1)*Planos!$E11))/Planos!$E11)+1))) | N13: =IF(OR(Planos!$A11="",NOT(ISNUMBER(Planos!$G11)),N(Planos!$E11)<=0),0,IF(Planos!$G11>EOMONTH(DATE(crono_ano_ref,9,1),0),0,MAX(0,INT((EOMONTH(DATE(crono_ano_ref,9,1),0)-IF(Planos!$G11>=DATE(crono_ano_ref,9,1),Planos!$G11,Planos!$G11+CEILING((DATE(crono_ano_ref,9,1)-Planos!$G11)/Planos!$E11,1)*Planos!$E11))/Planos!$E11)+1))) | O13: =IF(OR(Planos!$A11="",NOT(ISNUMBER(Planos!$G11)),N(Planos!$E11)<=0),0,IF(Planos!$G11>EOMONTH(DATE(crono_ano_ref,10,1),0),0,MAX(0,INT((EOMONTH(DATE(crono_ano_ref,10,1),0)-IF(Planos!$G11>=DATE(crono_ano_ref,10,1),Planos!$G11,Planos!$G11+CEILING((DATE(crono_ano_ref,10,1)-Planos!$G11)/Planos!$E11,1)*Planos!$E11))/Planos!$E11)+1))) | P13: =IF(OR(Planos!$A11="",NOT(ISNUMBER(Planos!$G11)),N(Planos!$E11)<=0),0,IF(Planos!$G11>EOMONTH(DATE(crono_ano_ref,11,1),0),0,MAX(0,INT((EOMONTH(DATE(crono_ano_ref,11,1),0)-IF(Planos!$G11>=DATE(crono_ano_ref,11,1),Planos!$G11,Planos!$G11+CEILING((DATE(crono_ano_ref,11,1)-Planos!$G11)/Planos!$E11,1)*Planos!$E11))/Planos!$E11)+1))) | Q13: =IF(OR(Planos!$A11="",NOT(ISNUMBER(Planos!$G11)),N(Planos!$E11)<=0),0,IF(Planos!$G11>EOMONTH(DATE(crono_ano_ref,12,1),0),0,MAX(0,INT((EOMONTH(DATE(crono_ano_ref,12,1),0)-IF(Planos!$G11>=DATE(crono_ano_ref,12,1),Planos!$G11,Planos!$G11+CEILING((DATE(crono_ano_ref,12,1)-Planos!$G11)/Planos!$E11,1)*Planos!$E11))/Planos!$E11)+1))) | R13: =SUM(F13:Q13)
A14: =IF(Planos!$A12="","",Planos!A12&"") | B14: =IF(Planos!$A12="","",Planos!B12&"") | C14: =IF(Planos!$A12="","",Planos!C12&"") | D14: =IF(Planos!$A12="","",N(Planos!E12)) | E14: =IF(Planos!$A12="","",N(Planos!K12)) | F14: =IF(OR(Planos!$A12="",NOT(ISNUMBER(Planos!$G12)),N(Planos!$E12)<=0),0,IF(Planos!$G12>EOMONTH(DATE(crono_ano_ref,1,1),0),0,MAX(0,INT((EOMONTH(DATE(crono_ano_ref,1,1),0)-IF(Planos!$G12>=DATE(crono_ano_ref,1,1),Planos!$G12,Planos!$G12+CEILING((DATE(crono_ano_ref,1,1)-Planos!$G12)/Planos!$E12,1)*Planos!$E12))/Planos!$E12)+1))) | G14: =IF(OR(Planos!$A12="",NOT(ISNUMBER(Planos!$G12)),N(Planos!$E12)<=0),0,IF(Planos!$G12>EOMONTH(DATE(crono_ano_ref,2,1),0),0,MAX(0,INT((EOMONTH(DATE(crono_ano_ref,2,1),0)-IF(Planos!$G12>=DATE(crono_ano_ref,2,1),Planos!$G12,Planos!$G12+CEILING((DATE(crono_ano_ref,2,1)-Planos!$G12)/Planos!$E12,1)*Planos!$E12))/Planos!$E12)+1))) | H14: =IF(OR(Planos!$A12="",NOT(ISNUMBER(Planos!$G12)),N(Planos!$E12)<=0),0,IF(Planos!$G12>EOMONTH(DATE(crono_ano_ref,3,1),0),0,MAX(0,INT((EOMONTH(DATE(crono_ano_ref,3,1),0)-IF(Planos!$G12>=DATE(crono_ano_ref,3,1),Planos!$G12,Planos!$G12+CEILING((DATE(crono_ano_ref,3,1)-Planos!$G12)/Planos!$E12,1)*Planos!$E12))/Planos!$E12)+1))) | I14: =IF(OR(Planos!$A12="",NOT(ISNUMBER(Planos!$G12)),N(Planos!$E12)<=0),0,IF(Planos!$G12>EOMONTH(DATE(crono_ano_ref,4,1),0),0,MAX(0,INT((EOMONTH(DATE(crono_ano_ref,4,1),0)-IF(Planos!$G12>=DATE(crono_ano_ref,4,1),Planos!$G12,Planos!$G12+CEILING((DATE(crono_ano_ref,4,1)-Planos!$G12)/Planos!$E12,1)*Planos!$E12))/Planos!$E12)+1))) | J14: =IF(OR(Planos!$A12="",NOT(ISNUMBER(Planos!$G12)),N(Planos!$E12)<=0),0,IF(Planos!$G12>EOMONTH(DATE(crono_ano_ref,5,1),0),0,MAX(0,INT((EOMONTH(DATE(crono_ano_ref,5,1),0)-IF(Planos!$G12>=DATE(crono_ano_ref,5,1),Planos!$G12,Planos!$G12+CEILING((DATE(crono_ano_ref,5,1)-Planos!$G12)/Planos!$E12,1)*Planos!$E12))/Planos!$E12)+1))) | K14: =IF(OR(Planos!$A12="",NOT(ISNUMBER(Planos!$G12)),N(Planos!$E12)<=0),0,IF(Planos!$G12>EOMONTH(DATE(crono_ano_ref,6,1),0),0,MAX(0,INT((EOMONTH(DATE(crono_ano_ref,6,1),0)-IF(Planos!$G12>=DATE(crono_ano_ref,6,1),Planos!$G12,Planos!$G12+CEILING((DATE(crono_ano_ref,6,1)-Planos!$G12)/Planos!$E12,1)*Planos!$E12))/Planos!$E12)+1))) | L14: =IF(OR(Planos!$A12="",NOT(ISNUMBER(Planos!$G12)),N(Planos!$E12)<=0),0,IF(Planos!$G12>EOMONTH(DATE(crono_ano_ref,7,1),0),0,MAX(0,INT((EOMONTH(DATE(crono_ano_ref,7,1),0)-IF(Planos!$G12>=DATE(crono_ano_ref,7,1),Planos!$G12,Planos!$G12+CEILING((DATE(crono_ano_ref,7,1)-Planos!$G12)/Planos!$E12,1)*Planos!$E12))/Planos!$E12)+1))) | M14: =IF(OR(Planos!$A12="",NOT(ISNUMBER(Planos!$G12)),N(Planos!$E12)<=0),0,IF(Planos!$G12>EOMONTH(DATE(crono_ano_ref,8,1),0),0,MAX(0,INT((EOMONTH(DATE(crono_ano_ref,8,1),0)-IF(Planos!$G12>=DATE(crono_ano_ref,8,1),Planos!$G12,Planos!$G12+CEILING((DATE(crono_ano_ref,8,1)-Planos!$G12)/Planos!$E12,1)*Planos!$E12))/Planos!$E12)+1))) | N14: =IF(OR(Planos!$A12="",NOT(ISNUMBER(Planos!$G12)),N(Planos!$E12)<=0),0,IF(Planos!$G12>EOMONTH(DATE(crono_ano_ref,9,1),0),0,MAX(0,INT((EOMONTH(DATE(crono_ano_ref,9,1),0)-IF(Planos!$G12>=DATE(crono_ano_ref,9,1),Planos!$G12,Planos!$G12+CEILING((DATE(crono_ano_ref,9,1)-Planos!$G12)/Planos!$E12,1)*Planos!$E12))/Planos!$E12)+1))) | O14: =IF(OR(Planos!$A12="",NOT(ISNUMBER(Planos!$G12)),N(Planos!$E12)<=0),0,IF(Planos!$G12>EOMONTH(DATE(crono_ano_ref,10,1),0),0,MAX(0,INT((EOMONTH(DATE(crono_ano_ref,10,1),0)-IF(Planos!$G12>=DATE(crono_ano_ref,10,1),Planos!$G12,Planos!$G12+CEILING((DATE(crono_ano_ref,10,1)-Planos!$G12)/Planos!$E12,1)*Planos!$E12))/Planos!$E12)+1))) | P14: =IF(OR(Planos!$A12="",NOT(ISNUMBER(Planos!$G12)),N(Planos!$E12)<=0),0,IF(Planos!$G12>EOMONTH(DATE(crono_ano_ref,11,1),0),0,MAX(0,INT((EOMONTH(DATE(crono_ano_ref,11,1),0)-IF(Planos!$G12>=DATE(crono_ano_ref,11,1),Planos!$G12,Planos!$G12+CEILING((DATE(crono_ano_ref,11,1)-Planos!$G12)/Planos!$E12,1)*Planos!$E12))/Planos!$E12)+1))) | Q14: =IF(OR(Planos!$A12="",NOT(ISNUMBER(Planos!$G12)),N(Planos!$E12)<=0),0,IF(Planos!$G12>EOMONTH(DATE(crono_ano_ref,12,1),0),0,MAX(0,INT((EOMONTH(DATE(crono_ano_ref,12,1),0)-IF(Planos!$G12>=DATE(crono_ano_ref,12,1),Planos!$G12,Planos!$G12+CEILING((DATE(crono_ano_ref,12,1)-Planos!$G12)/Planos!$E12,1)*Planos!$E12))/Planos!$E12)+1))) | R14: =SUM(F14:Q14)
