Workbook
Name lst_funcao: Listas!$H$4:$H$33
Name lst_treinamento: Listas!$J$4:$J$33
Name lst_orgao: Listas!$L$4:$L$33
Name lst_setor: Listas!$N$4:$N$33
Name lst_origem_nc: Listas!$P$4:$P$33
Name lst_metodo_causa: Listas!$R$4:$R$33
Name lst_status_acao: Listas!$T$4:$T$33
Name crit_matriz: Listas!$B$4:$F$8
Name rv_revisao: 'Revisões'!$A$4:$A$33
Name rv_data: 'Revisões'!$B$4:$B$33
Name cfg_elaborado: 'Instruções'!$C$15
Name cfg_aprovado: 'Instruções'!$C$16
Name cfg_revisao: 'Instruções'!$C$17
Name cfg_data_revisao: 'Instruções'!$C$18
Name pcmd_origem: 'Instruções'!$C$19
Name pcmd_emissao: 'Instruções'!$C$20

Sheet Instruções
C1: Kit de documentos de manutenção para auditoria Como usar, parâmetros do documento e conferências gerais. | F1: ="Rev. "&IF(cfg_revisao="","—",cfg_revisao)&IF(ISNUMBER(cfg_data_revisao)," · "&RIGHT("0"&DAY(cfg_data_revisao),2)&"/"&RIGHT("0"&MONTH(cfg_data_revisao),2)&"/"&YEAR(cfg_data_revisao),"")
F2: ="Elaborado: "&IF(cfg_elaborado="","A definir",cfg_elaborado)&CHAR(10)&"Aprovado: "&IF(cfg_aprovado="","A definir",cfg_aprovado)
A7: 1. COMO USAR
A8: 1) Preencha cada aba do kit com os registros da sua unidade. Campos azul-claro são editáveis; status e conferências são calculados (aviso 30 dias antes de vencer).
A9: 2) Responda o Checklist de Auditoria (Sim, Não ou Parcial) e acompanhe a prontidão no Painel. Regularize primeiro os itens Não.
A10: 3) Confirme requisitos legais e normas na fonte oficial, com versão e data. Este kit apoia a gestão e não certifica conformidade.
A11: Azul-claro: preencher. Cinza: automático (fórmula protegida sem senha: Revisão › Desproteger Planilha se precisar mudar a estrutura). ERRO em vermelho e Pendente em amarelo pedem ação.
A13: 2. PARÂMETROS DO DOCUMENTO
A14: Parâmetro | C14: Valor | E14: Orientação
A15: Elaborado por | E15: Nome de quem preparou o documento.
A16: Aprovado por (só após aprovação) | E16: Preencha somente após a aprovação efetiva.
A17: Revisão atual (automática) | C17: =IFERROR(LOOKUP(2,1/(rv_revisao<>""),rv_revisao)&"","") | E17: Última linha preenchida em Revisões.
A18: Data da revisão (automática) | C18: =IFERROR(1/(1/LOOKUP(2,1/(rv_revisao<>""),rv_data)),"") | E18: Data da mesma linha da revisão atual.
A19: Origem dos dados | E19: Ex.: preenchimento manual, exportação do sistema.
A20: Data de emissão | E20: Data em que este arquivo foi emitido.
A21: Site / unidade | E21: Usado na Matriz de Criticidade.
A22: Líder do workshop de criticidade | E22: Quem conduziu a pontuação.
A23: Data do workshop | E23: Data da última pontuação.
A25: 3. CONFERÊNCIAS
A26: Aba / verificação | B26: Linhas preenchidas | C26: Linhas com ERRO | D26: Capacidade / resultado
A27: Matriz de Criticidade | B27: =COUNTA('Matriz de Criticidade'!$A$4:$A$103) | C27: =COUNTIF('Matriz de Criticidade'!$O$4:$O$103,"ERRO*") | D27: ="Pontuados: "&COUNT('Matriz de Criticidade'!$L$4:$L$103)
A28: Plano de Calibração | B28: =COUNTA('Plano de Calibração'!$A$4:$A$103) | C28: =COUNTIF('Plano de Calibração'!$K$4:$K$103,"ERRO*") | D28: =IF(COUNTIF('Plano de Calibração'!$J$4:$J$103,"Vencido")>0,"Verificar: calibrações vencidas","OK")
A29: Competência e Treinamento | B29: =COUNTA('Competência e Treinamento'!$A$4:$A$203) | C29: =COUNTIF('Competência e Treinamento'!$J$4:$J$203,"ERRO*") | D29: =IF(COUNTIF('Competência e Treinamento'!$I$4:$I$203,"Vencido")>0,"Verificar: treinamentos vencidos","OK")
A30: Requisitos Legais | B30: =COUNTA('Requisitos Legais'!$A$4:$A$103) | C30: =COUNTIF('Requisitos Legais'!$I$4:$I$103,"ERRO*") | D30: =IF(COUNTIF('Requisitos Legais'!$G$4:$G$103,"Vencido")>0,"Verificar: requisitos vencidos","OK")
A31: Demais registros | B31: =COUNTA('Máquinas e riscos'!$A$4:$A$103)+COUNTA('Avaliação de Fornecedores'!$A$4:$A$63)+COUNTA('Lista Mestra de Documentos'!$A$4:$A$63)+COUNTA('Manutenção Autônoma (TPM)'!$A$4:$A$303) | C31: =COUNTIF('Máquinas e riscos'!$L$4:$L$103,"ERRO*")+COUNTIF('Avaliação de Fornecedores'!$K$4:$K$63,"ERRO*")+COUNTIF('Lista Mestra de Documentos'!$I$4:$I$63,"ERRO*")+COUNTIF('Manutenção Autônoma (TPM)'!$J$4:$J$303,"ERRO*") | D31: ="Máquinas, fornecedores, documentos e TPM"
A33: 4. ÍNDICE DAS ABAS (clique no nome)
A34: Painel | B34: Prontidão, vencidos e pendências do kit.
A35: Matriz de Criticidade | B35: Como a criticidade dos ativos foi definida.
A36: Plano de Calibração | B36: Instrumentos, certificados e vencimentos.
A37: NC e Ação Corretiva | B37: Formulário CAPA: causa, ação e eficácia.
A38: Competência e Treinamento | B38: Treinamentos e certificações da equipe.
A39: Requisitos Legais | B39: Licenças, NRs e laudos com fonte oficial.
A40: Máquinas e riscos | B40: Inventário de máquinas, riscos e proteções.
A41: Avaliação de Fornecedores | B41: Critério documentado de avaliação de terceiros.
A42: Checklist de Auditoria | B42: Autoavaliação antes da auditoria externa.
A43: Lista Mestra de Documentos | B43: Documentos controlados e revisões.
A44: Manutenção Autônoma (TPM) | B44: Checklist diário do operador.
A45: A3 - Resolução de Problemas | B45: Análise PDCA de uma página.
... A47: Revisões | B47: Histórico de revisões.
A49: PCMD-K08 · Modelo 2.0.0 · PCM Direto · Thiago Oliveira Lima · pcmdireto@gmail.com · Licença MIT · Sem macros, vínculos externos ou envio de dados.

Sheet Painel
C1: Painel de prontidão para auditoria Resumo automático do que está vencido ou pendente nas abas do kit. Nada para preencher aqui. | L1: ="Rev. "&IF(cfg_revisao="","—",cfg_revisao)&IF(ISNUMBER(cfg_data_revisao)," · "&RIGHT("0"&DAY(cfg_data_revisao),2)&"/"&RIGHT("0"&MONTH(cfg_data_revisao),2)&"/"&YEAR(cfg_data_revisao),"")
L2: ="Elaborado: "&IF(cfg_elaborado="","A definir",cfg_elaborado)&CHAR(10)&"Aprovado: "&IF(cfg_aprovado="","A definir",cfg_aprovado)
A4: PRONTIDÃO GERAL | D4: CALIBRAÇÕES VENCIDAS | G4: TREINAMENTOS VENCIDOS | J4: REQUISITOS LEGAIS VENCIDOS
A5: ='Checklist de Auditoria'!C29 | D5: =COUNTIF('Plano de Calibração'!$J$4:$J$103,"Vencido") | G5: =COUNTIF('Competência e Treinamento'!$I$4:$I$203,"Vencido") | J5: =COUNTIF('Requisitos Legais'!$G$4:$G$103,"Vencido")
A6: itens Sim ÷ itens do checklist interno | D6: instrumentos fora do prazo | G6: certificações expiradas | J6: licenças e laudos
A8: ="Revisões de documento vencidas: "&COUNTIF('Lista Mestra de Documentos'!$H$4:$H$63,"Revisão vencida")&" · Fornecedores com ressalva ou reprovados: "&(COUNTIF('Avaliação de Fornecedores'!$H$4:$H$63,"Aprovado com ressalva")+COUNTIF('Avaliação de Fornecedores'!$H$4:$H$63,"Reprovado"))&" · Ativos pontuados na criticidade: "&COUNT('Matriz de Criticidade'!$L$4:$L$103)
A10: PENDÊNCIAS POR DOCUMENTO | E10: CHECKLIST INTERNO | I10: ATIVOS POR CRITICIDADE
A28: DADOS DOS GRÁFICOS (automático, não digite)
A29: Pendência | C29: Valor | E29: Resposta | G29: Valor | I29: Criticidade | K29: Valor
A30: Calibração vencida | C30: =COUNTIF('Plano de Calibração'!$J$4:$J$103,"Vencido") | E30: Sim | G30: =COUNTIF('Checklist de Auditoria'!$C$13:$C$22,"Sim") | I30: Nível 5 | K30: =COUNTIF('Matriz de Criticidade'!$L$4:$L$103,5)
A31: Treinamento vencido | C31: =COUNTIF('Competência e Treinamento'!$I$4:$I$203,"Vencido") | E31: Parcial | G31: =COUNTIF('Checklist de Auditoria'!$C$13:$C$22,"Parcial") | I31: Nível 4 | K31: =COUNTIF('Matriz de Criticidade'!$L$4:$L$103,4)
A32: Requisito legal vencido | C32: =COUNTIF('Requisitos Legais'!$G$4:$G$103,"Vencido") | E32: Não | G32: =COUNTIF('Checklist de Auditoria'!$C$13:$C$22,"Não") | I32: Nível 3 | K32: =COUNTIF('Matriz de Criticidade'!$L$4:$L$103,3)
A33: Revisão de documento vencida | C33: =COUNTIF('Lista Mestra de Documentos'!$H$4:$H$63,"Revisão vencida") | E33: Sem resposta | G33: =10-COUNTA('Checklist de Auditoria'!$C$13:$C$22) | I33: Nível 2 | K33: =COUNTIF('Matriz de Criticidade'!$L$4:$L$103,2)
A34: Fornecedor com ressalva/reprovado | C34: =COUNTIF('Avaliação de Fornecedores'!$H$4:$H$63,"Aprovado com ressalva")+COUNTIF('Avaliação de Fornecedores'!$H$4:$H$63,"Reprovado") | I34: Nível 1 | K34: =COUNTIF('Matriz de Criticidade'!$L$4:$L$103,1)
A35: Análise de risco a revisar | C35: =COUNTIF('Máquinas e riscos'!$K$4:$K$103,"Revisar*")
A36: TPM: falha/alerta sem repasse | C36: =COUNTIF('Manutenção Autônoma (TPM)'!$J$4:$J$303,"Pendente*")

Sheet Matriz de Criticidade
C1: Matriz de criticidade de ativos Pontue S, E, P, Q e C de 1 a 5 e a probabilidade L de 1 a 5. A maior consequência cruza com L na matriz de referência (aba Listas). | O1: ="Rev. "&IF(cfg_revisao="","—",cfg_revisao)&IF(ISNUMBER(cfg_data_revisao)," · "&RIGHT("0"&DAY(cfg_data_revisao),2)&"/"&RIGHT("0"&MONTH(cfg_data_revisao),2)&"/"&YEAR(cfg_data_revisao),"")
O2: ="Elaborado: "&IF(cfg_elaborado="","A definir",cfg_elaborado)&CHAR(10)&"Aprovado: "&IF(cfg_aprovado="","A definir",cfg_aprovado)
A3: ID do ativo | B3: Descrição | C3: Local | D3: Função (frase única) | E3: S Segurança | F3: E Meio ambiente | G3: P Produção | H3: Q Qualidade | I3: C Custo | J3: L Probabilidade | K3: Consequência (maior) | L3: Criticidade (1-5) | M3: Estratégia recomendada | N3: Responsável | O3: Conferência
K4: =IF(COUNT(E4:I4)=0,"",MAX(E4:I4)) | L4: =IF(OR(COUNT(E4:I4)<5,NOT(ISNUMBER(J4))),"",IF(E4=5,5,INDEX(crit_matriz,6-K4,J4))) | M4: =IF(L4="","",IF(L4>=4,"Preditiva + redundância",IF(L4=3,"Preventiva por tempo/condição","Corretiva planejada"))) | O4: =IF(A4&B4="","",IF(A4="","ERRO: falta o ID do ativo",IF(COUNTIF($A$4:$A$103,A4)>1,"ERRO: ativo repetido",IF(COUNT(E4:J4)<6,"Pendente: pontue S, E, P, Q, C e L",IF(E4=5,"OK: criticidade 5 por Segurança = 5","OK")))))
K5: =IF(COUNT(E5:I5)=0,"",MAX(E5:I5)) | L5: =IF(OR(COUNT(E5:I5)<5,NOT(ISNUMBER(J5))),"",IF(E5=5,5,INDEX(crit_matriz,6-K5,J5))) | M5: =IF(L5="","",IF(L5>=4,"Preditiva + redundância",IF(L5=3,"Preventiva por tempo/condição","Corretiva planejada"))) | O5: =IF(A5&B5="","",IF(A5="","ERRO: falta o ID do ativo",IF(COUNTIF($A$4:$A$103,A5)>1,"ERRO: ativo repetido",IF(COUNT(E5:J5)<6,"Pendente: pontue S, E, P, Q, C e L",IF(E5=5,"OK: criticidade 5 por Segurança = 5","OK")))))
K6: =IF(COUNT(E6:I6)=0,"",MAX(E6:I6)) | L6: =IF(OR(COUNT(E6:I6)<5,NOT(ISNUMBER(J6))),"",IF(E6=5,5,INDEX(crit_matriz,6-K6,J6))) | M6: =IF(L6="","",IF(L6>=4,"Preditiva + redundância",IF(L6=3,"Preventiva por tempo/condição","Corretiva planejada"))) | O6: =IF(A6&B6="","",IF(A6="","ERRO: falta o ID do ativo",IF(COUNTIF($A$4:$A$103,A6)>1,"ERRO: ativo repetido",IF(COUNT(E6:J6)<6,"Pendente: pontue S, E, P, Q, C e L",IF(E6=5,"OK: criticidade 5 por Segurança = 5","OK")))))
K7: =IF(COUNT(E7:I7)=0,"",MAX(E7:I7)) | L7: =IF(OR(COUNT(E7:I7)<5,NOT(ISNUMBER(J7))),"",IF(E7=5,5,INDEX(crit_matriz,6-K7,J7))) | M7: =IF(L7="","",IF(L7>=4,"Preditiva + redundância",IF(L7=3,"Preventiva por tempo/condição","Corretiva planejada"))) | O7: =IF(A7&B7="","",IF(A7="","ERRO: falta o ID do ativo",IF(COUNTIF($A$4:$A$103,A7)>1,"ERRO: ativo repetido",IF(COUNT(E7:J7)<6,"Pendente: pontue S, E, P, Q, C e L",IF(E7=5,"OK: criticidade 5 por Segurança = 5","OK")))))
K8: =IF(COUNT(E8:I8)=0,"",MAX(E8:I8)) | L8: =IF(OR(COUNT(E8:I8)<5,NOT(ISNUMBER(J8))),"",IF(E8=5,5,INDEX(crit_matriz,6-K8,J8))) | M8: =IF(L8="","",IF(L8>=4,"Preditiva + redundância",IF(L8=3,"Preventiva por tempo/condição","Corretiva planejada"))) | O8: =IF(A8&B8="","",IF(A8="","ERRO: falta o ID do ativo",IF(COUNTIF($A$4:$A$103,A8)>1,"ERRO: ativo repetido",IF(COUNT(E8:J8)<6,"Pendente: pontue S, E, P, Q, C e L",IF(E8=5,"OK: criticidade 5 por Segurança = 5","OK")))))
K9: =IF(COUNT(E9:I9)=0,"",MAX(E9:I9)) | L9: =IF(OR(COUNT(E9:I9)<5,NOT(ISNUMBER(J9))),"",IF(E9=5,5,INDEX(crit_matriz,6-K9,J9))) | M9: =IF(L9="","",IF(L9>=4,"Preditiva + redundância",IF(L9=3,"Preventiva por tempo/condição","Corretiva planejada"))) | O9: =IF(A9&B9="","",IF(A9="","ERRO: falta o ID do ativo",IF(COUNTIF($A$4:$A$103,A9)>1,"ERRO: ativo repetido",IF(COUNT(E9:J9)<6,"Pendente: pontue S, E, P, Q, C e L",IF(E9=5,"OK: criticidade 5 por Segurança = 5","OK")))))
K10: =IF(COUNT(E10:I10)=0,"",MAX(E10:I10)) | L10: =IF(OR(COUNT(E10:I10)<5,NOT(ISNUMBER(J10))),"",IF(E10=5,5,INDEX(crit_matriz,6-K10,J10))) | M10: =IF(L10="","",IF(L10>=4,"Preditiva + redundância",IF(L10=3,"Preventiva por tempo/condição","Corretiva planejada"))) | O10: =IF(A10&B10="","",IF(A10="","ERRO: falta o ID do ativo",IF(COUNTIF($A$4:$A$103,A10)>1,"ERRO: ativo repetido",IF(COUNT(E10:J10)<6,"Pendente: pontue S, E, P, Q, C e L",IF(E10=5,"OK: criticidade 5 por Segurança = 5","OK")))))
K11: =IF(COUNT(E11:I11)=0,"",MAX(E11:I11)) | L11: =IF(OR(COUNT(E11:I11)<5,NOT(ISNUMBER(J11))),"",IF(E11=5,5,INDEX(crit_matriz,6-K11,J11))) | M11: =IF(L11="","",IF(L11>=4,"Preditiva + redundância",IF(L11=3,"Preventiva por tempo/condição","Corretiva planejada"))) | O11: =IF(A11&B11="","",IF(A11="","ERRO: falta o ID do ativo",IF(COUNTIF($A$4:$A$103,A11)>1,"ERRO: ativo repetido",IF(COUNT(E11:J11)<6,"Pendente: pontue S, E, P, Q, C e L",IF(E11=5,"OK: criticidade 5 por Segurança = 5","OK")))))
K12: =IF(COUNT(E12:I12)=0,"",MAX(E12:I12)) | L12: =IF(OR(COUNT(E12:I12)<5,NOT(ISNUMBER(J12))),"",IF(E12=5,5,INDEX(crit_matriz,6-K12,J12))) | M12: =IF(L12="","",IF(L12>=4,"Preditiva + redundância",IF(L12=3,"Preventiva por tempo/condição","Corretiva planejada"))) | O12: =IF(A12&B12="","",IF(A12="","ERRO: falta o ID do ativo",IF(COUNTIF($A$4:$A$103,A12)>1,"ERRO: ativo repetido",IF(COUNT(E12:J12)<6,"Pendente: pontue S, E, P, Q, C e L",IF(E12=5,"OK: criticidade 5 por Segurança = 5","OK")))))
K13: =IF(COUNT(E13:I13)=0,"",MAX(E13:I13)) | L13: =IF(OR(COUNT(E13:I13)<5,NOT(ISNUMBER(J13))),"",IF(E13=5,5,INDEX(crit_matriz,6-K13,J13))) | M13: =IF(L13="","",IF(L13>=4,"Preditiva + redundância",IF(L13=3,"Preventiva por tempo/condição","Corretiva planejada"))) | O13: =IF(A13&B13="","",IF(A13="","ERRO: falta o ID do ativo",IF(COUNTIF($A$4:$A$103,A13)>1,"ERRO: ativo repetido",IF(COUNT(E13:J13)<6,"Pendente: pontue S, E, P, Q, C e L",IF(E13=5,"OK: criticidade 5 por Segurança = 5","OK")))))
K14: =IF(COUNT(E14:I14)=0,"",MAX(E14:I14)) | L14: =IF(OR(COUNT(E14:I14)<5,NOT(ISNUMBER(J14))),"",IF(E14=5,5,INDEX(crit_matriz,6-K14,J14))) | M14: =IF(L14="","",IF(L14>=4,"Preditiva + redundância",IF(L14=3,"Preventiva por tempo/condição","Corretiva planejada"))) | O14: =IF(A14&B14="","",IF(A14="","ERRO: falta o ID do ativo",IF(COUNTIF($A$4:$A$103,A14)>1,"ERRO: ativo repetido",IF(COUNT(E14:J14)<6,"Pendente: pontue S, E, P, Q, C e L",IF(E14=5,"OK: criticidade 5 por Segurança = 5","OK")))))
K15: =IF(COUNT(E15:I15)=0,"",MAX(E15:I15)) | L15: =IF(OR(COUNT(E15:I15)<5,NOT(ISNUMBER(J15))),"",IF(E15=5,5,INDEX(crit_matriz,6-K15,J15))) | M15: =IF(L15="","",IF(L15>=4,"Preditiva + redundância",IF(L15=3,"Preventiva por tempo/condição","Corretiva planejada"))) | O15: =IF(A15&B15="","",IF(A15="","ERRO: falta o ID do ativo",IF(COUNTIF($A$4:$A$103,A15)>1,"ERRO: ativo repetido",IF(COUNT(E15:J15)<6,"Pendente: pontue S, E, P, Q, C e L",IF(E15=5,"OK: criticidade 5 por Segurança = 5","OK")))))
... K103: =IF(COUNT(E103:I103)=0,"",MAX(E103:I103)) | L103: =IF(OR(COUNT(E103:I103)<5,NOT(ISNUMBER(J103))),"",IF(E103=5,5,INDEX(crit_matriz,6-K103,J103))) | M103: =IF(L103="","",IF(L103>=4,"Preditiva + redundância",IF(L103=3,"Preventiva por tempo/condição","Corretiva planejada"))) | O103: =IF(A103&B103="","",IF(A103="","ERRO: falta o ID do ativo",IF(COUNTIF($A$4:$A$103,A103)>1,"ERRO: ativo repetido",IF(COUNT(E103:J103)<6,"Pendente: pontue S, E, P, Q, C e L",IF(E103=5,"OK: criticidade 5 por Segurança = 5","OK")))))

Sheet Plano de Calibração
C1: Plano de calibração de instrumentos Próxima calibração = última + frequência. Status com aviso de 30 dias. | K1: ="Rev. "&IF(cfg_revisao="","—",cfg_revisao)&IF(ISNUMBER(cfg_data_revisao)," · "&RIGHT("0"&DAY(cfg_data_revisao),2)&"/"&RIGHT("0"&MONTH(cfg_data_revisao),2)&"/"&YEAR(cfg_data_revisao),"")
K2: ="Elaborado: "&IF(cfg_elaborado="","A definir",cfg_elaborado)&CHAR(10)&"Aprovado: "&IF(cfg_aprovado="","A definir",cfg_aprovado)
A3: Código do instrumento | B3: Descrição | C3: Ativo / local vinculado | D3: Faixa de medição | E3: Frequência (meses) | F3: Última calibração | G3: Próxima calibração | H3: Laboratório / responsável | I3: Nº do certificado | J3: Status | K3: Conferência
G4: =IF(OR(NOT(ISNUMBER(F4)),N(E4)<=0),"",EDATE(F4,E4)) | J4: =IF(NOT(ISNUMBER(G4)),"",IF(G4<TODAY(),"Vencido",IF(G4-TODAY()<=30,"Vence em 30 dias","Em dia"))) | K4: =IF(A4&B4="","",IF(A4="","ERRO: falta o código",IF(COUNTIF($A$4:$A$103,A4)>1,"ERRO: código repetido",IF(AND(ISNUMBER(F4),F4>TODAY()),"ERRO: calibração no futuro",IF(OR(E4="",NOT(ISNUMBER(F4))),"Pendente: frequência e última calibração",IF(I4="","Pendente: informe o nº do certificado","OK"))))))
G5: =IF(OR(NOT(ISNUMBER(F5)),N(E5)<=0),"",EDATE(F5,E5)) | J5: =IF(NOT(ISNUMBER(G5)),"",IF(G5<TODAY(),"Vencido",IF(G5-TODAY()<=30,"Vence em 30 dias","Em dia"))) | K5: =IF(A5&B5="","",IF(A5="","ERRO: falta o código",IF(COUNTIF($A$4:$A$103,A5)>1,"ERRO: código repetido",IF(AND(ISNUMBER(F5),F5>TODAY()),"ERRO: calibração no futuro",IF(OR(E5="",NOT(ISNUMBER(F5))),"Pendente: frequência e última calibração",IF(I5="","Pendente: informe o nº do certificado","OK"))))))
G6: =IF(OR(NOT(ISNUMBER(F6)),N(E6)<=0),"",EDATE(F6,E6)) | J6: =IF(NOT(ISNUMBER(G6)),"",IF(G6<TODAY(),"Vencido",IF(G6-TODAY()<=30,"Vence em 30 dias","Em dia"))) | K6: =IF(A6&B6="","",IF(A6="","ERRO: falta o código",IF(COUNTIF($A$4:$A$103,A6)>1,"ERRO: código repetido",IF(AND(ISNUMBER(F6),F6>TODAY()),"ERRO: calibração no futuro",IF(OR(E6="",NOT(ISNUMBER(F6))),"Pendente: frequência e última calibração",IF(I6="","Pendente: informe o nº do certificado","OK"))))))
G7: =IF(OR(NOT(ISNUMBER(F7)),N(E7)<=0),"",EDATE(F7,E7)) | J7: =IF(NOT(ISNUMBER(G7)),"",IF(G7<TODAY(),"Vencido",IF(G7-TODAY()<=30,"Vence em 30 dias","Em dia"))) | K7: =IF(A7&B7="","",IF(A7="","ERRO: falta o código",IF(COUNTIF($A$4:$A$103,A7)>1,"ERRO: código repetido",IF(AND(ISNUMBER(F7),F7>TODAY()),"ERRO: calibração no futuro",IF(OR(E7="",NOT(ISNUMBER(F7))),"Pendente: frequência e última calibração",IF(I7="","Pendente: informe o nº do certificado","OK"))))))
G8: =IF(OR(NOT(ISNUMBER(F8)),N(E8)<=0),"",EDATE(F8,E8)) | J8: =IF(NOT(ISNUMBER(G8)),"",IF(G8<TODAY(),"Vencido",IF(G8-TODAY()<=30,"Vence em 30 dias","Em dia"))) | K8: =IF(A8&B8="","",IF(A8="","ERRO: falta o código",IF(COUNTIF($A$4:$A$103,A8)>1,"ERRO: código repetido",IF(AND(ISNUMBER(F8),F8>TODAY()),"ERRO: calibração no futuro",IF(OR(E8="",NOT(ISNUMBER(F8))),"Pendente: frequência e última calibração",IF(I8="","Pendente: informe o nº do certificado","OK"))))))
G9: =IF(OR(NOT(ISNUMBER(F9)),N(E9)<=0),"",EDATE(F9,E9)) | J9: =IF(NOT(ISNUMBER(G9)),"",IF(G9<TODAY(),"Vencido",IF(G9-TODAY()<=30,"Vence em 30 dias","Em dia"))) | K9: =IF(A9&B9="","",IF(A9="","ERRO: falta o código",IF(COUNTIF($A$4:$A$103,A9)>1,"ERRO: código repetido",IF(AND(ISNUMBER(F9),F9>TODAY()),"ERRO: calibração no futuro",IF(OR(E9="",NOT(ISNUMBER(F9))),"Pendente: frequência e última calibração",IF(I9="","Pendente: informe o nº do certificado","OK"))))))
G10: =IF(OR(NOT(ISNUMBER(F10)),N(E10)<=0),"",EDATE(F10,E10)) | J10: =IF(NOT(ISNUMBER(G10)),"",IF(G10<TODAY(),"Vencido",IF(G10-TODAY()<=30,"Vence em 30 dias","Em dia"))) | K10: =IF(A10&B10="","",IF(A10="","ERRO: falta o código",IF(COUNTIF($A$4:$A$103,A10)>1,"ERRO: código repetido",IF(AND(ISNUMBER(F10),F10>TODAY()),"ERRO: calibração no futuro",IF(OR(E10="",NOT(ISNUMBER(F10))),"Pendente: frequência e última calibração",IF(I10="","Pendente: informe o nº do certificado","OK"))))))
G11: =IF(OR(NOT(ISNUMBER(F11)),N(E11)<=0),"",EDATE(F11,E11)) | J11: =IF(NOT(ISNUMBER(G11)),"",IF(G11<TODAY(),"Vencido",IF(G11-TODAY()<=30,"Vence em 30 dias","Em dia"))) | K11: =IF(A11&B11="","",IF(A11="","ERRO: falta o código",IF(COUNTIF($A$4:$A$103,A11)>1,"ERRO: código repetido",IF(AND(ISNUMBER(F11),F11>TODAY()),"ERRO: calibração no futuro",IF(OR(E11="",NOT(ISNUMBER(F11))),"Pendente: frequência e última calibração",IF(I11="","Pendente: informe o nº do certificado","OK"))))))
G12: =IF(OR(NOT(ISNUMBER(F12)),N(E12)<=0),"",EDATE(F12,E12)) | J12: =IF(NOT(ISNUMBER(G12)),"",IF(G12<TODAY(),"Vencido",IF(G12-TODAY()<=30,"Vence em 30 dias","Em dia"))) | K12: =IF(A12&B12="","",IF(A12="","ERRO: falta o código",IF(COUNTIF($A$4:$A$103,A12)>1,"ERRO: código repetido",IF(AND(ISNUMBER(F12),F12>TODAY()),"ERRO: calibração no futuro",IF(OR(E12="",NOT(ISNUMBER(F12))),"Pendente: frequência e última calibração",IF(I12="","Pendente: informe o nº do certificado","OK"))))))
G13: =IF(OR(NOT(ISNUMBER(F13)),N(E13)<=0),"",EDATE(F13,E13)) | J13: =IF(NOT(ISNUMBER(G13)),"",IF(G13<TODAY(),"Vencido",IF(G13-TODAY()<=30,"Vence em 30 dias","Em dia"))) | K13: =IF(A13&B13="","",IF(A13="","ERRO: falta o código",IF(COUNTIF($A$4:$A$103,A13)>1,"ERRO: código repetido",IF(AND(ISNUMBER(F13),F13>TODAY()),"ERRO: calibração no futuro",IF(OR(E13="",NOT(ISNUMBER(F13))),"Pendente: frequência e última calibração",IF(I13="","Pendente: informe o nº do certificado","OK"))))))
G14: =IF(OR(NOT(ISNUMBER(F14)),N(E14)<=0),"",EDATE(F14,E14)) | J14: =IF(NOT(ISNUMBER(G14)),"",IF(G14<TODAY(),"Vencido",IF(G14-TODAY()<=30,"Vence em 30 dias","Em dia"))) | K14: =IF(A14&B14="","",IF(A14="","ERRO: falta o código",IF(COUNTIF($A$4:$A$103,A14)>1,"ERRO: código repetido",IF(AND(ISNUMBER(F14),F14>TODAY()),"ERRO: calibração no futuro",IF(OR(E14="",NOT(ISNUMBER(F14))),"Pendente: frequência e última calibração",IF(I14="","Pendente: informe o nº do certificado","OK"))))))
G15: =IF(OR(NOT(ISNUMBER(F15)),N(E15)<=0),"",EDATE(F15,E15)) | J15: =IF(NOT(ISNUMBER(G15)),"",IF(G15<TODAY(),"Vencido",IF(G15-TODAY()<=30,"Vence em 30 dias","Em dia"))) | K15: =IF(A15&B15="","",IF(A15="","ERRO: falta o código",IF(COUNTIF($A$4:$A$103,A15)>1,"ERRO: código repetido",IF(AND(ISNUMBER(F15),F15>TODAY()),"ERRO: calibração no futuro",IF(OR(E15="",NOT(ISNUMBER(F15))),"Pendente: frequência e última calibração",IF(I15="","Pendente: informe o nº do certificado","OK"))))))
... G103: =IF(OR(NOT(ISNUMBER(F103)),N(E103)<=0),"",EDATE(F103,E103)) | J103: =IF(NOT(ISNUMBER(G103)),"",IF(G103<TODAY(),"Vencido",IF(G103-TODAY()<=30,"Vence em 30 dias","Em dia"))) | K103: =IF(A103&B103="","",IF(A103="","ERRO: falta o código",IF(COUNTIF($A$4:$A$103,A103)>1,"ERRO: código repetido",IF(AND(ISNUMBER(F103),F103>TODAY()),"ERRO: calibração no futuro",IF(OR(E103="",NOT(ISNUMBER(F103))),"Pendente: frequência e última calibração",IF(I103="","Pendente: informe o nº do certificado","OK"))))))

Sheet NC e Ação Corretiva
C1: Não conformidade e ação corretiva (CAPA) Um registro por não conformidade. Imprima ou salve uma cópia por NC. | H1: ="Rev. "&IF(cfg_revisao="","—",cfg_revisao)&IF(ISNUMBER(cfg_data_revisao)," · "&RIGHT("0"&DAY(cfg_data_revisao),2)&"/"&RIGHT("0"&MONTH(cfg_data_revisao),2)&"/"&YEAR(cfg_data_revisao),"")
H2: ="Elaborado: "&IF(cfg_elaborado="","A definir",cfg_elaborado)&CHAR(10)&"Aprovado: "&IF(cfg_aprovado="","A definir",cfg_aprovado)
A4: 1. DADOS DO REGISTRO
A5: Nº da NC | D5: Data de abertura
A6: Origem | D6: Ativo / local
A7: Aberta por | D7: Requisito / referência
A9: 2. DESCRIÇÃO DA NÃO CONFORMIDADE
A12: 3. CONTENÇÃO IMEDIATA
A14: Responsável | D14: Data
A16: 4. ANÁLISE DE CAUSA
A17: Método
A18: Causa raiz
A20: 5. PLANO DE AÇÃO
A21: Ação | E21: Responsável | F21: Prazo | G21: Status
A27: 6. VERIFICAÇÃO DE EFICÁCIA
A28: Data da verificação | D28: A ação foi eficaz?
A29: Evidência
A30: Verificado por
A32: 7. ENCERRAMENTO (automático)
A33: Situação da NC | B33: =IF(B5="","",IF(OR(A10="",NOT(ISNUMBER(F5))),"Pendente: descreva a NC e a data de abertura",IF(B18="","Pendente: análise de causa",IF(COUNTA(A22:A25)=0,"Pendente: plano de ação",IF(COUNTIF(G22:G25,"Concluído")<COUNTA(A22:A25),"Pendente: ações em andamento",IF(F28="","Pendente: verificar a eficácia",IF(F28="Sim","OK: encerrada com eficácia comprovada","ERRO: ação não eficaz, reabra a análise de causa")))))))

Sheet Competência e Treinamento
C1: Competência e treinamento da equipe Uma linha por treinamento ou certificação. Status com aviso de 30 dias. | J1: ="Rev. "&IF(cfg_revisao="","—",cfg_revisao)&IF(ISNUMBER(cfg_data_revisao)," · "&RIGHT("0"&DAY(cfg_data_revisao),2)&"/"&RIGHT("0"&MONTH(cfg_data_revisao),2)&"/"&YEAR(cfg_data_revisao),"")
J2: ="Elaborado: "&IF(cfg_elaborado="","A definir",cfg_elaborado)&CHAR(10)&"Aprovado: "&IF(cfg_aprovado="","A definir",cfg_aprovado)
A3: Colaborador | B3: Função | C3: Treinamento / certificação | D3: Data de realização | E3: Validade | F3: Carga horária (h) | G3: Instrutor / instituição | H3: Evidência (nº certificado) | I3: Status | J3: Conferência
I4: =IF(A4="","",IF(NOT(ISNUMBER(E4)),"Sem validade",IF(NOT(ISNUMBER(E4)),"",IF(E4<TODAY(),"Vencido",IF(E4-TODAY()<=30,"Vence em 30 dias","Válido"))))) | J4: =IF(A4&C4="","",IF(OR(A4="",C4=""),"ERRO: informe colaborador e treinamento",IF(NOT(ISNUMBER(D4)),"Pendente: data de realização",IF(AND(ISNUMBER(E4),E4<D4),"ERRO: validade anterior à realização",IF(H4="","Pendente: registre a evidência","OK")))))
I5: =IF(A5="","",IF(NOT(ISNUMBER(E5)),"Sem validade",IF(NOT(ISNUMBER(E5)),"",IF(E5<TODAY(),"Vencido",IF(E5-TODAY()<=30,"Vence em 30 dias","Válido"))))) | J5: =IF(A5&C5="","",IF(OR(A5="",C5=""),"ERRO: informe colaborador e treinamento",IF(NOT(ISNUMBER(D5)),"Pendente: data de realização",IF(AND(ISNUMBER(E5),E5<D5),"ERRO: validade anterior à realização",IF(H5="","Pendente: registre a evidência","OK")))))
I6: =IF(A6="","",IF(NOT(ISNUMBER(E6)),"Sem validade",IF(NOT(ISNUMBER(E6)),"",IF(E6<TODAY(),"Vencido",IF(E6-TODAY()<=30,"Vence em 30 dias","Válido"))))) | J6: =IF(A6&C6="","",IF(OR(A6="",C6=""),"ERRO: informe colaborador e treinamento",IF(NOT(ISNUMBER(D6)),"Pendente: data de realização",IF(AND(ISNUMBER(E6),E6<D6),"ERRO: validade anterior à realização",IF(H6="","Pendente: registre a evidência","OK")))))
I7: =IF(A7="","",IF(NOT(ISNUMBER(E7)),"Sem validade",IF(NOT(ISNUMBER(E7)),"",IF(E7<TODAY(),"Vencido",IF(E7-TODAY()<=30,"Vence em 30 dias","Válido"))))) | J7: =IF(A7&C7="","",IF(OR(A7="",C7=""),"ERRO: informe colaborador e treinamento",IF(NOT(ISNUMBER(D7)),"Pendente: data de realização",IF(AND(ISNUMBER(E7),E7<D7),"ERRO: validade anterior à realização",IF(H7="","Pendente: registre a evidência","OK")))))
I8: =IF(A8="","",IF(NOT(ISNUMBER(E8)),"Sem validade",IF(NOT(ISNUMBER(E8)),"",IF(E8<TODAY(),"Vencido",IF(E8-TODAY()<=30,"Vence em 30 dias","Válido"))))) | J8: =IF(A8&C8="","",IF(OR(A8="",C8=""),"ERRO: informe colaborador e treinamento",IF(NOT(ISNUMBER(D8)),"Pendente: data de realização",IF(AND(ISNUMBER(E8),E8<D8),"ERRO: validade anterior à realização",IF(H8="","Pendente: registre a evidência","OK")))))
I9: =IF(A9="","",IF(NOT(ISNUMBER(E9)),"Sem validade",IF(NOT(ISNUMBER(E9)),"",IF(E9<TODAY(),"Vencido",IF(E9-TODAY()<=30,"Vence em 30 dias","Válido"))))) | J9: =IF(A9&C9="","",IF(OR(A9="",C9=""),"ERRO: informe colaborador e treinamento",IF(NOT(ISNUMBER(D9)),"Pendente: data de realização",IF(AND(ISNUMBER(E9),E9<D9),"ERRO: validade anterior à realização",IF(H9="","Pendente: registre a evidência","OK")))))
I10: =IF(A10="","",IF(NOT(ISNUMBER(E10)),"Sem validade",IF(NOT(ISNUMBER(E10)),"",IF(E10<TODAY(),"Vencido",IF(E10-TODAY()<=30,"Vence em 30 dias","Válido"))))) | J10: =IF(A10&C10="","",IF(OR(A10="",C10=""),"ERRO: informe colaborador e treinamento",IF(NOT(ISNUMBER(D10)),"Pendente: data de realização",IF(AND(ISNUMBER(E10),E10<D10),"ERRO: validade anterior à realização",IF(H10="","Pendente: registre a evidência","OK")))))
I11: =IF(A11="","",IF(NOT(ISNUMBER(E11)),"Sem validade",IF(NOT(ISNUMBER(E11)),"",IF(E11<TODAY(),"Vencido",IF(E11-TODAY()<=30,"Vence em 30 dias","Válido"))))) | J11: =IF(A11&C11="","",IF(OR(A11="",C11=""),"ERRO: informe colaborador e treinamento",IF(NOT(ISNUMBER(D11)),"Pendente: data de realização",IF(AND(ISNUMBER(E11),E11<D11),"ERRO: validade anterior à realização",IF(H11="","Pendente: registre a evidência","OK")))))
I12: =IF(A12="","",IF(NOT(ISNUMBER(E12)),"Sem validade",IF(NOT(ISNUMBER(E12)),"",IF(E12<TODAY(),"Vencido",IF(E12-TODAY()<=30,"Vence em 30 dias","Válido"))))) | J12: =IF(A12&C12="","",IF(OR(A12="",C12=""),"ERRO: informe colaborador e treinamento",IF(NOT(ISNUMBER(D12)),"Pendente: data de realização",IF(AND(ISNUMBER(E12),E12<D12),"ERRO: validade anterior à realização",IF(H12="","Pendente: registre a evidência","OK")))))
I13: =IF(A13="","",IF(NOT(ISNUMBER(E13)),"Sem validade",IF(NOT(ISNUMBER(E13)),"",IF(E13<TODAY(),"Vencido",IF(E13-TODAY()<=30,"Vence em 30 dias","Válido"))))) | J13: =IF(A13&C13="","",IF(OR(A13="",C13=""),"ERRO: informe colaborador e treinamento",IF(NOT(ISNUMBER(D13)),"Pendente: data de realização",IF(AND(ISNUMBER(E13),E13<D13),"ERRO: validade anterior à realização",IF(H13="","Pendente: registre a evidência","OK")))))
I14: =IF(A14="","",IF(NOT(ISNUMBER(E14)),"Sem validade",IF(NOT(ISNUMBER(E14)),"",IF(E14<TODAY(),"Vencido",IF(E14-TODAY()<=30,"Vence em 30 dias","Válido"))))) | J14: =IF(A14&C14="","",IF(OR(A14="",C14=""),"ERRO: informe colaborador e treinamento",IF(NOT(ISNUMBER(D14)),"Pendente: data de realização",IF(AND(ISNUMBER(E14),E14<D14),"ERRO: validade anterior à realização",IF(H14="","Pendente: registre a evidência","OK")))))
I15: =IF(A15="","",IF(NOT(ISNUMBER(E15)),"Sem validade",IF(NOT(ISNUMBER(E15)),"",IF(E15<TODAY(),"Vencido",IF(E15-TODAY()<=30,"Vence em 30 dias","Válido"))))) | J15: =IF(A15&C15="","",IF(OR(A15="",C15=""),"ERRO: informe colaborador e treinamento",IF(NOT(ISNUMBER(D15)),"Pendente: data de realização",IF(AND(ISNUMBER(E15),E15<D15),"ERRO: validade anterior à realização",IF(H15="","Pendente: registre a evidência","OK")))))
... I203: =IF(A203="","",IF(NOT(ISNUMBER(E203)),"Sem validade",IF(NOT(ISNUMBER(E203)),"",IF(E203<TODAY(),"Vencido",IF(E203-TODAY()<=30,"Vence em 30 dias","Válido"))))) | J203: =IF(A203&C203="","",IF(OR(A203="",C203=""),"ERRO: informe colaborador e treinamento",IF(NOT(ISNUMBER(D203)),"Pendente: data de realização",IF(AND(ISNUMBER(E203),E203<D203),"ERRO: validade anterior à realização",IF(H203="","Pendente: registre a evidência","OK")))))

Sheet Requisitos Legais
C1: Requisitos legais e normativos aplicáveis Confirme cada requisito na fonte oficial (HTTPS), com versão e data. Este modelo não certifica conformidade. | I1: ="Rev. "&IF(cfg_revisao="","—",cfg_revisao)&IF(ISNUMBER(cfg_data_revisao)," · "&RIGHT("0"&DAY(cfg_data_revisao),2)&"/"&RIGHT("0"&MONTH(cfg_data_revisao),2)&"/"&YEAR(cfg_data_revisao),"")
I2: ="Elaborado: "&IF(cfg_elaborado="","A definir",cfg_elaborado)&CHAR(10)&"Aprovado: "&IF(cfg_aprovado="","A definir",cfg_aprovado)
A3: Ativo / instalação | B3: Requisito aplicável | C3: Órgão fiscalizador | D3: Documento / comprovante | E3: Fonte oficial (HTTPS) | F3: Data de validade | G3: Status | H3: Responsável | I3: Conferência
G4: =IF(NOT(ISNUMBER(F4)),"",IF(F4<TODAY(),"Vencido",IF(F4-TODAY()<=30,"Vence em 30 dias","Em dia"))) | I4: =IF(A4&B4="","",IF(OR(A4="",B4=""),"ERRO: informe instalação e requisito",IF(E4="","Não verificado: registre a fonte oficial",IF(NOT(ISNUMBER(F4)),"Pendente: data de validade",IF(H4="","Pendente: responsável","OK")))))
G5: =IF(NOT(ISNUMBER(F5)),"",IF(F5<TODAY(),"Vencido",IF(F5-TODAY()<=30,"Vence em 30 dias","Em dia"))) | I5: =IF(A5&B5="","",IF(OR(A5="",B5=""),"ERRO: informe instalação e requisito",IF(E5="","Não verificado: registre a fonte oficial",IF(NOT(ISNUMBER(F5)),"Pendente: data de validade",IF(H5="","Pendente: responsável","OK")))))
G6: =IF(NOT(ISNUMBER(F6)),"",IF(F6<TODAY(),"Vencido",IF(F6-TODAY()<=30,"Vence em 30 dias","Em dia"))) | I6: =IF(A6&B6="","",IF(OR(A6="",B6=""),"ERRO: informe instalação e requisito",IF(E6="","Não verificado: registre a fonte oficial",IF(NOT(ISNUMBER(F6)),"Pendente: data de validade",IF(H6="","Pendente: responsável","OK")))))
G7: =IF(NOT(ISNUMBER(F7)),"",IF(F7<TODAY(),"Vencido",IF(F7-TODAY()<=30,"Vence em 30 dias","Em dia"))) | I7: =IF(A7&B7="","",IF(OR(A7="",B7=""),"ERRO: informe instalação e requisito",IF(E7="","Não verificado: registre a fonte oficial",IF(NOT(ISNUMBER(F7)),"Pendente: data de validade",IF(H7="","Pendente: responsável","OK")))))
G8: =IF(NOT(ISNUMBER(F8)),"",IF(F8<TODAY(),"Vencido",IF(F8-TODAY()<=30,"Vence em 30 dias","Em dia"))) | I8: =IF(A8&B8="","",IF(OR(A8="",B8=""),"ERRO: informe instalação e requisito",IF(E8="","Não verificado: registre a fonte oficial",IF(NOT(ISNUMBER(F8)),"Pendente: data de validade",IF(H8="","Pendente: responsável","OK")))))
G9: =IF(NOT(ISNUMBER(F9)),"",IF(F9<TODAY(),"Vencido",IF(F9-TODAY()<=30,"Vence em 30 dias","Em dia"))) | I9: =IF(A9&B9="","",IF(OR(A9="",B9=""),"ERRO: informe instalação e requisito",IF(E9="","Não verificado: registre a fonte oficial",IF(NOT(ISNUMBER(F9)),"Pendente: data de validade",IF(H9="","Pendente: responsável","OK")))))
G10: =IF(NOT(ISNUMBER(F10)),"",IF(F10<TODAY(),"Vencido",IF(F10-TODAY()<=30,"Vence em 30 dias","Em dia"))) | I10: =IF(A10&B10="","",IF(OR(A10="",B10=""),"ERRO: informe instalação e requisito",IF(E10="","Não verificado: registre a fonte oficial",IF(NOT(ISNUMBER(F10)),"Pendente: data de validade",IF(H10="","Pendente: responsável","OK")))))
G11: =IF(NOT(ISNUMBER(F11)),"",IF(F11<TODAY(),"Vencido",IF(F11-TODAY()<=30,"Vence em 30 dias","Em dia"))) | I11: =IF(A11&B11="","",IF(OR(A11="",B11=""),"ERRO: informe instalação e requisito",IF(E11="","Não verificado: registre a fonte oficial",IF(NOT(ISNUMBER(F11)),"Pendente: data de validade",IF(H11="","Pendente: responsável","OK")))))
G12: =IF(NOT(ISNUMBER(F12)),"",IF(F12<TODAY(),"Vencido",IF(F12-TODAY()<=30,"Vence em 30 dias","Em dia"))) | I12: =IF(A12&B12="","",IF(OR(A12="",B12=""),"ERRO: informe instalação e requisito",IF(E12="","Não verificado: registre a fonte oficial",IF(NOT(ISNUMBER(F12)),"Pendente: data de validade",IF(H12="","Pendente: responsável","OK")))))
G13: =IF(NOT(ISNUMBER(F13)),"",IF(F13<TODAY(),"Vencido",IF(F13-TODAY()<=30,"Vence em 30 dias","Em dia"))) | I13: =IF(A13&B13="","",IF(OR(A13="",B13=""),"ERRO: informe instalação e requisito",IF(E13="","Não verificado: registre a fonte oficial",IF(NOT(ISNUMBER(F13)),"Pendente: data de validade",IF(H13="","Pendente: responsável","OK")))))
G14: =IF(NOT(ISNUMBER(F14)),"",IF(F14<TODAY(),"Vencido",IF(F14-TODAY()<=30,"Vence em 30 dias","Em dia"))) | I14: =IF(A14&B14="","",IF(OR(A14="",B14=""),"ERRO: informe instalação e requisito",IF(E14="","Não verificado: registre a fonte oficial",IF(NOT(ISNUMBER(F14)),"Pendente: data de validade",IF(H14="","Pendente: responsável","OK")))))
G15: =IF(NOT(ISNUMBER(F15)),"",IF(F15<TODAY(),"Vencido",IF(F15-TODAY()<=30,"Vence em 30 dias","Em dia"))) | I15: =IF(A15&B15="","",IF(OR(A15="",B15=""),"ERRO: informe instalação e requisito",IF(E15="","Não verificado: registre a fonte oficial",IF(NOT(ISNUMBER(F15)),"Pendente: data de validade",IF(H15="","Pendente: responsável","OK")))))
... G103: =IF(NOT(ISNUMBER(F103)),"",IF(F103<TODAY(),"Vencido",IF(F103-TODAY()<=30,"Vence em 30 dias","Em dia"))) | I103: =IF(A103&B103="","",IF(OR(A103="",B103=""),"ERRO: informe instalação e requisito",IF(E103="","Não verificado: registre a fonte oficial",IF(NOT(ISNUMBER(F103)),"Pendente: data de validade",IF(H103="","Pendente: responsável","OK")))))

Sheet Máquinas e riscos
C1: Inventário de máquinas e riscos Identificação, localização e riscos de cada máquina. Análise de risco com mais de 24 meses pede revisão. | L1: ="Rev. "&IF(cfg_revisao="","—",cfg_revisao)&IF(ISNUMBER(cfg_data_revisao)," · "&RIGHT("0"&DAY(cfg_data_revisao),2)&"/"&RIGHT("0"&MONTH(cfg_data_revisao),2)&"/"&YEAR(cfg_data_revisao),"")
L2: ="Elaborado: "&IF(cfg_elaborado="","A definir",cfg_elaborado)&CHAR(10)&"Aprovado: "&IF(cfg_aprovado="","A definir",cfg_aprovado)
A3: Código do ativo | B3: Nome / tipo da máquina | C3: Fabricante | D3: Nº de série | E3: Ano | F3: Modelo | G3: Localização | H3: Pontos de risco identificados | I3: Medida de proteção existente | J3: Última análise de risco | K3: Situação da análise | L3: Conferência
K4: =IF(A4="","",IF(NOT(ISNUMBER(J4)),"Pendente: sem análise",IF(J4<EDATE(TODAY(),-24),"Revisar: mais de 24 meses","Em dia"))) | L4: =IF(A4&B4="","",IF(A4="","ERRO: falta o código",IF(COUNTIF($A$4:$A$103,A4)>1,"ERRO: código repetido",IF(OR(H4="",I4=""),"Pendente: riscos e proteções","OK"))))
K5: =IF(A5="","",IF(NOT(ISNUMBER(J5)),"Pendente: sem análise",IF(J5<EDATE(TODAY(),-24),"Revisar: mais de 24 meses","Em dia"))) | L5: =IF(A5&B5="","",IF(A5="","ERRO: falta o código",IF(COUNTIF($A$4:$A$103,A5)>1,"ERRO: código repetido",IF(OR(H5="",I5=""),"Pendente: riscos e proteções","OK"))))
K6: =IF(A6="","",IF(NOT(ISNUMBER(J6)),"Pendente: sem análise",IF(J6<EDATE(TODAY(),-24),"Revisar: mais de 24 meses","Em dia"))) | L6: =IF(A6&B6="","",IF(A6="","ERRO: falta o código",IF(COUNTIF($A$4:$A$103,A6)>1,"ERRO: código repetido",IF(OR(H6="",I6=""),"Pendente: riscos e proteções","OK"))))
K7: =IF(A7="","",IF(NOT(ISNUMBER(J7)),"Pendente: sem análise",IF(J7<EDATE(TODAY(),-24),"Revisar: mais de 24 meses","Em dia"))) | L7: =IF(A7&B7="","",IF(A7="","ERRO: falta o código",IF(COUNTIF($A$4:$A$103,A7)>1,"ERRO: código repetido",IF(OR(H7="",I7=""),"Pendente: riscos e proteções","OK"))))
K8: =IF(A8="","",IF(NOT(ISNUMBER(J8)),"Pendente: sem análise",IF(J8<EDATE(TODAY(),-24),"Revisar: mais de 24 meses","Em dia"))) | L8: =IF(A8&B8="","",IF(A8="","ERRO: falta o código",IF(COUNTIF($A$4:$A$103,A8)>1,"ERRO: código repetido",IF(OR(H8="",I8=""),"Pendente: riscos e proteções","OK"))))
K9: =IF(A9="","",IF(NOT(ISNUMBER(J9)),"Pendente: sem análise",IF(J9<EDATE(TODAY(),-24),"Revisar: mais de 24 meses","Em dia"))) | L9: =IF(A9&B9="","",IF(A9="","ERRO: falta o código",IF(COUNTIF($A$4:$A$103,A9)>1,"ERRO: código repetido",IF(OR(H9="",I9=""),"Pendente: riscos e proteções","OK"))))
K10: =IF(A10="","",IF(NOT(ISNUMBER(J10)),"Pendente: sem análise",IF(J10<EDATE(TODAY(),-24),"Revisar: mais de 24 meses","Em dia"))) | L10: =IF(A10&B10="","",IF(A10="","ERRO: falta o código",IF(COUNTIF($A$4:$A$103,A10)>1,"ERRO: código repetido",IF(OR(H10="",I10=""),"Pendente: riscos e proteções","OK"))))
K11: =IF(A11="","",IF(NOT(ISNUMBER(J11)),"Pendente: sem análise",IF(J11<EDATE(TODAY(),-24),"Revisar: mais de 24 meses","Em dia"))) | L11: =IF(A11&B11="","",IF(A11="","ERRO: falta o código",IF(COUNTIF($A$4:$A$103,A11)>1,"ERRO: código repetido",IF(OR(H11="",I11=""),"Pendente: riscos e proteções","OK"))))
K12: =IF(A12="","",IF(NOT(ISNUMBER(J12)),"Pendente: sem análise",IF(J12<EDATE(TODAY(),-24),"Revisar: mais de 24 meses","Em dia"))) | L12: =IF(A12&B12="","",IF(A12="","ERRO: falta o código",IF(COUNTIF($A$4:$A$103,A12)>1,"ERRO: código repetido",IF(OR(H12="",I12=""),"Pendente: riscos e proteções","OK"))))
K13: =IF(A13="","",IF(NOT(ISNUMBER(J13)),"Pendente: sem análise",IF(J13<EDATE(TODAY(),-24),"Revisar: mais de 24 meses","Em dia"))) | L13: =IF(A13&B13="","",IF(A13="","ERRO: falta o código",IF(COUNTIF($A$4:$A$103,A13)>1,"ERRO: código repetido",IF(OR(H13="",I13=""),"Pendente: riscos e proteções","OK"))))
K14: =IF(A14="","",IF(NOT(ISNUMBER(J14)),"Pendente: sem análise",IF(J14<EDATE(TODAY(),-24),"Revisar: mais de 24 meses","Em dia"))) | L14: =IF(A14&B14="","",IF(A14="","ERRO: falta o código",IF(COUNTIF($A$4:$A$103,A14)>1,"ERRO: código repetido",IF(OR(H14="",I14=""),"Pendente: riscos e proteções","OK"))))
K15: =IF(A15="","",IF(NOT(ISNUMBER(J15)),"Pendente: sem análise",IF(J15<EDATE(TODAY(),-24),"Revisar: mais de 24 meses","Em dia"))) | L15: =IF(A15&B15="","",IF(A15="","ERRO: falta o código",IF(COUNTIF($A$4:$A$103,A15)>1,"ERRO: código repetido",IF(OR(H15="",I15=""),"Pendente: riscos e proteções","OK"))))
... K103: =IF(A103="","",IF(NOT(ISNUMBER(J103)),"Pendente: sem análise",IF(J103<EDATE(TODAY(),-24),"Revisar: mais de 24 meses","Em dia"))) | L103: =IF(A103&B103="","",IF(A103="","ERRO: falta o código",IF(COUNTIF($A$4:$A$103,A103)>1,"ERRO: código repetido",IF(OR(H103="",I103=""),"Pendente: riscos e proteções","OK"))))

Sheet Avaliação de Fornecedores
C1: Avaliação de fornecedores de manutenção Notas de 1 a 5. Média ≥ 4 aprovado; ≥ 3 com ressalva; abaixo de 3 reprovado. | K1: ="Rev. "&IF(cfg_revisao="","—",cfg_revisao)&IF(ISNUMBER(cfg_data_revisao)," · "&RIGHT("0"&DAY(cfg_data_revisao),2)&"/"&RIGHT("0"&MONTH(cfg_data_revisao),2)&"/"&YEAR(cfg_data_revisao),"")
K2: ="Elaborado: "&IF(cfg_elaborado="","A definir",cfg_elaborado)&CHAR(10)&"Aprovado: "&IF(cfg_aprovado="","A definir",cfg_aprovado)
A3: Fornecedor | B3: Serviço / produto fornecido | C3: Data da avaliação | D3: Prazo de entrega (1-5) | E3: Qualidade do serviço (1-5) | F3: Conformidade documental (1-5) | G3: Nota média | H3: Classificação | I3: Próxima avaliação | J3: Situação | K3: Conferência
G4: =IF(COUNT(D4:F4)<3,"",AVERAGE(D4:F4)) | H4: =IF(G4="","",IF(G4>=4,"Aprovado",IF(G4>=3,"Aprovado com ressalva","Reprovado"))) | J4: =IF(NOT(ISNUMBER(I4)),"",IF(I4<TODAY(),"Avaliação vencida",IF(I4-TODAY()<=30,"Vence em 30 dias","Em dia"))) | K4: =IF(A4&B4="","",IF(A4="","ERRO: falta o fornecedor",IF(NOT(ISNUMBER(C4)),"Pendente: data da avaliação",IF(COUNT(D4:F4)<3,"Pendente: dê as três notas",IF(AND(ISNUMBER(I4),I4<C4),"ERRO: próxima avaliação anterior à avaliação",IF(NOT(ISNUMBER(I4)),"Pendente: agende a próxima avaliação","OK"))))))
G5: =IF(COUNT(D5:F5)<3,"",AVERAGE(D5:F5)) | H5: =IF(G5="","",IF(G5>=4,"Aprovado",IF(G5>=3,"Aprovado com ressalva","Reprovado"))) | J5: =IF(NOT(ISNUMBER(I5)),"",IF(I5<TODAY(),"Avaliação vencida",IF(I5-TODAY()<=30,"Vence em 30 dias","Em dia"))) | K5: =IF(A5&B5="","",IF(A5="","ERRO: falta o fornecedor",IF(NOT(ISNUMBER(C5)),"Pendente: data da avaliação",IF(COUNT(D5:F5)<3,"Pendente: dê as três notas",IF(AND(ISNUMBER(I5),I5<C5),"ERRO: próxima avaliação anterior à avaliação",IF(NOT(ISNUMBER(I5)),"Pendente: agende a próxima avaliação","OK"))))))
G6: =IF(COUNT(D6:F6)<3,"",AVERAGE(D6:F6)) | H6: =IF(G6="","",IF(G6>=4,"Aprovado",IF(G6>=3,"Aprovado com ressalva","Reprovado"))) | J6: =IF(NOT(ISNUMBER(I6)),"",IF(I6<TODAY(),"Avaliação vencida",IF(I6-TODAY()<=30,"Vence em 30 dias","Em dia"))) | K6: =IF(A6&B6="","",IF(A6="","ERRO: falta o fornecedor",IF(NOT(ISNUMBER(C6)),"Pendente: data da avaliação",IF(COUNT(D6:F6)<3,"Pendente: dê as três notas",IF(AND(ISNUMBER(I6),I6<C6),"ERRO: próxima avaliação anterior à avaliação",IF(NOT(ISNUMBER(I6)),"Pendente: agende a próxima avaliação","OK"))))))
G7: =IF(COUNT(D7:F7)<3,"",AVERAGE(D7:F7)) | H7: =IF(G7="","",IF(G7>=4,"Aprovado",IF(G7>=3,"Aprovado com ressalva","Reprovado"))) | J7: =IF(NOT(ISNUMBER(I7)),"",IF(I7<TODAY(),"Avaliação vencida",IF(I7-TODAY()<=30,"Vence em 30 dias","Em dia"))) | K7: =IF(A7&B7="","",IF(A7="","ERRO: falta o fornecedor",IF(NOT(ISNUMBER(C7)),"Pendente: data da avaliação",IF(COUNT(D7:F7)<3,"Pendente: dê as três notas",IF(AND(ISNUMBER(I7),I7<C7),"ERRO: próxima avaliação anterior à avaliação",IF(NOT(ISNUMBER(I7)),"Pendente: agende a próxima avaliação","OK"))))))
G8: =IF(COUNT(D8:F8)<3,"",AVERAGE(D8:F8)) | H8: =IF(G8="","",IF(G8>=4,"Aprovado",IF(G8>=3,"Aprovado com ressalva","Reprovado"))) | J8: =IF(NOT(ISNUMBER(I8)),"",IF(I8<TODAY(),"Avaliação vencida",IF(I8-TODAY()<=30,"Vence em 30 dias","Em dia"))) | K8: =IF(A8&B8="","",IF(A8="","ERRO: falta o fornecedor",IF(NOT(ISNUMBER(C8)),"Pendente: data da avaliação",IF(COUNT(D8:F8)<3,"Pendente: dê as três notas",IF(AND(ISNUMBER(I8),I8<C8),"ERRO: próxima avaliação anterior à avaliação",IF(NOT(ISNUMBER(I8)),"Pendente: agende a próxima avaliação","OK"))))))
G9: =IF(COUNT(D9:F9)<3,"",AVERAGE(D9:F9)) | H9: =IF(G9="","",IF(G9>=4,"Aprovado",IF(G9>=3,"Aprovado com ressalva","Reprovado"))) | J9: =IF(NOT(ISNUMBER(I9)),"",IF(I9<TODAY(),"Avaliação vencida",IF(I9-TODAY()<=30,"Vence em 30 dias","Em dia"))) | K9: =IF(A9&B9="","",IF(A9="","ERRO: falta o fornecedor",IF(NOT(ISNUMBER(C9)),"Pendente: data da avaliação",IF(COUNT(D9:F9)<3,"Pendente: dê as três notas",IF(AND(ISNUMBER(I9),I9<C9),"ERRO: próxima avaliação anterior à avaliação",IF(NOT(ISNUMBER(I9)),"Pendente: agende a próxima avaliação","OK"))))))
G10: =IF(COUNT(D10:F10)<3,"",AVERAGE(D10:F10)) | H10: =IF(G10="","",IF(G10>=4,"Aprovado",IF(G10>=3,"Aprovado com ressalva","Reprovado"))) | J10: =IF(NOT(ISNUMBER(I10)),"",IF(I10<TODAY(),"Avaliação vencida",IF(I10-TODAY()<=30,"Vence em 30 dias","Em dia"))) | K10: =IF(A10&B10="","",IF(A10="","ERRO: falta o fornecedor",IF(NOT(ISNUMBER(C10)),"Pendente: data da avaliação",IF(COUNT(D10:F10)<3,"Pendente: dê as três notas",IF(AND(ISNUMBER(I10),I10<C10),"ERRO: próxima avaliação anterior à avaliação",IF(NOT(ISNUMBER(I10)),"Pendente: agende a próxima avaliação","OK"))))))
G11: =IF(COUNT(D11:F11)<3,"",AVERAGE(D11:F11)) | H11: =IF(G11="","",IF(G11>=4,"Aprovado",IF(G11>=3,"Aprovado com ressalva","Reprovado"))) | J11: =IF(NOT(ISNUMBER(I11)),"",IF(I11<TODAY(),"Avaliação vencida",IF(I11-TODAY()<=30,"Vence em 30 dias","Em dia"))) | K11: =IF(A11&B11="","",IF(A11="","ERRO: falta o fornecedor",IF(NOT(ISNUMBER(C11)),"Pendente: data da avaliação",IF(COUNT(D11:F11)<3,"Pendente: dê as três notas",IF(AND(ISNUMBER(I11),I11<C11),"ERRO: próxima avaliação anterior à avaliação",IF(NOT(ISNUMBER(I11)),"Pendente: agende a próxima avaliação","OK"))))))
G12: =IF(COUNT(D12:F12)<3,"",AVERAGE(D12:F12)) | H12: =IF(G12="","",IF(G12>=4,"Aprovado",IF(G12>=3,"Aprovado com ressalva","Reprovado"))) | J12: =IF(NOT(ISNUMBER(I12)),"",IF(I12<TODAY(),"Avaliação vencida",IF(I12-TODAY()<=30,"Vence em 30 dias","Em dia"))) | K12: =IF(A12&B12="","",IF(A12="","ERRO: falta o fornecedor",IF(NOT(ISNUMBER(C12)),"Pendente: data da avaliação",IF(COUNT(D12:F12)<3,"Pendente: dê as três notas",IF(AND(ISNUMBER(I12),I12<C12),"ERRO: próxima avaliação anterior à avaliação",IF(NOT(ISNUMBER(I12)),"Pendente: agende a próxima avaliação","OK"))))))
G13: =IF(COUNT(D13:F13)<3,"",AVERAGE(D13:F13)) | H13: =IF(G13="","",IF(G13>=4,"Aprovado",IF(G13>=3,"Aprovado com ressalva","Reprovado"))) | J13: =IF(NOT(ISNUMBER(I13)),"",IF(I13<TODAY(),"Avaliação vencida",IF(I13-TODAY()<=30,"Vence em 30 dias","Em dia"))) | K13: =IF(A13&B13="","",IF(A13="","ERRO: falta o fornecedor",IF(NOT(ISNUMBER(C13)),"Pendente: data da avaliação",IF(COUNT(D13:F13)<3,"Pendente: dê as três notas",IF(AND(ISNUMBER(I13),I13<C13),"ERRO: próxima avaliação anterior à avaliação",IF(NOT(ISNUMBER(I13)),"Pendente: agende a próxima avaliação","OK"))))))
G14: =IF(COUNT(D14:F14)<3,"",AVERAGE(D14:F14)) | H14: =IF(G14="","",IF(G14>=4,"Aprovado",IF(G14>=3,"Aprovado com ressalva","Reprovado"))) | J14: =IF(NOT(ISNUMBER(I14)),"",IF(I14<TODAY(),"Avaliação vencida",IF(I14-TODAY()<=30,"Vence em 30 dias","Em dia"))) | K14: =IF(A14&B14="","",IF(A14="","ERRO: falta o fornecedor",IF(NOT(ISNUMBER(C14)),"Pendente: data da avaliação",IF(COUNT(D14:F14)<3,"Pendente: dê as três notas",IF(AND(ISNUMBER(I14),I14<C14),"ERRO: próxima avaliação anterior à avaliação",IF(NOT(ISNUMBER(I14)),"Pendente: agende a próxima avaliação","OK"))))))
G15: =IF(COUNT(D15:F15)<3,"",AVERAGE(D15:F15)) | H15: =IF(G15="","",IF(G15>=4,"Aprovado",IF(G15>=3,"Aprovado com ressalva","Reprovado"))) | J15: =IF(NOT(ISNUMBER(I15)),"",IF(I15<TODAY(),"Avaliação vencida",IF(I15-TODAY()<=30,"Vence em 30 dias","Em dia"))) | K15: =IF(A15&B15="","",IF(A15="","ERRO: falta o fornecedor",IF(NOT(ISNUMBER(C15)),"Pendente: data da avaliação",IF(COUNT(D15:F15)<3,"Pendente: dê as três notas",IF(AND(ISNUMBER(I15),I15<C15),"ERRO: próxima avaliação anterior à avaliação",IF(NOT(ISNUMBER(I15)),"Pendente: agende a próxima avaliação","OK"))))))
... G63: =IF(COUNT(D63:F63)<3,"",AVERAGE(D63:F63)) | H63: =IF(G63="","",IF(G63>=4,"Aprovado",IF(G63>=3,"Aprovado com ressalva","Reprovado"))) | J63: =IF(NOT(ISNUMBER(I63)),"",IF(I63<TODAY(),"Avaliação vencida",IF(I63-TODAY()<=30,"Vence em 30 dias","Em dia"))) | K63: =IF(A63&B63="","",IF(A63="","ERRO: falta o fornecedor",IF(NOT(ISNUMBER(C63)),"Pendente: data da avaliação",IF(COUNT(D63:F63)<3,"Pendente: dê as três notas",IF(AND(ISNUMBER(I63),I63<C63),"ERRO: próxima avaliação anterior à avaliação",IF(NOT(ISNUMBER(I63)),"Pendente: agende a próxima avaliação","OK"))))))

Sheet Checklist de Auditoria
C1: Checklist de auditoria interna de manutenção Responda Sim, Não ou Parcial para cada item e veja o nível de prontidão antes da auditoria externa. | D1: ="Rev. "&IF(cfg_revisao="","—",cfg_revisao)&IF(ISNUMBER(cfg_data_revisao)," · "&RIGHT("0"&DAY(cfg_data_revisao),2)&"/"&RIGHT("0"&MONTH(cfg_data_revisao),2)&"/"&YEAR(cfg_data_revisao),"")
D2: ="Elaborado: "&IF(cfg_elaborado="","A definir",cfg_elaborado)&CHAR(10)&"Aprovado: "&IF(cfg_aprovado="","A definir",cfg_aprovado)
A4: DADOS DA AUDITORIA
A5: Site / setor | C5: Data da auditoria
A6: Auditor | C6: Responsável pela manutenção
A7: Período coberto | C7: Última auditoria
A9: AUTOAVALIAÇÃO
A12: Item verificado | B12: Documento / aba relacionada | C12: Situação | D12: Observação
A13: Existe cadastro atualizado de todos os ativos, com criticidade definida? | B13: Matriz de Criticidade
A14: As OS registram causa, ação e evidência de execução? | B14: Sistema de OS (PCMD-K02 / K09)
A15: Os instrumentos de medição têm plano de calibração em dia? | B15: Plano de Calibração
A16: Há inventário de máquinas com riscos e proteções identificados? | B16: Máquinas e riscos
A17: As não conformidades têm ação corretiva com verificação de eficácia registrada? | B17: NC e Ação Corretiva
A18: A equipe tem treinamento/certificação válida e registrada? | B18: Competência e Treinamento
A19: As licenças e requisitos legais estão mapeados, com fonte oficial, e no prazo? | B19: Requisitos Legais
A20: Fornecedores terceirizados de manutenção são avaliados periodicamente? | B20: Avaliação de Fornecedores
A21: Os indicadores (MTBF, MTTR, disponibilidade) são calculados com dados reais? | B21: Dashboard de KPIs (PCMD-K06)
A22: Existe análise de causa raiz para as piores falhas recorrentes? | B22: A3 - Resolução de Problemas
A24: RESULTADO DA AUTOAVALIAÇÃO (automático)
A25: Itens respondidos | C25: =COUNTA(C13:C22)&" de 10"
A26: Sim / Parcial / Não | C26: =COUNTIF(C13:C22,"Sim")&" / "&COUNTIF(C13:C22,"Parcial")&" / "&COUNTIF(C13:C22,"Não")
A27: Itens a regularizar primeiro | C27: =IF(COUNTIF(C13:C22,"Não")>0,"Priorize os "&COUNTIF(C13:C22,"Não")&" item(ns) Não antes da auditoria externa","")
A28: Situação | C28: =IF(COUNTA(C13:C22)<10,"Pendente: responda todos os itens",IF(COUNTIF(C13:C22,"Não")>0,"Verificar: há itens Não","OK"))
A29: Nível de prontidão (% de itens Sim) | C29: =COUNTIF(C13:C22,"Sim")/10
A31: ASSINATURAS
A32: Função | B32: Nome | C32: Data | D32: Assinatura
A33: Auditor
A34: Responsável pela manutenção

Sheet Lista Mestra de Documentos
C1: Lista mestra de documentos Documentos controlados do sistema de manutenção, revisão vigente e próxima revisão. | I1: ="Rev. "&IF(cfg_revisao="","—",cfg_revisao)&IF(ISNUMBER(cfg_data_revisao)," · "&RIGHT("0"&DAY(cfg_data_revisao),2)&"/"&RIGHT("0"&MONTH(cfg_data_revisao),2)&"/"&YEAR(cfg_data_revisao),"")
I2: ="Elaborado: "&IF(cfg_elaborado="","A definir",cfg_elaborado)&CHAR(10)&"Aprovado: "&IF(cfg_aprovado="","A definir",cfg_aprovado)
A3: Código do documento | B3: Nome do documento | C3: Revisão | D3: Data da revisão | E3: Aprovado por | F3: Local de arquivamento | G3: Próxima revisão prevista | H3: Status | I3: Conferência
H4: =IF(NOT(ISNUMBER(G4)),"",IF(G4<TODAY(),"Revisão vencida",IF(G4-TODAY()<=30,"Vence em 30 dias","Em dia"))) | I4: =IF(A4&B4="","",IF(A4="","ERRO: falta o código",IF(COUNTIF($A$4:$A$63,A4)>1,"ERRO: código repetido",IF(AND(ISNUMBER(D4),ISNUMBER(G4),G4<D4),"ERRO: próxima revisão anterior à revisão",IF(OR(C4="",NOT(ISNUMBER(D4)),E4=""),"Pendente: revisão, data e aprovador","OK")))))
H5: =IF(NOT(ISNUMBER(G5)),"",IF(G5<TODAY(),"Revisão vencida",IF(G5-TODAY()<=30,"Vence em 30 dias","Em dia"))) | I5: =IF(A5&B5="","",IF(A5="","ERRO: falta o código",IF(COUNTIF($A$4:$A$63,A5)>1,"ERRO: código repetido",IF(AND(ISNUMBER(D5),ISNUMBER(G5),G5<D5),"ERRO: próxima revisão anterior à revisão",IF(OR(C5="",NOT(ISNUMBER(D5)),E5=""),"Pendente: revisão, data e aprovador","OK")))))
H6: =IF(NOT(ISNUMBER(G6)),"",IF(G6<TODAY(),"Revisão vencida",IF(G6-TODAY()<=30,"Vence em 30 dias","Em dia"))) | I6: =IF(A6&B6="","",IF(A6="","ERRO: falta o código",IF(COUNTIF($A$4:$A$63,A6)>1,"ERRO: código repetido",IF(AND(ISNUMBER(D6),ISNUMBER(G6),G6<D6),"ERRO: próxima revisão anterior à revisão",IF(OR(C6="",NOT(ISNUMBER(D6)),E6=""),"Pendente: revisão, data e aprovador","OK")))))
H7: =IF(NOT(ISNUMBER(G7)),"",IF(G7<TODAY(),"Revisão vencida",IF(G7-TODAY()<=30,"Vence em 30 dias","Em dia"))) | I7: =IF(A7&B7="","",IF(A7="","ERRO: falta o código",IF(COUNTIF($A$4:$A$63,A7)>1,"ERRO: código repetido",IF(AND(ISNUMBER(D7),ISNUMBER(G7),G7<D7),"ERRO: próxima revisão anterior à revisão",IF(OR(C7="",NOT(ISNUMBER(D7)),E7=""),"Pendente: revisão, data e aprovador","OK")))))
H8: =IF(NOT(ISNUMBER(G8)),"",IF(G8<TODAY(),"Revisão vencida",IF(G8-TODAY()<=30,"Vence em 30 dias","Em dia"))) | I8: =IF(A8&B8="","",IF(A8="","ERRO: falta o código",IF(COUNTIF($A$4:$A$63,A8)>1,"ERRO: código repetido",IF(AND(ISNUMBER(D8),ISNUMBER(G8),G8<D8),"ERRO: próxima revisão anterior à revisão",IF(OR(C8="",NOT(ISNUMBER(D8)),E8=""),"Pendente: revisão, data e aprovador","OK")))))
H9: =IF(NOT(ISNUMBER(G9)),"",IF(G9<TODAY(),"Revisão vencida",IF(G9-TODAY()<=30,"Vence em 30 dias","Em dia"))) | I9: =IF(A9&B9="","",IF(A9="","ERRO: falta o código",IF(COUNTIF($A$4:$A$63,A9)>1,"ERRO: código repetido",IF(AND(ISNUMBER(D9),ISNUMBER(G9),G9<D9),"ERRO: próxima revisão anterior à revisão",IF(OR(C9="",NOT(ISNUMBER(D9)),E9=""),"Pendente: revisão, data e aprovador","OK")))))
H10: =IF(NOT(ISNUMBER(G10)),"",IF(G10<TODAY(),"Revisão vencida",IF(G10-TODAY()<=30,"Vence em 30 dias","Em dia"))) | I10: =IF(A10&B10="","",IF(A10="","ERRO: falta o código",IF(COUNTIF($A$4:$A$63,A10)>1,"ERRO: código repetido",IF(AND(ISNUMBER(D10),ISNUMBER(G10),G10<D10),"ERRO: próxima revisão anterior à revisão",IF(OR(C10="",NOT(ISNUMBER(D10)),E10=""),"Pendente: revisão, data e aprovador","OK")))))
H11: =IF(NOT(ISNUMBER(G11)),"",IF(G11<TODAY(),"Revisão vencida",IF(G11-TODAY()<=30,"Vence em 30 dias","Em dia"))) | I11: =IF(A11&B11="","",IF(A11="","ERRO: falta o código",IF(COUNTIF($A$4:$A$63,A11)>1,"ERRO: código repetido",IF(AND(ISNUMBER(D11),ISNUMBER(G11),G11<D11),"ERRO: próxima revisão anterior à revisão",IF(OR(C11="",NOT(ISNUMBER(D11)),E11=""),"Pendente: revisão, data e aprovador","OK")))))
H12: =IF(NOT(ISNUMBER(G12)),"",IF(G12<TODAY(),"Revisão vencida",IF(G12-TODAY()<=30,"Vence em 30 dias","Em dia"))) | I12: =IF(A12&B12="","",IF(A12="","ERRO: falta o código",IF(COUNTIF($A$4:$A$63,A12)>1,"ERRO: código repetido",IF(AND(ISNUMBER(D12),ISNUMBER(G12),G12<D12),"ERRO: próxima revisão anterior à revisão",IF(OR(C12="",NOT(ISNUMBER(D12)),E12=""),"Pendente: revisão, data e aprovador","OK")))))
H13: =IF(NOT(ISNUMBER(G13)),"",IF(G13<TODAY(),"Revisão vencida",IF(G13-TODAY()<=30,"Vence em 30 dias","Em dia"))) | I13: =IF(A13&B13="","",IF(A13="","ERRO: falta o código",IF(COUNTIF($A$4:$A$63,A13)>1,"ERRO: código repetido",IF(AND(ISNUMBER(D13),ISNUMBER(G13),G13<D13),"ERRO: próxima revisão anterior à revisão",IF(OR(C13="",NOT(ISNUMBER(D13)),E13=""),"Pendente: revisão, data e aprovador","OK")))))
H14: =IF(NOT(ISNUMBER(G14)),"",IF(G14<TODAY(),"Revisão vencida",IF(G14-TODAY()<=30,"Vence em 30 dias","Em dia"))) | I14: =IF(A14&B14="","",IF(A14="","ERRO: falta o código",IF(COUNTIF($A$4:$A$63,A14)>1,"ERRO: código repetido",IF(AND(ISNUMBER(D14),ISNUMBER(G14),G14<D14),"ERRO: próxima revisão anterior à revisão",IF(OR(C14="",NOT(ISNUMBER(D14)),E14=""),"Pendente: revisão, data e aprovador","OK")))))
H15: =IF(NOT(ISNUMBER(G15)),"",IF(G15<TODAY(),"Revisão vencida",IF(G15-TODAY()<=30,"Vence em 30 dias","Em dia"))) | I15: =IF(A15&B15="","",IF(A15="","ERRO: falta o código",IF(COUNTIF($A$4:$A$63,A15)>1,"ERRO: código repetido",IF(AND(ISNUMBER(D15),ISNUMBER(G15),G15<D15),"ERRO: próxima revisão anterior à revisão",IF(OR(C15="",NOT(ISNUMBER(D15)),E15=""),"Pendente: revisão, data e aprovador","OK")))))
... H63: =IF(NOT(ISNUMBER(G63)),"",IF(G63<TODAY(),"Revisão vencida",IF(G63-TODAY()<=30,"Vence em 30 dias","Em dia"))) | I63: =IF(A63&B63="","",IF(A63="","ERRO: falta o código",IF(COUNTIF($A$4:$A$63,A63)>1,"ERRO: código repetido",IF(AND(ISNUMBER(D63),ISNUMBER(G63),G63<D63),"ERRO: próxima revisão anterior à revisão",IF(OR(C63="",NOT(ISNUMBER(D63)),E63=""),"Pendente: revisão, data e aprovador","OK")))))

Sheet Manutenção Autônoma (TPM)
C1: Plano de manutenção autônoma (TPM) Checklist do operador: limpeza, inspeção visual e lubrificação básica. Falha ou alerta deve ser repassado à manutenção. | J1: ="Rev. "&IF(cfg_revisao="","—",cfg_revisao)&IF(ISNUMBER(cfg_data_revisao)," · "&RIGHT("0"&DAY(cfg_data_revisao),2)&"/"&RIGHT("0"&MONTH(cfg_data_revisao),2)&"/"&YEAR(cfg_data_revisao),"")
J2: ="Elaborado: "&IF(cfg_elaborado="","A definir",cfg_elaborado)&CHAR(10)&"Aprovado: "&IF(cfg_aprovado="","A definir",cfg_aprovado)
A3: Ativo | B3: Item verificado (limpeza, inspeção, lubrificação) | C3: Frequência | D3: Turno | E3: Data | F3: Operador | G3: Situação | H3: O que foi observado | I3: Repassado à manutenção? | J3: Conferência
J4: =IF(A4&B4="","",IF(OR(A4="",B4=""),"ERRO: informe ativo e item",IF(NOT(ISNUMBER(E4)),"Pendente: data",IF(AND(OR(G4="Falha",G4="Alerta"),I4<>"Sim"),"Pendente: repasse a falha/alerta à manutenção",IF(G4="","Pendente: situação","OK")))))
J5: =IF(A5&B5="","",IF(OR(A5="",B5=""),"ERRO: informe ativo e item",IF(NOT(ISNUMBER(E5)),"Pendente: data",IF(AND(OR(G5="Falha",G5="Alerta"),I5<>"Sim"),"Pendente: repasse a falha/alerta à manutenção",IF(G5="","Pendente: situação","OK")))))
J6: =IF(A6&B6="","",IF(OR(A6="",B6=""),"ERRO: informe ativo e item",IF(NOT(ISNUMBER(E6)),"Pendente: data",IF(AND(OR(G6="Falha",G6="Alerta"),I6<>"Sim"),"Pendente: repasse a falha/alerta à manutenção",IF(G6="","Pendente: situação","OK")))))
J7: =IF(A7&B7="","",IF(OR(A7="",B7=""),"ERRO: informe ativo e item",IF(NOT(ISNUMBER(E7)),"Pendente: data",IF(AND(OR(G7="Falha",G7="Alerta"),I7<>"Sim"),"Pendente: repasse a falha/alerta à manutenção",IF(G7="","Pendente: situação","OK")))))
J8: =IF(A8&B8="","",IF(OR(A8="",B8=""),"ERRO: informe ativo e item",IF(NOT(ISNUMBER(E8)),"Pendente: data",IF(AND(OR(G8="Falha",G8="Alerta"),I8<>"Sim"),"Pendente: repasse a falha/alerta à manutenção",IF(G8="","Pendente: situação","OK")))))
J9: =IF(A9&B9="","",IF(OR(A9="",B9=""),"ERRO: informe ativo e item",IF(NOT(ISNUMBER(E9)),"Pendente: data",IF(AND(OR(G9="Falha",G9="Alerta"),I9<>"Sim"),"Pendente: repasse a falha/alerta à manutenção",IF(G9="","Pendente: situação","OK")))))
J10: =IF(A10&B10="","",IF(OR(A10="",B10=""),"ERRO: informe ativo e item",IF(NOT(ISNUMBER(E10)),"Pendente: data",IF(AND(OR(G10="Falha",G10="Alerta"),I10<>"Sim"),"Pendente: repasse a falha/alerta à manutenção",IF(G10="","Pendente: situação","OK")))))
J11: =IF(A11&B11="","",IF(OR(A11="",B11=""),"ERRO: informe ativo e item",IF(NOT(ISNUMBER(E11)),"Pendente: data",IF(AND(OR(G11="Falha",G11="Alerta"),I11<>"Sim"),"Pendente: repasse a falha/alerta à manutenção",IF(G11="","Pendente: situação","OK")))))
J12: =IF(A12&B12="","",IF(OR(A12="",B12=""),"ERRO: informe ativo e item",IF(NOT(ISNUMBER(E12)),"Pendente: data",IF(AND(OR(G12="Falha",G12="Alerta"),I12<>"Sim"),"Pendente: repasse a falha/alerta à manutenção",IF(G12="","Pendente: situação","OK")))))
J13: =IF(A13&B13="","",IF(OR(A13="",B13=""),"ERRO: informe ativo e item",IF(NOT(ISNUMBER(E13)),"Pendente: data",IF(AND(OR(G13="Falha",G13="Alerta"),I13<>"Sim"),"Pendente: repasse a falha/alerta à manutenção",IF(G13="","Pendente: situação","OK")))))
J14: =IF(A14&B14="","",IF(OR(A14="",B14=""),"ERRO: informe ativo e item",IF(NOT(ISNUMBER(E14)),"Pendente: data",IF(AND(OR(G14="Falha",G14="Alerta"),I14<>"Sim"),"Pendente: repasse a falha/alerta à manutenção",IF(G14="","Pendente: situação","OK")))))
J15: =IF(A15&B15="","",IF(OR(A15="",B15=""),"ERRO: informe ativo e item",IF(NOT(ISNUMBER(E15)),"Pendente: data",IF(AND(OR(G15="Falha",G15="Alerta"),I15<>"Sim"),"Pendente: repasse a falha/alerta à manutenção",IF(G15="","Pendente: situação","OK")))))
... J303: =IF(A303&B303="","",IF(OR(A303="",B303=""),"ERRO: informe ativo e item",IF(NOT(ISNUMBER(E303)),"Pendente: data",IF(AND(OR(G303="Falha",G303="Alerta"),I303<>"Sim"),"Pendente: repasse a falha/alerta à manutenção",IF(G303="","Pendente: situação","OK")))))

Sheet A3 - Resolução de Problemas
C1: A3 de resolução de problemas Uma página PDCA para falhas recorrentes ou não conformidades que pedem análise mais profunda. | H1: ="Rev. "&IF(cfg_revisao="","—",cfg_revisao)&IF(ISNUMBER(cfg_data_revisao)," · "&RIGHT("0"&DAY(cfg_data_revisao),2)&"/"&RIGHT("0"&MONTH(cfg_data_revisao),2)&"/"&YEAR(cfg_data_revisao),"")
