Workbook
Name at_codigo: Ativos!$A$4:$A$203
Name at_setor: Ativos!$D$4:$D$203
Name at_conferencia: Ativos!$J$4:$J$203
Name fm_nivel: FMEA!$J$4:$J$303
Name fm_conferencia: FMEA!$N$4:$N$303
Name pl_codigo: Planos!$A$4:$A$203
Name pl_situacao: Planos!$I$4:$I$203
Name pl_conferencia: Planos!$L$4:$L$203
Name os_numero: 'Programação'!$A$4:$A$503
Name os_kanban: 'Programação'!$N$4:$N$503
Name os_conferencia: 'Programação'!$O$4:$O$503
Name os_chave: 'Programação'!$P$4:$P$503
Name os_rank: 'Programação'!$Q$4:$Q$503
Name cal_mes: 'Calendário'!$B$4
Name cal_ano: 'Calendário'!$D$4
Name rca_os: RCA!$A$4:$A$103
Name rca_conferencia: RCA!$J$4:$J$103
Name eq_nome: Equipe!$A$6:$A$45
Name eq_ferias_conf: Equipe!$I$49:$I$108
Name pr_conferencia: 'Apontamento de Produção'!$I$4:$I$503
Name lst_frequencia: Listas!$A$4:$A$33
Name lst_frequencia_meses: Listas!$B$4:$B$33
Name lst_tipo_ativo: Listas!$D$4:$D$33
Name lst_setor: Listas!$F$4:$F$33
Name lst_setor_filtro: Listas!$H$4:$H$33
Name lst_status_ativo: Listas!$J$4:$J$33
Name lst_tipo_atividade: Listas!$L$4:$L$33
Name lst_tipo_os: Listas!$N$4:$N$33
Name lst_status_os: Listas!$P$4:$P$33
Name lst_turno: Listas!$R$4:$R$33
Name lst_status_ferias: Listas!$T$4:$T$33
Name lst_tipo_feriado: Listas!$V$4:$V$33
Name rv_revisao: 'Revisões'!$A$4:$A$33
Name rv_data: 'Revisões'!$B$4:$B$33
Name cfg_elaborado: 'Instruções'!$C$15
Name cfg_aprovado: 'Instruções'!$C$16
Name cfg_revisao: 'Instruções'!$C$17
Name cfg_data_revisao: 'Instruções'!$C$18
Name pcmd_origem: 'Instruções'!$C$19
Name pcmd_emissao: 'Instruções'!$C$20
Name ano_crono: 'Instruções'!$C$21
Name ano_ref: 'Instruções'!$C$22
Name kanban_setor: 'Instruções'!$C$23

Sheet Instruções
C1: CMMS completo — sistema de gestão de manutenção Como usar, parâmetros do documento e conferências gerais. | F1: ="Rev. "&IF(cfg_revisao="","—",cfg_revisao)&IF(ISNUMBER(cfg_data_revisao)," · "&RIGHT("0"&DAY(cfg_data_revisao),2)&"/"&RIGHT("0"&MONTH(cfg_data_revisao),2)&"/"&YEAR(cfg_data_revisao),"")
F2: ="Elaborado: "&IF(cfg_elaborado="","A definir",cfg_elaborado)&CHAR(10)&"Aprovado: "&IF(cfg_aprovado="","A definir",cfg_aprovado)
A7: 1. COMO USAR
A8: 1) Cadastre setores (Listas), Ativos, Peças Críticas, Equipe e os Planos de preventiva. Faça a FMEA dos ativos críticos.
A9: 2) Na Programação, registre cada OS (preventiva com o código do plano, corretiva com tempo parado e causa). Kanban, Calendário, Cronograma e KPIs se atualizam sozinhos.
A10: 3) Lance o Apontamento de Produção para o OEE, analise as Piores Falhas na aba RCA e confira férias e feriados contra a agenda de OS.
A11: Azul-claro: preencher. Cinza: automático (fórmula protegida, não digite). ERRO em vermelho e Pendente em amarelo pedem ação; OK em verde.
A13: 2. PARÂMETROS DO DOCUMENTO
A14: Parâmetro | C14: Valor | E14: Orientação
A15: Elaborado por | E15: Nome de quem preparou o documento.
A16: Aprovado por (só após aprovação) | E16: Preencha somente após a aprovação efetiva.
A17: Revisão atual (automática) | C17: =IFERROR(LOOKUP(2,1/(rv_revisao<>""),rv_revisao)&"","") | E17: Última linha preenchida em Revisões.
A18: Data da revisão (automática) | C18: =IFERROR(1/(1/LOOKUP(2,1/(rv_revisao<>""),rv_data)),"") | E18: Data da mesma linha da revisão atual.
A19: Origem dos dados | E19: Ex.: preenchimento manual, exportação do sistema.
A20: Data de emissão | E20: Data em que este arquivo foi emitido.
A21: Ano do cronograma | E21: Vazio = ano atual.
A22: Ano usado (automático) | C22: =IF(ISNUMBER(ano_crono),ano_crono,YEAR(TODAY())) | E22: Ano aplicado no Cronograma Anual.
A23: Setor do Kanban | C23: Todos | E23: Todos ou um setor da aba Listas.
A25: 3. CONFERÊNCIAS
A26: Aba / verificação | B26: Linhas preenchidas | C26: Linhas com ERRO | D26: Capacidade / resultado
A27: Ativos e peças | B27: =COUNTA(at_codigo) | C27: =COUNTIF(at_conferencia,"ERRO*")+COUNTIF('Peças Críticas'!$I$4:$I$203,"ERRO*") | D27: ="Peças: "&COUNTA('Peças Críticas'!$A$4:$A$203)
A28: FMEA e Planos | B28: =COUNTA(FMEA!$A$4:$A$303)+COUNTA(pl_codigo) | C28: =COUNTIF(fm_conferencia,"ERRO*")+COUNTIF(pl_conferencia,"ERRO*") | D28: =IF(COUNTIF(pl_situacao,"Vencido")>0,"Verificar: há planos vencidos","OK")
A29: Programação (OS) | B29: =COUNTA(os_numero) | C29: =COUNTIF(os_conferencia,"ERRO*") | D29: =IF(COUNTA(Programação!$A$504:$A$2503)>0,"ATENÇÃO: há OS além da linha 503","OK")
A30: RCA, equipe e produção | B30: =COUNTA(rca_os)+COUNTA(eq_nome) | C30: =COUNTIF(rca_conferencia,"ERRO*")+COUNTIF(eq_ferias_conf,"ERRO*")+COUNTIF(pr_conferencia,"ERRO*") | D30: =IF(COUNTIF('Piores Falhas'!$G$4:$G$13,"Pendente*")>0,"Pendente: piores falhas sem RCA","OK")
A32: 4. ÍNDICE DAS ABAS (clique no nome)
A33: Painel | B33: Visão geral: ativos, planos vencidos, OS atrasadas, riscos e gráficos.
A34: Ativos | B34: Módulo 1: cadastro de máquinas.
A35: Peças Críticas | B35: Módulo 1: peças críticas com curva ABC.
A36: FMEA | B36: Módulo 2: modos de falha e NPR.
A37: Planos | B37: Módulo 3: biblioteca de preventivas.
A38: Cronograma Anual | B38: Plano × mês (✔ executado, ● programado).
A39: Programação | B39: Módulo 4: programação e execução de OS.
A40: Kanban | B40: Quadro visual das OS por situação.
A41: Calendário | B41: OS programadas por dia.
A42: KPIs por Ativo | B42: Módulo 5: MTBF, MTTR, disponibilidade e OEE.
A43: Piores Falhas | B43: Módulo 6: 10 corretivas com mais tempo parado.
A44: RCA | B44: Módulo 6: análises de causa raiz.
... A48: Revisões | B48: Histórico de revisões.
A50: PCMD-K09 · Modelo 2.0.0 · PCM Direto · Thiago Oliveira Lima · pcmdireto@gmail.com · Licença MIT · Sem macros, vínculos externos ou envio de dados.

Sheet Painel
C1: Painel de manutenção — visão geral Resumo automático dos módulos. Nada para preencher aqui. | L1: ="Rev. "&IF(cfg_revisao="","—",cfg_revisao)&IF(ISNUMBER(cfg_data_revisao)," · "&RIGHT("0"&DAY(cfg_data_revisao),2)&"/"&RIGHT("0"&MONTH(cfg_data_revisao),2)&"/"&YEAR(cfg_data_revisao),"")
L2: ="Elaborado: "&IF(cfg_elaborado="","A definir",cfg_elaborado)&CHAR(10)&"Aprovado: "&IF(cfg_aprovado="","A definir",cfg_aprovado)
A4: ATIVOS CADASTRADOS | D4: PLANOS VENCIDOS | G4: OS ATRASADAS | J4: RISCOS CRÍTICOS (FMEA)
A5: =COUNTA(at_codigo) | D5: =COUNTIF(pl_situacao,"Vencido") | G5: =COUNTIF(os_kanban,"Atrasado") | J5: =COUNTIF(fm_nivel,"Crítico")
A6: equipamentos no cadastro | D6: preventivas com data vencida | G6: programadas e não concluídas | J6: NPR de 200 ou mais
A8: ="Disponibilidade média: "&IFERROR(FIXED(AVERAGE('KPIs por Ativo'!$I$4:$I$63)*100,1)&"%","—")&" · OEE médio: "&IFERROR(FIXED(AVERAGE('KPIs por Ativo'!$L$4:$L$63)*100,1)&"%","—")&" · Planos: "&COUNTA(pl_codigo)&" · OS abertas: "&(COUNTA(os_numero)-COUNTIF(os_kanban,"Concluído"))
A10: OS POR SITUAÇÃO | E10: RISCOS (FMEA) POR NÍVEL | I10: DISPONIBILIDADE POR ATIVO
A28: DADOS DOS GRÁFICOS (automático, não digite)
A29: Situação | C29: Valor | E29: Nível | G29: Valor | I29: Ativo | K29: Valor
A30: Programado | C30: =COUNTIF(os_kanban,"Programado") | E30: Crítico | G30: =COUNTIF(fm_nivel,"Crítico") | I30: ='KPIs por Ativo'!A4&"" | K30: =N('KPIs por Ativo'!I4)
A31: Em andamento | C31: =COUNTIF(os_kanban,"Em andamento") | E31: Alto | G31: =COUNTIF(fm_nivel,"Alto") | I31: ='KPIs por Ativo'!A5&"" | K31: =N('KPIs por Ativo'!I5)
A32: Atrasado | C32: =COUNTIF(os_kanban,"Atrasado") | E32: Médio | G32: =COUNTIF(fm_nivel,"Médio") | I32: ='KPIs por Ativo'!A6&"" | K32: =N('KPIs por Ativo'!I6)
A33: Concluído | C33: =COUNTIF(os_kanban,"Concluído") | E33: Baixo | G33: =COUNTIF(fm_nivel,"Baixo") | I33: ='KPIs por Ativo'!A7&"" | K33: =N('KPIs por Ativo'!I7)
A34: Backlog | C34: =COUNTIF(os_kanban,"Backlog") | I34: ='KPIs por Ativo'!A8&"" | K34: =N('KPIs por Ativo'!I8)
I35: ='KPIs por Ativo'!A9&"" | K35: =N('KPIs por Ativo'!I9)
I36: ='KPIs por Ativo'!A10&"" | K36: =N('KPIs por Ativo'!I10)
I37: ='KPIs por Ativo'!A11&"" | K37: =N('KPIs por Ativo'!I11)
I38: ='KPIs por Ativo'!A12&"" | K38: =N('KPIs por Ativo'!I12)
I39: ='KPIs por Ativo'!A13&"" | K39: =N('KPIs por Ativo'!I13)
I40: ='KPIs por Ativo'!A14&"" | K40: =N('KPIs por Ativo'!I14)
I41: ='KPIs por Ativo'!A15&"" | K41: =N('KPIs por Ativo'!I15)

Sheet Ativos
C1: Módulo 1 — Base de ativos Cadastro das máquinas. Setor e criticidade alimentam OS, Kanban e KPIs. | J1: ="Rev. "&IF(cfg_revisao="","—",cfg_revisao)&IF(ISNUMBER(cfg_data_revisao)," · "&RIGHT("0"&DAY(cfg_data_revisao),2)&"/"&RIGHT("0"&MONTH(cfg_data_revisao),2)&"/"&YEAR(cfg_data_revisao),"")
J2: ="Elaborado: "&IF(cfg_elaborado="","A definir",cfg_elaborado)&CHAR(10)&"Aprovado: "&IF(cfg_aprovado="","A definir",cfg_aprovado)
A3: Código do ativo | B3: Nome do ativo | C3: Tipo | D3: Setor / área | E3: Criticidade (A/B/C) | F3: Data de aquisição | G3: Status | H3: Fabricante | I3: Observações | J3: Conferência
J4: =IF(A4&B4="","",IF(A4="","ERRO: falta o código",IF(COUNTIF(at_codigo,A4)>1,"ERRO: código repetido",IF(OR(D4="",E4=""),"Pendente: setor e criticidade","OK"))))
J5: =IF(A5&B5="","",IF(A5="","ERRO: falta o código",IF(COUNTIF(at_codigo,A5)>1,"ERRO: código repetido",IF(OR(D5="",E5=""),"Pendente: setor e criticidade","OK"))))
J6: =IF(A6&B6="","",IF(A6="","ERRO: falta o código",IF(COUNTIF(at_codigo,A6)>1,"ERRO: código repetido",IF(OR(D6="",E6=""),"Pendente: setor e criticidade","OK"))))
J7: =IF(A7&B7="","",IF(A7="","ERRO: falta o código",IF(COUNTIF(at_codigo,A7)>1,"ERRO: código repetido",IF(OR(D7="",E7=""),"Pendente: setor e criticidade","OK"))))
J8: =IF(A8&B8="","",IF(A8="","ERRO: falta o código",IF(COUNTIF(at_codigo,A8)>1,"ERRO: código repetido",IF(OR(D8="",E8=""),"Pendente: setor e criticidade","OK"))))
J9: =IF(A9&B9="","",IF(A9="","ERRO: falta o código",IF(COUNTIF(at_codigo,A9)>1,"ERRO: código repetido",IF(OR(D9="",E9=""),"Pendente: setor e criticidade","OK"))))
J10: =IF(A10&B10="","",IF(A10="","ERRO: falta o código",IF(COUNTIF(at_codigo,A10)>1,"ERRO: código repetido",IF(OR(D10="",E10=""),"Pendente: setor e criticidade","OK"))))
J11: =IF(A11&B11="","",IF(A11="","ERRO: falta o código",IF(COUNTIF(at_codigo,A11)>1,"ERRO: código repetido",IF(OR(D11="",E11=""),"Pendente: setor e criticidade","OK"))))
J12: =IF(A12&B12="","",IF(A12="","ERRO: falta o código",IF(COUNTIF(at_codigo,A12)>1,"ERRO: código repetido",IF(OR(D12="",E12=""),"Pendente: setor e criticidade","OK"))))
J13: =IF(A13&B13="","",IF(A13="","ERRO: falta o código",IF(COUNTIF(at_codigo,A13)>1,"ERRO: código repetido",IF(OR(D13="",E13=""),"Pendente: setor e criticidade","OK"))))
J14: =IF(A14&B14="","",IF(A14="","ERRO: falta o código",IF(COUNTIF(at_codigo,A14)>1,"ERRO: código repetido",IF(OR(D14="",E14=""),"Pendente: setor e criticidade","OK"))))
J15: =IF(A15&B15="","",IF(A15="","ERRO: falta o código",IF(COUNTIF(at_codigo,A15)>1,"ERRO: código repetido",IF(OR(D15="",E15=""),"Pendente: setor e criticidade","OK"))))
... J203: =IF(A203&B203="","",IF(A203="","ERRO: falta o código",IF(COUNTIF(at_codigo,A203)>1,"ERRO: código repetido",IF(OR(D203="",E203=""),"Pendente: setor e criticidade","OK"))))

Sheet Peças Críticas
C1: Módulo 1 — Peças críticas e curva ABC Valor anual = consumo × custo. Curva ABC: A até 80% do valor acumulado, B até 95%, C o restante. | I1: ="Rev. "&IF(cfg_revisao="","—",cfg_revisao)&IF(ISNUMBER(cfg_data_revisao)," · "&RIGHT("0"&DAY(cfg_data_revisao),2)&"/"&RIGHT("0"&MONTH(cfg_data_revisao),2)&"/"&YEAR(cfg_data_revisao),"")
I2: ="Elaborado: "&IF(cfg_elaborado="","A definir",cfg_elaborado)&CHAR(10)&"Aprovado: "&IF(cfg_aprovado="","A definir",cfg_aprovado)
A3: Código da peça | B3: Descrição | C3: Ativo | D3: Consumo anual (un) | E3: Custo unitário | F3: Valor anual | G3: % acumulado | H3: Curva ABC | I3: Conferência
F4: =IF(OR(A4="",NOT(ISNUMBER(D4)),NOT(ISNUMBER(E4))),"",D4*E4) | G4: =IF(F4="","",IFERROR(SUMIF($F$4:$F$203,">="&F4)/SUM($F$4:$F$203),"")) | H4: =IF(G4="","",IF(G4<=0.8,"A",IF(G4<=0.95,"B","C"))) | I4: =IF(A4&B4="","",IF(A4="","ERRO: falta o código",IF(COUNTIF($A$4:$A$203,A4)>1,"ERRO: peça repetida",IF(F4="","Pendente: consumo e custo","OK"))))
F5: =IF(OR(A5="",NOT(ISNUMBER(D5)),NOT(ISNUMBER(E5))),"",D5*E5) | G5: =IF(F5="","",IFERROR(SUMIF($F$4:$F$203,">="&F5)/SUM($F$4:$F$203),"")) | H5: =IF(G5="","",IF(G5<=0.8,"A",IF(G5<=0.95,"B","C"))) | I5: =IF(A5&B5="","",IF(A5="","ERRO: falta o código",IF(COUNTIF($A$4:$A$203,A5)>1,"ERRO: peça repetida",IF(F5="","Pendente: consumo e custo","OK"))))
F6: =IF(OR(A6="",NOT(ISNUMBER(D6)),NOT(ISNUMBER(E6))),"",D6*E6) | G6: =IF(F6="","",IFERROR(SUMIF($F$4:$F$203,">="&F6)/SUM($F$4:$F$203),"")) | H6: =IF(G6="","",IF(G6<=0.8,"A",IF(G6<=0.95,"B","C"))) | I6: =IF(A6&B6="","",IF(A6="","ERRO: falta o código",IF(COUNTIF($A$4:$A$203,A6)>1,"ERRO: peça repetida",IF(F6="","Pendente: consumo e custo","OK"))))
F7: =IF(OR(A7="",NOT(ISNUMBER(D7)),NOT(ISNUMBER(E7))),"",D7*E7) | G7: =IF(F7="","",IFERROR(SUMIF($F$4:$F$203,">="&F7)/SUM($F$4:$F$203),"")) | H7: =IF(G7="","",IF(G7<=0.8,"A",IF(G7<=0.95,"B","C"))) | I7: =IF(A7&B7="","",IF(A7="","ERRO: falta o código",IF(COUNTIF($A$4:$A$203,A7)>1,"ERRO: peça repetida",IF(F7="","Pendente: consumo e custo","OK"))))
F8: =IF(OR(A8="",NOT(ISNUMBER(D8)),NOT(ISNUMBER(E8))),"",D8*E8) | G8: =IF(F8="","",IFERROR(SUMIF($F$4:$F$203,">="&F8)/SUM($F$4:$F$203),"")) | H8: =IF(G8="","",IF(G8<=0.8,"A",IF(G8<=0.95,"B","C"))) | I8: =IF(A8&B8="","",IF(A8="","ERRO: falta o código",IF(COUNTIF($A$4:$A$203,A8)>1,"ERRO: peça repetida",IF(F8="","Pendente: consumo e custo","OK"))))
F9: =IF(OR(A9="",NOT(ISNUMBER(D9)),NOT(ISNUMBER(E9))),"",D9*E9) | G9: =IF(F9="","",IFERROR(SUMIF($F$4:$F$203,">="&F9)/SUM($F$4:$F$203),"")) | H9: =IF(G9="","",IF(G9<=0.8,"A",IF(G9<=0.95,"B","C"))) | I9: =IF(A9&B9="","",IF(A9="","ERRO: falta o código",IF(COUNTIF($A$4:$A$203,A9)>1,"ERRO: peça repetida",IF(F9="","Pendente: consumo e custo","OK"))))
F10: =IF(OR(A10="",NOT(ISNUMBER(D10)),NOT(ISNUMBER(E10))),"",D10*E10) | G10: =IF(F10="","",IFERROR(SUMIF($F$4:$F$203,">="&F10)/SUM($F$4:$F$203),"")) | H10: =IF(G10="","",IF(G10<=0.8,"A",IF(G10<=0.95,"B","C"))) | I10: =IF(A10&B10="","",IF(A10="","ERRO: falta o código",IF(COUNTIF($A$4:$A$203,A10)>1,"ERRO: peça repetida",IF(F10="","Pendente: consumo e custo","OK"))))
F11: =IF(OR(A11="",NOT(ISNUMBER(D11)),NOT(ISNUMBER(E11))),"",D11*E11) | G11: =IF(F11="","",IFERROR(SUMIF($F$4:$F$203,">="&F11)/SUM($F$4:$F$203),"")) | H11: =IF(G11="","",IF(G11<=0.8,"A",IF(G11<=0.95,"B","C"))) | I11: =IF(A11&B11="","",IF(A11="","ERRO: falta o código",IF(COUNTIF($A$4:$A$203,A11)>1,"ERRO: peça repetida",IF(F11="","Pendente: consumo e custo","OK"))))
F12: =IF(OR(A12="",NOT(ISNUMBER(D12)),NOT(ISNUMBER(E12))),"",D12*E12) | G12: =IF(F12="","",IFERROR(SUMIF($F$4:$F$203,">="&F12)/SUM($F$4:$F$203),"")) | H12: =IF(G12="","",IF(G12<=0.8,"A",IF(G12<=0.95,"B","C"))) | I12: =IF(A12&B12="","",IF(A12="","ERRO: falta o código",IF(COUNTIF($A$4:$A$203,A12)>1,"ERRO: peça repetida",IF(F12="","Pendente: consumo e custo","OK"))))
F13: =IF(OR(A13="",NOT(ISNUMBER(D13)),NOT(ISNUMBER(E13))),"",D13*E13) | G13: =IF(F13="","",IFERROR(SUMIF($F$4:$F$203,">="&F13)/SUM($F$4:$F$203),"")) | H13: =IF(G13="","",IF(G13<=0.8,"A",IF(G13<=0.95,"B","C"))) | I13: =IF(A13&B13="","",IF(A13="","ERRO: falta o código",IF(COUNTIF($A$4:$A$203,A13)>1,"ERRO: peça repetida",IF(F13="","Pendente: consumo e custo","OK"))))
F14: =IF(OR(A14="",NOT(ISNUMBER(D14)),NOT(ISNUMBER(E14))),"",D14*E14) | G14: =IF(F14="","",IFERROR(SUMIF($F$4:$F$203,">="&F14)/SUM($F$4:$F$203),"")) | H14: =IF(G14="","",IF(G14<=0.8,"A",IF(G14<=0.95,"B","C"))) | I14: =IF(A14&B14="","",IF(A14="","ERRO: falta o código",IF(COUNTIF($A$4:$A$203,A14)>1,"ERRO: peça repetida",IF(F14="","Pendente: consumo e custo","OK"))))
F15: =IF(OR(A15="",NOT(ISNUMBER(D15)),NOT(ISNUMBER(E15))),"",D15*E15) | G15: =IF(F15="","",IFERROR(SUMIF($F$4:$F$203,">="&F15)/SUM($F$4:$F$203),"")) | H15: =IF(G15="","",IF(G15<=0.8,"A",IF(G15<=0.95,"B","C"))) | I15: =IF(A15&B15="","",IF(A15="","ERRO: falta o código",IF(COUNTIF($A$4:$A$203,A15)>1,"ERRO: peça repetida",IF(F15="","Pendente: consumo e custo","OK"))))
... F203: =IF(OR(A203="",NOT(ISNUMBER(D203)),NOT(ISNUMBER(E203))),"",D203*E203) | G203: =IF(F203="","",IFERROR(SUMIF($F$4:$F$203,">="&F203)/SUM($F$4:$F$203),"")) | H203: =IF(G203="","",IF(G203<=0.8,"A",IF(G203<=0.95,"B","C"))) | I203: =IF(A203&B203="","",IF(A203="","ERRO: falta o código",IF(COUNTIF($A$4:$A$203,A203)>1,"ERRO: peça repetida",IF(F203="","Pendente: consumo e custo","OK"))))

Sheet FMEA
C1: Módulo 2 — Matriz FMEA NPR = Severidade × Ocorrência × Detecção (1 a 10). Escala de referência na aba Listas. | N1: ="Rev. "&IF(cfg_revisao="","—",cfg_revisao)&IF(ISNUMBER(cfg_data_revisao)," · "&RIGHT("0"&DAY(cfg_data_revisao),2)&"/"&RIGHT("0"&MONTH(cfg_data_revisao),2)&"/"&YEAR(cfg_data_revisao),"")
N2: ="Elaborado: "&IF(cfg_elaborado="","A definir",cfg_elaborado)&CHAR(10)&"Aprovado: "&IF(cfg_aprovado="","A definir",cfg_aprovado)
A3: Ativo | B3: Função | C3: Modo de falha | D3: Efeito da falha | E3: Causa potencial | F3: Severidade (1-10) | G3: Ocorrência (1-10) | H3: Detecção (1-10) | I3: NPR | J3: Nível de risco | K3: Ação recomendada | L3: Responsável | M3: Prazo | N3: Conferência
I4: =IF(COUNT(F4:H4)<3,"",F4*G4*H4) | J4: =IF(I4="","",IF(I4>=200,"Crítico",IF(I4>=100,"Alto",IF(I4>=50,"Médio","Baixo")))) | N4: =IF(A4&C4="","",IF(OR(A4="",C4=""),"ERRO: informe ativo e modo de falha",IF(COUNT(F4:H4)<3,"Pendente: dê S, O e D",IF(AND(I4>=100,K4=""),"Pendente: defina a ação para risco Alto/Crítico",IF(AND(K4<>"",OR(L4="",NOT(ISNUMBER(M4)))),"Pendente: responsável e prazo da ação","OK")))))
I5: =IF(COUNT(F5:H5)<3,"",F5*G5*H5) | J5: =IF(I5="","",IF(I5>=200,"Crítico",IF(I5>=100,"Alto",IF(I5>=50,"Médio","Baixo")))) | N5: =IF(A5&C5="","",IF(OR(A5="",C5=""),"ERRO: informe ativo e modo de falha",IF(COUNT(F5:H5)<3,"Pendente: dê S, O e D",IF(AND(I5>=100,K5=""),"Pendente: defina a ação para risco Alto/Crítico",IF(AND(K5<>"",OR(L5="",NOT(ISNUMBER(M5)))),"Pendente: responsável e prazo da ação","OK")))))
I6: =IF(COUNT(F6:H6)<3,"",F6*G6*H6) | J6: =IF(I6="","",IF(I6>=200,"Crítico",IF(I6>=100,"Alto",IF(I6>=50,"Médio","Baixo")))) | N6: =IF(A6&C6="","",IF(OR(A6="",C6=""),"ERRO: informe ativo e modo de falha",IF(COUNT(F6:H6)<3,"Pendente: dê S, O e D",IF(AND(I6>=100,K6=""),"Pendente: defina a ação para risco Alto/Crítico",IF(AND(K6<>"",OR(L6="",NOT(ISNUMBER(M6)))),"Pendente: responsável e prazo da ação","OK")))))
I7: =IF(COUNT(F7:H7)<3,"",F7*G7*H7) | J7: =IF(I7="","",IF(I7>=200,"Crítico",IF(I7>=100,"Alto",IF(I7>=50,"Médio","Baixo")))) | N7: =IF(A7&C7="","",IF(OR(A7="",C7=""),"ERRO: informe ativo e modo de falha",IF(COUNT(F7:H7)<3,"Pendente: dê S, O e D",IF(AND(I7>=100,K7=""),"Pendente: defina a ação para risco Alto/Crítico",IF(AND(K7<>"",OR(L7="",NOT(ISNUMBER(M7)))),"Pendente: responsável e prazo da ação","OK")))))
I8: =IF(COUNT(F8:H8)<3,"",F8*G8*H8) | J8: =IF(I8="","",IF(I8>=200,"Crítico",IF(I8>=100,"Alto",IF(I8>=50,"Médio","Baixo")))) | N8: =IF(A8&C8="","",IF(OR(A8="",C8=""),"ERRO: informe ativo e modo de falha",IF(COUNT(F8:H8)<3,"Pendente: dê S, O e D",IF(AND(I8>=100,K8=""),"Pendente: defina a ação para risco Alto/Crítico",IF(AND(K8<>"",OR(L8="",NOT(ISNUMBER(M8)))),"Pendente: responsável e prazo da ação","OK")))))
I9: =IF(COUNT(F9:H9)<3,"",F9*G9*H9) | J9: =IF(I9="","",IF(I9>=200,"Crítico",IF(I9>=100,"Alto",IF(I9>=50,"Médio","Baixo")))) | N9: =IF(A9&C9="","",IF(OR(A9="",C9=""),"ERRO: informe ativo e modo de falha",IF(COUNT(F9:H9)<3,"Pendente: dê S, O e D",IF(AND(I9>=100,K9=""),"Pendente: defina a ação para risco Alto/Crítico",IF(AND(K9<>"",OR(L9="",NOT(ISNUMBER(M9)))),"Pendente: responsável e prazo da ação","OK")))))
I10: =IF(COUNT(F10:H10)<3,"",F10*G10*H10) | J10: =IF(I10="","",IF(I10>=200,"Crítico",IF(I10>=100,"Alto",IF(I10>=50,"Médio","Baixo")))) | N10: =IF(A10&C10="","",IF(OR(A10="",C10=""),"ERRO: informe ativo e modo de falha",IF(COUNT(F10:H10)<3,"Pendente: dê S, O e D",IF(AND(I10>=100,K10=""),"Pendente: defina a ação para risco Alto/Crítico",IF(AND(K10<>"",OR(L10="",NOT(ISNUMBER(M10)))),"Pendente: responsável e prazo da ação","OK")))))
I11: =IF(COUNT(F11:H11)<3,"",F11*G11*H11) | J11: =IF(I11="","",IF(I11>=200,"Crítico",IF(I11>=100,"Alto",IF(I11>=50,"Médio","Baixo")))) | N11: =IF(A11&C11="","",IF(OR(A11="",C11=""),"ERRO: informe ativo e modo de falha",IF(COUNT(F11:H11)<3,"Pendente: dê S, O e D",IF(AND(I11>=100,K11=""),"Pendente: defina a ação para risco Alto/Crítico",IF(AND(K11<>"",OR(L11="",NOT(ISNUMBER(M11)))),"Pendente: responsável e prazo da ação","OK")))))
I12: =IF(COUNT(F12:H12)<3,"",F12*G12*H12) | J12: =IF(I12="","",IF(I12>=200,"Crítico",IF(I12>=100,"Alto",IF(I12>=50,"Médio","Baixo")))) | N12: =IF(A12&C12="","",IF(OR(A12="",C12=""),"ERRO: informe ativo e modo de falha",IF(COUNT(F12:H12)<3,"Pendente: dê S, O e D",IF(AND(I12>=100,K12=""),"Pendente: defina a ação para risco Alto/Crítico",IF(AND(K12<>"",OR(L12="",NOT(ISNUMBER(M12)))),"Pendente: responsável e prazo da ação","OK")))))
I13: =IF(COUNT(F13:H13)<3,"",F13*G13*H13) | J13: =IF(I13="","",IF(I13>=200,"Crítico",IF(I13>=100,"Alto",IF(I13>=50,"Médio","Baixo")))) | N13: =IF(A13&C13="","",IF(OR(A13="",C13=""),"ERRO: informe ativo e modo de falha",IF(COUNT(F13:H13)<3,"Pendente: dê S, O e D",IF(AND(I13>=100,K13=""),"Pendente: defina a ação para risco Alto/Crítico",IF(AND(K13<>"",OR(L13="",NOT(ISNUMBER(M13)))),"Pendente: responsável e prazo da ação","OK")))))
I14: =IF(COUNT(F14:H14)<3,"",F14*G14*H14) | J14: =IF(I14="","",IF(I14>=200,"Crítico",IF(I14>=100,"Alto",IF(I14>=50,"Médio","Baixo")))) | N14: =IF(A14&C14="","",IF(OR(A14="",C14=""),"ERRO: informe ativo e modo de falha",IF(COUNT(F14:H14)<3,"Pendente: dê S, O e D",IF(AND(I14>=100,K14=""),"Pendente: defina a ação para risco Alto/Crítico",IF(AND(K14<>"",OR(L14="",NOT(ISNUMBER(M14)))),"Pendente: responsável e prazo da ação","OK")))))
I15: =IF(COUNT(F15:H15)<3,"",F15*G15*H15) | J15: =IF(I15="","",IF(I15>=200,"Crítico",IF(I15>=100,"Alto",IF(I15>=50,"Médio","Baixo")))) | N15: =IF(A15&C15="","",IF(OR(A15="",C15=""),"ERRO: informe ativo e modo de falha",IF(COUNT(F15:H15)<3,"Pendente: dê S, O e D",IF(AND(I15>=100,K15=""),"Pendente: defina a ação para risco Alto/Crítico",IF(AND(K15<>"",OR(L15="",NOT(ISNUMBER(M15)))),"Pendente: responsável e prazo da ação","OK")))))
... I303: =IF(COUNT(F303:H303)<3,"",F303*G303*H303) | J303: =IF(I303="","",IF(I303>=200,"Crítico",IF(I303>=100,"Alto",IF(I303>=50,"Médio","Baixo")))) | N303: =IF(A303&C303="","",IF(OR(A303="",C303=""),"ERRO: informe ativo e modo de falha",IF(COUNT(F303:H303)<3,"Pendente: dê S, O e D",IF(AND(I303>=100,K303=""),"Pendente: defina a ação para risco Alto/Crítico",IF(AND(K303<>"",OR(L303="",NOT(ISNUMBER(M303)))),"Pendente: responsável e prazo da ação","OK")))))

Sheet Planos
C1: Módulo 3 — Biblioteca de planos (preventivas) Próxima execução = última execução + frequência (em meses, aba Listas). | L1: ="Rev. "&IF(cfg_revisao="","—",cfg_revisao)&IF(ISNUMBER(cfg_data_revisao)," · "&RIGHT("0"&DAY(cfg_data_revisao),2)&"/"&RIGHT("0"&MONTH(cfg_data_revisao),2)&"/"&YEAR(cfg_data_revisao),"")
L2: ="Elaborado: "&IF(cfg_elaborado="","A definir",cfg_elaborado)&CHAR(10)&"Aprovado: "&IF(cfg_aprovado="","A definir",cfg_aprovado)
A3: Código do plano | B3: Ativo | C3: Escopo do serviço | D3: Tipo de atividade | E3: Frequência | F3: Tempo estimado (h) | G3: Última execução | H3: Próxima execução | I3: Situação | J3: Responsável | K3: Observações | L3: Conferência
H4: =IF(OR(NOT(ISNUMBER(G4)),ISNA(MATCH(E4,lst_frequencia,0))),"",EDATE(G4,INDEX(lst_frequencia_meses,MATCH(E4,lst_frequencia,0)))) | I4: =IF(A4="","",IF(H4="","Sem data",IF(H4<TODAY(),"Vencido",IF(H4-TODAY()<=7,"Programar","Em dia")))) | L4: =IF(A4&B4&C4="","",IF(A4="","ERRO: falta o código do plano",IF(COUNTIF(pl_codigo,A4)>1,"ERRO: plano repetido",IF(ISNA(MATCH(B4,at_codigo,0)),"ERRO: ativo não cadastrado",IF(ISNA(MATCH(E4,lst_frequencia,0)),"Pendente: escolha a frequência",IF(NOT(ISNUMBER(G4)),"Pendente: última execução",IF(G4>TODAY(),"ERRO: última execução no futuro","OK")))))))
H5: =IF(OR(NOT(ISNUMBER(G5)),ISNA(MATCH(E5,lst_frequencia,0))),"",EDATE(G5,INDEX(lst_frequencia_meses,MATCH(E5,lst_frequencia,0)))) | I5: =IF(A5="","",IF(H5="","Sem data",IF(H5<TODAY(),"Vencido",IF(H5-TODAY()<=7,"Programar","Em dia")))) | L5: =IF(A5&B5&C5="","",IF(A5="","ERRO: falta o código do plano",IF(COUNTIF(pl_codigo,A5)>1,"ERRO: plano repetido",IF(ISNA(MATCH(B5,at_codigo,0)),"ERRO: ativo não cadastrado",IF(ISNA(MATCH(E5,lst_frequencia,0)),"Pendente: escolha a frequência",IF(NOT(ISNUMBER(G5)),"Pendente: última execução",IF(G5>TODAY(),"ERRO: última execução no futuro","OK")))))))
H6: =IF(OR(NOT(ISNUMBER(G6)),ISNA(MATCH(E6,lst_frequencia,0))),"",EDATE(G6,INDEX(lst_frequencia_meses,MATCH(E6,lst_frequencia,0)))) | I6: =IF(A6="","",IF(H6="","Sem data",IF(H6<TODAY(),"Vencido",IF(H6-TODAY()<=7,"Programar","Em dia")))) | L6: =IF(A6&B6&C6="","",IF(A6="","ERRO: falta o código do plano",IF(COUNTIF(pl_codigo,A6)>1,"ERRO: plano repetido",IF(ISNA(MATCH(B6,at_codigo,0)),"ERRO: ativo não cadastrado",IF(ISNA(MATCH(E6,lst_frequencia,0)),"Pendente: escolha a frequência",IF(NOT(ISNUMBER(G6)),"Pendente: última execução",IF(G6>TODAY(),"ERRO: última execução no futuro","OK")))))))
H7: =IF(OR(NOT(ISNUMBER(G7)),ISNA(MATCH(E7,lst_frequencia,0))),"",EDATE(G7,INDEX(lst_frequencia_meses,MATCH(E7,lst_frequencia,0)))) | I7: =IF(A7="","",IF(H7="","Sem data",IF(H7<TODAY(),"Vencido",IF(H7-TODAY()<=7,"Programar","Em dia")))) | L7: =IF(A7&B7&C7="","",IF(A7="","ERRO: falta o código do plano",IF(COUNTIF(pl_codigo,A7)>1,"ERRO: plano repetido",IF(ISNA(MATCH(B7,at_codigo,0)),"ERRO: ativo não cadastrado",IF(ISNA(MATCH(E7,lst_frequencia,0)),"Pendente: escolha a frequência",IF(NOT(ISNUMBER(G7)),"Pendente: última execução",IF(G7>TODAY(),"ERRO: última execução no futuro","OK")))))))
H8: =IF(OR(NOT(ISNUMBER(G8)),ISNA(MATCH(E8,lst_frequencia,0))),"",EDATE(G8,INDEX(lst_frequencia_meses,MATCH(E8,lst_frequencia,0)))) | I8: =IF(A8="","",IF(H8="","Sem data",IF(H8<TODAY(),"Vencido",IF(H8-TODAY()<=7,"Programar","Em dia")))) | L8: =IF(A8&B8&C8="","",IF(A8="","ERRO: falta o código do plano",IF(COUNTIF(pl_codigo,A8)>1,"ERRO: plano repetido",IF(ISNA(MATCH(B8,at_codigo,0)),"ERRO: ativo não cadastrado",IF(ISNA(MATCH(E8,lst_frequencia,0)),"Pendente: escolha a frequência",IF(NOT(ISNUMBER(G8)),"Pendente: última execução",IF(G8>TODAY(),"ERRO: última execução no futuro","OK")))))))
H9: =IF(OR(NOT(ISNUMBER(G9)),ISNA(MATCH(E9,lst_frequencia,0))),"",EDATE(G9,INDEX(lst_frequencia_meses,MATCH(E9,lst_frequencia,0)))) | I9: =IF(A9="","",IF(H9="","Sem data",IF(H9<TODAY(),"Vencido",IF(H9-TODAY()<=7,"Programar","Em dia")))) | L9: =IF(A9&B9&C9="","",IF(A9="","ERRO: falta o código do plano",IF(COUNTIF(pl_codigo,A9)>1,"ERRO: plano repetido",IF(ISNA(MATCH(B9,at_codigo,0)),"ERRO: ativo não cadastrado",IF(ISNA(MATCH(E9,lst_frequencia,0)),"Pendente: escolha a frequência",IF(NOT(ISNUMBER(G9)),"Pendente: última execução",IF(G9>TODAY(),"ERRO: última execução no futuro","OK")))))))
H10: =IF(OR(NOT(ISNUMBER(G10)),ISNA(MATCH(E10,lst_frequencia,0))),"",EDATE(G10,INDEX(lst_frequencia_meses,MATCH(E10,lst_frequencia,0)))) | I10: =IF(A10="","",IF(H10="","Sem data",IF(H10<TODAY(),"Vencido",IF(H10-TODAY()<=7,"Programar","Em dia")))) | L10: =IF(A10&B10&C10="","",IF(A10="","ERRO: falta o código do plano",IF(COUNTIF(pl_codigo,A10)>1,"ERRO: plano repetido",IF(ISNA(MATCH(B10,at_codigo,0)),"ERRO: ativo não cadastrado",IF(ISNA(MATCH(E10,lst_frequencia,0)),"Pendente: escolha a frequência",IF(NOT(ISNUMBER(G10)),"Pendente: última execução",IF(G10>TODAY(),"ERRO: última execução no futuro","OK")))))))
H11: =IF(OR(NOT(ISNUMBER(G11)),ISNA(MATCH(E11,lst_frequencia,0))),"",EDATE(G11,INDEX(lst_frequencia_meses,MATCH(E11,lst_frequencia,0)))) | I11: =IF(A11="","",IF(H11="","Sem data",IF(H11<TODAY(),"Vencido",IF(H11-TODAY()<=7,"Programar","Em dia")))) | L11: =IF(A11&B11&C11="","",IF(A11="","ERRO: falta o código do plano",IF(COUNTIF(pl_codigo,A11)>1,"ERRO: plano repetido",IF(ISNA(MATCH(B11,at_codigo,0)),"ERRO: ativo não cadastrado",IF(ISNA(MATCH(E11,lst_frequencia,0)),"Pendente: escolha a frequência",IF(NOT(ISNUMBER(G11)),"Pendente: última execução",IF(G11>TODAY(),"ERRO: última execução no futuro","OK")))))))
H12: =IF(OR(NOT(ISNUMBER(G12)),ISNA(MATCH(E12,lst_frequencia,0))),"",EDATE(G12,INDEX(lst_frequencia_meses,MATCH(E12,lst_frequencia,0)))) | I12: =IF(A12="","",IF(H12="","Sem data",IF(H12<TODAY(),"Vencido",IF(H12-TODAY()<=7,"Programar","Em dia")))) | L12: =IF(A12&B12&C12="","",IF(A12="","ERRO: falta o código do plano",IF(COUNTIF(pl_codigo,A12)>1,"ERRO: plano repetido",IF(ISNA(MATCH(B12,at_codigo,0)),"ERRO: ativo não cadastrado",IF(ISNA(MATCH(E12,lst_frequencia,0)),"Pendente: escolha a frequência",IF(NOT(ISNUMBER(G12)),"Pendente: última execução",IF(G12>TODAY(),"ERRO: última execução no futuro","OK")))))))
H13: =IF(OR(NOT(ISNUMBER(G13)),ISNA(MATCH(E13,lst_frequencia,0))),"",EDATE(G13,INDEX(lst_frequencia_meses,MATCH(E13,lst_frequencia,0)))) | I13: =IF(A13="","",IF(H13="","Sem data",IF(H13<TODAY(),"Vencido",IF(H13-TODAY()<=7,"Programar","Em dia")))) | L13: =IF(A13&B13&C13="","",IF(A13="","ERRO: falta o código do plano",IF(COUNTIF(pl_codigo,A13)>1,"ERRO: plano repetido",IF(ISNA(MATCH(B13,at_codigo,0)),"ERRO: ativo não cadastrado",IF(ISNA(MATCH(E13,lst_frequencia,0)),"Pendente: escolha a frequência",IF(NOT(ISNUMBER(G13)),"Pendente: última execução",IF(G13>TODAY(),"ERRO: última execução no futuro","OK")))))))
H14: =IF(OR(NOT(ISNUMBER(G14)),ISNA(MATCH(E14,lst_frequencia,0))),"",EDATE(G14,INDEX(lst_frequencia_meses,MATCH(E14,lst_frequencia,0)))) | I14: =IF(A14="","",IF(H14="","Sem data",IF(H14<TODAY(),"Vencido",IF(H14-TODAY()<=7,"Programar","Em dia")))) | L14: =IF(A14&B14&C14="","",IF(A14="","ERRO: falta o código do plano",IF(COUNTIF(pl_codigo,A14)>1,"ERRO: plano repetido",IF(ISNA(MATCH(B14,at_codigo,0)),"ERRO: ativo não cadastrado",IF(ISNA(MATCH(E14,lst_frequencia,0)),"Pendente: escolha a frequência",IF(NOT(ISNUMBER(G14)),"Pendente: última execução",IF(G14>TODAY(),"ERRO: última execução no futuro","OK")))))))
H15: =IF(OR(NOT(ISNUMBER(G15)),ISNA(MATCH(E15,lst_frequencia,0))),"",EDATE(G15,INDEX(lst_frequencia_meses,MATCH(E15,lst_frequencia,0)))) | I15: =IF(A15="","",IF(H15="","Sem data",IF(H15<TODAY(),"Vencido",IF(H15-TODAY()<=7,"Programar","Em dia")))) | L15: =IF(A15&B15&C15="","",IF(A15="","ERRO: falta o código do plano",IF(COUNTIF(pl_codigo,A15)>1,"ERRO: plano repetido",IF(ISNA(MATCH(B15,at_codigo,0)),"ERRO: ativo não cadastrado",IF(ISNA(MATCH(E15,lst_frequencia,0)),"Pendente: escolha a frequência",IF(NOT(ISNUMBER(G15)),"Pendente: última execução",IF(G15>TODAY(),"ERRO: última execução no futuro","OK")))))))
... H203: =IF(OR(NOT(ISNUMBER(G203)),ISNA(MATCH(E203,lst_frequencia,0))),"",EDATE(G203,INDEX(lst_frequencia_meses,MATCH(E203,lst_frequencia,0)))) | I203: =IF(A203="","",IF(H203="","Sem data",IF(H203<TODAY(),"Vencido",IF(H203-TODAY()<=7,"Programar","Em dia")))) | L203: =IF(A203&B203&C203="","",IF(A203="","ERRO: falta o código do plano",IF(COUNTIF(pl_codigo,A203)>1,"ERRO: plano repetido",IF(ISNA(MATCH(B203,at_codigo,0)),"ERRO: ativo não cadastrado",IF(ISNA(MATCH(E203,lst_frequencia,0)),"Pendente: escolha a frequência",IF(NOT(ISNUMBER(G203)),"Pendente: última execução",IF(G203>TODAY(),"ERRO: última execução no futuro","OK")))))))

Sheet Cronograma Anual
C1: Cronograma anual de preventivas ✔ = OS preventiva concluída do plano no mês · ● = programado e ainda não executado. Lê Planos e Programação. | P1: ="Rev. "&IF(cfg_revisao="","—",cfg_revisao)&IF(ISNUMBER(cfg_data_revisao)," · "&RIGHT("0"&DAY(cfg_data_revisao),2)&"/"&RIGHT("0"&MONTH(cfg_data_revisao),2)&"/"&YEAR(cfg_data_revisao),"")
P2: ="Elaborado: "&IF(cfg_elaborado="","A definir",cfg_elaborado)&CHAR(10)&"Aprovado: "&IF(cfg_aprovado="","A definir",cfg_aprovado)
A3: Plano | B3: Ativo | C3: Escopo | D3: Jan | E3: Fev | F3: Mar | G3: Abr | H3: Mai | I3: Jun | J3: Jul | K3: Ago | L3: Set | M3: Out | N3: Nov | O3: Dez | P3: % realizado
A4: ="Programadas (●) e executadas (✔) · ano "&ano_ref | D4: =COUNTIF(D5:D204,"●")&"/"&COUNTIF(D5:D204,"✔") | E4: =COUNTIF(E5:E204,"●")&"/"&COUNTIF(E5:E204,"✔") | F4: =COUNTIF(F5:F204,"●")&"/"&COUNTIF(F5:F204,"✔") | G4: =COUNTIF(G5:G204,"●")&"/"&COUNTIF(G5:G204,"✔") | H4: =COUNTIF(H5:H204,"●")&"/"&COUNTIF(H5:H204,"✔") | I4: =COUNTIF(I5:I204,"●")&"/"&COUNTIF(I5:I204,"✔") | J4: =COUNTIF(J5:J204,"●")&"/"&COUNTIF(J5:J204,"✔") | K4: =COUNTIF(K5:K204,"●")&"/"&COUNTIF(K5:K204,"✔") | ... O4: =COUNTIF(O5:O204,"●")&"/"&COUNTIF(O5:O204,"✔") | P4: =IFERROR(COUNTIF(D5:O204,"✔")/(COUNTIF(D5:O204,"✔")+COUNTIF(D5:O204,"●")),"")
A5: =IF(Planos!$A4<>"",Planos!A4&"","") | B5: =IF(Planos!$A4<>"",Planos!B4&"","") | C5: =IF(Planos!$A4<>"",Planos!C4&"","") | D5: =IF(NOT(Planos!$A4<>""),"",IF(COUNTIFS(Programação!$B$4:$B$503,Planos!$A4,Programação!$I$4:$I$503,"Concluído",Programação!$G$4:$G$503,">="&DATE(ano_ref,1,1),Programação!$G$4:$G$503,"<="&EOMONTH(DATE(ano_ref,1,1),0))>0,"✔",IF(AND(ISNUMBER(Planos!$G4),IFERROR(INDEX(lst_frequencia_meses,MATCH(Planos!$E4,lst_frequencia,0)),0)>0,(ano_ref*12+1)-(YEAR(Planos!$G4)*12+MONTH(Planos!$G4))>0,MOD((ano_ref*12+1)-(YEAR(Planos!$G4)*12+MONTH(Planos!$G4)),MAX(1,IFERROR(INDEX(lst_frequencia_meses,MATCH(Planos!$E4,lst_frequencia,0)),0)))=0),"●",""))) | E5: =IF(NOT(Planos!$A4<>""),"",IF(COUNTIFS(Programação!$B$4:$B$503,Planos!$A4,Programação!$I$4:$I$503,"Concluído",Programação!$G$4:$G$503,">="&DATE(ano_ref,2,1),Programação!$G$4:$G$503,"<="&EOMONTH(DATE(ano_ref,2,1),0))>0,"✔",IF(AND(ISNUMBER(Planos!$G4),IFERROR(INDEX(lst_frequencia_meses,MATCH(Planos!$E4,lst_frequencia,0)),0)>0,(ano_ref*12+2)-(YEAR(Planos!$G4)*12+MONTH(Planos!$G4))>0,MOD((ano_ref*12+2)-(YEAR(Planos!$G4)*12+MONTH(Planos!$G4)),MAX(1,IFERROR(INDEX(lst_frequencia_meses,MATCH(Planos!$E4,lst_frequencia,0)),0)))=0),"●",""))) | F5: =IF(NOT(Planos!$A4<>""),"",IF(COUNTIFS(Programação!$B$4:$B$503,Planos!$A4,Programação!$I$4:$I$503,"Concluído",Programação!$G$4:$G$503,">="&DATE(ano_ref,3,1),Programação!$G$4:$G$503,"<="&EOMONTH(DATE(ano_ref,3,1),0))>0,"✔",IF(AND(ISNUMBER(Planos!$G4),IFERROR(INDEX(lst_frequencia_meses,MATCH(Planos!$E4,lst_frequencia,0)),0)>0,(ano_ref*12+3)-(YEAR(Planos!$G4)*12+MONTH(Planos!$G4))>0,MOD((ano_ref*12+3)-(YEAR(Planos!$G4)*12+MONTH(Planos!$G4)),MAX(1,IFERROR(INDEX(lst_frequencia_meses,MATCH(Planos!$E4,lst_frequencia,0)),0)))=0),"●",""))) | G5: =IF(NOT(Planos!$A4<>""),"",IF(COUNTIFS(Programação!$B$4:$B$503,Planos!$A4,Programação!$I$4:$I$503,"Concluído",Programação!$G$4:$G$503,">="&DATE(ano_ref,4,1),Programação!$G$4:$G$503,"<="&EOMONTH(DATE(ano_ref,4,1),0))>0,"✔",IF(AND(ISNUMBER(Planos!$G4),IFERROR(INDEX(lst_frequencia_meses,MATCH(Planos!$E4,lst_frequencia,0)),0)>0,(ano_ref*12+4)-(YEAR(Planos!$G4)*12+MONTH(Planos!$G4))>0,MOD((ano_ref*12+4)-(YEAR(Planos!$G4)*12+MONTH(Planos!$G4)),MAX(1,IFERROR(INDEX(lst_frequencia_meses,MATCH(Planos!$E4,lst_frequencia,0)),0)))=0),"●",""))) | H5: =IF(NOT(Planos!$A4<>""),"",IF(COUNTIFS(Programação!$B$4:$B$503,Planos!$A4,Programação!$I$4:$I$503,"Concluído",Programação!$G$4:$G$503,">="&DATE(ano_ref,5,1),Programação!$G$4:$G$503,"<="&EOMONTH(DATE(ano_ref,5,1),0))>0,"✔",IF(AND(ISNUMBER(Planos!$G4),IFERROR(INDEX(lst_frequencia_meses,MATCH(Planos!$E4,lst_frequencia,0)),0)>0,(ano_ref*12+5)-(YEAR(Planos!$G4)*12+MONTH(Planos!$G4))>0,MOD((ano_ref*12+5)-(YEAR(Planos!$G4)*12+MONTH(Planos!$G4)),MAX(1,IFERROR(INDEX(lst_frequencia_meses,MATCH(Planos!$E4,lst_frequencia,0)),0)))=0),"●",""))) | I5: =IF(NOT(Planos!$A4<>""),"",IF(COUNTIFS(Programação!$B$4:$B$503,Planos!$A4,Programação!$I$4:$I$503,"Concluído",Programação!$G$4:$G$503,">="&DATE(ano_ref,6,1),Programação!$G$4:$G$503,"<="&EOMONTH(DATE(ano_ref,6,1),0))>0,"✔",IF(AND(ISNUMBER(Planos!$G4),IFERROR(INDEX(lst_frequencia_meses,MATCH(Planos!$E4,lst_frequencia,0)),0)>0,(ano_ref*12+6)-(YEAR(Planos!$G4)*12+MONTH(Planos!$G4))>0,MOD((ano_ref*12+6)-(YEAR(Planos!$G4)*12+MONTH(Planos!$G4)),MAX(1,IFERROR(INDEX(lst_frequencia_meses,MATCH(Planos!$E4,lst_frequencia,0)),0)))=0),"●",""))) | J5: =IF(NOT(Planos!$A4<>""),"",IF(COUNTIFS(Programação!$B$4:$B$503,Planos!$A4,Programação!$I$4:$I$503,"Concluído",Programação!$G$4:$G$503,">="&DATE(ano_ref,7,1),Programação!$G$4:$G$503,"<="&EOMONTH(DATE(ano_ref,7,1),0))>0,"✔",IF(AND(ISNUMBER(Planos!$G4),IFERROR(INDEX(lst_frequencia_meses,MATCH(Planos!$E4,lst_frequencia,0)),0)>0,(ano_ref*12+7)-(YEAR(Planos!$G4)*12+MONTH(Planos!$G4))>0,MOD((ano_ref*12+7)-(YEAR(Planos!$G4)*12+MONTH(Planos!$G4)),MAX(1,IFERROR(INDEX(lst_frequencia_meses,MATCH(Planos!$E4,lst_frequencia,0)),0)))=0),"●",""))) | K5: =IF(NOT(Planos!$A4<>""),"",IF(COUNTIFS(Programação!$B$4:$B$503,Planos!$A4,Programação!$I$4:$I$503,"Concluído",Programação!$G$4:$G$503,">="&DATE(ano_ref,8,1),Programação!$G$4:$G$503,"<="&EOMONTH(DATE(ano_ref,8,1),0))>0,"✔",IF(AND(ISNUMBER(Planos!$G4),IFERROR(INDEX(lst_frequencia_meses,MATCH(Planos!$E4,lst_frequencia,0)),0)>0,(ano_ref*12+8)-(YEAR(Planos!$G4)*12+MONTH(Planos!$G4))>0,MOD((ano_ref*12+8)-(YEAR(Planos!$G4)*12+MONTH(Planos!$G4)),MAX(1,IFERROR(INDEX(lst_frequencia_meses,MATCH(Planos!$E4,lst_frequencia,0)),0)))=0),"●",""))) | L5: =IF(NOT(Planos!$A4<>""),"",IF(COUNTIFS(Programação!$B$4:$B$503,Planos!$A4,Programação!$I$4:$I$503,"Concluído",Programação!$G$4:$G$503,">="&DATE(ano_ref,9,1),Programação!$G$4:$G$503,"<="&EOMONTH(DATE(ano_ref,9,1),0))>0,"✔",IF(AND(ISNUMBER(Planos!$G4),IFERROR(INDEX(lst_frequencia_meses,MATCH(Planos!$E4,lst_frequencia,0)),0)>0,(ano_ref*12+9)-(YEAR(Planos!$G4)*12+MONTH(Planos!$G4))>0,MOD((ano_ref*12+9)-(YEAR(Planos!$G4)*12+MONTH(Planos!$G4)),MAX(1,IFERROR(INDEX(lst_frequencia_meses,MATCH(Planos!$E4,lst_frequencia,0)),0)))=0),"●",""))) | M5: =IF(NOT(Planos!$A4<>""),"",IF(COUNTIFS(Programação!$B$4:$B$503,Planos!$A4,Programação!$I$4:$I$503,"Concluído",Programação!$G$4:$G$503,">="&DATE(ano_ref,10,1),Programação!$G$4:$G$503,"<="&EOMONTH(DATE(ano_ref,10,1),0))>0,"✔",IF(AND(ISNUMBER(Planos!$G4),IFERROR(INDEX(lst_frequencia_meses,MATCH(Planos!$E4,lst_frequencia,0)),0)>0,(ano_ref*12+10)-(YEAR(Planos!$G4)*12+MONTH(Planos!$G4))>0,MOD((ano_ref*12+10)-(YEAR(Planos!$G4)*12+MONTH(Planos!$G4)),MAX(1,IFERROR(INDEX(lst_frequencia_meses,MATCH(Planos!$E4,lst_frequencia,0)),0)))=0),"●",""))) | N5: =IF(NOT(Planos!$A4<>""),"",IF(COUNTIFS(Programação!$B$4:$B$503,Planos!$A4,Programação!$I$4:$I$503,"Concluído",Programação!$G$4:$G$503,">="&DATE(ano_ref,11,1),Programação!$G$4:$G$503,"<="&EOMONTH(DATE(ano_ref,11,1),0))>0,"✔",IF(AND(ISNUMBER(Planos!$G4),IFERROR(INDEX(lst_frequencia_meses,MATCH(Planos!$E4,lst_frequencia,0)),0)>0,(ano_ref*12+11)-(YEAR(Planos!$G4)*12+MONTH(Planos!$G4))>0,MOD((ano_ref*12+11)-(YEAR(Planos!$G4)*12+MONTH(Planos!$G4)),MAX(1,IFERROR(INDEX(lst_frequencia_meses,MATCH(Planos!$E4,lst_frequencia,0)),0)))=0),"●",""))) | O5: =IF(NOT(Planos!$A4<>""),"",IF(COUNTIFS(Programação!$B$4:$B$503,Planos!$A4,Programação!$I$4:$I$503,"Concluído",Programação!$G$4:$G$503,">="&DATE(ano_ref,12,1),Programação!$G$4:$G$503,"<="&EOMONTH(DATE(ano_ref,12,1),0))>0,"✔",IF(AND(ISNUMBER(Planos!$G4),IFERROR(INDEX(lst_frequencia_meses,MATCH(Planos!$E4,lst_frequencia,0)),0)>0,(ano_ref*12+12)-(YEAR(Planos!$G4)*12+MONTH(Planos!$G4))>0,MOD((ano_ref*12+12)-(YEAR(Planos!$G4)*12+MONTH(Planos!$G4)),MAX(1,IFERROR(INDEX(lst_frequencia_meses,MATCH(Planos!$E4,lst_frequencia,0)),0)))=0),"●",""))) | P5: =IF(COUNTIF(D5:O5,"✔")+COUNTIF(D5:O5,"●")=0,"",COUNTIF(D5:O5,"✔")/(COUNTIF(D5:O5,"✔")+COUNTIF(D5:O5,"●")))
A6: =IF(Planos!$A5<>"",Planos!A5&"","") | B6: =IF(Planos!$A5<>"",Planos!B5&"","") | C6: =IF(Planos!$A5<>"",Planos!C5&"","") | D6: =IF(NOT(Planos!$A5<>""),"",IF(COUNTIFS(Programação!$B$4:$B$503,Planos!$A5,Programação!$I$4:$I$503,"Concluído",Programação!$G$4:$G$503,">="&DATE(ano_ref,1,1),Programação!$G$4:$G$503,"<="&EOMONTH(DATE(ano_ref,1,1),0))>0,"✔",IF(AND(ISNUMBER(Planos!$G5),IFERROR(INDEX(lst_frequencia_meses,MATCH(Planos!$E5,lst_frequencia,0)),0)>0,(ano_ref*12+1)-(YEAR(Planos!$G5)*12+MONTH(Planos!$G5))>0,MOD((ano_ref*12+1)-(YEAR(Planos!$G5)*12+MONTH(Planos!$G5)),MAX(1,IFERROR(INDEX(lst_frequencia_meses,MATCH(Planos!$E5,lst_frequencia,0)),0)))=0),"●",""))) | E6: =IF(NOT(Planos!$A5<>""),"",IF(COUNTIFS(Programação!$B$4:$B$503,Planos!$A5,Programação!$I$4:$I$503,"Concluído",Programação!$G$4:$G$503,">="&DATE(ano_ref,2,1),Programação!$G$4:$G$503,"<="&EOMONTH(DATE(ano_ref,2,1),0))>0,"✔",IF(AND(ISNUMBER(Planos!$G5),IFERROR(INDEX(lst_frequencia_meses,MATCH(Planos!$E5,lst_frequencia,0)),0)>0,(ano_ref*12+2)-(YEAR(Planos!$G5)*12+MONTH(Planos!$G5))>0,MOD((ano_ref*12+2)-(YEAR(Planos!$G5)*12+MONTH(Planos!$G5)),MAX(1,IFERROR(INDEX(lst_frequencia_meses,MATCH(Planos!$E5,lst_frequencia,0)),0)))=0),"●",""))) | F6: =IF(NOT(Planos!$A5<>""),"",IF(COUNTIFS(Programação!$B$4:$B$503,Planos!$A5,Programação!$I$4:$I$503,"Concluído",Programação!$G$4:$G$503,">="&DATE(ano_ref,3,1),Programação!$G$4:$G$503,"<="&EOMONTH(DATE(ano_ref,3,1),0))>0,"✔",IF(AND(ISNUMBER(Planos!$G5),IFERROR(INDEX(lst_frequencia_meses,MATCH(Planos!$E5,lst_frequencia,0)),0)>0,(ano_ref*12+3)-(YEAR(Planos!$G5)*12+MONTH(Planos!$G5))>0,MOD((ano_ref*12+3)-(YEAR(Planos!$G5)*12+MONTH(Planos!$G5)),MAX(1,IFERROR(INDEX(lst_frequencia_meses,MATCH(Planos!$E5,lst_frequencia,0)),0)))=0),"●",""))) | G6: =IF(NOT(Planos!$A5<>""),"",IF(COUNTIFS(Programação!$B$4:$B$503,Planos!$A5,Programação!$I$4:$I$503,"Concluído",Programação!$G$4:$G$503,">="&DATE(ano_ref,4,1),Programação!$G$4:$G$503,"<="&EOMONTH(DATE(ano_ref,4,1),0))>0,"✔",IF(AND(ISNUMBER(Planos!$G5),IFERROR(INDEX(lst_frequencia_meses,MATCH(Planos!$E5,lst_frequencia,0)),0)>0,(ano_ref*12+4)-(YEAR(Planos!$G5)*12+MONTH(Planos!$G5))>0,MOD((ano_ref*12+4)-(YEAR(Planos!$G5)*12+MONTH(Planos!$G5)),MAX(1,IFERROR(INDEX(lst_frequencia_meses,MATCH(Planos!$E5,lst_frequencia,0)),0)))=0),"●",""))) | H6: =IF(NOT(Planos!$A5<>""),"",IF(COUNTIFS(Programação!$B$4:$B$503,Planos!$A5,Programação!$I$4:$I$503,"Concluído",Programação!$G$4:$G$503,">="&DATE(ano_ref,5,1),Programação!$G$4:$G$503,"<="&EOMONTH(DATE(ano_ref,5,1),0))>0,"✔",IF(AND(ISNUMBER(Planos!$G5),IFERROR(INDEX(lst_frequencia_meses,MATCH(Planos!$E5,lst_frequencia,0)),0)>0,(ano_ref*12+5)-(YEAR(Planos!$G5)*12+MONTH(Planos!$G5))>0,MOD((ano_ref*12+5)-(YEAR(Planos!$G5)*12+MONTH(Planos!$G5)),MAX(1,IFERROR(INDEX(lst_frequencia_meses,MATCH(Planos!$E5,lst_frequencia,0)),0)))=0),"●",""))) | I6: =IF(NOT(Planos!$A5<>""),"",IF(COUNTIFS(Programação!$B$4:$B$503,Planos!$A5,Programação!$I$4:$I$503,"Concluído",Programação!$G$4:$G$503,">="&DATE(ano_ref,6,1),Programação!$G$4:$G$503,"<="&EOMONTH(DATE(ano_ref,6,1),0))>0,"✔",IF(AND(ISNUMBER(Planos!$G5),IFERROR(INDEX(lst_frequencia_meses,MATCH(Planos!$E5,lst_frequencia,0)),0)>0,(ano_ref*12+6)-(YEAR(Planos!$G5)*12+MONTH(Planos!$G5))>0,MOD((ano_ref*12+6)-(YEAR(Planos!$G5)*12+MONTH(Planos!$G5)),MAX(1,IFERROR(INDEX(lst_frequencia_meses,MATCH(Planos!$E5,lst_frequencia,0)),0)))=0),"●",""))) | J6: =IF(NOT(Planos!$A5<>""),"",IF(COUNTIFS(Programação!$B$4:$B$503,Planos!$A5,Programação!$I$4:$I$503,"Concluído",Programação!$G$4:$G$503,">="&DATE(ano_ref,7,1),Programação!$G$4:$G$503,"<="&EOMONTH(DATE(ano_ref,7,1),0))>0,"✔",IF(AND(ISNUMBER(Planos!$G5),IFERROR(INDEX(lst_frequencia_meses,MATCH(Planos!$E5,lst_frequencia,0)),0)>0,(ano_ref*12+7)-(YEAR(Planos!$G5)*12+MONTH(Planos!$G5))>0,MOD((ano_ref*12+7)-(YEAR(Planos!$G5)*12+MONTH(Planos!$G5)),MAX(1,IFERROR(INDEX(lst_frequencia_meses,MATCH(Planos!$E5,lst_frequencia,0)),0)))=0),"●",""))) | K6: =IF(NOT(Planos!$A5<>""),"",IF(COUNTIFS(Programação!$B$4:$B$503,Planos!$A5,Programação!$I$4:$I$503,"Concluído",Programação!$G$4:$G$503,">="&DATE(ano_ref,8,1),Programação!$G$4:$G$503,"<="&EOMONTH(DATE(ano_ref,8,1),0))>0,"✔",IF(AND(ISNUMBER(Planos!$G5),IFERROR(INDEX(lst_frequencia_meses,MATCH(Planos!$E5,lst_frequencia,0)),0)>0,(ano_ref*12+8)-(YEAR(Planos!$G5)*12+MONTH(Planos!$G5))>0,MOD((ano_ref*12+8)-(YEAR(Planos!$G5)*12+MONTH(Planos!$G5)),MAX(1,IFERROR(INDEX(lst_frequencia_meses,MATCH(Planos!$E5,lst_frequencia,0)),0)))=0),"●",""))) | L6: =IF(NOT(Planos!$A5<>""),"",IF(COUNTIFS(Programação!$B$4:$B$503,Planos!$A5,Programação!$I$4:$I$503,"Concluído",Programação!$G$4:$G$503,">="&DATE(ano_ref,9,1),Programação!$G$4:$G$503,"<="&EOMONTH(DATE(ano_ref,9,1),0))>0,"✔",IF(AND(ISNUMBER(Planos!$G5),IFERROR(INDEX(lst_frequencia_meses,MATCH(Planos!$E5,lst_frequencia,0)),0)>0,(ano_ref*12+9)-(YEAR(Planos!$G5)*12+MONTH(Planos!$G5))>0,MOD((ano_ref*12+9)-(YEAR(Planos!$G5)*12+MONTH(Planos!$G5)),MAX(1,IFERROR(INDEX(lst_frequencia_meses,MATCH(Planos!$E5,lst_frequencia,0)),0)))=0),"●",""))) | M6: =IF(NOT(Planos!$A5<>""),"",IF(COUNTIFS(Programação!$B$4:$B$503,Planos!$A5,Programação!$I$4:$I$503,"Concluído",Programação!$G$4:$G$503,">="&DATE(ano_ref,10,1),Programação!$G$4:$G$503,"<="&EOMONTH(DATE(ano_ref,10,1),0))>0,"✔",IF(AND(ISNUMBER(Planos!$G5),IFERROR(INDEX(lst_frequencia_meses,MATCH(Planos!$E5,lst_frequencia,0)),0)>0,(ano_ref*12+10)-(YEAR(Planos!$G5)*12+MONTH(Planos!$G5))>0,MOD((ano_ref*12+10)-(YEAR(Planos!$G5)*12+MONTH(Planos!$G5)),MAX(1,IFERROR(INDEX(lst_frequencia_meses,MATCH(Planos!$E5,lst_frequencia,0)),0)))=0),"●",""))) | N6: =IF(NOT(Planos!$A5<>""),"",IF(COUNTIFS(Programação!$B$4:$B$503,Planos!$A5,Programação!$I$4:$I$503,"Concluído",Programação!$G$4:$G$503,">="&DATE(ano_ref,11,1),Programação!$G$4:$G$503,"<="&EOMONTH(DATE(ano_ref,11,1),0))>0,"✔",IF(AND(ISNUMBER(Planos!$G5),IFERROR(INDEX(lst_frequencia_meses,MATCH(Planos!$E5,lst_frequencia,0)),0)>0,(ano_ref*12+11)-(YEAR(Planos!$G5)*12+MONTH(Planos!$G5))>0,MOD((ano_ref*12+11)-(YEAR(Planos!$G5)*12+MONTH(Planos!$G5)),MAX(1,IFERROR(INDEX(lst_frequencia_meses,MATCH(Planos!$E5,lst_frequencia,0)),0)))=0),"●",""))) | O6: =IF(NOT(Planos!$A5<>""),"",IF(COUNTIFS(Programação!$B$4:$B$503,Planos!$A5,Programação!$I$4:$I$503,"Concluído",Programação!$G$4:$G$503,">="&DATE(ano_ref,12,1),Programação!$G$4:$G$503,"<="&EOMONTH(DATE(ano_ref,12,1),0))>0,"✔",IF(AND(ISNUMBER(Planos!$G5),IFERROR(INDEX(lst_frequencia_meses,MATCH(Planos!$E5,lst_frequencia,0)),0)>0,(ano_ref*12+12)-(YEAR(Planos!$G5)*12+MONTH(Planos!$G5))>0,MOD((ano_ref*12+12)-(YEAR(Planos!$G5)*12+MONTH(Planos!$G5)),MAX(1,IFERROR(INDEX(lst_frequencia_meses,MATCH(Planos!$E5,lst_frequencia,0)),0)))=0),"●",""))) | P6: =IF(COUNTIF(D6:O6,"✔")+COUNTIF(D6:O6,"●")=0,"",COUNTIF(D6:O6,"✔")/(COUNTIF(D6:O6,"✔")+COUNTIF(D6:O6,"●")))
A7: =IF(Planos!$A6<>"",Planos!A6&"","") | B7: =IF(Planos!$A6<>"",Planos!B6&"","") | C7: =IF(Planos!$A6<>"",Planos!C6&"","") | D7: =IF(NOT(Planos!$A6<>""),"",IF(COUNTIFS(Programação!$B$4:$B$503,Planos!$A6,Programação!$I$4:$I$503,"Concluído",Programação!$G$4:$G$503,">="&DATE(ano_ref,1,1),Programação!$G$4:$G$503,"<="&EOMONTH(DATE(ano_ref,1,1),0))>0,"✔",IF(AND(ISNUMBER(Planos!$G6),IFERROR(INDEX(lst_frequencia_meses,MATCH(Planos!$E6,lst_frequencia,0)),0)>0,(ano_ref*12+1)-(YEAR(Planos!$G6)*12+MONTH(Planos!$G6))>0,MOD((ano_ref*12+1)-(YEAR(Planos!$G6)*12+MONTH(Planos!$G6)),MAX(1,IFERROR(INDEX(lst_frequencia_meses,MATCH(Planos!$E6,lst_frequencia,0)),0)))=0),"●",""))) | E7: =IF(NOT(Planos!$A6<>""),"",IF(COUNTIFS(Programação!$B$4:$B$503,Planos!$A6,Programação!$I$4:$I$503,"Concluído",Programação!$G$4:$G$503,">="&DATE(ano_ref,2,1),Programação!$G$4:$G$503,"<="&EOMONTH(DATE(ano_ref,2,1),0))>0,"✔",IF(AND(ISNUMBER(Planos!$G6),IFERROR(INDEX(lst_frequencia_meses,MATCH(Planos!$E6,lst_frequencia,0)),0)>0,(ano_ref*12+2)-(YEAR(Planos!$G6)*12+MONTH(Planos!$G6))>0,MOD((ano_ref*12+2)-(YEAR(Planos!$G6)*12+MONTH(Planos!$G6)),MAX(1,IFERROR(INDEX(lst_frequencia_meses,MATCH(Planos!$E6,lst_frequencia,0)),0)))=0),"●",""))) | F7: =IF(NOT(Planos!$A6<>""),"",IF(COUNTIFS(Programação!$B$4:$B$503,Planos!$A6,Programação!$I$4:$I$503,"Concluído",Programação!$G$4:$G$503,">="&DATE(ano_ref,3,1),Programação!$G$4:$G$503,"<="&EOMONTH(DATE(ano_ref,3,1),0))>0,"✔",IF(AND(ISNUMBER(Planos!$G6),IFERROR(INDEX(lst_frequencia_meses,MATCH(Planos!$E6,lst_frequencia,0)),0)>0,(ano_ref*12+3)-(YEAR(Planos!$G6)*12+MONTH(Planos!$G6))>0,MOD((ano_ref*12+3)-(YEAR(Planos!$G6)*12+MONTH(Planos!$G6)),MAX(1,IFERROR(INDEX(lst_frequencia_meses,MATCH(Planos!$E6,lst_frequencia,0)),0)))=0),"●",""))) | G7: =IF(NOT(Planos!$A6<>""),"",IF(COUNTIFS(Programação!$B$4:$B$503,Planos!$A6,Programação!$I$4:$I$503,"Concluído",Programação!$G$4:$G$503,">="&DATE(ano_ref,4,1),Programação!$G$4:$G$503,"<="&EOMONTH(DATE(ano_ref,4,1),0))>0,"✔",IF(AND(ISNUMBER(Planos!$G6),IFERROR(INDEX(lst_frequencia_meses,MATCH(Planos!$E6,lst_frequencia,0)),0)>0,(ano_ref*12+4)-(YEAR(Planos!$G6)*12+MONTH(Planos!$G6))>0,MOD((ano_ref*12+4)-(YEAR(Planos!$G6)*12+MONTH(Planos!$G6)),MAX(1,IFERROR(INDEX(lst_frequencia_meses,MATCH(Planos!$E6,lst_frequencia,0)),0)))=0),"●",""))) | H7: =IF(NOT(Planos!$A6<>""),"",IF(COUNTIFS(Programação!$B$4:$B$503,Planos!$A6,Programação!$I$4:$I$503,"Concluído",Programação!$G$4:$G$503,">="&DATE(ano_ref,5,1),Programação!$G$4:$G$503,"<="&EOMONTH(DATE(ano_ref,5,1),0))>0,"✔",IF(AND(ISNUMBER(Planos!$G6),IFERROR(INDEX(lst_frequencia_meses,MATCH(Planos!$E6,lst_frequencia,0)),0)>0,(ano_ref*12+5)-(YEAR(Planos!$G6)*12+MONTH(Planos!$G6))>0,MOD((ano_ref*12+5)-(YEAR(Planos!$G6)*12+MONTH(Planos!$G6)),MAX(1,IFERROR(INDEX(lst_frequencia_meses,MATCH(Planos!$E6,lst_frequencia,0)),0)))=0),"●",""))) | I7: =IF(NOT(Planos!$A6<>""),"",IF(COUNTIFS(Programação!$B$4:$B$503,Planos!$A6,Programação!$I$4:$I$503,"Concluído",Programação!$G$4:$G$503,">="&DATE(ano_ref,6,1),Programação!$G$4:$G$503,"<="&EOMONTH(DATE(ano_ref,6,1),0))>0,"✔",IF(AND(ISNUMBER(Planos!$G6),IFERROR(INDEX(lst_frequencia_meses,MATCH(Planos!$E6,lst_frequencia,0)),0)>0,(ano_ref*12+6)-(YEAR(Planos!$G6)*12+MONTH(Planos!$G6))>0,MOD((ano_ref*12+6)-(YEAR(Planos!$G6)*12+MONTH(Planos!$G6)),MAX(1,IFERROR(INDEX(lst_frequencia_meses,MATCH(Planos!$E6,lst_frequencia,0)),0)))=0),"●",""))) | J7: =IF(NOT(Planos!$A6<>""),"",IF(COUNTIFS(Programação!$B$4:$B$503,Planos!$A6,Programação!$I$4:$I$503,"Concluído",Programação!$G$4:$G$503,">="&DATE(ano_ref,7,1),Programação!$G$4:$G$503,"<="&EOMONTH(DATE(ano_ref,7,1),0))>0,"✔",IF(AND(ISNUMBER(Planos!$G6),IFERROR(INDEX(lst_frequencia_meses,MATCH(Planos!$E6,lst_frequencia,0)),0)>0,(ano_ref*12+7)-(YEAR(Planos!$G6)*12+MONTH(Planos!$G6))>0,MOD((ano_ref*12+7)-(YEAR(Planos!$G6)*12+MONTH(Planos!$G6)),MAX(1,IFERROR(INDEX(lst_frequencia_meses,MATCH(Planos!$E6,lst_frequencia,0)),0)))=0),"●",""))) | K7: =IF(NOT(Planos!$A6<>""),"",IF(COUNTIFS(Programação!$B$4:$B$503,Planos!$A6,Programação!$I$4:$I$503,"Concluído",Programação!$G$4:$G$503,">="&DATE(ano_ref,8,1),Programação!$G$4:$G$503,"<="&EOMONTH(DATE(ano_ref,8,1),0))>0,"✔",IF(AND(ISNUMBER(Planos!$G6),IFERROR(INDEX(lst_frequencia_meses,MATCH(Planos!$E6,lst_frequencia,0)),0)>0,(ano_ref*12+8)-(YEAR(Planos!$G6)*12+MONTH(Planos!$G6))>0,MOD((ano_ref*12+8)-(YEAR(Planos!$G6)*12+MONTH(Planos!$G6)),MAX(1,IFERROR(INDEX(lst_frequencia_meses,MATCH(Planos!$E6,lst_frequencia,0)),0)))=0),"●",""))) | L7: =IF(NOT(Planos!$A6<>""),"",IF(COUNTIFS(Programação!$B$4:$B$503,Planos!$A6,Programação!$I$4:$I$503,"Concluído",Programação!$G$4:$G$503,">="&DATE(ano_ref,9,1),Programação!$G$4:$G$503,"<="&EOMONTH(DATE(ano_ref,9,1),0))>0,"✔",IF(AND(ISNUMBER(Planos!$G6),IFERROR(INDEX(lst_frequencia_meses,MATCH(Planos!$E6,lst_frequencia,0)),0)>0,(ano_ref*12+9)-(YEAR(Planos!$G6)*12+MONTH(Planos!$G6))>0,MOD((ano_ref*12+9)-(YEAR(Planos!$G6)*12+MONTH(Planos!$G6)),MAX(1,IFERROR(INDEX(lst_frequencia_meses,MATCH(Planos!$E6,lst_frequencia,0)),0)))=0),"●",""))) | M7: =IF(NOT(Planos!$A6<>""),"",IF(COUNTIFS(Programação!$B$4:$B$503,Planos!$A6,Programação!$I$4:$I$503,"Concluído",Programação!$G$4:$G$503,">="&DATE(ano_ref,10,1),Programação!$G$4:$G$503,"<="&EOMONTH(DATE(ano_ref,10,1),0))>0,"✔",IF(AND(ISNUMBER(Planos!$G6),IFERROR(INDEX(lst_frequencia_meses,MATCH(Planos!$E6,lst_frequencia,0)),0)>0,(ano_ref*12+10)-(YEAR(Planos!$G6)*12+MONTH(Planos!$G6))>0,MOD((ano_ref*12+10)-(YEAR(Planos!$G6)*12+MONTH(Planos!$G6)),MAX(1,IFERROR(INDEX(lst_frequencia_meses,MATCH(Planos!$E6,lst_frequencia,0)),0)))=0),"●",""))) | N7: =IF(NOT(Planos!$A6<>""),"",IF(COUNTIFS(Programação!$B$4:$B$503,Planos!$A6,Programação!$I$4:$I$503,"Concluído",Programação!$G$4:$G$503,">="&DATE(ano_ref,11,1),Programação!$G$4:$G$503,"<="&EOMONTH(DATE(ano_ref,11,1),0))>0,"✔",IF(AND(ISNUMBER(Planos!$G6),IFERROR(INDEX(lst_frequencia_meses,MATCH(Planos!$E6,lst_frequencia,0)),0)>0,(ano_ref*12+11)-(YEAR(Planos!$G6)*12+MONTH(Planos!$G6))>0,MOD((ano_ref*12+11)-(YEAR(Planos!$G6)*12+MONTH(Planos!$G6)),MAX(1,IFERROR(INDEX(lst_frequencia_meses,MATCH(Planos!$E6,lst_frequencia,0)),0)))=0),"●",""))) | O7: =IF(NOT(Planos!$A6<>""),"",IF(COUNTIFS(Programação!$B$4:$B$503,Planos!$A6,Programação!$I$4:$I$503,"Concluído",Programação!$G$4:$G$503,">="&DATE(ano_ref,12,1),Programação!$G$4:$G$503,"<="&EOMONTH(DATE(ano_ref,12,1),0))>0,"✔",IF(AND(ISNUMBER(Planos!$G6),IFERROR(INDEX(lst_frequencia_meses,MATCH(Planos!$E6,lst_frequencia,0)),0)>0,(ano_ref*12+12)-(YEAR(Planos!$G6)*12+MONTH(Planos!$G6))>0,MOD((ano_ref*12+12)-(YEAR(Planos!$G6)*12+MONTH(Planos!$G6)),MAX(1,IFERROR(INDEX(lst_frequencia_meses,MATCH(Planos!$E6,lst_frequencia,0)),0)))=0),"●",""))) | P7: =IF(COUNTIF(D7:O7,"✔")+COUNTIF(D7:O7,"●")=0,"",COUNTIF(D7:O7,"✔")/(COUNTIF(D7:O7,"✔")+COUNTIF(D7:O7,"●")))
A8: =IF(Planos!$A7<>"",Planos!A7&"","") | B8: =IF(Planos!$A7<>"",Planos!B7&"","") | C8: =IF(Planos!$A7<>"",Planos!C7&"","") | D8: =IF(NOT(Planos!$A7<>""),"",IF(COUNTIFS(Programação!$B$4:$B$503,Planos!$A7,Programação!$I$4:$I$503,"Concluído",Programação!$G$4:$G$503,">="&DATE(ano_ref,1,1),Programação!$G$4:$G$503,"<="&EOMONTH(DATE(ano_ref,1,1),0))>0,"✔",IF(AND(ISNUMBER(Planos!$G7),IFERROR(INDEX(lst_frequencia_meses,MATCH(Planos!$E7,lst_frequencia,0)),0)>0,(ano_ref*12+1)-(YEAR(Planos!$G7)*12+MONTH(Planos!$G7))>0,MOD((ano_ref*12+1)-(YEAR(Planos!$G7)*12+MONTH(Planos!$G7)),MAX(1,IFERROR(INDEX(lst_frequencia_meses,MATCH(Planos!$E7,lst_frequencia,0)),0)))=0),"●",""))) | E8: =IF(NOT(Planos!$A7<>""),"",IF(COUNTIFS(Programação!$B$4:$B$503,Planos!$A7,Programação!$I$4:$I$503,"Concluído",Programação!$G$4:$G$503,">="&DATE(ano_ref,2,1),Programação!$G$4:$G$503,"<="&EOMONTH(DATE(ano_ref,2,1),0))>0,"✔",IF(AND(ISNUMBER(Planos!$G7),IFERROR(INDEX(lst_frequencia_meses,MATCH(Planos!$E7,lst_frequencia,0)),0)>0,(ano_ref*12+2)-(YEAR(Planos!$G7)*12+MONTH(Planos!$G7))>0,MOD((ano_ref*12+2)-(YEAR(Planos!$G7)*12+MONTH(Planos!$G7)),MAX(1,IFERROR(INDEX(lst_frequencia_meses,MATCH(Planos!$E7,lst_frequencia,0)),0)))=0),"●",""))) | F8: =IF(NOT(Planos!$A7<>""),"",IF(COUNTIFS(Programação!$B$4:$B$503,Planos!$A7,Programação!$I$4:$I$503,"Concluído",Programação!$G$4:$G$503,">="&DATE(ano_ref,3,1),Programação!$G$4:$G$503,"<="&EOMONTH(DATE(ano_ref,3,1),0))>0,"✔",IF(AND(ISNUMBER(Planos!$G7),IFERROR(INDEX(lst_frequencia_meses,MATCH(Planos!$E7,lst_frequencia,0)),0)>0,(ano_ref*12+3)-(YEAR(Planos!$G7)*12+MONTH(Planos!$G7))>0,MOD((ano_ref*12+3)-(YEAR(Planos!$G7)*12+MONTH(Planos!$G7)),MAX(1,IFERROR(INDEX(lst_frequencia_meses,MATCH(Planos!$E7,lst_frequencia,0)),0)))=0),"●",""))) | G8: =IF(NOT(Planos!$A7<>""),"",IF(COUNTIFS(Programação!$B$4:$B$503,Planos!$A7,Programação!$I$4:$I$503,"Concluído",Programação!$G$4:$G$503,">="&DATE(ano_ref,4,1),Programação!$G$4:$G$503,"<="&EOMONTH(DATE(ano_ref,4,1),0))>0,"✔",IF(AND(ISNUMBER(Planos!$G7),IFERROR(INDEX(lst_frequencia_meses,MATCH(Planos!$E7,lst_frequencia,0)),0)>0,(ano_ref*12+4)-(YEAR(Planos!$G7)*12+MONTH(Planos!$G7))>0,MOD((ano_ref*12+4)-(YEAR(Planos!$G7)*12+MONTH(Planos!$G7)),MAX(1,IFERROR(INDEX(lst_frequencia_meses,MATCH(Planos!$E7,lst_frequencia,0)),0)))=0),"●",""))) | H8: =IF(NOT(Planos!$A7<>""),"",IF(COUNTIFS(Programação!$B$4:$B$503,Planos!$A7,Programação!$I$4:$I$503,"Concluído",Programação!$G$4:$G$503,">="&DATE(ano_ref,5,1),Programação!$G$4:$G$503,"<="&EOMONTH(DATE(ano_ref,5,1),0))>0,"✔",IF(AND(ISNUMBER(Planos!$G7),IFERROR(INDEX(lst_frequencia_meses,MATCH(Planos!$E7,lst_frequencia,0)),0)>0,(ano_ref*12+5)-(YEAR(Planos!$G7)*12+MONTH(Planos!$G7))>0,MOD((ano_ref*12+5)-(YEAR(Planos!$G7)*12+MONTH(Planos!$G7)),MAX(1,IFERROR(INDEX(lst_frequencia_meses,MATCH(Planos!$E7,lst_frequencia,0)),0)))=0),"●",""))) | I8: =IF(NOT(Planos!$A7<>""),"",IF(COUNTIFS(Programação!$B$4:$B$503,Planos!$A7,Programação!$I$4:$I$503,"Concluído",Programação!$G$4:$G$503,">="&DATE(ano_ref,6,1),Programação!$G$4:$G$503,"<="&EOMONTH(DATE(ano_ref,6,1),0))>0,"✔",IF(AND(ISNUMBER(Planos!$G7),IFERROR(INDEX(lst_frequencia_meses,MATCH(Planos!$E7,lst_frequencia,0)),0)>0,(ano_ref*12+6)-(YEAR(Planos!$G7)*12+MONTH(Planos!$G7))>0,MOD((ano_ref*12+6)-(YEAR(Planos!$G7)*12+MONTH(Planos!$G7)),MAX(1,IFERROR(INDEX(lst_frequencia_meses,MATCH(Planos!$E7,lst_frequencia,0)),0)))=0),"●",""))) | J8: =IF(NOT(Planos!$A7<>""),"",IF(COUNTIFS(Programação!$B$4:$B$503,Planos!$A7,Programação!$I$4:$I$503,"Concluído",Programação!$G$4:$G$503,">="&DATE(ano_ref,7,1),Programação!$G$4:$G$503,"<="&EOMONTH(DATE(ano_ref,7,1),0))>0,"✔",IF(AND(ISNUMBER(Planos!$G7),IFERROR(INDEX(lst_frequencia_meses,MATCH(Planos!$E7,lst_frequencia,0)),0)>0,(ano_ref*12+7)-(YEAR(Planos!$G7)*12+MONTH(Planos!$G7))>0,MOD((ano_ref*12+7)-(YEAR(Planos!$G7)*12+MONTH(Planos!$G7)),MAX(1,IFERROR(INDEX(lst_frequencia_meses,MATCH(Planos!$E7,lst_frequencia,0)),0)))=0),"●",""))) | K8: =IF(NOT(Planos!$A7<>""),"",IF(COUNTIFS(Programação!$B$4:$B$503,Planos!$A7,Programação!$I$4:$I$503,"Concluído",Programação!$G$4:$G$503,">="&DATE(ano_ref,8,1),Programação!$G$4:$G$503,"<="&EOMONTH(DATE(ano_ref,8,1),0))>0,"✔",IF(AND(ISNUMBER(Planos!$G7),IFERROR(INDEX(lst_frequencia_meses,MATCH(Planos!$E7,lst_frequencia,0)),0)>0,(ano_ref*12+8)-(YEAR(Planos!$G7)*12+MONTH(Planos!$G7))>0,MOD((ano_ref*12+8)-(YEAR(Planos!$G7)*12+MONTH(Planos!$G7)),MAX(1,IFERROR(INDEX(lst_frequencia_meses,MATCH(Planos!$E7,lst_frequencia,0)),0)))=0),"●",""))) | L8: =IF(NOT(Planos!$A7<>""),"",IF(COUNTIFS(Programação!$B$4:$B$503,Planos!$A7,Programação!$I$4:$I$503,"Concluído",Programação!$G$4:$G$503,">="&DATE(ano_ref,9,1),Programação!$G$4:$G$503,"<="&EOMONTH(DATE(ano_ref,9,1),0))>0,"✔",IF(AND(ISNUMBER(Planos!$G7),IFERROR(INDEX(lst_frequencia_meses,MATCH(Planos!$E7,lst_frequencia,0)),0)>0,(ano_ref*12+9)-(YEAR(Planos!$G7)*12+MONTH(Planos!$G7))>0,MOD((ano_ref*12+9)-(YEAR(Planos!$G7)*12+MONTH(Planos!$G7)),MAX(1,IFERROR(INDEX(lst_frequencia_meses,MATCH(Planos!$E7,lst_frequencia,0)),0)))=0),"●",""))) | M8: =IF(NOT(Planos!$A7<>""),"",IF(COUNTIFS(Programação!$B$4:$B$503,Planos!$A7,Programação!$I$4:$I$503,"Concluído",Programação!$G$4:$G$503,">="&DATE(ano_ref,10,1),Programação!$G$4:$G$503,"<="&EOMONTH(DATE(ano_ref,10,1),0))>0,"✔",IF(AND(ISNUMBER(Planos!$G7),IFERROR(INDEX(lst_frequencia_meses,MATCH(Planos!$E7,lst_frequencia,0)),0)>0,(ano_ref*12+10)-(YEAR(Planos!$G7)*12+MONTH(Planos!$G7))>0,MOD((ano_ref*12+10)-(YEAR(Planos!$G7)*12+MONTH(Planos!$G7)),MAX(1,IFERROR(INDEX(lst_frequencia_meses,MATCH(Planos!$E7,lst_frequencia,0)),0)))=0),"●",""))) | N8: =IF(NOT(Planos!$A7<>""),"",IF(COUNTIFS(Programação!$B$4:$B$503,Planos!$A7,Programação!$I$4:$I$503,"Concluído",Programação!$G$4:$G$503,">="&DATE(ano_ref,11,1),Programação!$G$4:$G$503,"<="&EOMONTH(DATE(ano_ref,11,1),0))>0,"✔",IF(AND(ISNUMBER(Planos!$G7),IFERROR(INDEX(lst_frequencia_meses,MATCH(Planos!$E7,lst_frequencia,0)),0)>0,(ano_ref*12+11)-(YEAR(Planos!$G7)*12+MONTH(Planos!$G7))>0,MOD((ano_ref*12+11)-(YEAR(Planos!$G7)*12+MONTH(Planos!$G7)),MAX(1,IFERROR(INDEX(lst_frequencia_meses,MATCH(Planos!$E7,lst_frequencia,0)),0)))=0),"●",""))) | O8: =IF(NOT(Planos!$A7<>""),"",IF(COUNTIFS(Programação!$B$4:$B$503,Planos!$A7,Programação!$I$4:$I$503,"Concluído",Programação!$G$4:$G$503,">="&DATE(ano_ref,12,1),Programação!$G$4:$G$503,"<="&EOMONTH(DATE(ano_ref,12,1),0))>0,"✔",IF(AND(ISNUMBER(Planos!$G7),IFERROR(INDEX(lst_frequencia_meses,MATCH(Planos!$E7,lst_frequencia,0)),0)>0,(ano_ref*12+12)-(YEAR(Planos!$G7)*12+MONTH(Planos!$G7))>0,MOD((ano_ref*12+12)-(YEAR(Planos!$G7)*12+MONTH(Planos!$G7)),MAX(1,IFERROR(INDEX(lst_frequencia_meses,MATCH(Planos!$E7,lst_frequencia,0)),0)))=0),"●",""))) | P8: =IF(COUNTIF(D8:O8,"✔")+COUNTIF(D8:O8,"●")=0,"",COUNTIF(D8:O8,"✔")/(COUNTIF(D8:O8,"✔")+COUNTIF(D8:O8,"●")))
